Workbook
Name Element: 'Infrastructure Benchmarks'!$O$2:$O$349
Name Project: 'Infrastructure Benchmarks'!$G$2:$G$349
Name ROW_Rate: 'Infrastructure Benchmarks'!$Q$2:$Q$349

Sheet Infrastructure Benchmarks
B1: Asset | C1: Country | D1: City | E1: Area | F1: Alias | G1: Project | H1: Employer | I1: Contractor | J1: Status | K1: Contract | L1: Right of Way Area | M1: GLA | N1: GFA | O1: Element | P1: Total Cost | Q1: ROW Rate | R1: GLA Rate | S1: GFA Rate | T1: FAR (GFA/GLA) | U1: ROW/GLA | V1: Year | W1: CHART
A2: 101 | B2: Residential | C2: United Arab Emirates | D2: Abu Dhabi | E2: Saih Al Sidirah | F2: Project 16.1 | G2: Al Ghadeer | H2: Aldar | I2: Nael & Bin Harmal Hydroexport | J2: Award | K2: Lump Sum | L2: 100434 | M2: 223475 | N2: 150223 | O2: Preliminaries | P2: 3229230 | Q2: =$P2/L2 -> 32.152757 | R2: =$P2/M2 -> 14.450073 | S2: =$P2/N2 -> 21.496242 | T2: =N2/M2 -> 0.67221389 | U2: =L2/M2 -> 0.4494194 | V2: 2016 | W2: NO
A3: 102 | B3: Residential | C3: United Arab Emirates | D3: Abu Dhabi | E3: Saih Al Sidirah | F3: Project 16.1 | G3: Al Ghadeer | H3: Aldar | I3: Nael & Bin Harmal Hydroexport | J3: Award | K3: Lump Sum | L3: 100434 | M3: 223475 | N3: 150223 | O3: Ground Investigation | P3: 0 | Q3: =$P3/L3 -> 0 | R3: =$P3/M3 -> 0 | S3: =$P3/N3 -> 0 | T3: =N3/M3 -> 0.67221389 | U3: =L3/M3 -> 0.4494194 | V3: 2016 | W3: NO
A4: 103 | B4: Residential | C4: United Arab Emirates | D4: Abu Dhabi | E4: Saih Al Sidirah | F4: Project 16.1 | G4: Al Ghadeer | H4: Aldar | I4: Nael & Bin Harmal Hydroexport | J4: Award | K4: Lump Sum | L4: 100434 | M4: 223475 | N4: 150223 | O4: Demolition & Site Clearance | P4: 0 | Q4: =$P4/L4 -> 0 | R4: =$P4/M4 -> 0 | S4: =$P4/N4 -> 0 | T4: =N4/M4 -> 0.67221389 | U4: =L4/M4 -> 0.4494194 | V4: 2016 | W4: NO
A5: 104 | B5: Residential | C5: United Arab Emirates | D5: Abu Dhabi | E5: Saih Al Sidirah | F5: Project 16.1 | G5: Al Ghadeer | H5: Aldar | I5: Nael & Bin Harmal Hydroexport | J5: Award | K5: Lump Sum | L5: 100434 | M5: 223475 | N5: 150223 | O5: Earthworks | P5: 1306500 | Q5: =$P5/L5 -> 13.008543 | R5: =$P5/M5 -> 5.8462915 | S5: =$P5/N5 -> 8.6970704 | T5: =N5/M5 -> 0.67221389 | U5: =L5/M5 -> 0.4494194 | V5: 2016 | W5: NO
A6: 105 | B6: Residential | C6: United Arab Emirates | D6: Abu Dhabi | E6: Saih Al Sidirah | F6: Project 16.1 | G6: Al Ghadeer | H6: Aldar | I6: Nael & Bin Harmal Hydroexport | J6: Award | K6: Lump Sum | L6: 100434 | M6: 223475 | N6: 150223 | O6: Sewerage | P6: 6087803 | Q6: =$P6/L6 -> 60.614961 | R6: =$P6/M6 -> 27.241539 | S6: =$P6/N6 -> 40.525106 | T6: =N6/M6 -> 0.67221389 | U6: =L6/M6 -> 0.4494194 | V6: 2016 | W6: NO
A7: 106 | B7: Residential | C7: United Arab Emirates | D7: Abu Dhabi | E7: Saih Al Sidirah | F7: Project 16.1 | G7: Al Ghadeer | H7: Aldar | I7: Nael & Bin Harmal Hydroexport | J7: Award | K7: Lump Sum | L7: 100434 | M7: 223475 | N7: 150223 | O7: Stormwater | P7: 4303883 | Q7: =$P7/L7 -> 42.852849 | R7: =$P7/M7 -> 19.258901 | S7: =$P7/N7 -> 28.64996 | T7: =N7/M7 -> 0.67221389 | U7: =L7/M7 -> 0.4494194 | V7: 2016 | W7: NO
A8: 107 | B8: Residential | C8: United Arab Emirates | D8: Abu Dhabi | E8: Saih Al Sidirah | F8: Project 16.1 | G8: Al Ghadeer | H8: Aldar | I8: Nael & Bin Harmal Hydroexport | J8: Award | K8: Lump Sum | L8: 100434 | M8: 223475 | N8: 150223 | O8: Potable Water | P8: 6258278 | Q8: =$P8/L8 -> 62.312344 | R8: =$P8/M8 -> 28.004376 | S8: =$P8/N8 -> 41.659919 | T8: =N8/M8 -> 0.67221389 | U8: =L8/M8 -> 0.4494194 | V8: 2016 | W8: NO
A9: 108 | B9: Residential | C9: United Arab Emirates | D9: Abu Dhabi | E9: Saih Al Sidirah | F9: Project 16.1 | G9: Al Ghadeer | H9: Aldar | I9: Nael & Bin Harmal Hydroexport | J9: Award | K9: Lump Sum | L9: 100434 | M9: 223475 | N9: 150223 | O9: Irrigation | P9: 1776461 | Q9: =$P9/L9 -> 17.687845 | R9: =$P9/M9 -> 7.9492605 | S9: =$P9/N9 -> 11.825493 | T9: =N9/M9 -> 0.67221389 | U9: =L9/M9 -> 0.4494194 | V9: 2016 | W9: NO
A10: 109 | B10: Residential | C10: United Arab Emirates | D10: Abu Dhabi | E10: Saih Al Sidirah | F10: Project 16.1 | G10: Al Ghadeer | H10: Aldar | I10: Nael & Bin Harmal Hydroexport | J10: Award | K10: Lump Sum | L10: 100434 | M10: 223475 | N10: 150223 | O10: Chilled Water | P10: 0 | Q10: =$P10/L10 -> 0 | R10: =$P10/M10 -> 0 | S10: =$P10/N10 -> 0 | T10: =N10/M10 -> 0.67221389 | U10: =L10/M10 -> 0.4494194 | V10: 2016 | W10: NO
A11: 110 | B11: Residential | C11: United Arab Emirates | D11: Abu Dhabi | E11: Saih Al Sidirah | F11: Project 16.1 | G11: Al Ghadeer | H11: Aldar | I11: Nael & Bin Harmal Hydroexport | J11: Award | K11: Lump Sum | L11: 100434 | M11: 223475 | N11: 150223 | O11: Gas | P11: 1189404 | Q11: =$P11/L11 -> 11.842643 | R11: =$P11/M11 -> 5.3223135 | S11: =$P11/N11 -> 7.9175892 | T11: =N11/M11 -> 0.67221389 | U11: =L11/M11 -> 0.4494194 | V11: 2016 | W11: NO
A12: 111 | B12: Residential | C12: United Arab Emirates | D12: Abu Dhabi | E12: Saih Al Sidirah | F12: Project 16.1 | G12: Al Ghadeer | H12: Aldar | I12: Nael & Bin Harmal Hydroexport | J12: Award | K12: Lump Sum | L12: 100434 | M12: 223475 | N12: 150223 | O12: Electrical | P12: 12406293 | Q12: =$P12/L12 -> 123.52682 | R12: =$P12/M12 -> 55.515351 | S12: =$P12/N12 -> 82.585842 | T12: =N12/M12 -> 0.67221389 | U12: =L12/M12 -> 0.4494194 | V12: 2016 | W12: NO
A13: 112 | B13: Residential | C13: United Arab Emirates | D13: Abu Dhabi | E13: Saih Al Sidirah | F13: Project 16.1 | G13: Al Ghadeer | H13: Aldar | I13: Nael & Bin Harmal Hydroexport | J13: Award | K13: Lump Sum | L13: 100434 | M13: 223475 | N13: 150223 | O13: Telecom | P13: 3548838 | Q13: =$P13/L13 -> 35.335026 | R13: =$P13/M13 -> 15.880246 | S13: =$P13/N13 -> 23.623799 | T13: =N13/M13 -> 0.67221389 | U13: =L13/M13 -> 0.4494194 | V13: 2016 | W13: NO
... A199: 724 | B199: Residential | C199: United Arab Emirates | D199: Dubai | E199: Jebel Ali | F199: Project 22.1 | G199: Al Furjan Package 3 | H199: Nakheel | I199: ASGC | J199: Award | K199: Lump Sum | L199: 76187 | M199: 224528 | N199: 89355 | O199: Roads | P199: 9920837.4 | Q199: =$P199/L199 -> 130.21693 | R199: =$P199/M199 -> 44.185301 | S199: =$P199/N199 -> 111.02722 | T199: =N199/M199 -> 0.39796818 | U199: =L199/M199 -> 0.33932071 | V199: 2021 | W199: YES
A200: 725 | B200: Residential | C200: United Arab Emirates | D200: Dubai | E200: Jebel Ali | F200: Project 22.1 | G200: Al Furjan Package 3 | H200: Nakheel | I200: ASGC | J200: Award | K200: Lump Sum | L200: 76187 | M200: 224528 | N200: 89355 | O200: Streetscape | Q200: =$P200/L200 -> 0 | R200: =$P200/M200 -> 0 | S200: =$P200/N200 -> 0 | T200: =N200/M200 -> 0.39796818 | U200: =L200/M200 -> 0.33932071 | V200: 2021 | W200: YES
A201: 726 | B201: Residential | C201: United Arab Emirates | D201: Dubai | E201: Jebel Ali | F201: Project 22.1 | G201: Al Furjan Package 3 | H201: Nakheel | I201: ASGC | J201: Award | K201: Lump Sum | L201: 76187 | M201: 224528 | N201: 89355 | O201: Public Realm - Open Space | P201: 0 | Q201: =$P201/L201 -> 0 | R201: =$P201/M201 -> 0 | S201: =$P201/N201 -> 0 | T201: =N201/M201 -> 0.39796818 | U201: =L201/M201 -> 0.33932071 | V201: 2021 | W201: YES
A202: 727 | B202: Residential | C202: United Arab Emirates | D202: Dubai | E202: Jebel Ali | F202: Project 22.1 | G202: Al Furjan Package 3 | H202: Nakheel | I202: ASGC | J202: Award | K202: Lump Sum | L202: 76187 | M202: 224528 | N202: 89355 | O202: Public Realm - Park | P202: 0 | Q202: =$P202/L202 -> 0 | R202: =$P202/M202 -> 0 | S202: =$P202/N202 -> 0 | T202: =N202/M202 -> 0.39796818 | U202: =L202/M202 -> 0.33932071 | V202: 2021 | W202: YES
A203: 728 | B203: Residential | C203: United Arab Emirates | D203: Dubai | E203: Jebel Ali | F203: Project 22.1 | G203: Al Furjan Package 3 | H203: Nakheel | I203: ASGC | J203: Award | K203: Lump Sum | L203: 76187 | M203: 224528 | N203: 89355 | O203: Bridges & Tunnels | P203: 0 | Q203: =$P203/L203 -> 0 | R203: =$P203/M203 -> 0 | S203: =$P203/N203 -> 0 | T203: =N203/M203 -> 0.39796818 | U203: =L203/M203 -> 0.33932071 | V203: 2021 | W203: YES
A204: 729 | B204: Residential | C204: United Arab Emirates | D204: Dubai | E204: Jebel Ali | F204: Project 22.1 | G204: Al Furjan Package 3 | H204: Nakheel | I204: ASGC | J204: Award | K204: Lump Sum | L204: 76187 | M204: 224528 | N204: 89355 | O204: Land Reclamation & Marine | P204: 0 | Q204: =$P204/L204 -> 0 | R204: =$P204/M204 -> 0 | S204: =$P204/N204 -> 0 | T204: =N204/M204 -> 0.39796818 | U204: =L204/M204 -> 0.33932071 | V204: 2021 | W204: YES
A205: 801 | B205: Residential | C205: United Arab Emirates | D205: Dubai | E205: Jebel Ali | F205: Project 22.2 | G205: Al Furjan Package 5 | H205: Nakheel | I205: ASGC | J205: Award | K205: Lump Sum | L205: 80570 | M205: 233506 | N205: 79924 | O205: Preliminaries | P205: 6239606.2 | Q205: =$P205/L205 -> 77.443294 | R205: =$P205/M205 -> 26.721396 | S205: =$P205/N205 -> 78.069243 | T205: =N205/M205 -> 0.34227814 | U205: =L205/M205 -> 0.34504467 | V205: 2021 | W205: YES
A206: 802 | B206: Residential | C206: United Arab Emirates | D206: Dubai | E206: Jebel Ali | F206: Project 22.2 | G206: Al Furjan Package 5 | H206: Nakheel | I206: ASGC | J206: Award | K206: Lump Sum | L206: 80570 | M206: 233506 | N206: 79924 | O206: Ground Investigation | P206: 0 | Q206: =$P206/L206 -> 0 | R206: =$P206/M206 -> 0 | S206: =$P206/N206 -> 0 | T206: =N206/M206 -> 0.34227814 | U206: =L206/M206 -> 0.34504467 | V206: 2021 | W206: YES
A207: 803 | B207: Residential | C207: United Arab Emirates | D207: Dubai | E207: Jebel Ali | F207: Project 22.2 | G207: Al Furjan Package 5 | H207: Nakheel | I207: ASGC | J207: Award | K207: Lump Sum | L207: 80570 | M207: 233506 | N207: 79924 | O207: Demolition & Site Clearance | P207: 4120409.2 | Q207: =$P207/L207 -> 51.140738 | R207: =$P207/M207 -> 17.645839 | S207: =$P207/N207 -> 51.554092 | T207: =N207/M207 -> 0.34227814 | U207: =L207/M207 -> 0.34504467 | V207: 2021 | W207: YES
A208: 804 | B208: Residential | C208: United Arab Emirates | D208: Dubai | E208: Jebel Ali | F208: Project 22.2 | G208: Al Furjan Package 5 | H208: Nakheel | I208: ASGC | J208: Award | K208: Lump Sum | L208: 80570 | M208: 233506 | N208: 79924 | O208: Earthworks | P208: 1123818.2 | Q208: =$P208/L208 -> 13.948345 | R208: =$P208/M208 -> 4.8128021 | S208: =$P208/N208 -> 14.061085 | T208: =N208/M208 -> 0.34227814 | U208: =L208/M208 -> 0.34504467 | V208: 2021 | W208: YES
A209: 805 | B209: Residential | C209: United Arab Emirates | D209: Dubai | E209: Jebel Ali | F209: Project 22.2 | G209: Al Furjan Package 5 | H209: Nakheel | I209: ASGC | J209: Award | K209: Lump Sum | L209: 80570 | M209: 233506 | N209: 79924 | O209: Sewerage | P209: 6682238.8 | Q209: =$P209/L209 -> 82.937059 | R209: =$P209/M209 -> 28.61699 | S209: =$P209/N209 -> 83.607413 | T209: =N209/M209 -> 0.34227814 | U209: =L209/M209 -> 0.34504467 | V209: 2021 | W209: YES
A210: 806 | B210: Residential | C210: United Arab Emirates | D210: Dubai | E210: Jebel Ali | F210: Project 22.2 | G210: Al Furjan Package 5 | H210: Nakheel | I210: ASGC | J210: Award | K210: Lump Sum | L210: 80570 | M210: 233506 | N210: 79924 | O210: Stormwater | P210: 8685486 | Q210: =$P210/L210 -> 107.8005 | R210: =$P210/M210 -> 37.195986 | S210: =$P210/N210 -> 108.67181 | T210: =N210/M210 -> 0.34227814 | U210: =L210/M210 -> 0.34504467 | V210: 2021 | W210: YES
A211: 807 | B211: Residential | C211: United Arab Emirates | D211: Dubai | E211: Jebel Ali | F211: Project 22.2 | G211: Al Furjan Package 5 | H211: Nakheel | I211: ASGC | J211: Award | K211: Lump Sum | L211: 80570 | M211: 233506 | N211: 79924 | O211: Potable Water | P211: 11274837 | Q211: =$P211/L211 -> 139.9384 | R211: =$P211/M211 -> 48.284999 | S211: =$P211/N211 -> 141.06948 | T211: =N211/M211 -> 0.34227814 | U211: =L211/M211 -> 0.34504467 | V211: 2021 | W211: YES
A212: 808 | B212: Residential | C212: United Arab Emirates | D212: Dubai | E212: Jebel Ali | F212: Project 22.2 | G212: Al Furjan Package 5 | H212: Nakheel | I212: ASGC | J212: Award | K212: Lump Sum | L212: 80570 | M212: 233506 | N212: 79924 | O212: Irrigation | P212: 8636185.1 | Q212: =$P212/L212 -> 107.18859 | R212: =$P212/M212 -> 36.984853 | S212: =$P212/N212 -> 108.05497 | T212: =N212/M212 -> 0.34227814 | U212: =L212/M212 -> 0.34504467 | V212: 2021 | W212: YES
... A228: 824 | B228: Residential | C228: United Arab Emirates | D228: Dubai | E228: Jebel Ali | F228: Project 22.2 | G228: Al Furjan Package 5 | H228: Nakheel | I228: ASGC | J228: Award | K228: Lump Sum | L228: 80570 | M228: 233506 | N228: 79924 | O228: Roads | P228: 11228730 | Q228: =$P228/L228 -> 139.36614 | R228: =$P228/M228 -> 48.087544 | S228: =$P228/N228 -> 140.49259 | T228: =N228/M228 -> 0.34227814 | U228: =L228/M228 -> 0.34504467 | V228: 2021 | W228: YES
A229: 825 | B229: Residential | C229: United Arab Emirates | D229: Dubai | E229: Jebel Ali | F229: Project 22.2 | G229: Al Furjan Package 5 | H229: Nakheel | I229: ASGC | J229: Award | K229: Lump Sum | L229: 80570 | M229: 233506 | N229: 79924 | O229: Streetscape | Q229: =$P229/L229 -> 0 | R229: =$P229/M229 -> 0 | S229: =$P229/N229 -> 0 | T229: =N229/M229 -> 0.34227814 | U229: =L229/M229 -> 0.34504467 | V229: 2021 | W229: YES
A230: 826 | B230: Residential | C230: United Arab Emirates | D230: Dubai | E230: Jebel Ali | F230: Project 22.2 | G230: Al Furjan Package 5 | H230: Nakheel | I230: ASGC | J230: Award | K230: Lump Sum | L230: 80570 | M230: 233506 | N230: 79924 | O230: Public Realm - Open Space | P230: 0 | Q230: =$P230/L230 -> 0 | R230: =$P230/M230 -> 0 | S230: =$P230/N230 -> 0 | T230: =N230/M230 -> 0.34227814 | U230: =L230/M230 -> 0.34504467 | V230: 2021 | W230: YES
A231: 827 | B231: Residential | C231: United Arab Emirates | D231: Dubai | E231: Jebel Ali | F231: Project 22.2 | G231: Al Furjan Package 5 | H231: Nakheel | I231: ASGC | J231: Award | K231: Lump Sum | L231: 80570 | M231: 233506 | N231: 79924 | O231: Public Realm - Park | P231: 0 | Q231: =$P231/L231 -> 0 | R231: =$P231/M231 -> 0 | S231: =$P231/N231 -> 0 | T231: =N231/M231 -> 0.34227814 | U231: =L231/M231 -> 0.34504467 | V231: 2021 | W231: YES
A232: 828 | B232: Residential | C232: United Arab Emirates | D232: Dubai | E232: Jebel Ali | F232: Project 22.2 | G232: Al Furjan Package 5 | H232: Nakheel | I232: ASGC | J232: Award | K232: Lump Sum | L232: 80570 | M232: 233506 | N232: 79924 | O232: Bridges & Tunnels | P232: 0 | Q232: =$P232/L232 -> 0 | R232: =$P232/M232 -> 0 | S232: =$P232/N232 -> 0 | T232: =N232/M232 -> 0.34227814 | U232: =L232/M232 -> 0.34504467 | V232: 2021 | W232: YES
A233: 829 | B233: Residential | C233: United Arab Emirates | D233: Dubai | E233: Jebel Ali | F233: Project 22.2 | G233: Al Furjan Package 5 | H233: Nakheel | I233: ASGC | J233: Award | K233: Lump Sum | L233: 80570 | M233: 233506 | N233: 79924 | O233: Land Reclamation & Marine | P233: 0 | Q233: =$P233/L233 -> 0 | R233: =$P233/M233 -> 0 | S233: =$P233/N233 -> 0 | T233: =N233/M233 -> 0.34227814 | U233: =L233/M233 -> 0.34504467 | V233: 2021 | W233: YES
A234: 901 | B234: Residential | C234: United Arab Emirates | D234: Dubai | E234: Al Barsha South | F234: Project 23.1 | G234: Dubai Hills Estate | H234: Emaar | I234: Multiple | J234: Award | K234: Lump Sum | L234: 2904714 | M234: 10851011 | N234: 6412481 | O234: Preliminaries | P234: 6.5192526e+08 | Q234: =$P234/L234 -> 224.43699 | R234: =$P234/M234 -> 60.079679 | S234: =$P234/N234 -> 101.66506 | T234: =N234/M234 -> 0.59095701 | U234: =L234/M234 -> 0.26769063 | V234: 2023 | W234: YES
A235: 902 | B235: Residential | C235: United Arab Emirates | D235: Dubai | E235: Al Barsha South | F235: Project 23.1 | G235: Dubai Hills Estate | H235: Emaar | I235: Multiple | J235: Award | K235: Lump Sum | L235: 2904714 | M235: 10851011 | N235: 6412481 | O235: Ground Investigation | P235: 0 | Q235: =$P235/L235 -> 0 | R235: =$P235/M235 -> 0 | S235: =$P235/N235 -> 0 | T235: =N235/M235 -> 0.59095701 | U235: =L235/M235 -> 0.26769063 | V235: 2023 | W235: YES
A236: 903 | B236: Residential | C236: United Arab Emirates | D236: Dubai | E236: Al Barsha South | F236: Project 23.1 | G236: Dubai Hills Estate | H236: Emaar | I236: Multiple | J236: Award | K236: Lump Sum | L236: 2904714 | M236: 10851011 | N236: 6412481 | O236: Demolition & Site Clearance | P236: 70929000 | Q236: =$P236/L236 -> 24.418583 | R236: =$P236/M236 -> 6.5366259 | S236: =$P236/N236 -> 11.061085 | T236: =N236/M236 -> 0.59095701 | U236: =L236/M236 -> 0.26769063 | V236: 2023 | W236: YES
A237: 904 | B237: Residential | C237: United Arab Emirates | D237: Dubai | E237: Al Barsha South | F237: Project 23.1 | G237: Dubai Hills Estate | H237: Emaar | I237: Multiple | J237: Award | K237: Lump Sum | L237: 2904714 | M237: 10851011 | N237: 6412481 | O237: Earthworks | P237: 1.2149271e+08 | Q237: =$P237/L237 -> 41.82605 | R237: =$P237/M237 -> 11.196442 | S237: =$P237/N237 -> 18.946288 | T237: =N237/M237 -> 0.59095701 | U237: =L237/M237 -> 0.26769063 | V237: 2023 | W237: YES
A238: 905 | B238: Residential | C238: United Arab Emirates | D238: Dubai | E238: Al Barsha South | F238: Project 23.1 | G238: Dubai Hills Estate | H238: Emaar | I238: Multiple | J238: Award | K238: Lump Sum | L238: 2904714 | M238: 10851011 | N238: 6412481 | O238: Sewerage | P238: 4.4648258e+08 | Q238: =$P238/L238 -> 153.70965 | R238: =$P238/M238 -> 41.146634 | S238: =$P238/N238 -> 69.62712 | T238: =N238/M238 -> 0.59095701 | U238: =L238/M238 -> 0.26769063 | V238: 2023 | W238: YES
A239: 906 | B239: Residential | C239: United Arab Emirates | D239: Dubai | E239: Al Barsha South | F239: Project 23.1 | G239: Dubai Hills Estate | H239: Emaar | I239: Multiple | J239: Award | K239: Lump Sum | L239: 2904714 | M239: 10851011 | N239: 6412481 | O239: Stormwater | P239: 3.1362699e+08 | Q239: =$P239/L239 -> 107.97173 | R239: =$P239/M239 -> 28.90302 | S239: =$P239/N239 -> 48.908837 | T239: =N239/M239 -> 0.59095701 | U239: =L239/M239 -> 0.26769063 | V239: 2023 | W239: YES
A240: 907 | B240: Residential | C240: United Arab Emirates | D240: Dubai | E240: Al Barsha South | F240: Project 23.1 | G240: Dubai Hills Estate | H240: Emaar | I240: Multiple | J240: Award | K240: Lump Sum | L240: 2904714 | M240: 10851011 | N240: 6412481 | O240: Potable Water | P240: 2.2054716e+08 | Q240: =$P240/L240 -> 75.927323 | R240: =$P240/M240 -> 20.325033 | S240: =$P240/N240 -> 34.393421 | T240: =N240/M240 -> 0.59095701 | U240: =L240/M240 -> 0.26769063 | V240: 2023 | W240: YES
...

Sheet Sheet1
B4: Al Ghadeer | C4: Merief | D4: Nareel Island | E4: West Yas | F4: Precinct G, H & D | G4: Al Jurf | H4: Al Furjan Package 3 | I4: Al Furjan Package 5 | J4: Dubai Hills Estate | K4: PJA Fronds I to P | L4: Ghaf Woods | M4: PJA Spine District
A5: Preliminaries
A6: Ground Investigation
A7: Demolition & Site Clearance
A8: Earthworks
A9: Sewerage
A10: Stormwater
A11: Potable Water
A12: Irrigation
A13: Chilled Water
A14: Gas
A15: Electrical
A16: Telecom
... A33: Land Reclamation & Marine

Sheet Infrastructure Benchmarks-ref
A1: Asset | B1: Country | C1: City | D1: Area | E1: Column1 | F1: Project | G1: Employer | H1: Contractor | I1: Status | J1: Contract | K1: Right of Way Area | L1: GLA | M1: GFA | N1: Element | O1: Total Cost | P1: ROW Rate | Q1: GLA Rate | R1: GFA Rate | S1: Year
A2: Residential | B2: United Arab Emirates | C2: Dubai | D2: Jebel Ali | F2: Fronds I | G2: The Palm Jebel Ali CO. LLC | I2: Tender Return | J2: Lump Sum | N2: Preliminaries | P2: ='Infrastructure Benchmarks-ref'!$O2/'Infrastructure Benchmarks-ref'!$K2 -> #DIV/0! | Q2: ='Infrastructure Benchmarks-ref'!$O2/'Infrastructure Benchmarks-ref'!$L2 -> #DIV/0! | R2: ='Infrastructure Benchmarks-ref'!$O2/'Infrastructure Benchmarks-ref'!$M2 -> #DIV/0!
A3: Residential | B3: United Arab Emirates | C3: Dubai | D3: Jebel Ali | F3: Fronds I | G3: The Palm Jebel Ali CO. LLC | I3: Tender Return | J3: Lump Sum | N3: Ground Investigation | P3: ='Infrastructure Benchmarks-ref'!$O3/'Infrastructure Benchmarks-ref'!$K3 -> #DIV/0! | Q3: ='Infrastructure Benchmarks-ref'!$O3/'Infrastructure Benchmarks-ref'!$L3 -> #DIV/0! | R3: ='Infrastructure Benchmarks-ref'!$O3/'Infrastructure Benchmarks-ref'!$M3 -> #DIV/0!
A4: Residential | B4: United Arab Emirates | C4: Dubai | D4: Jebel Ali | F4: Fronds I | G4: The Palm Jebel Ali CO. LLC | I4: Tender Return | J4: Lump Sum | N4: Demolition & Site Clearance | O4: 29999 | P4: ='Infrastructure Benchmarks-ref'!$O4/'Infrastructure Benchmarks-ref'!$K4 -> #DIV/0! | Q4: ='Infrastructure Benchmarks-ref'!$O4/'Infrastructure Benchmarks-ref'!$L4 -> #DIV/0! | R4: ='Infrastructure Benchmarks-ref'!$O4/'Infrastructure Benchmarks-ref'!$M4 -> #DIV/0!
A5: Residential | B5: United Arab Emirates | C5: Dubai | D5: Jebel Ali | F5: Fronds I | G5: The Palm Jebel Ali CO. LLC | I5: Tender Return | J5: Lump Sum | N5: Earthworks | O5: 3122614 | P5: ='Infrastructure Benchmarks-ref'!$O5/'Infrastructure Benchmarks-ref'!$K5 -> #DIV/0! | Q5: ='Infrastructure Benchmarks-ref'!$O5/'Infrastructure Benchmarks-ref'!$L5 -> #DIV/0! | R5: ='Infrastructure Benchmarks-ref'!$O5/'Infrastructure Benchmarks-ref'!$M5 -> #DIV/0!
A6: Residential | B6: United Arab Emirates | C6: Dubai | D6: Jebel Ali | F6: Fronds I | G6: The Palm Jebel Ali CO. LLC | I6: Tender Return | J6: Lump Sum | N6: Sewerage | O6: =2227597.75+4329962 -> 6557559.8 | P6: ='Infrastructure Benchmarks-ref'!$O6/'Infrastructure Benchmarks-ref'!$K6 -> #DIV/0! | Q6: ='Infrastructure Benchmarks-ref'!$O6/'Infrastructure Benchmarks-ref'!$L6 -> #DIV/0! | R6: ='Infrastructure Benchmarks-ref'!$O6/'Infrastructure Benchmarks-ref'!$M6 -> #DIV/0!
A7: Residential | B7: United Arab Emirates | C7: Dubai | D7: Jebel Ali | F7: Fronds I | G7: The Palm Jebel Ali CO. LLC | I7: Tender Return | J7: Lump Sum | N7: Stormwater | O7: 2781340 | P7: ='Infrastructure Benchmarks-ref'!$O7/'Infrastructure Benchmarks-ref'!$K7 -> #DIV/0! | Q7: ='Infrastructure Benchmarks-ref'!$O7/'Infrastructure Benchmarks-ref'!$L7 -> #DIV/0! | R7: ='Infrastructure Benchmarks-ref'!$O7/'Infrastructure Benchmarks-ref'!$M7 -> #DIV/0!
A8: Residential | B8: United Arab Emirates | C8: Dubai | D8: Jebel Ali | F8: Fronds I | G8: The Palm Jebel Ali CO. LLC | I8: Tender Return | J8: Lump Sum | N8: Potable Water | O8: =3626597+2074818 -> 5701415 | P8: ='Infrastructure Benchmarks-ref'!$O8/'Infrastructure Benchmarks-ref'!$K8 -> #DIV/0! | Q8: ='Infrastructure Benchmarks-ref'!$O8/'Infrastructure Benchmarks-ref'!$L8 -> #DIV/0! | R8: ='Infrastructure Benchmarks-ref'!$O8/'Infrastructure Benchmarks-ref'!$M8 -> #DIV/0!
A9: Residential | B9: United Arab Emirates | C9: Dubai | D9: Jebel Ali | F9: Fronds I | G9: The Palm Jebel Ali CO. LLC | I9: Tender Return | J9: Lump Sum | N9: Irrigation | O9: 1220969 | P9: ='Infrastructure Benchmarks-ref'!$O9/'Infrastructure Benchmarks-ref'!$K9 -> #DIV/0! | Q9: ='Infrastructure Benchmarks-ref'!$O9/'Infrastructure Benchmarks-ref'!$L9 -> #DIV/0! | R9: ='Infrastructure Benchmarks-ref'!$O9/'Infrastructure Benchmarks-ref'!$M9 -> #DIV/0!
A10: Residential | B10: United Arab Emirates | C10: Dubai | D10: Jebel Ali | F10: Fronds I | G10: The Palm Jebel Ali CO. LLC | I10: Tender Return | J10: Lump Sum | N10: Chilled Water | P10: ='Infrastructure Benchmarks-ref'!$O10/'Infrastructure Benchmarks-ref'!$K10 -> #DIV/0! | Q10: ='Infrastructure Benchmarks-ref'!$O10/'Infrastructure Benchmarks-ref'!$L10 -> #DIV/0! | R10: ='Infrastructure Benchmarks-ref'!$O10/'Infrastructure Benchmarks-ref'!$M10 -> #DIV/0!
A11: Residential | B11: United Arab Emirates | C11: Dubai | D11: Jebel Ali | F11: Fronds I | G11: The Palm Jebel Ali CO. LLC | I11: Tender Return | J11: Lump Sum | N11: Gas | O11: =146516+3750000 -> 3896516 | P11: ='Infrastructure Benchmarks-ref'!$O11/'Infrastructure Benchmarks-ref'!$K11 -> #DIV/0! | Q11: ='Infrastructure Benchmarks-ref'!$O11/'Infrastructure Benchmarks-ref'!$L11 -> #DIV/0! | R11: ='Infrastructure Benchmarks-ref'!$O11/'Infrastructure Benchmarks-ref'!$M11 -> #DIV/0!
A12: Residential | B12: United Arab Emirates | C12: Dubai | D12: Jebel Ali | F12: Fronds I | G12: The Palm Jebel Ali CO. LLC | I12: Tender Return | J12: Lump Sum | N12: Electrical | O12: 2493989 | P12: ='Infrastructure Benchmarks-ref'!$O12/'Infrastructure Benchmarks-ref'!$K12 -> #DIV/0! | Q12: ='Infrastructure Benchmarks-ref'!$O12/'Infrastructure Benchmarks-ref'!$L12 -> #DIV/0! | R12: ='Infrastructure Benchmarks-ref'!$O12/'Infrastructure Benchmarks-ref'!$M12 -> #DIV/0!
A13: Residential | B13: United Arab Emirates | C13: Dubai | D13: Jebel Ali | F13: Fronds I | G13: The Palm Jebel Ali CO. LLC | I13: Tender Return | J13: Lump Sum | N13: Telecom | O13: 841204 | P13: ='Infrastructure Benchmarks-ref'!$O13/'Infrastructure Benchmarks-ref'!$K13 -> #DIV/0! | Q13: ='Infrastructure Benchmarks-ref'!$O13/'Infrastructure Benchmarks-ref'!$L13 -> #DIV/0! | R13: ='Infrastructure Benchmarks-ref'!$O13/'Infrastructure Benchmarks-ref'!$M13 -> #DIV/0!
A14: Residential | B14: United Arab Emirates | C14: Dubai | D14: Jebel Ali | F14: Fronds I | G14: The Palm Jebel Ali CO. LLC | I14: Tender Return | J14: Lump Sum | N14: Security | O14: 757152 | P14: ='Infrastructure Benchmarks-ref'!$O14/'Infrastructure Benchmarks-ref'!$K14 -> #DIV/0! | Q14: ='Infrastructure Benchmarks-ref'!$O14/'Infrastructure Benchmarks-ref'!$L14 -> #DIV/0! | R14: ='Infrastructure Benchmarks-ref'!$O14/'Infrastructure Benchmarks-ref'!$M14 -> #DIV/0!
A15: Residential | B15: United Arab Emirates | C15: Dubai | D15: Jebel Ali | F15: Fronds I | G15: The Palm Jebel Ali CO. LLC | I15: Tender Return | J15: Lump Sum | N15: Streetlighting | O15: 1919942 | P15: ='Infrastructure Benchmarks-ref'!$O15/'Infrastructure Benchmarks-ref'!$K15 -> #DIV/0! | Q15: ='Infrastructure Benchmarks-ref'!$O15/'Infrastructure Benchmarks-ref'!$L15 -> #DIV/0! | R15: ='Infrastructure Benchmarks-ref'!$O15/'Infrastructure Benchmarks-ref'!$M15 -> #DIV/0!
A16: Residential | B16: United Arab Emirates | C16: Dubai | D16: Jebel Ali | F16: Fronds I | G16: The Palm Jebel Ali CO. LLC | I16: Tender Return | J16: Lump Sum | N16: Employer's Network | P16: ='Infrastructure Benchmarks-ref'!$O16/'Infrastructure Benchmarks-ref'!$K16 -> #DIV/0! | Q16: ='Infrastructure Benchmarks-ref'!$O16/'Infrastructure Benchmarks-ref'!$L16 -> #DIV/0! | R16: ='Infrastructure Benchmarks-ref'!$O16/'Infrastructure Benchmarks-ref'!$M16 -> #DIV/0!
A17: Residential | B17: United Arab Emirates | C17: Dubai | D17: Jebel Ali | F17: Fronds I | G17: The Palm Jebel Ali CO. LLC | I17: Tender Return | J17: Lump Sum | N17: Offsite Utility Connections | P17: ='Infrastructure Benchmarks-ref'!$O17/'Infrastructure Benchmarks-ref'!$K17 -> #DIV/0! | Q17: ='Infrastructure Benchmarks-ref'!$O17/'Infrastructure Benchmarks-ref'!$L17 -> #DIV/0! | R17: ='Infrastructure Benchmarks-ref'!$O17/'Infrastructure Benchmarks-ref'!$M17 -> #DIV/0!
A18: Residential | B18: United Arab Emirates | C18: Dubai | D18: Jebel Ali | F18: Fronds I | G18: The Palm Jebel Ali CO. LLC | I18: Tender Return | J18: Lump Sum | N18: Sewerage Treatment Plant | P18: ='Infrastructure Benchmarks-ref'!$O18/'Infrastructure Benchmarks-ref'!$K18 -> #DIV/0! | Q18: ='Infrastructure Benchmarks-ref'!$O18/'Infrastructure Benchmarks-ref'!$L18 -> #DIV/0! | R18: ='Infrastructure Benchmarks-ref'!$O18/'Infrastructure Benchmarks-ref'!$M18 -> #DIV/0!
A19: Residential | B19: United Arab Emirates | C19: Dubai | D19: Jebel Ali | F19: Fronds I | G19: The Palm Jebel Ali CO. LLC | I19: Tender Return | J19: Lump Sum | N19: Irrigation Pumping Station | P19: ='Infrastructure Benchmarks-ref'!$O19/'Infrastructure Benchmarks-ref'!$K19 -> #DIV/0! | Q19: ='Infrastructure Benchmarks-ref'!$O19/'Infrastructure Benchmarks-ref'!$L19 -> #DIV/0! | R19: ='Infrastructure Benchmarks-ref'!$O19/'Infrastructure Benchmarks-ref'!$M19 -> #DIV/0!
A20: Residential | B20: United Arab Emirates | C20: Dubai | D20: Jebel Ali | F20: Fronds I | G20: The Palm Jebel Ali CO. LLC | I20: Tender Return | J20: Lump Sum | N20: Potable Water Pumping Station | P20: ='Infrastructure Benchmarks-ref'!$O20/'Infrastructure Benchmarks-ref'!$K20 -> #DIV/0! | Q20: ='Infrastructure Benchmarks-ref'!$O20/'Infrastructure Benchmarks-ref'!$L20 -> #DIV/0! | R20: ='Infrastructure Benchmarks-ref'!$O20/'Infrastructure Benchmarks-ref'!$M20 -> #DIV/0!
A21: Residential | B21: United Arab Emirates | C21: Dubai | D21: Jebel Ali | F21: Fronds I | G21: The Palm Jebel Ali CO. LLC | I21: Tender Return | J21: Lump Sum | N21: District Cooling Plant | P21: ='Infrastructure Benchmarks-ref'!$O21/'Infrastructure Benchmarks-ref'!$K21 -> #DIV/0! | Q21: ='Infrastructure Benchmarks-ref'!$O21/'Infrastructure Benchmarks-ref'!$L21 -> #DIV/0! | R21: ='Infrastructure Benchmarks-ref'!$O21/'Infrastructure Benchmarks-ref'!$M21 -> #DIV/0!
A22: Residential | B22: United Arab Emirates | C22: Dubai | D22: Jebel Ali | F22: Fronds I | G22: The Palm Jebel Ali CO. LLC | I22: Tender Return | J22: Lump Sum | N22: Substation - 132kV | P22: ='Infrastructure Benchmarks-ref'!$O22/'Infrastructure Benchmarks-ref'!$K22 -> #DIV/0! | Q22: ='Infrastructure Benchmarks-ref'!$O22/'Infrastructure Benchmarks-ref'!$L22 -> #DIV/0! | R22: ='Infrastructure Benchmarks-ref'!$O22/'Infrastructure Benchmarks-ref'!$M22 -> #DIV/0!
A23: Residential | B23: United Arab Emirates | C23: Dubai | D23: Jebel Ali | F23: Fronds I | G23: The Palm Jebel Ali CO. LLC | I23: Tender Return | J23: Lump Sum | N23: Substation - 0.4/11-22kV | P23: ='Infrastructure Benchmarks-ref'!$O23/'Infrastructure Benchmarks-ref'!$K23 -> #DIV/0! | Q23: ='Infrastructure Benchmarks-ref'!$O23/'Infrastructure Benchmarks-ref'!$L23 -> #DIV/0! | R23: ='Infrastructure Benchmarks-ref'!$O23/'Infrastructure Benchmarks-ref'!$M23 -> #DIV/0!
A24: Residential | B24: United Arab Emirates | C24: Dubai | D24: Jebel Ali | F24: Fronds I | G24: The Palm Jebel Ali CO. LLC | I24: Tender Return | J24: Lump Sum | N24: Other Utility Buildings | P24: ='Infrastructure Benchmarks-ref'!$O24/'Infrastructure Benchmarks-ref'!$K24 -> #DIV/0! | Q24: ='Infrastructure Benchmarks-ref'!$O24/'Infrastructure Benchmarks-ref'!$L24 -> #DIV/0! | R24: ='Infrastructure Benchmarks-ref'!$O24/'Infrastructure Benchmarks-ref'!$M24 -> #DIV/0!
A25: Residential | B25: United Arab Emirates | C25: Dubai | D25: Jebel Ali | F25: Fronds I | G25: The Palm Jebel Ali CO. LLC | I25: Tender Return | J25: Lump Sum | N25: Roads | O25: =4432975+15979 -> 4448954 | P25: ='Infrastructure Benchmarks-ref'!$O25/'Infrastructure Benchmarks-ref'!$K25 -> #DIV/0! | Q25: ='Infrastructure Benchmarks-ref'!$O25/'Infrastructure Benchmarks-ref'!$L25 -> #DIV/0! | R25: ='Infrastructure Benchmarks-ref'!$O25/'Infrastructure Benchmarks-ref'!$M25 -> #DIV/0!
A26: Residential | B26: United Arab Emirates | C26: Dubai | D26: Jebel Ali | F26: Fronds I | G26: The Palm Jebel Ali CO. LLC | I26: Tender Return | J26: Lump Sum | N26: Streetscape | P26: ='Infrastructure Benchmarks-ref'!$O26/'Infrastructure Benchmarks-ref'!$K26 -> #DIV/0! | Q26: ='Infrastructure Benchmarks-ref'!$O26/'Infrastructure Benchmarks-ref'!$L26 -> #DIV/0! | R26: ='Infrastructure Benchmarks-ref'!$O26/'Infrastructure Benchmarks-ref'!$M26 -> #DIV/0!
A27: Residential | B27: United Arab Emirates | C27: Dubai | D27: Jebel Ali | F27: Fronds I | G27: The Palm Jebel Ali CO. LLC | I27: Tender Return | J27: Lump Sum | N27: Public Realm - Open Space | P27: ='Infrastructure Benchmarks-ref'!$O27/'Infrastructure Benchmarks-ref'!$K27 -> #DIV/0! | Q27: ='Infrastructure Benchmarks-ref'!$O27/'Infrastructure Benchmarks-ref'!$L27 -> #DIV/0! | R27: ='Infrastructure Benchmarks-ref'!$O27/'Infrastructure Benchmarks-ref'!$M27 -> #DIV/0!
A28: Residential | B28: United Arab Emirates | C28: Dubai | D28: Jebel Ali | F28: Fronds I | G28: The Palm Jebel Ali CO. LLC | I28: Tender Return | J28: Lump Sum | N28: Public Realm - Park | P28: ='Infrastructure Benchmarks-ref'!$O28/'Infrastructure Benchmarks-ref'!$K28 -> #DIV/0! | Q28: ='Infrastructure Benchmarks-ref'!$O28/'Infrastructure Benchmarks-ref'!$L28 -> #DIV/0! | R28: ='Infrastructure Benchmarks-ref'!$O28/'Infrastructure Benchmarks-ref'!$M28 -> #DIV/0!
A29: Residential | B29: United Arab Emirates | C29: Dubai | D29: Jebel Ali | F29: Fronds I | G29: The Palm Jebel Ali CO. LLC | I29: Tender Return | J29: Lump Sum | N29: Bridges & Tunnels | P29: ='Infrastructure Benchmarks-ref'!$O29/'Infrastructure Benchmarks-ref'!$K29 -> #DIV/0! | Q29: ='Infrastructure Benchmarks-ref'!$O29/'Infrastructure Benchmarks-ref'!$L29 -> #DIV/0! | R29: ='Infrastructure Benchmarks-ref'!$O29/'Infrastructure Benchmarks-ref'!$M29 -> #DIV/0!
A30: Residential | B30: United Arab Emirates | C30: Dubai | D30: Jebel Ali | F30: Fronds I | G30: The Palm Jebel Ali CO. LLC | I30: Tender Return | J30: Lump Sum | N30: Land Reclamation & Marine | P30: ='Infrastructure Benchmarks-ref'!$O30/'Infrastructure Benchmarks-ref'!$K30 -> #DIV/0! | Q30: ='Infrastructure Benchmarks-ref'!$O30/'Infrastructure Benchmarks-ref'!$L30 -> #DIV/0! | R30: ='Infrastructure Benchmarks-ref'!$O30/'Infrastructure Benchmarks-ref'!$M30 -> #DIV/0!
A32: Residential | B32: United Arab Emirates | C32: Dubai | D32: Jebel Ali | F32: Fronds J | G32: The Palm Jebel Ali CO. LLC | I32: Tender Return | J32: Lump Sum | N32: Potable Water | O32: =3504195+3085106 -> 6589301 | P32: ='Infrastructure Benchmarks-ref'!$O32/'Infrastructure Benchmarks-ref'!$K32 -> #DIV/0! | Q32: ='Infrastructure Benchmarks-ref'!$O32/'Infrastructure Benchmarks-ref'!$L32 -> #DIV/0! | R32: ='Infrastructure Benchmarks-ref'!$O32/'Infrastructure Benchmarks-ref'!$M32 -> #DIV/0!
A33: Residential | B33: United Arab Emirates | C33: Dubai | D33: Jebel Ali | F33: Fronds J | G33: The Palm Jebel Ali CO. LLC | I33: Tender Return | J33: Lump Sum | N33: Irrigation | O33: 2232935 | P33: ='Infrastructure Benchmarks-ref'!$O33/'Infrastructure Benchmarks-ref'!$K33 -> #DIV/0! | Q33: ='Infrastructure Benchmarks-ref'!$O33/'Infrastructure Benchmarks-ref'!$L33 -> #DIV/0! | R33: ='Infrastructure Benchmarks-ref'!$O33/'Infrastructure Benchmarks-ref'!$M33 -> #DIV/0!
A34: Residential | B34: United Arab Emirates | C34: Dubai | D34: Jebel Ali | F34: Fronds J | G34: The Palm Jebel Ali CO. LLC | I34: Tender Return | J34: Lump Sum | N34: Chilled Water | P34: ='Infrastructure Benchmarks-ref'!$O34/'Infrastructure Benchmarks-ref'!$K34 -> #DIV/0! | Q34: ='Infrastructure Benchmarks-ref'!$O34/'Infrastructure Benchmarks-ref'!$L34 -> #DIV/0! | R34: ='Infrastructure Benchmarks-ref'!$O34/'Infrastructure Benchmarks-ref'!$M34 -> #DIV/0!
A35: Residential | B35: United Arab Emirates | C35: Dubai | D35: Jebel Ali | F35: Fronds J | G35: The Palm Jebel Ali CO. LLC | I35: Tender Return | J35: Lump Sum | N35: Gas | O35: =233148+3750000 -> 3983148 | P35: ='Infrastructure Benchmarks-ref'!$O35/'Infrastructure Benchmarks-ref'!$K35 -> #DIV/0! | Q35: ='Infrastructure Benchmarks-ref'!$O35/'Infrastructure Benchmarks-ref'!$L35 -> #DIV/0! | R35: ='Infrastructure Benchmarks-ref'!$O35/'Infrastructure Benchmarks-ref'!$M35 -> #DIV/0!
A36: Residential | B36: United Arab Emirates | C36: Dubai | D36: Jebel Ali | F36: Fronds J | G36: The Palm Jebel Ali CO. LLC | I36: Tender Return | J36: Lump Sum | N36: Electrical | O36: 3804956 | P36: ='Infrastructure Benchmarks-ref'!$O36/'Infrastructure Benchmarks-ref'!$K36 -> #DIV/0! | Q36: ='Infrastructure Benchmarks-ref'!$O36/'Infrastructure Benchmarks-ref'!$L36 -> #DIV/0! | R36: ='Infrastructure Benchmarks-ref'!$O36/'Infrastructure Benchmarks-ref'!$M36 -> #DIV/0!
A37: Residential | B37: United Arab Emirates | C37: Dubai | D37: Jebel Ali | F37: Fronds J | G37: The Palm Jebel Ali CO. LLC | I37: Tender Return | J37: Lump Sum | N37: Telecom | O37: 1299229 | P37: ='Infrastructure Benchmarks-ref'!$O37/'Infrastructure Benchmarks-ref'!$K37 -> #DIV/0! | Q37: ='Infrastructure Benchmarks-ref'!$O37/'Infrastructure Benchmarks-ref'!$L37 -> #DIV/0! | R37: ='Infrastructure Benchmarks-ref'!$O37/'Infrastructure Benchmarks-ref'!$M37 -> #DIV/0!
A38: Residential | B38: United Arab Emirates | C38: Dubai | D38: Jebel Ali | F38: Fronds J | G38: The Palm Jebel Ali CO. LLC | I38: Tender Return | J38: Lump Sum | N38: Security | O38: 1165033 | P38: ='Infrastructure Benchmarks-ref'!$O38/'Infrastructure Benchmarks-ref'!$K38 -> #DIV/0! | Q38: ='Infrastructure Benchmarks-ref'!$O38/'Infrastructure Benchmarks-ref'!$L38 -> #DIV/0! | R38: ='Infrastructure Benchmarks-ref'!$O38/'Infrastructure Benchmarks-ref'!$M38 -> #DIV/0!
A39: Residential | B39: United Arab Emirates | C39: Dubai | D39: Jebel Ali | F39: Fronds J | G39: The Palm Jebel Ali CO. LLC | I39: Tender Return | J39: Lump Sum | N39: Streetlighting | O39: 3121561 | P39: ='Infrastructure Benchmarks-ref'!$O39/'Infrastructure Benchmarks-ref'!$K39 -> #DIV/0! | Q39: ='Infrastructure Benchmarks-ref'!$O39/'Infrastructure Benchmarks-ref'!$L39 -> #DIV/0! | R39: ='Infrastructure Benchmarks-ref'!$O39/'Infrastructure Benchmarks-ref'!$M39 -> #DIV/0!
A40: Residential | B40: United Arab Emirates | C40: Dubai | D40: Jebel Ali | F40: Fronds J | G40: The Palm Jebel Ali CO. LLC | I40: Tender Return | J40: Lump Sum | N40: Employer's Network | P40: ='Infrastructure Benchmarks-ref'!$O40/'Infrastructure Benchmarks-ref'!$K40 -> #DIV/0! | Q40: ='Infrastructure Benchmarks-ref'!$O40/'Infrastructure Benchmarks-ref'!$L40 -> #DIV/0! | R40: ='Infrastructure Benchmarks-ref'!$O40/'Infrastructure Benchmarks-ref'!$M40 -> #DIV/0!
A41: Residential | B41: United Arab Emirates | C41: Dubai | D41: Jebel Ali | F41: Fronds J | G41: The Palm Jebel Ali CO. LLC | I41: Tender Return | J41: Lump Sum | N41: Offsite Utility Connections | P41: ='Infrastructure Benchmarks-ref'!$O41/'Infrastructure Benchmarks-ref'!$K41 -> #DIV/0! | Q41: ='Infrastructure Benchmarks-ref'!$O41/'Infrastructure Benchmarks-ref'!$L41 -> #DIV/0! | R41: ='Infrastructure Benchmarks-ref'!$O41/'Infrastructure Benchmarks-ref'!$M41 -> #DIV/0!
...

Sheet Infrastructure Benchmarks - ref
A1: Asset | B1: Country | C1: City | D1: Area | E1: Column1 | F1: Project | G1: Employer | H1: Contractor | I1: Status | J1: Contract | K1: Right of Way Area | L1: GLA | M1: GFA | N1: Element | O1: Total Cost | P1: ROW Rate | Q1: GLA Rate | R1: GFA Rate | S1: Year
A2: Residential | B2: United Arab Emirates | C2: Abu Dhabi | D2: Ghantoot | E2: Project B | F2: Al Jurf | G2: IMKAN | H2: Nael & Bin Harmal Hydroexport | I2: Award | J2: Lump Sum | K2: 157951 | L2: 557289 | M2: 119039 | N2: Preliminaries | O2: =8271141+1800000 -> 10071141 | P2: ='Infrastructure Benchmarks - ref'!$O2/'Infrastructure Benchmarks - ref'!$K2 -> 63.761173 | Q2: ='Infrastructure Benchmarks - ref'!$O2/'Infrastructure Benchmarks - ref'!$L2 -> 18.071667 | R2: ='Infrastructure Benchmarks - ref'!$O2/'Infrastructure Benchmarks - ref'!$M2 -> 84.60371 | S2: 2019
A3: Residential | B3: United Arab Emirates | C3: Abu Dhabi | D3: Ghantoot | E3: Project B | F3: Al Jurf | G3: IMKAN | H3: Nael & Bin Harmal Hydroexport | I3: Award | J3: Lump Sum | K3: 157951 | L3: 557289 | M3: 119039 | N3: Ground Investigation | O3: 0 | P3: 0 | Q3: 0 | R3: 0 | S3: 2019
A4: Residential | B4: United Arab Emirates | C4: Abu Dhabi | D4: Ghantoot | E4: Project B | F4: Al Jurf | G4: IMKAN | H4: Nael & Bin Harmal Hydroexport | I4: Award | J4: Lump Sum | K4: 157951 | L4: 557289 | M4: 119039 | N4: Demolition & Site Clearance | O4: 2581835 | P4: ='Infrastructure Benchmarks - ref'!$O4/'Infrastructure Benchmarks - ref'!$K4 -> 16.345797 | Q4: ='Infrastructure Benchmarks - ref'!$O4/'Infrastructure Benchmarks - ref'!$L4 -> 4.6328476 | R4: ='Infrastructure Benchmarks - ref'!$O4/'Infrastructure Benchmarks - ref'!$M4 -> 21.688984 | S4: 2019
A5: Residential | B5: United Arab Emirates | C5: Abu Dhabi | D5: Ghantoot | E5: Project B | F5: Al Jurf | G5: IMKAN | H5: Nael & Bin Harmal Hydroexport | I5: Award | J5: Lump Sum | K5: 157951 | L5: 557289 | M5: 119039 | N5: Earthworks | O5: =2470109+588937 -> 3059046 | P5: ='Infrastructure Benchmarks - ref'!$O5/'Infrastructure Benchmarks - ref'!$K5 -> 19.367057 | Q5: ='Infrastructure Benchmarks - ref'!$O5/'Infrastructure Benchmarks - ref'!$L5 -> 5.4891555 | R5: ='Infrastructure Benchmarks - ref'!$O5/'Infrastructure Benchmarks - ref'!$M5 -> 25.697847 | S5: 2019
A6: Residential | B6: United Arab Emirates | C6: Abu Dhabi | D6: Ghantoot | E6: Project B | F6: Al Jurf | G6: IMKAN | H6: Nael & Bin Harmal Hydroexport | I6: Award | J6: Lump Sum | K6: 157951 | L6: 557289 | M6: 119039 | N6: Sewerage | O6: 10577574 | P6: ='Infrastructure Benchmarks - ref'!$O6/'Infrastructure Benchmarks - ref'!$K6 -> 66.967439 | Q6: ='Infrastructure Benchmarks - ref'!$O6/'Infrastructure Benchmarks - ref'!$L6 -> 18.980411 | R6: ='Infrastructure Benchmarks - ref'!$O6/'Infrastructure Benchmarks - ref'!$M6 -> 88.858055 | S6: 2019
A7: Residential | B7: United Arab Emirates | C7: Abu Dhabi | D7: Ghantoot | E7: Project B | F7: Al Jurf | G7: IMKAN | H7: Nael & Bin Harmal Hydroexport | I7: Award | J7: Lump Sum | K7: 157951 | L7: 557289 | M7: 119039 | N7: Stormwater | O7: 12917468 | P7: ='Infrastructure Benchmarks - ref'!$O7/'Infrastructure Benchmarks - ref'!$K7 -> 81.781489 | Q7: ='Infrastructure Benchmarks - ref'!$O7/'Infrastructure Benchmarks - ref'!$L7 -> 23.179119 | R7: ='Infrastructure Benchmarks - ref'!$O7/'Infrastructure Benchmarks - ref'!$M7 -> 108.51459 | S7: 2019
A8: Residential | B8: United Arab Emirates | C8: Abu Dhabi | D8: Ghantoot | E8: Project B | F8: Al Jurf | G8: IMKAN | H8: Nael & Bin Harmal Hydroexport | I8: Award | J8: Lump Sum | K8: 157951 | L8: 557289 | M8: 119039 | N8: Potable Water | O8: =14515264+1154862 -> 15670126 | P8: ='Infrastructure Benchmarks - ref'!$O8/'Infrastructure Benchmarks - ref'!$K8 -> 99.20878 | Q8: ='Infrastructure Benchmarks - ref'!$O8/'Infrastructure Benchmarks - ref'!$L8 -> 28.118491 | R8: ='Infrastructure Benchmarks - ref'!$O8/'Infrastructure Benchmarks - ref'!$M8 -> 131.63859 | S8: 2019
A9: Residential | B9: United Arab Emirates | C9: Abu Dhabi | D9: Ghantoot | E9: Project B | F9: Al Jurf | G9: IMKAN | H9: Nael & Bin Harmal Hydroexport | I9: Award | J9: Lump Sum | K9: 157951 | L9: 557289 | M9: 119039 | N9: Irrigation | O9: =2308327+989147 -> 3297474 | P9: ='Infrastructure Benchmarks - ref'!$O9/'Infrastructure Benchmarks - ref'!$K9 -> 20.876563 | Q9: ='Infrastructure Benchmarks - ref'!$O9/'Infrastructure Benchmarks - ref'!$L9 -> 5.916991 | R9: ='Infrastructure Benchmarks - ref'!$O9/'Infrastructure Benchmarks - ref'!$M9 -> 27.700787 | S9: 2019
A10: Residential | B10: United Arab Emirates | C10: Abu Dhabi | D10: Ghantoot | E10: Project B | F10: Al Jurf | G10: IMKAN | H10: Nael & Bin Harmal Hydroexport | I10: Award | J10: Lump Sum | K10: 157951 | L10: 557289 | M10: 119039 | N10: Chilled Water | O10: 0 | P10: 0 | Q10: 0 | R10: 0 | S10: 2019
A11: Residential | B11: United Arab Emirates | C11: Abu Dhabi | D11: Ghantoot | E11: Project B | F11: Al Jurf | G11: IMKAN | H11: Nael & Bin Harmal Hydroexport | I11: Award | J11: Lump Sum | K11: 157951 | L11: 557289 | M11: 119039 | N11: Gas | O11: 0 | P11: 0 | Q11: 0 | R11: 0 | S11: 2019
A12: Residential | B12: United Arab Emirates | C12: Abu Dhabi | D12: Ghantoot | E12: Project B | F12: Al Jurf | G12: IMKAN | H12: Nael & Bin Harmal Hydroexport | I12: Award | J12: Lump Sum | K12: 157951 | L12: 557289 | M12: 119039 | N12: Electrical | O12: =9592149+5368538 -> 14960687 | P12: ='Infrastructure Benchmarks - ref'!$O12/'Infrastructure Benchmarks - ref'!$K12 -> 94.717267 | Q12: ='Infrastructure Benchmarks - ref'!$O12/'Infrastructure Benchmarks - ref'!$L12 -> 26.845473 | R12: ='Infrastructure Benchmarks - ref'!$O12/'Infrastructure Benchmarks - ref'!$M12 -> 125.67887 | S12: 2019
A13: Residential | B13: United Arab Emirates | C13: Abu Dhabi | D13: Ghantoot | E13: Project B | F13: Al Jurf | G13: IMKAN | H13: Nael & Bin Harmal Hydroexport | I13: Award | J13: Lump Sum | K13: 157951 | L13: 557289 | M13: 119039 | N13: Telecom | O13: =4038113+291267 -> 4329380 | P13: ='Infrastructure Benchmarks - ref'!$O13/'Infrastructure Benchmarks - ref'!$K13 -> 27.40964 | Q13: ='Infrastructure Benchmarks - ref'!$O13/'Infrastructure Benchmarks - ref'!$L13 -> 7.7686443 | R13: ='Infrastructure Benchmarks - ref'!$O13/'Infrastructure Benchmarks - ref'!$M13 -> 36.369425 | S13: 2019
A14: Residential | B14: United Arab Emirates | C14: Abu Dhabi | D14: Ghantoot | E14: Project B | F14: Al Jurf | G14: IMKAN | H14: Nael & Bin Harmal Hydroexport | I14: Award | J14: Lump Sum | K14: 157951 | L14: 557289 | M14: 119039 | N14: Security | O14: 0 | P14: 0 | Q14: 0 | R14: 0 | S14: 2019
A15: Residential | B15: United Arab Emirates | C15: Abu Dhabi | D15: Ghantoot | E15: Project B | F15: Al Jurf | G15: IMKAN | H15: Nael & Bin Harmal Hydroexport | I15: Award | J15: Lump Sum | K15: 157951 | L15: 557289 | M15: 119039 | N15: Streetlighting | O15: 4319911 | P15: ='Infrastructure Benchmarks - ref'!$O15/'Infrastructure Benchmarks - ref'!$K15 -> 27.349691 | Q15: ='Infrastructure Benchmarks - ref'!$O15/'Infrastructure Benchmarks - ref'!$L15 -> 7.7516531 | R15: ='Infrastructure Benchmarks - ref'!$O15/'Infrastructure Benchmarks - ref'!$M15 -> 36.28988 | S15: 2019
A16: Residential | B16: United Arab Emirates | C16: Abu Dhabi | D16: Ghantoot | E16: Project B | F16: Al Jurf | G16: IMKAN | H16: Nael & Bin Harmal Hydroexport | I16: Award | J16: Lump Sum | K16: 157951 | L16: 557289 | M16: 119039 | N16: Employer's Network | O16: 0 | P16: 0 | Q16: 0 | R16: 0 | S16: 2019
A17: Residential | B17: United Arab Emirates | C17: Abu Dhabi | D17: Ghantoot | E17: Project B | F17: Al Jurf | G17: IMKAN | H17: Nael & Bin Harmal Hydroexport | I17: Award | J17: Lump Sum | K17: 157951 | L17: 557289 | M17: 119039 | N17: Offsite Utility Connections | O17: =3968636+10801402 -> 14770038 | P17: ='Infrastructure Benchmarks - ref'!$O17/'Infrastructure Benchmarks - ref'!$K17 -> 93.510253 | Q17: ='Infrastructure Benchmarks - ref'!$O17/'Infrastructure Benchmarks - ref'!$L17 -> 26.503373 | R17: ='Infrastructure Benchmarks - ref'!$O17/'Infrastructure Benchmarks - ref'!$M17 -> 124.0773 | S17: 2019
A18: Residential | B18: United Arab Emirates | C18: Abu Dhabi | D18: Ghantoot | E18: Project B | F18: Al Jurf | G18: IMKAN | H18: Nael & Bin Harmal Hydroexport | I18: Award | J18: Lump Sum | K18: 157951 | L18: 557289 | M18: 119039 | N18: Sewerage Treatment Plant | O18: 3900000 | P18: ='Infrastructure Benchmarks - ref'!$O18/'Infrastructure Benchmarks - ref'!$K18 -> 24.691202 | Q18: ='Infrastructure Benchmarks - ref'!$O18/'Infrastructure Benchmarks - ref'!$L18 -> 6.9981643 | R18: ='Infrastructure Benchmarks - ref'!$O18/'Infrastructure Benchmarks - ref'!$M18 -> 32.762372 | S18: 2019
A19: Residential | B19: United Arab Emirates | C19: Abu Dhabi | D19: Ghantoot | E19: Project B | F19: Al Jurf | G19: IMKAN | H19: Nael & Bin Harmal Hydroexport | I19: Award | J19: Lump Sum | K19: 157951 | L19: 557289 | M19: 119039 | N19: Irrigation Pumping Station | O19: 2700000 | P19: ='Infrastructure Benchmarks - ref'!$O19/'Infrastructure Benchmarks - ref'!$K19 -> 17.093909 | Q19: ='Infrastructure Benchmarks - ref'!$O19/'Infrastructure Benchmarks - ref'!$L19 -> 4.844883 | R19: ='Infrastructure Benchmarks - ref'!$O19/'Infrastructure Benchmarks - ref'!$M19 -> 22.681642 | S19: 2019
A20: Residential | B20: United Arab Emirates | C20: Abu Dhabi | D20: Ghantoot | E20: Project B | F20: Al Jurf | G20: IMKAN | H20: Nael & Bin Harmal Hydroexport | I20: Award | J20: Lump Sum | K20: 157951 | L20: 557289 | M20: 119039 | N20: Potable Water Pumping Station | O20: 0 | P20: 0 | Q20: 0 | R20: 0 | S20: 2019
A21: Residential | B21: United Arab Emirates | C21: Abu Dhabi | D21: Ghantoot | E21: Project B | F21: Al Jurf | G21: IMKAN | H21: Nael & Bin Harmal Hydroexport | I21: Award | J21: Lump Sum | K21: 157951 | L21: 557289 | M21: 119039 | N21: District Cooling Plant | O21: 0 | P21: 0 | Q21: 0 | R21: 0 | S21: 2019
A22: Residential | B22: United Arab Emirates | C22: Abu Dhabi | D22: Ghantoot | E22: Project B | F22: Al Jurf | G22: IMKAN | H22: Nael & Bin Harmal Hydroexport | I22: Award | J22: Lump Sum | K22: 157951 | L22: 557289 | M22: 119039 | N22: Substation - 132kV | O22: 0 | P22: 0 | Q22: 0 | R22: 0 | S22: 2019
A23: Residential | B23: United Arab Emirates | C23: Abu Dhabi | D23: Ghantoot | E23: Project B | F23: Al Jurf | G23: IMKAN | H23: Nael & Bin Harmal Hydroexport | I23: Award | J23: Lump Sum | K23: 157951 | L23: 557289 | M23: 119039 | N23: Substation - 0.4/11-22kV | O23: 9438518 | P23: ='Infrastructure Benchmarks - ref'!$O23/'Infrastructure Benchmarks - ref'!$K23 -> 59.755988 | Q23: ='Infrastructure Benchmarks - ref'!$O23/'Infrastructure Benchmarks - ref'!$L23 -> 16.936487 | R23: ='Infrastructure Benchmarks - ref'!$O23/'Infrastructure Benchmarks - ref'!$M23 -> 79.289292 | S23: 2019
A24: Residential | B24: United Arab Emirates | C24: Abu Dhabi | D24: Ghantoot | E24: Project B | F24: Al Jurf | G24: IMKAN | H24: Nael & Bin Harmal Hydroexport | I24: Award | J24: Lump Sum | K24: 157951 | L24: 557289 | M24: 119039 | N24: Other Utility Buildings | O24: 0 | P24: 0 | Q24: 0 | R24: 0 | S24: 2019
A25: Residential | B25: United Arab Emirates | C25: Abu Dhabi | D25: Ghantoot | E25: Project B | F25: Al Jurf | G25: IMKAN | H25: Nael & Bin Harmal Hydroexport | I25: Award | J25: Lump Sum | K25: 157951 | L25: 557289 | M25: 119039 | N25: Roads | O25: 8852560 | P25: ='Infrastructure Benchmarks - ref'!$O25/'Infrastructure Benchmarks - ref'!$K25 -> 56.046242 | Q25: ='Infrastructure Benchmarks - ref'!$O25/'Infrastructure Benchmarks - ref'!$L25 -> 15.885043 | R25: ='Infrastructure Benchmarks - ref'!$O25/'Infrastructure Benchmarks - ref'!$M25 -> 74.366888 | S25: 2019
A26: Residential | B26: United Arab Emirates | C26: Abu Dhabi | D26: Ghantoot | E26: Project B | F26: Al Jurf | G26: IMKAN | H26: Nael & Bin Harmal Hydroexport | I26: Award | J26: Lump Sum | K26: 157951 | L26: 557289 | M26: 119039 | N26: Streetscape | O26: 30334415 | P26: ='Infrastructure Benchmarks - ref'!$O26/'Infrastructure Benchmarks - ref'!$K26 -> 192.04953 | Q26: ='Infrastructure Benchmarks - ref'!$O26/'Infrastructure Benchmarks - ref'!$L26 -> 54.432108 | R26: ='Infrastructure Benchmarks - ref'!$O26/'Infrastructure Benchmarks - ref'!$M26 -> 254.82754 | S26: 2019
A27: Residential | B27: United Arab Emirates | C27: Abu Dhabi | D27: Ghantoot | E27: Project B | F27: Al Jurf | G27: IMKAN | H27: Nael & Bin Harmal Hydroexport | I27: Estimate | J27: Lump Sum | K27: 157951 | L27: 557289 | M27: 119039 | N27: Public Realm - Open Space | O27: 18545787 | P27: ='Infrastructure Benchmarks - ref'!$O27/'Infrastructure Benchmarks - ref'!$K27 -> 117.41481 | Q27: ='Infrastructure Benchmarks - ref'!$O27/'Infrastructure Benchmarks - ref'!$L27 -> 33.278581 | R27: ='Infrastructure Benchmarks - ref'!$O27/'Infrastructure Benchmarks - ref'!$M27 -> 155.79589 | S27: 2019
A28: Residential | B28: United Arab Emirates | C28: Abu Dhabi | D28: Ghantoot | E28: Project B | F28: Al Jurf | G28: IMKAN | H28: Nael & Bin Harmal Hydroexport | I28: Estimate | J28: Lump Sum | K28: 157951 | L28: 557289 | M28: 119039 | N28: Public Realm - Park | O28: 11519715 | P28: ='Infrastructure Benchmarks - ref'!$O28/'Infrastructure Benchmarks - ref'!$K28 -> 72.932207 | Q28: ='Infrastructure Benchmarks - ref'!$O28/'Infrastructure Benchmarks - ref'!$L28 -> 20.670989 | R28: ='Infrastructure Benchmarks - ref'!$O28/'Infrastructure Benchmarks - ref'!$M28 -> 96.772612 | S28: 2019
A29: Residential | B29: United Arab Emirates | C29: Abu Dhabi | D29: Ghantoot | E29: Project B | F29: Al Jurf | G29: IMKAN | H29: Nael & Bin Harmal Hydroexport | I29: Award | J29: Lump Sum | K29: 157951 | L29: 557289 | M29: 119039 | N29: Bridges & Tunnels | O29: 0 | P29: 0 | Q29: 0 | R29: 0 | S29: 2019
A30: Residential | B30: United Arab Emirates | C30: Abu Dhabi | D30: Ghantoot | E30: Project B | F30: Al Jurf | G30: IMKAN | H30: Nael & Bin Harmal Hydroexport | I30: Award | J30: Lump Sum | K30: 157951 | L30: 557289 | M30: 119039 | N30: Land Reclamation & Marine | O30: 0 | P30: 0 | Q30: 0 | R30: 0 | S30: 2019
A31: Residential | B31: United Arab Emirates | C31: Abu Dhabi | D31: Yas Island | E31: Project H | F31: West Yas | G31: Aldar | H31: Unknown | I31: Award | J31: Lump Sum | K31: 580094 | L31: 2044670 | M31: 710886 | N31: Preliminaries | O31: 19449911 | P31: ='Infrastructure Benchmarks - ref'!$O31/'Infrastructure Benchmarks - ref'!$K31 -> 33.528895 | Q31: ='Infrastructure Benchmarks - ref'!$O31/'Infrastructure Benchmarks - ref'!$L31 -> 9.5124939 | R31: ='Infrastructure Benchmarks - ref'!$O31/'Infrastructure Benchmarks - ref'!$M31 -> 27.360099 | S31: 2016
A32: Residential | B32: United Arab Emirates | C32: Abu Dhabi | D32: Yas Island | E32: Project H | F32: West Yas | G32: Aldar | H32: Unknown | I32: Award | J32: Lump Sum | K32: 580094 | L32: 2044670 | M32: 710886 | N32: Ground Investigation | O32: 0 | P32: 0 | Q32: 0 | R32: 0 | S32: 2016
A33: Residential | B33: United Arab Emirates | C33: Abu Dhabi | D33: Yas Island | E33: Project H | F33: West Yas | G33: Aldar | H33: Unknown | I33: Award | J33: Lump Sum | K33: 580094 | L33: 2044670 | M33: 710886 | N33: Demolition & Site Clearance | O33: 0 | P33: ='Infrastructure Benchmarks - ref'!$O33/'Infrastructure Benchmarks - ref'!$K33 -> 0 | Q33: ='Infrastructure Benchmarks - ref'!$O33/'Infrastructure Benchmarks - ref'!$L33 -> 0 | R33: ='Infrastructure Benchmarks - ref'!$O33/'Infrastructure Benchmarks - ref'!$M33 -> 0 | S33: 2016
A34: Residential | B34: United Arab Emirates | C34: Abu Dhabi | D34: Yas Island | E34: Project H | F34: West Yas | G34: Aldar | H34: Unknown | I34: Award | J34: Lump Sum | K34: 580094 | L34: 2044670 | M34: 710886 | N34: Earthworks | O34: 33077291 | P34: ='Infrastructure Benchmarks - ref'!$O34/'Infrastructure Benchmarks - ref'!$K34 -> 57.020571 | Q34: ='Infrastructure Benchmarks - ref'!$O34/'Infrastructure Benchmarks - ref'!$L34 -> 16.177325 | R34: ='Infrastructure Benchmarks - ref'!$O34/'Infrastructure Benchmarks - ref'!$M34 -> 46.52967 | S34: 2016
A35: Residential | B35: United Arab Emirates | C35: Abu Dhabi | D35: Yas Island | E35: Project H | F35: West Yas | G35: Aldar | H35: Unknown | I35: Award | J35: Lump Sum | K35: 580094 | L35: 2044670 | M35: 710886 | N35: Sewerage | O35: 33797356 | P35: ='Infrastructure Benchmarks - ref'!$O35/'Infrastructure Benchmarks - ref'!$K35 -> 58.261861 | Q35: ='Infrastructure Benchmarks - ref'!$O35/'Infrastructure Benchmarks - ref'!$L35 -> 16.529492 | R35: ='Infrastructure Benchmarks - ref'!$O35/'Infrastructure Benchmarks - ref'!$M35 -> 47.542582 | S35: 2016
A36: Residential | B36: United Arab Emirates | C36: Abu Dhabi | D36: Yas Island | E36: Project H | F36: West Yas | G36: Aldar | H36: Unknown | I36: Award | J36: Lump Sum | K36: 580094 | L36: 2044670 | M36: 710886 | N36: Stormwater | O36: 27138491 | P36: ='Infrastructure Benchmarks - ref'!$O36/'Infrastructure Benchmarks - ref'!$K36 -> 46.78292 | Q36: ='Infrastructure Benchmarks - ref'!$O36/'Infrastructure Benchmarks - ref'!$L36 -> 13.272798 | R36: ='Infrastructure Benchmarks - ref'!$O36/'Infrastructure Benchmarks - ref'!$M36 -> 38.175588 | S36: 2016
A37: Residential | B37: United Arab Emirates | C37: Abu Dhabi | D37: Yas Island | E37: Project H | F37: West Yas | G37: Aldar | H37: Unknown | I37: Award | J37: Lump Sum | K37: 580094 | L37: 2044670 | M37: 710886 | N37: Potable Water | O37: 23519786 | P37: ='Infrastructure Benchmarks - ref'!$O37/'Infrastructure Benchmarks - ref'!$K37 -> 40.544784 | Q37: ='Infrastructure Benchmarks - ref'!$O37/'Infrastructure Benchmarks - ref'!$L37 -> 11.502974 | R37: ='Infrastructure Benchmarks - ref'!$O37/'Infrastructure Benchmarks - ref'!$M37 -> 33.085173 | S37: 2016
A38: Residential | B38: United Arab Emirates | C38: Abu Dhabi | D38: Yas Island | E38: Project H | F38: West Yas | G38: Aldar | H38: Unknown | I38: Award | J38: Lump Sum | K38: 580094 | L38: 2044670 | M38: 710886 | N38: Irrigation | O38: 22532960 | P38: ='Infrastructure Benchmarks - ref'!$O38/'Infrastructure Benchmarks - ref'!$K38 -> 38.843636 | Q38: ='Infrastructure Benchmarks - ref'!$O38/'Infrastructure Benchmarks - ref'!$L38 -> 11.020341 | R38: ='Infrastructure Benchmarks - ref'!$O38/'Infrastructure Benchmarks - ref'!$M38 -> 31.697009 | S38: 2016
A39: Residential | B39: United Arab Emirates | C39: Abu Dhabi | D39: Yas Island | E39: Project H | F39: West Yas | G39: Aldar | H39: Unknown | I39: Award | J39: Lump Sum | K39: 580094 | L39: 2044670 | M39: 710886 | N39: Chilled Water | O39: 0 | P39: 0 | Q39: 0 | R39: 0 | S39: 2016
A40: Residential | B40: United Arab Emirates | C40: Abu Dhabi | D40: Yas Island | E40: Project H | F40: West Yas | G40: Aldar | H40: Unknown | I40: Award | J40: Lump Sum | K40: 580094 | L40: 2044670 | M40: 710886 | N40: Gas | O40: 4878211 | P40: ='Infrastructure Benchmarks - ref'!$O40/'Infrastructure Benchmarks - ref'!$K40 -> 8.4093457 | Q40: ='Infrastructure Benchmarks - ref'!$O40/'Infrastructure Benchmarks - ref'!$L40 -> 2.3858182 | R40: ='Infrastructure Benchmarks - ref'!$O40/'Infrastructure Benchmarks - ref'!$M40 -> 6.8621565 | S40: 2016
...

Sheet Template
A1: Asset | B1: Country | C1: City | D1: Area | E1: Project | F1: Employer | G1: Contractor | H1: Status | I1: Contract | J1: Right of Way Area | K1: GLA | L1: GFA | M1: Element | N1: Total Cost | O1: ROW Rate | P1: GLA Rate | Q1: GFA Rate | R1: Year
A2: Residential | B2: United Arab Emirates | C2: Abu Dhabi | D2: Ghantoot | E2: Al Jurf | F2: IMKAN | G2: Nael & Bin Harmal Hyrdroexport | H2: Award | I2: Lump Sum | J2: 157951 | K2: 557289 | L2: 119039 | M2: Preliminaries | N2: =8271141+1800000 -> 10071141 | O2: =financials345[[#This Row],[Total Cost]]/financials345[[#This Row],[Right of Way Area]] -> 63.761173 | P2: =financials345[[#This Row],[Total Cost]]/financials345[[#This Row],[GLA]] -> 18.071667 | Q2: =financials345[[#This Row],[Total Cost]]/financials345[[#This Row],[GFA]] -> 84.60371 | R2: 2019
A3: Residential | B3: United Arab Emirates | C3: Abu Dhabi | D3: Ghantoot | E3: Al Jurf | F3: IMKAN | G3: Nael & Bin Harmal Hyrdroexport | H3: Award | I3: Lump Sum | J3: 157951 | K3: 557289 | L3: 119039 | M3: Ground Investigation | N3: Included | O3: N/A | P3: N/A | Q3: N/A | R3: 2019
O683: =financials345[[#This Row],[Total Cost]]/financials345[[#This Row],[Right of Way Area]] -> #VALUE!
O684: =financials345[[#This Row],[Total Cost]]/financials345[[#This Row],[Right of Way Area]] -> #VALUE!
O685: =financials345[[#This Row],[Total Cost]]/financials345[[#This Row],[Right of Way Area]] -> #VALUE!
O686: =financials345[[#This Row],[Total Cost]]/financials345[[#This Row],[Right of Way Area]] -> #VALUE!
O687: =financials345[[#This Row],[Total Cost]]/financials345[[#This Row],[Right of Way Area]] -> #VALUE!
O688: =financials345[[#This Row],[Total Cost]]/financials345[[#This Row],[Right of Way Area]] -> #VALUE!
O689: =financials345[[#This Row],[Total Cost]]/financials345[[#This Row],[Right of Way Area]] -> #VALUE!
O690: =financials345[[#This Row],[Total Cost]]/financials345[[#This Row],[Right of Way Area]] -> #VALUE!
O691: =financials345[[#This Row],[Total Cost]]/financials345[[#This Row],[Right of Way Area]] -> #VALUE!
O692: =financials345[[#This Row],[Total Cost]]/financials345[[#This Row],[Right of Way Area]] -> #VALUE!
O693: =financials345[[#This Row],[Total Cost]]/financials345[[#This Row],[Right of Way Area]] -> #VALUE!
O694: =financials345[[#This Row],[Total Cost]]/financials345[[#This Row],[Right of Way Area]] -> #VALUE!
... O737: =financials345[[#This Row],[Total Cost]]/financials345[[#This Row],[Right of Way Area]] -> #VALUE!

Sheet Utility Building Benchmarks
A1: Asset | B1: Country | C1: City | D1: Area | E1: Project | F1: Employer | G1: Contractor | H1: Status | I1: Contract | J1: Element | K1: Total Cost | L1: Year
A2: Mixed Use | B2: United Arab Emirates | C2: Dubai | D2: Downtown | E2: Downtown Dubai | F2: Emaar | G2: Siemens | H2: Award | I2: Lump Sum (D&B) | J2: 132 kV Substation | K2: 59378010 | L2: 2010
A3: Mixed Use | B3: United Arab Emirates | C3: Dubai | D3: Downtown | E3: Downtown Dubai | F3: Emaar | G3: Siemens | H3: Award | I3: Lump Sum (D&B) | J3: 132 kV Substation | K3: 62663785 | L3: 2010
A4: Mixed Use | B4: United Arab Emirates | C4: Dubai | D4: Downtown | E4: Downtown Dubai | F4: Emaar | G4: EEE | H4: Award | I4: Lump Sum (D&B) | J4: 132 kV Substation | K4: 68921078 | L4: 2015
A5: Mixed Use | B5: United Arab Emirates | C5: Dubai | D5: Downtown | E5: Downtown Dubai | F5: Emaar | G5: EEE | H5: Award | I5: Lump Sum (D&B) | J5: 132 kV Substation | K5: 81678186 | L5: 2015
