Workbook

Sheet Data Orig
A3: Average Construction Material Prices
A4: Value in AED
A5: Materials | B5: Quantity | C5: 2018 | D5: 2018 | E5: 2018 | F5: 2018 | G5: 2018 | H5: 2019 | I5: 2019 | J5: 2019 | K5: 2019 | L5: 2019 | M5: 2020 | N5: 2020 | O5: 2020 | P5: 2020 | Q5: 2020 | R5: 2021 | S5: 2021 | T5: 2021 | U5: 2021 | V5: 2021 | W5: 2022 | X5: 2022 | Y5: 2022 | Z5: 2022 | AA5: 2022 | AB5: 2023 | AC5: 2023 | AD5: 2023 | AE5: 2023 | AF5: 2023
C6: Quarter 1 | D6: Quarter 2 | E6: Quarter 3 | F6: Quarter 4 | G6: Year | H6: Quarter 1 | I6: Quarter 2 | J6: Quarter 3 | K6: Quarter 4 | L6: Year | M6: Quarter 1 | N6: Quarter 2 | O6: Quarter 3 | P6: Quarter 4 | Q6: Year | R6: Quarter 1 | S6: Quarter 2 | T6: Quarter 3 | U6: Quarter 4 | V6: Year | W6: Quarter 1 | X6: Quarter 2 | Y6: Quarter 3 | Z6: Quarter 4 | AA6: Year | AB6: Quarter 1 | AC6: Quarter 2 | AD6: Quarter 3 | AE6: Quarter 4 | AF6: Year
A7: Cement
A8: Sulphate Resistance Cement | B8: 50 kg bag | C8: 15.62 | D8: 15.36 | E8: 15.62 | F8: 15.531667 | G8: 15.431687 | H8: 16.41 | I8: 16.14 | J8: 16.14 | K8: 15.89 | L8: 16.15 | M8: 15.69 | N8: 15.27 | O8: 14.79 | P8: 14.79 | Q8: 15.13 | R8: 14.79 | S8: 14.93 | T8: 14.75 | U8: 14.79 | V8: 14.82 | W8: 14.53 | X8: 14.79 | Y8: 15.49 | Z8: 15.66 | AA8: 15.11 | AB8: 15.36 | AC8: 16.23 | AD8: 16.01 | AE8: 15.49 | AF8: 15.77 | AH8: =AF8-C8 -> 0.15 | AI8: =AH8/C8 -> 0.009603073
A9: Portland Cement | B9: 50 kg bag | C9: 14.91 | D9: 14.61 | E9: 14.788333 | F9: 14.496667 | G9: 14.619041 | H9: 14.93 | I9: 14.7 | J9: 14.64 | K9: 14.18 | L9: 14.61 | M9: 14.18 | N9: 14.09 | O9: 13.39 | P9: 13.13 | Q9: 13.7 | R9: 12.96 | S9: 12.34 | T9: 11.81 | U9: 11.11 | V9: 12.06 | W9: 11.15 | X9: 11.46 | Y9: 12.13 | Z9: 12.82 | AA9: 11.89 | AB9: 12.52 | AC9: 13.9 | AD9: 13.72 | AE9: 12.92 | AF9: 13.26 | AH9: =AF9-C9 -> -1.65 | AI9: =AH9/C9 -> -0.11066398
A10: White Cement | B10: 50 kg bag | C10: 35.78 | D10: 35.78 | E10: 35.775714 | F10: 36.175238 | G10: 35.913095 | H10: 36.4 | I10: 36.4 | J10: 36.4 | K10: 36.4 | L10: 36.4 | M10: 36.4 | N10: 36.28 | O10: 35.82 | P10: 35.82 | Q10: 36.04 | R10: 34.71 | S10: 35.35 | T10: 34.94 | U10: 34.83 | V10: 34.96 | W10: 34.83 | X10: 34.53 | Y10: 34.48 | Z10: 34.36 | AA10: 34.55 | AB10: 34.01 | AC10: 34.07 | AD10: 34.3 | AE10: 34.3 | AF10: 34.17 | AH10: =AF10-C10 -> -1.61 | AI10: =AH10/C10 -> -0.044997205
A11: Lime | B11: 20 kg bag | C11: 18.64 | D11: 18.64 | E11: 18.6375 | F11: 18.6375 | G11: 18.6375 | H11: 15.75 | I11: 15.75 | J11: 15.75 | K11: 15.75 | L11: 15.75 | M11: 15.75 | N11: 15.75 | O11: 15.75 | P11: 15.75 | Q11: 15.75 | R11: 15.75 | S11: 15.75 | T11: 15.75 | U11: 15.75 | V11: 15.75 | W11: 15.75 | X11: 15.75 | Y11: 15.75 | Z11: 15.75 | AA11: 15.75 | AB11: 15.75 | AC11: 15.75 | AD11: 15.75 | AE11: 15.75 | AF11: 15.75 | AH11: =AF11-C11 -> -2.89 | AI11: =AH11/C11 -> -0.15504292
A12: Gypsum | B12: 25 kg bag | C12: 9.15 | D12: 9 | E12: 8.9 | F12: 8.8 | G12: 8.9625 | H12: 8.28 | I12: 7.82 | J12: 7.7 | K12: 7.7 | L12: 7.88 | M12: 7.82 | N12: 8.05 | O12: 8.05 | P12: 8.05 | Q12: 7.99 | R12: 8.05 | S12: 8.05 | T12: 8.05 | U12: 8.05 | V12: 8.05 | W12: 8.05 | X12: 8.05 | Y12: 8.05 | Z12: 8.05 | AA12: 8.05 | AB12: 8.05 | AC12: 7.93 | AD12: 7.7 | AE12: 7.7 | AF12: 7.85 | AH12: =AF12-C12 -> -1.3 | AI12: =AH12/C12 -> -0.1420765
A13: Aggregates & Sand | AH13: =AF13-C13 -> 0 | AI13: =AH13/C13 -> #DIV/0!
A14: Aggregates 3/4 | B14: 20 m3 | C14: 1155 | D14: 1254.75 | E14: 1222.375 | F14: 1245.7083 | G14: 1222.7969 | H14: 1207.5 | I14: 1207.5 | J14: 1161.39 | K14: 1138.33 | L14: 1178.68 | M14: 1138.33 | N14: 1115 | O14: 1103.33 | P14: 1097.5 | Q14: 1113.54 | R14: 1091.39 | S14: 1147.78 | T14: 1168.33 | U14: 1168.33 | V14: 1143.96 | W14: 1179.44 | X14: 1223.33 | Y14: 1223.33 | Z14: 1223.33 | AA14: 1212.36 | AB14: 1223.33 | AC14: 1173.33 | AD14: 1190.83 | AE14: 1190.83 | AF14: 1194.58 | AH14: =AF14-C14 -> 39.58 | AI14: =AH14/C14 -> 0.034268398
A15: Aggregates 3/8 | B15: 20 m3 | C15: 1204.88 | D15: 1304.63 | E15: 1304.625 | F15: 1304.625 | G15: 1283.1702 | H15: 1207.5 | I15: 1207.5 | J15: 1161.39 | K15: 1138.33 | L15: 1178.68 | M15: 1138.33 | N15: 1115 | O15: 1103.33 | P15: 1097.5 | Q15: 1113.54 | R15: 1091.39 | S15: 1147.78 | T15: 1168.33 | U15: 1168.33 | V15: 1143.96 | W15: 1179.44 | X15: 1223.33 | Y15: 1223.33 | Z15: 1223.33 | AA15: 1212.36 | AB15: 1223.33 | AC15: 1173.33 | AD15: 1190.83 | AE15: 1190.83 | AF15: 1194.58 | AH15: =AF15-C15 -> -10.3 | AI15: =AH15/C15 -> -0.0085485692
A16: Aggregates 3/16 | B16: 20 m3 | C16: 1325.63 | D16: 1437.19 | E16: 1437.1875 | F16: 1437.1875 | G16: 1413.1287 | H16: 1338.75 | I16: 1338.75 | J16: 1331.69 | K16: 1318.17 | L16: 1331.84 | M16: 1318.17 | N16: 1311.17 | O16: 1307.67 | P16: 1300.67 | Q16: 1309.42 | R16: 1292.22 | S16: 1263.33 | T16: 1341.11 | U16: 1286.67 | V16: 1295.83 | W16: 1296.67 | X16: 1383.33 | Y16: 1383.33 | Z16: 1383.33 | AA16: 1361.67 | AB16: 1383.33 | AC16: 1370 | AD16: 1370 | AE16: 1370 | AF16: 1373.33 | AH16: =AF16-C16 -> 47.7 | AI16: =AH16/C16 -> 0.035982891
A17: Sand / White | B17: 20 m3 | C17: 866.25 | D17: 866.25 | E17: 866.25 | F17: 877.5 | G17: 876.89638 | H17: 840 | I17: 840 | J17: 798.89 | K17: 763.33 | L17: 810.55 | M17: 763.33 | N17: 763.33 | O17: 763.33 | P17: 763.33 | Q17: 763.33 | R17: 793.33 | S17: 805.56 | T17: 830 | U17: 830 | V17: 814.72 | W17: 830 | X17: 793.33 | Y17: 793.33 | Z17: 793.33 | AA17: 802.5 | AB17: 793.33 | AC17: 758.33 | AD17: 770.58 | AE17: 770.58 | AF17: 773.21 | AH17: =AF17-C17 -> -93.04 | AI17: =AH17/C17 -> -0.10740548
A18: Sand / Black | B18: 20 m3 | C18: 984.38 | D18: 1118.94 | E18: 1099.6875 | F18: 1127.6042 | G18: 1091.5532 | H18: 1101.67 | I18: 1101.67 | J18: 1075 | K18: 1061.67 | L18: 1085 | M18: 1061.67 | N18: 1061.67 | O18: 1061.67 | P18: 1061.67 | Q18: 1061.67 | R18: 1085.28 | S18: 1100.83 | T18: 1100.83 | U18: 1100.83 | V18: 1096.94 | W18: 1100.83 | X18: 1116.67 | Y18: 1116.67 | Z18: 1116.67 | AA18: 1112.71 | AB18: 1116.67 | AC18: 1083.33 | AD18: 1083.33 | AE18: 1083.33 | AF18: 1091.67 | AH18: =AF18-C18 -> 107.29 | AI18: =AH18/C18 -> 0.10899246
A19: Sand / Red | B19: 20 m3 | C19: 616.88 | D19: 637.88 | E19: 641 | F19: 716.04167 | G19: 658.52659 | H19: 560.83 | I19: 560.83 | J19: 548.61 | K19: 542.5 | L19: 553.19 | M19: 542.5 | N19: 542.5 | O19: 542.5 | P19: 542.5 | Q19: 542.5 | R19: 601.67 | S19: 601.67 | T19: 601.67 | U19: 626.67 | V19: 607.92 | W19: 626.67 | X19: 606.67 | Y19: 606.67 | Z19: 606.67 | AA19: 611.67 | AB19: 606.67 | AC19: 596.67 | AD19: 596.67 | AE19: 596.67 | AF19: 599.17 | AH19: =AF19-C19 -> -17.71 | AI19: =AH19/C19 -> -0.028708987
A20: Blocks | AH20: =AF20-C20 -> 0 | AI20: =AH20/C20 -> #DIV/0!
A21: Hollow - 4 cm | B21: Piece | C21: 2.52 | D21: 2.52 | E21: 2.5383333 | F21: 2.4683333 | G21: 2.4914468 | H21: 2.18 | I21: 2.18 | J21: 2.18 | K21: 2.18 | L21: 2.18 | M21: 2.11 | N21: 2.02 | O21: 1.93 | P21: 1.93 | Q21: 2 | R21: 1.93 | S21: 1.93 | T21: 1.93 | U21: 1.93 | V21: 1.93 | W21: 1.95 | X21: 2 | Y21: 2 | Z21: 2 | AA21: 1.99 | AB21: 2 | AC21: 2.03 | AD21: 2.07 | AE21: 2.07 | AF21: 2.04 | AH21: =AF21-C21 -> -0.48 | AI21: =AH21/C21 -> -0.19047619
A22: Hollow - 6 cm | B22: Piece | C22: 2.66 | D22: 2.7 | E22: 2.7391667 | F22: 2.6919444 | G22: 2.6911136 | H22: 2.39 | I22: 2.39 | J22: 2.39 | K22: 2.39 | L22: 2.39 | M22: 2.32 | N22: 2.23 | O22: 2.14 | P22: 2.14 | Q22: 2.21 | R22: 2.14 | S22: 2.14 | T22: 2.14 | U22: 2.14 | V22: 2.14 | W22: 2.16 | X22: 2.21 | Y22: 2.21 | Z22: 2.21 | AA22: 2.2 | AB22: 2.21 | AC22: 2.23 | AD22: 2.24 | AE22: 2.24 | AF22: 2.23 | AH22: =AF22-C22 -> -0.43 | AI22: =AH22/C22 -> -0.16165414
A23: Hollow - 8 cm | B23: Piece | C23: 2.87 | D23: 2.91 | E23: 2.9583333 | F23: 2.9405556 | G23: 2.9129618 | H23: 2.6 | I23: 2.6 | J23: 2.6 | K23: 2.6 | L23: 2.6 | M23: 2.55 | N23: 2.46 | O23: 2.35 | P23: 2.35 | Q23: 2.43 | R23: 2.35 | S23: 2.35 | T23: 2.35 | U23: 2.35 | V23: 2.35 | W23: 2.37 | X23: 2.42 | Y23: 2.42 | Z23: 2.42 | AA23: 2.41 | AB23: 2.42 | AC23: 2.45 | AD23: 2.49 | AE23: 2.45 | AF23: 2.45 | AH23: =AF23-C23 -> -0.42 | AI23: =AH23/C23 -> -0.14634146
A24: Solid - 4 cm | B24: Piece | C24: 3.31 | D24: 3.4 | E24: 3.4925 | F24: 3.4216667 | G24: 3.3966775 | H24: 3.23 | I24: 3.23 | J24: 3.23 | K24: 3.23 | L24: 3.23 | M24: 3.16 | N24: 3.06 | O24: 2.94 | P24: 2.94 | Q24: 3.03 | R24: 2.94 | S24: 2.94 | T24: 2.94 | U24: 2.94 | V24: 2.94 | W24: 2.97 | X24: 3.01 | Y24: 3.01 | Z24: 3.01 | AA24: 3 | AB24: 3.01 | AC24: 3.09 | AD24: 3.12 | AE24: 3.12 | AF24: 3.08 | AH24: =AF24-C24 -> -0.23 | AI24: =AH24/C24 -> -0.069486405
A25: Solid - 6 cm | B25: Piece | C25: 3.75 | D25: 3.75 | E25: 3.8333333 | F25: 3.7977778 | G25: 3.7733119 | H25: 3.47 | I25: 3.47 | J25: 3.47 | K25: 3.47 | L25: 3.47 | M25: 3.42 | N25: 3.42 | O25: 3.42 | P25: 3.42 | Q25: 3.42 | R25: 3.42 | S25: 3.42 | T25: 3.42 | U25: 3.42 | V25: 3.42 | W25: 3.42 | X25: 3.42 | Y25: 3.42 | Z25: 3.42 | AA25: 3.42 | AB25: 3.42 | AC25: 3.44 | AD25: 3.42 | AE25: 3.41 | AF25: 3.42 | AH25: =AF25-C25 -> -0.33 | AI25: =AH25/C25 -> -0.088
A26: Solid - 8 cm | B26: Piece | C26: 3.95 | D26: 3.99 | E26: 4.044 | F26: 3.9726667 | G26: 3.9786491 | H26: 3.65 | I26: 3.65 | J26: 3.65 | K26: 3.65 | L26: 3.65 | M26: 3.6 | N26: 3.51 | O26: 3.4 | P26: 3.4 | Q26: 3.48 | R26: 3.4 | S26: 3.4 | T26: 3.4 | U26: 3.4 | V26: 3.4 | W26: 3.42 | X26: 3.47 | Y26: 3.47 | Z26: 3.47 | AA26: 3.46 | AB26: 3.47 | AC26: 3.5 | AD26: 3.54 | AE26: 3.54 | AF26: 3.51 | AH26: =AF26-C26 -> -0.44 | AI26: =AH26/C26 -> -0.11139241
A27: Concrete | AH27: =AF27-C27 -> 0 | AI27: =AH27/C27 -> #DIV/0!
A28: Ready Mix / Normal (neutin 40) | B28: m3 | C28: 263.38 | D28: 263.81 | E28: 263.8125 | F28: 266 | G28: 264.18329 | H28: 266.32 | I28: 253.75 | J28: 251.48 | K28: 248.5 | L28: 255.01 | M28: 246.36 | N28: 236.25 | O28: 231.03 | P28: 229.56 | Q28: 235.8 | R28: 219.27 | S28: 205.64 | T28: 200.03 | U28: 195.95 | V28: 205.22 | W28: 206.12 | X28: 218.38 | Y28: 222.34 | Z28: 226.24 | AA28: 218.27 | AB28: 230.09 | AC28: 240.92 | AD28: 242.35 | AE28: 243.4 | AF28: 239.19 | AH28: =AF28-C28 -> -24.19 | AI28: =AH28/C28 -> -0.091844483
A29: Ready Mix / Sulphate Resistance (neutin 40) | B29: m3 | C29: 267.17 | D29: 267.75 | E29: 267.75 | F29: 267.16667 | G29: 267.39066 | H29: 264.25 | I29: 253.98 | J29: 254.92 | K29: 254.54 | L29: 256.92 | M29: 248.7 | N29: 244.28 | O29: 240.98 | P29: 238.37 | Q29: 243.08 | R29: 231.83 | S29: 211.1 | T29: 203.57 | U29: 198.81 | V29: 211.33 | W29: 213.96 | X29: 229.83 | Y29: 232.87 | Z29: 235.43 | AA29: 228.02 | AB29: 240.55 | AC29: 249.57 | AD29: 239.43 | AE29: 241.66 | AF29: 242.8 | AH29: =AF29-C29 -> -24.37 | AI29: =AH29/C29 -> -0.091215331
A30: Steel | AH30: =AF30-C30 -> 0 | AI30: =AH30/C30 -> #DIV/0!
A31: Steel Bars 6 - 8 mm | B31: Tons | C31: 2699.38 | D31: 2613.52 | E31: 2498.125 | F31: 2303.5467 | G31: 2527.485 | H31: 2353.02 | I31: 2300.38 | J31: 2231.25 | K31: 2086.15 | L31: 2242.7 | M31: 2184 | N31: 2018.75 | O31: 2065 | P31: 2339.17 | Q31: 2151.73 | R31: 2846.55 | S31: 3076.39 | T31: 3054.29 | U31: 2829.87 | V31: 2951.78 | W31: 3103.7 | X31: 3363.89 | Y31: 2689.87 | Z31: 2587.77 | AA31: 2936.31 | AB31: 2825.66 | AC31: 2835.06 | AD31: 2634.05 | AE31: 2713.19 | AF31: 2751.99 | AH31: =AF31-C31 -> 52.61 | AI31: =AH31/C31 -> 0.019489661
A32: Steel Bars 10 - 25 | B32: Tons | C32: 2623.63 | D32: 2567.69 | E32: 2444.4007 | F32: 2246.2303 | G32: 2469.3638 | H32: 2156.03 | I32: 2136.46 | J32: 2089.56 | K32: 2007.4 | L32: 2097.36 | M32: 2073.17 | N32: 1898.02 | O32: 1936.67 | P32: 2181.67 | Q32: 2022.38 | R32: 2735.89 | S32: 2943.68 | T32: 2930.7 | U32: 2703.11 | V32: 2828.35 | W32: 2986.39 | X32: 3233.17 | Y32: 2537.22 | Z32: 2421.54 | AA32: 2794.58 | AB32: 2651.64 | AC32: 2669.23 | AD32: 2502.52 | AE32: 2594.45 | AF32: 2604.46 | AH32: =AF32-C32 -> -19.17 | AI32: =AH32/C32 -> -0.0073066705
A33: B.R.C. Mesh 6 m.m | B33: (8*16) feet | C33: 73.57 | D33: 71.21 | E33: 73.856667 | F33: 65.329667 | G33: 70.959722 | H33: 61.02 | I33: 59.73 | J33: 59.27 | K33: 55.56 | L33: 58.9 | M33: 59.44 | N33: 55.91 | O33: 57.63 | P33: 62.48 | Q33: 58.87 | R33: 76.35 | S33: 81.41 | T33: 79.16 | U33: 74.75 | V33: 77.92 | W33: 76.55 | X33: 82.43 | Y33: 64.71 | Z33: 60.74 | AA33: 71.11 | AB33: 66.21 | AC33: 64.62 | AD33: 61.28 | AE33: 62.66 | AF33: 63.69 | AH33: =AF33-C33 -> -9.88 | AI33: =AH33/C33 -> -0.13429387
A34: B.R.C. Mesh 7 m.m | B34: (8*16) feet | C34: 98.67 | D34: 97.77 | E34: 97.083333 | F34: 93.392222 | G34: 96.853874 | H34: 88.78 | I34: 86.92 | J34: 84.17 | K34: 78.14 | L34: 84.5 | M34: 82.98 | N34: 78.4 | O34: 79.68 | P34: 85.4 | Q34: 81.62 | R34: 102.46 | S34: 112.44 | T34: 112.44 | U34: 109.34 | V34: 109.17 | W34: 106.55 | X34: 115.02 | Y34: 91.7 | Z34: 86.67 | AA34: 99.99 | AB34: 90.7 | AC34: 87.02 | AD34: 81 | AE34: 81.25 | AF34: 84.99 | AH34: =AF34-C34 -> -13.68 | AI34: =AH34/C34 -> -0.13864396
A35: B.R.C. Mesh 8 m.m | B35: (8*16) feet | C35: 127.16 | D35: 122.64 | E35: 119.95 | F35: 118.72067 | G35: 122.06246 | H35: 112.23 | I35: 108.5 | J35: 107.13 | K35: 100.34 | L35: 107.05 | M35: 103.57 | N35: 97.45 | O35: 99.98 | P35: 107.92 | Q35: 102.23 | R35: 131.32 | S35: 139.68 | T35: 141 | U35: 131.38 | V35: 135.85 | W35: 142.13 | X35: 158.17 | Y35: 124.7 | Z35: 117 | AA35: 135.5 | AB35: 121.4 | AC35: 121.21 | AD35: 111.29 | AE35: 110.96 | AF35: 116.21 | AH35: =AF35-C35 -> -10.95 | AI35: =AH35/C35 -> -0.086111985
A37: Source: Dubai Statistics Centre
B39: QUARTER | C39: 2018-Q1 | D39: 2018-Q2 | E39: 2018-Q3 | F39: 2018-Q4 | G39: 2018-Year | H39: 2019-Q1 | I39: 2019-Q2 | J39: 2019-Q3 | K39: 2019-Q4 | L39: 2019-Year | M39: 2020-Q1 | N39: 2020-Q2 | O39: 2020-Q3 | P39: 2020-Q4 | Q39: 2020-Year | R39: 2021-Q1 | S39: 2021-Q2 | T39: 2021-Q3 | U39: 2021-Q4 | V39: 2021-Year | W39: 2022-Q1 | X39: 2022-Q2 | Y39: 2022-Q3 | Z39: 2022-Q4 | AA39: 2022-Year | AB39: 2023-Q1 | AC39: 2023-Q2 | AD39: 2023-Q3 | AE39: 2023-Q4
B40: CEMENT | C40: =AVERAGE(C8:C10) -> 22.103333 | D40: =AVERAGE(D8:D10) -> 21.916667 | E40: =AVERAGE(E8:E10) -> 22.061349 | F40: =AVERAGE(F8:F10) -> 22.067857 | G40: =AVERAGE(G8:G10) -> 21.987941 | H40: =AVERAGE(H8:H10) -> 22.58 | I40: =AVERAGE(I8:I10) -> 22.413333 | J40: =AVERAGE(J8:J10) -> 22.393333 | ... AE40: =AVERAGE(AE8:AE10) -> 20.903333
B41: LIME / GYPSUM | C41: =AVERAGE(C11:C12) -> 13.895 | D41: =AVERAGE(D11:D12) -> 13.82 | E41: =AVERAGE(E11:E12) -> 13.76875 | F41: =AVERAGE(F11:F12) -> 13.71875 | G41: =AVERAGE(G11:G12) -> 13.8 | H41: =AVERAGE(H11:H12) -> 12.015 | I41: =AVERAGE(I11:I12) -> 11.785 | J41: =AVERAGE(J11:J12) -> 11.725 | ... AE41: =AVERAGE(AE11:AE12) -> 11.725
B42: AGGREGATE | C42: =AVERAGE(C14:C16) -> 1228.5033 | D42: =AVERAGE(D14:D16) -> 1332.19 | E42: =AVERAGE(E14:E16) -> 1321.3958 | F42: =AVERAGE(F14:F16) -> 1329.1736 | G42: =AVERAGE(G14:G16) -> 1306.3653 | H42: =AVERAGE(H14:H16) -> 1251.25 | I42: =AVERAGE(I14:I16) -> 1251.25 | J42: =AVERAGE(J14:J16) -> 1218.1567 | ... AE42: =AVERAGE(AE14:AE16) -> 1250.5533
B43: SAND | C43: =AVERAGE(C17:C19) -> 822.50333 | D43: =AVERAGE(D17:D19) -> 874.35667 | E43: =AVERAGE(E17:E19) -> 868.97917 | F43: =AVERAGE(F17:F19) -> 907.04861 | G43: =AVERAGE(G17:G19) -> 875.65872 | H43: =AVERAGE(H17:H19) -> 834.16667 | I43: =AVERAGE(I17:I19) -> 834.16667 | J43: =AVERAGE(J17:J19) -> 807.5 | ... AE43: =AVERAGE(AE17:AE19) -> 816.86
B44: BLOCKS | C44: =AVERAGE(C21:C26) -> 3.1766667 | D44: =AVERAGE(D21:D26) -> 3.2116667 | E44: =AVERAGE(E21:E26) -> 3.2676111 | F44: =AVERAGE(F21:F26) -> 3.2154907 | G44: =AVERAGE(G21:G26) -> 3.2073601 | H44: =AVERAGE(H21:H26) -> 2.92 | I44: =AVERAGE(I21:I26) -> 2.92 | J44: =AVERAGE(J21:J26) -> 2.92 | ... AE44: =AVERAGE(AE21:AE26) -> 2.805
...

Sheet Data Live
A3: Average Construction Material Prices
A4: Materials | B4: Quantity | D4: Currency | E4: 2018 | F4: 2018 | G4: 2018 | H4: 2018 | I4: 2019 | J4: 2019 | K4: 2019 | L4: 2019 | M4: 2020 | N4: 2020 | O4: 2020 | P4: 2020 | Q4: 2021 | R4: 2021 | S4: 2021 | T4: 2021 | U4: 2022 | V4: 2022 | W4: 2022 | X4: 2022 | Y4: 2023 | Z4: 2023 | AA4: 2023 | AB4: 2023
E5: Quarter 1 | F5: Quarter 2 | G5: Quarter 3 | H5: Quarter 4 | I5: Quarter 1 | J5: Quarter 2 | K5: Quarter 3 | L5: Quarter 4 | M5: Quarter 1 | N5: Quarter 2 | O5: Quarter 3 | P5: Quarter 4 | Q5: Quarter 1 | R5: Quarter 2 | S5: Quarter 3 | T5: Quarter 4 | U5: Quarter 1 | V5: Quarter 2 | W5: Quarter 3 | X5: Quarter 4 | Y5: Quarter 1 | Z5: Quarter 2 | AA5: Quarter 3 | AB5: Quarter 4
A6: Cement
A7: Sulphate Resistance Cement | B7: 100Nr, 50 kg bag | C7: 100 | D7: AED | E7: ='Data Orig'!C8*$C7 -> 1562 | F7: ='Data Orig'!D8*$C7 -> 1536 | G7: ='Data Orig'!E8*$C7 -> 1562 | H7: ='Data Orig'!F8*$C7 -> 1553.1667 | I7: ='Data Orig'!H8*$C7 -> 1641 | J7: ='Data Orig'!I8*$C7 -> 1614 | K7: ='Data Orig'!J8*$C7 -> 1614 | L7: ='Data Orig'!K8*$C7 -> 1589 | M7: ='Data Orig'!M8*$C7 -> 1569 | N7: ='Data Orig'!N8*$C7 -> 1527 | O7: ='Data Orig'!O8*$C7 -> 1479 | P7: ='Data Orig'!P8*$C7 -> 1479 | Q7: ='Data Orig'!R8*$C7 -> 1479 | R7: ='Data Orig'!S8*$C7 -> 1493 | S7: ='Data Orig'!T8*$C7 -> 1475 | T7: ='Data Orig'!U8*$C7 -> 1479 | U7: ='Data Orig'!W8*$C7 -> 1453 | V7: ='Data Orig'!X8*$C7 -> 1479 | W7: ='Data Orig'!Y8*$C7 -> 1549 | X7: ='Data Orig'!Z8*$C7 -> 1566 | Y7: ='Data Orig'!AB8*$C7 -> 1536 | Z7: ='Data Orig'!AC8*$C7 -> 1623 | AA7: ='Data Orig'!AD8*$C7 -> 1601 | AB7: ='Data Orig'!AE8*$C7 -> 1549
A8: Portland Cement | B8: 100Nr, 50 kg bag | C8: 100 | D8: AED | E8: ='Data Orig'!C9*$C8 -> 1491 | F8: ='Data Orig'!D9*$C8 -> 1461 | G8: ='Data Orig'!E9*$C8 -> 1478.8333 | H8: ='Data Orig'!F9*$C8 -> 1449.6667 | I8: ='Data Orig'!H9*$C8 -> 1493 | J8: ='Data Orig'!I9*$C8 -> 1470 | K8: ='Data Orig'!J9*$C8 -> 1464 | L8: ='Data Orig'!K9*$C8 -> 1418 | M8: ='Data Orig'!M9*$C8 -> 1418 | N8: ='Data Orig'!N9*$C8 -> 1409 | O8: ='Data Orig'!O9*$C8 -> 1339 | P8: ='Data Orig'!P9*$C8 -> 1313 | Q8: ='Data Orig'!R9*$C8 -> 1296 | R8: ='Data Orig'!S9*$C8 -> 1234 | S8: ='Data Orig'!T9*$C8 -> 1181 | T8: ='Data Orig'!U9*$C8 -> 1111 | U8: ='Data Orig'!W9*$C8 -> 1115 | V8: ='Data Orig'!X9*$C8 -> 1146 | W8: ='Data Orig'!Y9*$C8 -> 1213 | X8: ='Data Orig'!Z9*$C8 -> 1282 | Y8: ='Data Orig'!AB9*$C8 -> 1252 | Z8: ='Data Orig'!AC9*$C8 -> 1390 | AA8: ='Data Orig'!AD9*$C8 -> 1372 | AB8: ='Data Orig'!AE9*$C8 -> 1292
A9: White Cement | B9: 100Nr, 50 kg bag | C9: 100 | D9: AED | E9: ='Data Orig'!C10*$C9 -> 3578 | F9: ='Data Orig'!D10*$C9 -> 3578 | G9: ='Data Orig'!E10*$C9 -> 3577.5714 | H9: ='Data Orig'!F10*$C9 -> 3617.5238 | I9: ='Data Orig'!H10*$C9 -> 3640 | J9: ='Data Orig'!I10*$C9 -> 3640 | K9: ='Data Orig'!J10*$C9 -> 3640 | L9: ='Data Orig'!K10*$C9 -> 3640 | M9: ='Data Orig'!M10*$C9 -> 3640 | N9: ='Data Orig'!N10*$C9 -> 3628 | O9: ='Data Orig'!O10*$C9 -> 3582 | P9: ='Data Orig'!P10*$C9 -> 3582 | Q9: ='Data Orig'!R10*$C9 -> 3471 | R9: ='Data Orig'!S10*$C9 -> 3535 | S9: ='Data Orig'!T10*$C9 -> 3494 | T9: ='Data Orig'!U10*$C9 -> 3483 | U9: ='Data Orig'!W10*$C9 -> 3483 | V9: ='Data Orig'!X10*$C9 -> 3453 | W9: ='Data Orig'!Y10*$C9 -> 3448 | X9: ='Data Orig'!Z10*$C9 -> 3436 | Y9: ='Data Orig'!AB10*$C9 -> 3401 | Z9: ='Data Orig'!AC10*$C9 -> 3407 | AA9: ='Data Orig'!AD10*$C9 -> 3430 | AB9: ='Data Orig'!AE10*$C9 -> 3430
A10: Lime | B10: 100Nr, 20 kg bag | C10: 100 | D10: AED | E10: ='Data Orig'!C11*$C10 -> 1864 | F10: ='Data Orig'!D11*$C10 -> 1864 | G10: ='Data Orig'!E11*$C10 -> 1863.75 | H10: ='Data Orig'!F11*$C10 -> 1863.75 | I10: ='Data Orig'!H11*$C10 -> 1575 | J10: ='Data Orig'!I11*$C10 -> 1575 | K10: ='Data Orig'!J11*$C10 -> 1575 | L10: ='Data Orig'!K11*$C10 -> 1575 | M10: ='Data Orig'!M11*$C10 -> 1575 | N10: ='Data Orig'!N11*$C10 -> 1575 | O10: ='Data Orig'!O11*$C10 -> 1575 | P10: ='Data Orig'!P11*$C10 -> 1575 | Q10: ='Data Orig'!R11*$C10 -> 1575 | R10: ='Data Orig'!S11*$C10 -> 1575 | S10: ='Data Orig'!T11*$C10 -> 1575 | T10: ='Data Orig'!U11*$C10 -> 1575 | U10: ='Data Orig'!W11*$C10 -> 1575 | V10: ='Data Orig'!X11*$C10 -> 1575 | W10: ='Data Orig'!Y11*$C10 -> 1575 | X10: ='Data Orig'!Z11*$C10 -> 1575 | Y10: ='Data Orig'!AB11*$C10 -> 1575 | Z10: ='Data Orig'!AC11*$C10 -> 1575 | AA10: ='Data Orig'!AD11*$C10 -> 1575 | AB10: ='Data Orig'!AE11*$C10 -> 1575
A11: Gypsum | B11: 100Nr, 25 kg bag | C11: 100 | D11: AED | E11: ='Data Orig'!C12*$C11 -> 915 | F11: ='Data Orig'!D12*$C11 -> 900 | G11: ='Data Orig'!E12*$C11 -> 890 | H11: ='Data Orig'!F12*$C11 -> 880 | I11: ='Data Orig'!H12*$C11 -> 828 | J11: ='Data Orig'!I12*$C11 -> 782 | K11: ='Data Orig'!J12*$C11 -> 770 | L11: ='Data Orig'!K12*$C11 -> 770 | M11: ='Data Orig'!M12*$C11 -> 782 | N11: ='Data Orig'!N12*$C11 -> 805 | O11: ='Data Orig'!O12*$C11 -> 805 | P11: ='Data Orig'!P12*$C11 -> 805 | Q11: ='Data Orig'!R12*$C11 -> 805 | R11: ='Data Orig'!S12*$C11 -> 805 | S11: ='Data Orig'!T12*$C11 -> 805 | T11: ='Data Orig'!U12*$C11 -> 805 | U11: ='Data Orig'!W12*$C11 -> 805 | V11: ='Data Orig'!X12*$C11 -> 805 | W11: ='Data Orig'!Y12*$C11 -> 805 | X11: ='Data Orig'!Z12*$C11 -> 805 | Y11: ='Data Orig'!AB12*$C11 -> 805 | Z11: ='Data Orig'!AC12*$C11 -> 793 | AA11: ='Data Orig'!AD12*$C11 -> 770 | AB11: ='Data Orig'!AE12*$C11 -> 770
A12: Aggregates & Sand
A13: Aggregates 3/4 | B13: 20 m3 | C13: 1 | D13: AED | E13: ='Data Orig'!C14*$C13 -> 1155 | F13: ='Data Orig'!D14*$C13 -> 1254.75 | G13: ='Data Orig'!E14*$C13 -> 1222.375 | H13: ='Data Orig'!F14*$C13 -> 1245.7083 | I13: ='Data Orig'!H14*$C13 -> 1207.5 | J13: ='Data Orig'!I14*$C13 -> 1207.5 | K13: ='Data Orig'!J14*$C13 -> 1161.39 | L13: ='Data Orig'!K14*$C13 -> 1138.33 | M13: ='Data Orig'!M14*$C13 -> 1138.33 | N13: ='Data Orig'!N14*$C13 -> 1115 | O13: ='Data Orig'!O14*$C13 -> 1103.33 | P13: ='Data Orig'!P14*$C13 -> 1097.5 | Q13: ='Data Orig'!R14*$C13 -> 1091.39 | R13: ='Data Orig'!S14*$C13 -> 1147.78 | S13: ='Data Orig'!T14*$C13 -> 1168.33 | T13: ='Data Orig'!U14*$C13 -> 1168.33 | U13: ='Data Orig'!W14*$C13 -> 1179.44 | V13: ='Data Orig'!X14*$C13 -> 1223.33 | W13: ='Data Orig'!Y14*$C13 -> 1223.33 | X13: ='Data Orig'!Z14*$C13 -> 1223.33 | Y13: ='Data Orig'!AB14*$C13 -> 1223.33 | Z13: ='Data Orig'!AC14*$C13 -> 1173.33 | AA13: ='Data Orig'!AD14*$C13 -> 1190.83 | AB13: ='Data Orig'!AE14*$C13 -> 1190.83
A14: Aggregates 3/8 | B14: 20 m3 | C14: 1 | D14: AED | E14: ='Data Orig'!C15*$C14 -> 1204.88 | F14: ='Data Orig'!D15*$C14 -> 1304.63 | G14: ='Data Orig'!E15*$C14 -> 1304.625 | H14: ='Data Orig'!F15*$C14 -> 1304.625 | I14: ='Data Orig'!H15*$C14 -> 1207.5 | J14: ='Data Orig'!I15*$C14 -> 1207.5 | K14: ='Data Orig'!J15*$C14 -> 1161.39 | L14: ='Data Orig'!K15*$C14 -> 1138.33 | M14: ='Data Orig'!M15*$C14 -> 1138.33 | N14: ='Data Orig'!N15*$C14 -> 1115 | O14: ='Data Orig'!O15*$C14 -> 1103.33 | P14: ='Data Orig'!P15*$C14 -> 1097.5 | Q14: ='Data Orig'!R15*$C14 -> 1091.39 | R14: ='Data Orig'!S15*$C14 -> 1147.78 | S14: ='Data Orig'!T15*$C14 -> 1168.33 | T14: ='Data Orig'!U15*$C14 -> 1168.33 | U14: ='Data Orig'!W15*$C14 -> 1179.44 | V14: ='Data Orig'!X15*$C14 -> 1223.33 | W14: ='Data Orig'!Y15*$C14 -> 1223.33 | X14: ='Data Orig'!Z15*$C14 -> 1223.33 | Y14: ='Data Orig'!AB15*$C14 -> 1223.33 | Z14: ='Data Orig'!AC15*$C14 -> 1173.33 | AA14: ='Data Orig'!AD15*$C14 -> 1190.83 | AB14: ='Data Orig'!AE15*$C14 -> 1190.83
A15: Aggregates 3/16 | B15: 20 m3 | C15: 1 | D15: AED | E15: ='Data Orig'!C16*$C15 -> 1325.63 | F15: ='Data Orig'!D16*$C15 -> 1437.19 | G15: ='Data Orig'!E16*$C15 -> 1437.1875 | H15: ='Data Orig'!F16*$C15 -> 1437.1875 | I15: ='Data Orig'!H16*$C15 -> 1338.75 | J15: ='Data Orig'!I16*$C15 -> 1338.75 | K15: ='Data Orig'!J16*$C15 -> 1331.69 | L15: ='Data Orig'!K16*$C15 -> 1318.17 | M15: ='Data Orig'!M16*$C15 -> 1318.17 | N15: ='Data Orig'!N16*$C15 -> 1311.17 | O15: ='Data Orig'!O16*$C15 -> 1307.67 | P15: ='Data Orig'!P16*$C15 -> 1300.67 | Q15: ='Data Orig'!R16*$C15 -> 1292.22 | R15: ='Data Orig'!S16*$C15 -> 1263.33 | S15: ='Data Orig'!T16*$C15 -> 1341.11 | T15: ='Data Orig'!U16*$C15 -> 1286.67 | U15: ='Data Orig'!W16*$C15 -> 1296.67 | V15: ='Data Orig'!X16*$C15 -> 1383.33 | W15: ='Data Orig'!Y16*$C15 -> 1383.33 | X15: ='Data Orig'!Z16*$C15 -> 1383.33 | Y15: ='Data Orig'!AB16*$C15 -> 1383.33 | Z15: ='Data Orig'!AC16*$C15 -> 1370 | AA15: ='Data Orig'!AD16*$C15 -> 1370 | AB15: ='Data Orig'!AE16*$C15 -> 1370
A16: Sand / White | B16: 20 m3 | C16: 1 | D16: AED | E16: ='Data Orig'!C17*$C16 -> 866.25 | F16: ='Data Orig'!D17*$C16 -> 866.25 | G16: ='Data Orig'!E17*$C16 -> 866.25 | H16: ='Data Orig'!F17*$C16 -> 877.5 | I16: ='Data Orig'!H17*$C16 -> 840 | J16: ='Data Orig'!I17*$C16 -> 840 | K16: ='Data Orig'!J17*$C16 -> 798.89 | L16: ='Data Orig'!K17*$C16 -> 763.33 | M16: ='Data Orig'!M17*$C16 -> 763.33 | N16: ='Data Orig'!N17*$C16 -> 763.33 | O16: ='Data Orig'!O17*$C16 -> 763.33 | P16: ='Data Orig'!P17*$C16 -> 763.33 | Q16: ='Data Orig'!R17*$C16 -> 793.33 | R16: ='Data Orig'!S17*$C16 -> 805.56 | S16: ='Data Orig'!T17*$C16 -> 830 | T16: ='Data Orig'!U17*$C16 -> 830 | U16: ='Data Orig'!W17*$C16 -> 830 | V16: ='Data Orig'!X17*$C16 -> 793.33 | W16: ='Data Orig'!Y17*$C16 -> 793.33 | X16: ='Data Orig'!Z17*$C16 -> 793.33 | Y16: ='Data Orig'!AB17*$C16 -> 793.33 | Z16: ='Data Orig'!AC17*$C16 -> 758.33 | AA16: ='Data Orig'!AD17*$C16 -> 770.58 | AB16: ='Data Orig'!AE17*$C16 -> 770.58
A17: Sand / Black | B17: 20 m3 | C17: 1 | D17: AED | E17: ='Data Orig'!C18*$C17 -> 984.38 | F17: ='Data Orig'!D18*$C17 -> 1118.94 | G17: ='Data Orig'!E18*$C17 -> 1099.6875 | H17: ='Data Orig'!F18*$C17 -> 1127.6042 | I17: ='Data Orig'!H18*$C17 -> 1101.67 | J17: ='Data Orig'!I18*$C17 -> 1101.67 | K17: ='Data Orig'!J18*$C17 -> 1075 | L17: ='Data Orig'!K18*$C17 -> 1061.67 | M17: ='Data Orig'!M18*$C17 -> 1061.67 | N17: ='Data Orig'!N18*$C17 -> 1061.67 | O17: ='Data Orig'!O18*$C17 -> 1061.67 | P17: ='Data Orig'!P18*$C17 -> 1061.67 | Q17: ='Data Orig'!R18*$C17 -> 1085.28 | R17: ='Data Orig'!S18*$C17 -> 1100.83 | S17: ='Data Orig'!T18*$C17 -> 1100.83 | T17: ='Data Orig'!U18*$C17 -> 1100.83 | U17: ='Data Orig'!W18*$C17 -> 1100.83 | V17: ='Data Orig'!X18*$C17 -> 1116.67 | W17: ='Data Orig'!Y18*$C17 -> 1116.67 | X17: ='Data Orig'!Z18*$C17 -> 1116.67 | Y17: ='Data Orig'!AB18*$C17 -> 1116.67 | Z17: ='Data Orig'!AC18*$C17 -> 1083.33 | AA17: ='Data Orig'!AD18*$C17 -> 1083.33 | AB17: ='Data Orig'!AE18*$C17 -> 1083.33
A18: Sand / Red | B18: 20 m3 | C18: 1 | D18: AED | E18: ='Data Orig'!C19*$C18 -> 616.88 | F18: ='Data Orig'!D19*$C18 -> 637.88 | G18: ='Data Orig'!E19*$C18 -> 641 | H18: ='Data Orig'!F19*$C18 -> 716.04167 | I18: ='Data Orig'!H19*$C18 -> 560.83 | J18: ='Data Orig'!I19*$C18 -> 560.83 | K18: ='Data Orig'!J19*$C18 -> 548.61 | L18: ='Data Orig'!K19*$C18 -> 542.5 | M18: ='Data Orig'!M19*$C18 -> 542.5 | N18: ='Data Orig'!N19*$C18 -> 542.5 | O18: ='Data Orig'!O19*$C18 -> 542.5 | P18: ='Data Orig'!P19*$C18 -> 542.5 | Q18: ='Data Orig'!R19*$C18 -> 601.67 | R18: ='Data Orig'!S19*$C18 -> 601.67 | S18: ='Data Orig'!T19*$C18 -> 601.67 | T18: ='Data Orig'!U19*$C18 -> 626.67 | U18: ='Data Orig'!W19*$C18 -> 626.67 | V18: ='Data Orig'!X19*$C18 -> 606.67 | W18: ='Data Orig'!Y19*$C18 -> 606.67 | X18: ='Data Orig'!Z19*$C18 -> 606.67 | Y18: ='Data Orig'!AB19*$C18 -> 606.67 | Z18: ='Data Orig'!AC19*$C18 -> 596.67 | AA18: ='Data Orig'!AD19*$C18 -> 596.67 | AB18: ='Data Orig'!AE19*$C18 -> 596.67
A19: Blocks
A20: Hollow - 4 cm | B20: 200 Blocks | C20: 200 | D20: AED | E20: ='Data Orig'!C21*$C20 -> 504 | F20: ='Data Orig'!D21*$C20 -> 504 | G20: ='Data Orig'!E21*$C20 -> 507.66667 | H20: ='Data Orig'!F21*$C20 -> 493.66667 | I20: ='Data Orig'!H21*$C20 -> 436 | J20: ='Data Orig'!I21*$C20 -> 436 | K20: ='Data Orig'!J21*$C20 -> 436 | L20: ='Data Orig'!K21*$C20 -> 436 | M20: ='Data Orig'!M21*$C20 -> 422 | N20: ='Data Orig'!N21*$C20 -> 404 | O20: ='Data Orig'!O21*$C20 -> 386 | P20: ='Data Orig'!P21*$C20 -> 386 | Q20: ='Data Orig'!R21*$C20 -> 386 | R20: ='Data Orig'!S21*$C20 -> 386 | S20: ='Data Orig'!T21*$C20 -> 386 | T20: ='Data Orig'!U21*$C20 -> 386 | U20: ='Data Orig'!W21*$C20 -> 390 | V20: ='Data Orig'!X21*$C20 -> 400 | W20: ='Data Orig'!Y21*$C20 -> 400 | X20: ='Data Orig'!Z21*$C20 -> 400 | Y20: ='Data Orig'!AB21*$C20 -> 400 | Z20: ='Data Orig'!AC21*$C20 -> 406 | AA20: ='Data Orig'!AD21*$C20 -> 414 | AB20: ='Data Orig'!AE21*$C20 -> 414
A21: Hollow - 6 cm | B21: 200 Blocks | C21: =C20 -> 200 | D21: AED | E21: ='Data Orig'!C22*$C21 -> 532 | F21: ='Data Orig'!D22*$C21 -> 540 | G21: ='Data Orig'!E22*$C21 -> 547.83333 | H21: ='Data Orig'!F22*$C21 -> 538.38889 | I21: ='Data Orig'!H22*$C21 -> 478 | J21: ='Data Orig'!I22*$C21 -> 478 | K21: ='Data Orig'!J22*$C21 -> 478 | L21: ='Data Orig'!K22*$C21 -> 478 | M21: ='Data Orig'!M22*$C21 -> 464 | N21: ='Data Orig'!N22*$C21 -> 446 | O21: ='Data Orig'!O22*$C21 -> 428 | P21: ='Data Orig'!P22*$C21 -> 428 | Q21: ='Data Orig'!R22*$C21 -> 428 | R21: ='Data Orig'!S22*$C21 -> 428 | S21: ='Data Orig'!T22*$C21 -> 428 | T21: ='Data Orig'!U22*$C21 -> 428 | U21: ='Data Orig'!W22*$C21 -> 432 | V21: ='Data Orig'!X22*$C21 -> 442 | W21: ='Data Orig'!Y22*$C21 -> 442 | X21: ='Data Orig'!Z22*$C21 -> 442 | Y21: ='Data Orig'!AB22*$C21 -> 442 | Z21: ='Data Orig'!AC22*$C21 -> 446 | AA21: ='Data Orig'!AD22*$C21 -> 448 | AB21: ='Data Orig'!AE22*$C21 -> 448
A22: Hollow - 8 cm | B22: 200 Blocks | C22: =C21 -> 200 | D22: AED | E22: ='Data Orig'!C23*$C22 -> 574 | F22: ='Data Orig'!D23*$C22 -> 582 | G22: ='Data Orig'!E23*$C22 -> 591.66667 | H22: ='Data Orig'!F23*$C22 -> 588.11111 | I22: ='Data Orig'!H23*$C22 -> 520 | J22: ='Data Orig'!I23*$C22 -> 520 | K22: ='Data Orig'!J23*$C22 -> 520 | L22: ='Data Orig'!K23*$C22 -> 520 | M22: ='Data Orig'!M23*$C22 -> 510 | N22: ='Data Orig'!N23*$C22 -> 492 | O22: ='Data Orig'!O23*$C22 -> 470 | P22: ='Data Orig'!P23*$C22 -> 470 | Q22: ='Data Orig'!R23*$C22 -> 470 | R22: ='Data Orig'!S23*$C22 -> 470 | S22: ='Data Orig'!T23*$C22 -> 470 | T22: ='Data Orig'!U23*$C22 -> 470 | U22: ='Data Orig'!W23*$C22 -> 474 | V22: ='Data Orig'!X23*$C22 -> 484 | W22: ='Data Orig'!Y23*$C22 -> 484 | X22: ='Data Orig'!Z23*$C22 -> 484 | Y22: ='Data Orig'!AB23*$C22 -> 484 | Z22: ='Data Orig'!AC23*$C22 -> 490 | AA22: ='Data Orig'!AD23*$C22 -> 498 | AB22: ='Data Orig'!AE23*$C22 -> 490
A23: Solid - 4 cm | B23: 200 Blocks | C23: =C22 -> 200 | D23: AED | E23: ='Data Orig'!C24*$C23 -> 662 | F23: ='Data Orig'!D24*$C23 -> 680 | G23: ='Data Orig'!E24*$C23 -> 698.5 | H23: ='Data Orig'!F24*$C23 -> 684.33333 | I23: ='Data Orig'!H24*$C23 -> 646 | J23: ='Data Orig'!I24*$C23 -> 646 | K23: ='Data Orig'!J24*$C23 -> 646 | L23: ='Data Orig'!K24*$C23 -> 646 | M23: ='Data Orig'!M24*$C23 -> 632 | N23: ='Data Orig'!N24*$C23 -> 612 | O23: ='Data Orig'!O24*$C23 -> 588 | P23: ='Data Orig'!P24*$C23 -> 588 | Q23: ='Data Orig'!R24*$C23 -> 588 | R23: ='Data Orig'!S24*$C23 -> 588 | S23: ='Data Orig'!T24*$C23 -> 588 | T23: ='Data Orig'!U24*$C23 -> 588 | U23: ='Data Orig'!W24*$C23 -> 594 | V23: ='Data Orig'!X24*$C23 -> 602 | W23: ='Data Orig'!Y24*$C23 -> 602 | X23: ='Data Orig'!Z24*$C23 -> 602 | Y23: ='Data Orig'!AB24*$C23 -> 602 | Z23: ='Data Orig'!AC24*$C23 -> 618 | AA23: ='Data Orig'!AD24*$C23 -> 624 | AB23: ='Data Orig'!AE24*$C23 -> 624
A24: Solid - 6 cm | B24: 200 Blocks | C24: =C23 -> 200 | D24: AED | E24: ='Data Orig'!C25*$C24 -> 750 | F24: ='Data Orig'!D25*$C24 -> 750 | G24: ='Data Orig'!E25*$C24 -> 766.66667 | H24: ='Data Orig'!F25*$C24 -> 759.55556 | I24: ='Data Orig'!H25*$C24 -> 694 | J24: ='Data Orig'!I25*$C24 -> 694 | K24: ='Data Orig'!J25*$C24 -> 694 | L24: ='Data Orig'!K25*$C24 -> 694 | M24: ='Data Orig'!M25*$C24 -> 684 | N24: ='Data Orig'!N25*$C24 -> 684 | O24: ='Data Orig'!O25*$C24 -> 684 | P24: ='Data Orig'!P25*$C24 -> 684 | Q24: ='Data Orig'!R25*$C24 -> 684 | R24: ='Data Orig'!S25*$C24 -> 684 | S24: ='Data Orig'!T25*$C24 -> 684 | T24: ='Data Orig'!U25*$C24 -> 684 | U24: ='Data Orig'!W25*$C24 -> 684 | V24: ='Data Orig'!X25*$C24 -> 684 | W24: ='Data Orig'!Y25*$C24 -> 684 | X24: ='Data Orig'!Z25*$C24 -> 684 | Y24: ='Data Orig'!AB25*$C24 -> 684 | Z24: ='Data Orig'!AC25*$C24 -> 688 | AA24: ='Data Orig'!AD25*$C24 -> 684 | AB24: ='Data Orig'!AE25*$C24 -> 682
A25: Solid - 8 cm | B25: 200 Blocks | C25: =C24 -> 200 | D25: AED | E25: ='Data Orig'!C26*$C25 -> 790 | F25: ='Data Orig'!D26*$C25 -> 798 | G25: ='Data Orig'!E26*$C25 -> 808.8 | H25: ='Data Orig'!F26*$C25 -> 794.53333 | I25: ='Data Orig'!H26*$C25 -> 730 | J25: ='Data Orig'!I26*$C25 -> 730 | K25: ='Data Orig'!J26*$C25 -> 730 | L25: ='Data Orig'!K26*$C25 -> 730 | M25: ='Data Orig'!M26*$C25 -> 720 | N25: ='Data Orig'!N26*$C25 -> 702 | O25: ='Data Orig'!O26*$C25 -> 680 | P25: ='Data Orig'!P26*$C25 -> 680 | Q25: ='Data Orig'!R26*$C25 -> 680 | R25: ='Data Orig'!S26*$C25 -> 680 | S25: ='Data Orig'!T26*$C25 -> 680 | T25: ='Data Orig'!U26*$C25 -> 680 | U25: ='Data Orig'!W26*$C25 -> 684 | V25: ='Data Orig'!X26*$C25 -> 694 | W25: ='Data Orig'!Y26*$C25 -> 694 | X25: ='Data Orig'!Z26*$C25 -> 694 | Y25: ='Data Orig'!AB26*$C25 -> 694 | Z25: ='Data Orig'!AC26*$C25 -> 700 | AA25: ='Data Orig'!AD26*$C25 -> 708 | AB25: ='Data Orig'!AE26*$C25 -> 708
A26: Concrete
A27: Ready Mix / Normal (40N) | B27: 10 m3 | C27: 10 | D27: AED | E27: ='Data Orig'!C28*$C27 -> 2633.8 | F27: ='Data Orig'!D28*$C27 -> 2638.1 | G27: ='Data Orig'!E28*$C27 -> 2638.125 | H27: ='Data Orig'!F28*$C27 -> 2660 | I27: ='Data Orig'!H28*$C27 -> 2663.2 | J27: ='Data Orig'!I28*$C27 -> 2537.5 | K27: ='Data Orig'!J28*$C27 -> 2514.8 | L27: ='Data Orig'!K28*$C27 -> 2485 | M27: ='Data Orig'!M28*$C27 -> 2463.6 | N27: ='Data Orig'!N28*$C27 -> 2362.5 | O27: ='Data Orig'!O28*$C27 -> 2310.3 | P27: ='Data Orig'!P28*$C27 -> 2295.6 | Q27: ='Data Orig'!R28*$C27 -> 2192.7 | R27: ='Data Orig'!S28*$C27 -> 2056.4 | S27: ='Data Orig'!T28*$C27 -> 2000.3 | T27: ='Data Orig'!U28*$C27 -> 1959.5 | U27: ='Data Orig'!W28*$C27 -> 2061.2 | V27: ='Data Orig'!X28*$C27 -> 2183.8 | W27: ='Data Orig'!Y28*$C27 -> 2223.4 | X27: ='Data Orig'!Z28*$C27 -> 2262.4 | Y27: ='Data Orig'!AB28*$C27 -> 2300.9 | Z27: ='Data Orig'!AC28*$C27 -> 2409.2 | AA27: ='Data Orig'!AD28*$C27 -> 2423.5 | AB27: ='Data Orig'!AE28*$C27 -> 2434
A28: Ready Mix / Sulphate Resistance (40N) | B28: 10 m3 | C28: 10 | D28: AED | E28: ='Data Orig'!C29*$C28 -> 2671.7 | F28: ='Data Orig'!D29*$C28 -> 2677.5 | G28: ='Data Orig'!E29*$C28 -> 2677.5 | H28: ='Data Orig'!F29*$C28 -> 2671.6667 | I28: ='Data Orig'!H29*$C28 -> 2642.5 | J28: ='Data Orig'!I29*$C28 -> 2539.8 | K28: ='Data Orig'!J29*$C28 -> 2549.2 | L28: ='Data Orig'!K29*$C28 -> 2545.4 | M28: ='Data Orig'!M29*$C28 -> 2487 | N28: ='Data Orig'!N29*$C28 -> 2442.8 | O28: ='Data Orig'!O29*$C28 -> 2409.8 | P28: ='Data Orig'!P29*$C28 -> 2383.7 | Q28: ='Data Orig'!R29*$C28 -> 2318.3 | R28: ='Data Orig'!S29*$C28 -> 2111 | S28: ='Data Orig'!T29*$C28 -> 2035.7 | T28: ='Data Orig'!U29*$C28 -> 1988.1 | U28: ='Data Orig'!W29*$C28 -> 2139.6 | V28: ='Data Orig'!X29*$C28 -> 2298.3 | W28: ='Data Orig'!Y29*$C28 -> 2328.7 | X28: ='Data Orig'!Z29*$C28 -> 2354.3 | Y28: ='Data Orig'!AB29*$C28 -> 2405.5 | Z28: ='Data Orig'!AC29*$C28 -> 2495.7 | AA28: ='Data Orig'!AD29*$C28 -> 2394.3 | AB28: ='Data Orig'!AE29*$C28 -> 2416.6
A29: Steel
A30: Steel Bars 6 - 8 mm | B30: Tons | C30: 1 | D30: AED | E30: ='Data Orig'!C31*$C30 -> 2699.38 | F30: ='Data Orig'!D31*$C30 -> 2613.52 | G30: ='Data Orig'!E31*$C30 -> 2498.125 | H30: ='Data Orig'!F31*$C30 -> 2303.5467 | I30: ='Data Orig'!H31*$C30 -> 2353.02 | J30: ='Data Orig'!I31*$C30 -> 2300.38 | K30: ='Data Orig'!J31*$C30 -> 2231.25 | L30: ='Data Orig'!K31*$C30 -> 2086.15 | M30: ='Data Orig'!M31*$C30 -> 2184 | N30: ='Data Orig'!N31*$C30 -> 2018.75 | O30: ='Data Orig'!O31*$C30 -> 2065 | P30: ='Data Orig'!P31*$C30 -> 2339.17 | Q30: ='Data Orig'!R31*$C30 -> 2846.55 | R30: ='Data Orig'!S31*$C30 -> 3076.39 | S30: ='Data Orig'!T31*$C30 -> 3054.29 | T30: ='Data Orig'!U31*$C30 -> 2829.87 | U30: ='Data Orig'!W31*$C30 -> 3103.7 | V30: ='Data Orig'!X31*$C30 -> 3363.89 | W30: ='Data Orig'!Y31*$C30 -> 2689.87 | X30: ='Data Orig'!Z31*$C30 -> 2587.77 | Y30: ='Data Orig'!AB31*$C30 -> 2825.66 | Z30: ='Data Orig'!AC31*$C30 -> 2835.06 | AA30: ='Data Orig'!AD31*$C30 -> 2634.05 | AB30: ='Data Orig'!AE31*$C30 -> 2713.19
A31: Steel Bars 10 - 25 | B31: Tons | C31: 1 | D31: AED | E31: ='Data Orig'!C32*$C31 -> 2623.63 | F31: ='Data Orig'!D32*$C31 -> 2567.69 | G31: ='Data Orig'!E32*$C31 -> 2444.4007 | H31: ='Data Orig'!F32*$C31 -> 2246.2303 | I31: ='Data Orig'!H32*$C31 -> 2156.03 | J31: ='Data Orig'!I32*$C31 -> 2136.46 | K31: ='Data Orig'!J32*$C31 -> 2089.56 | L31: ='Data Orig'!K32*$C31 -> 2007.4 | M31: ='Data Orig'!M32*$C31 -> 2073.17 | N31: ='Data Orig'!N32*$C31 -> 1898.02 | O31: ='Data Orig'!O32*$C31 -> 1936.67 | P31: ='Data Orig'!P32*$C31 -> 2181.67 | Q31: ='Data Orig'!R32*$C31 -> 2735.89 | R31: ='Data Orig'!S32*$C31 -> 2943.68 | S31: ='Data Orig'!T32*$C31 -> 2930.7 | T31: ='Data Orig'!U32*$C31 -> 2703.11 | U31: ='Data Orig'!W32*$C31 -> 2986.39 | V31: ='Data Orig'!X32*$C31 -> 3233.17 | W31: ='Data Orig'!Y32*$C31 -> 2537.22 | X31: ='Data Orig'!Z32*$C31 -> 2421.54 | Y31: ='Data Orig'!AB32*$C31 -> 2651.64 | Z31: ='Data Orig'!AC32*$C31 -> 2669.23 | AA31: ='Data Orig'!AD32*$C31 -> 2502.52 | AB31: ='Data Orig'!AE32*$C31 -> 2594.45
A32: B.R.C. Mesh 6 m.m | B32: 25Nr, (8*16) feet | C32: 25 | D32: AED | E32: ='Data Orig'!C33*$C32 -> 1839.25 | F32: ='Data Orig'!D33*$C32 -> 1780.25 | G32: ='Data Orig'!E33*$C32 -> 1846.4167 | H32: ='Data Orig'!F33*$C32 -> 1633.2417 | I32: ='Data Orig'!H33*$C32 -> 1525.5 | J32: ='Data Orig'!I33*$C32 -> 1493.25 | K32: ='Data Orig'!J33*$C32 -> 1481.75 | L32: ='Data Orig'!K33*$C32 -> 1389 | M32: ='Data Orig'!M33*$C32 -> 1486 | N32: ='Data Orig'!N33*$C32 -> 1397.75 | O32: ='Data Orig'!O33*$C32 -> 1440.75 | P32: ='Data Orig'!P33*$C32 -> 1562 | Q32: ='Data Orig'!R33*$C32 -> 1908.75 | R32: ='Data Orig'!S33*$C32 -> 2035.25 | S32: ='Data Orig'!T33*$C32 -> 1979 | T32: ='Data Orig'!U33*$C32 -> 1868.75 | U32: ='Data Orig'!W33*$C32 -> 1913.75 | V32: ='Data Orig'!X33*$C32 -> 2060.75 | W32: ='Data Orig'!Y33*$C32 -> 1617.75 | X32: ='Data Orig'!Z33*$C32 -> 1518.5 | Y32: ='Data Orig'!AB33*$C32 -> 1655.25 | Z32: ='Data Orig'!AC33*$C32 -> 1615.5 | AA32: ='Data Orig'!AD33*$C32 -> 1532 | AB32: ='Data Orig'!AE33*$C32 -> 1566.5
A33: B.R.C. Mesh 7 m.m | B33: 25Nr, (8*16) feet | C33: 25 | D33: AED | E33: ='Data Orig'!C34*$C33 -> 2466.75 | F33: ='Data Orig'!D34*$C33 -> 2444.25 | G33: ='Data Orig'!E34*$C33 -> 2427.0833 | H33: ='Data Orig'!F34*$C33 -> 2334.8056 | I33: ='Data Orig'!H34*$C33 -> 2219.5 | J33: ='Data Orig'!I34*$C33 -> 2173 | K33: ='Data Orig'!J34*$C33 -> 2104.25 | L33: ='Data Orig'!K34*$C33 -> 1953.5 | M33: ='Data Orig'!M34*$C33 -> 2074.5 | N33: ='Data Orig'!N34*$C33 -> 1960 | O33: ='Data Orig'!O34*$C33 -> 1992 | P33: ='Data Orig'!P34*$C33 -> 2135 | Q33: ='Data Orig'!R34*$C33 -> 2561.5 | R33: ='Data Orig'!S34*$C33 -> 2811 | S33: ='Data Orig'!T34*$C33 -> 2811 | T33: ='Data Orig'!U34*$C33 -> 2733.5 | U33: ='Data Orig'!W34*$C33 -> 2663.75 | V33: ='Data Orig'!X34*$C33 -> 2875.5 | W33: ='Data Orig'!Y34*$C33 -> 2292.5 | X33: ='Data Orig'!Z34*$C33 -> 2166.75 | Y33: ='Data Orig'!AB34*$C33 -> 2267.5 | Z33: ='Data Orig'!AC34*$C33 -> 2175.5 | AA33: ='Data Orig'!AD34*$C33 -> 2025 | AB33: ='Data Orig'!AE34*$C33 -> 2031.25
A34: B.R.C. Mesh 8 m.m | B34: 25Nr, (8*16) feet | C34: 25 | D34: AED | E34: ='Data Orig'!C35*$C34 -> 3179 | F34: ='Data Orig'!D35*$C34 -> 3066 | G34: ='Data Orig'!E35*$C34 -> 2998.75 | H34: ='Data Orig'!F35*$C34 -> 2968.0167 | I34: ='Data Orig'!H35*$C34 -> 2805.75 | J34: ='Data Orig'!I35*$C34 -> 2712.5 | K34: ='Data Orig'!J35*$C34 -> 2678.25 | L34: ='Data Orig'!K35*$C34 -> 2508.5 | M34: ='Data Orig'!M35*$C34 -> 2589.25 | N34: ='Data Orig'!N35*$C34 -> 2436.25 | O34: ='Data Orig'!O35*$C34 -> 2499.5 | P34: ='Data Orig'!P35*$C34 -> 2698 | Q34: ='Data Orig'!R35*$C34 -> 3283 | R34: ='Data Orig'!S35*$C34 -> 3492 | S34: ='Data Orig'!T35*$C34 -> 3525 | T34: ='Data Orig'!U35*$C34 -> 3284.5 | U34: ='Data Orig'!W35*$C34 -> 3553.25 | V34: ='Data Orig'!X35*$C34 -> 3954.25 | W34: ='Data Orig'!Y35*$C34 -> 3117.5 | X34: ='Data Orig'!Z35*$C34 -> 2925 | Y34: ='Data Orig'!AB35*$C34 -> 3035 | Z34: ='Data Orig'!AC35*$C34 -> 3030.25 | AA34: ='Data Orig'!AD35*$C34 -> 2782.25 | AB34: ='Data Orig'!AE35*$C34 -> 2774
A35: Source: Dubai Statistics Centre
B38: QUARTER | E38: 2018-Q1 | F38: 2018-Q2 | G38: 2018-Q3 | H38: 2018-Q4 | I38: 2019-Q1 | J38: 2019-Q2 | K38: 2019-Q3 | L38: 2019-Q4 | M38: 2020-Q1 | N38: 2020-Q2 | O38: 2020-Q3 | P38: 2020-Q4 | Q38: 2021-Q1 | R38: 2021-Q2 | S38: 2021-Q3 | T38: 2021-Q4 | U38: 2022-Q1 | V38: 2022-Q2 | W38: 2022-Q3 | X38: 2022-Q4 | Y38: 2023-Q1 | Z38: 2023-Q2 | AA38: 2023-Q3 | AB38: 2023-Q4
B39: CEMENT | E39: =AVERAGE(E7:E9) -> 2210.3333 | F39: =AVERAGE(F7:F9) -> 2191.6667 | G39: =AVERAGE(G7:G9) -> 2206.1349 | H39: =AVERAGE(H7:H9) -> 2206.7857 | I39: =AVERAGE(I7:I9) -> 2258 | J39: =AVERAGE(J7:J9) -> 2241.3333 | K39: =AVERAGE(K7:K9) -> 2239.3333 | L39: =AVERAGE(L7:L9) -> 2215.6667 | ... AB39: =AVERAGE(AB7:AB9) -> 2090.3333
B40: LIME / GYPSUM | E40: =AVERAGE(E10:E11) -> 1389.5 | F40: =AVERAGE(F10:F11) -> 1382 | G40: =AVERAGE(G10:G11) -> 1376.875 | H40: =AVERAGE(H10:H11) -> 1371.875 | I40: =AVERAGE(I10:I11) -> 1201.5 | J40: =AVERAGE(J10:J11) -> 1178.5 | K40: =AVERAGE(K10:K11) -> 1172.5 | L40: =AVERAGE(L10:L11) -> 1172.5 | ... AB40: =AVERAGE(AB10:AB11) -> 1172.5
B41: AGGREGATE | E41: =AVERAGE(E13:E15) -> 1228.5033 | F41: =AVERAGE(F13:F15) -> 1332.19 | G41: =AVERAGE(G13:G15) -> 1321.3958 | H41: =AVERAGE(H13:H15) -> 1329.1736 | I41: =AVERAGE(I13:I15) -> 1251.25 | J41: =AVERAGE(J13:J15) -> 1251.25 | K41: =AVERAGE(K13:K15) -> 1218.1567 | L41: =AVERAGE(L13:L15) -> 1198.2767 | ... AB41: =AVERAGE(AB13:AB15) -> 1250.5533
B42: SAND | E42: =AVERAGE(E16:E18) -> 822.50333 | F42: =AVERAGE(F16:F18) -> 874.35667 | G42: =AVERAGE(G16:G18) -> 868.97917 | H42: =AVERAGE(H16:H18) -> 907.04861 | I42: =AVERAGE(I16:I18) -> 834.16667 | J42: =AVERAGE(J16:J18) -> 834.16667 | K42: =AVERAGE(K16:K18) -> 807.5 | L42: =AVERAGE(L16:L18) -> 789.16667 | ... AB42: =AVERAGE(AB16:AB18) -> 816.86
B43: BLOCKS | E43: =AVERAGE(E20:E25) -> 635.33333 | F43: =AVERAGE(F20:F25) -> 642.33333 | G43: =AVERAGE(G20:G25) -> 653.52222 | H43: =AVERAGE(H20:H25) -> 643.09815 | I43: =AVERAGE(I20:I25) -> 584 | J43: =AVERAGE(J20:J25) -> 584 | K43: =AVERAGE(K20:K25) -> 584 | L43: =AVERAGE(L20:L25) -> 584 | ... AB43: =AVERAGE(AB20:AB25) -> 561
B44: READY MIX | E44: =AVERAGE(E27:E28) -> 2652.75 | F44: =AVERAGE(F27:F28) -> 2657.8 | G44: =AVERAGE(G27:G28) -> 2657.8125 | H44: =AVERAGE(H27:H28) -> 2665.8333 | I44: =AVERAGE(I27:I28) -> 2652.85 | J44: =AVERAGE(J27:J28) -> 2538.65 | K44: =AVERAGE(K27:K28) -> 2532 | L44: =AVERAGE(L27:L28) -> 2515.2 | ... AB44: =AVERAGE(AB27:AB28) -> 2425.3
...
