Workbook

Sheet Rates
A1: Asset | B1: Country | C1: City | D1: Project | E1: Base Date | F1: Contractor | G1: Status | H1: Contract Type | I1: BUA | J1: GIA | K1: GFA | L1: Keys | M1: NRM Lvl 1 | N1: POMI | O1: Description | P1: Quantity | Q1: Unit | R1: Contract Rate | S1: Average Tender Rate
A3: Townhouses | B3: UAE | C3: Dubai | D3: The Valley - Nara | E3: 2022 | F3: METAC | G3: Award | H3: Fixed Price Lump Sum | I3: 69927 | K3: 53764 | L3: 372 | M3: Foundations | N3: Concrete Work | O3: Plain concrete; concrete grade C20/16 | P3: 30 | Q3: m3 | R3: 370 | S3: 309
A4: =A3 -> Townhouses | B4: =B3 -> UAE | C4: =C3 -> Dubai | D4: =D3 -> The Valley - Nara | E4: =E3 -> 2022 | F4: =F3 -> METAC | G4: =G3 -> Award | H4: =H3 -> Fixed Price Lump Sum | M4: Lowest Floor Construction | N4: Concrete Work | O4: Reinforced concrete; concrete grade C25 | P4: 51 | Q4: m3 | R4: 370 | S4: 305

Sheet Data
B1: Asset Lvl 1 | C1: Asset Lvl 2 | D1: Asset Lvl 3 | E1: Country | F1: City | G1: Developer | H1: Alias Lvl 1 | I1: Alias Lvl 2 | J1: Project Lvl 1 | K1: Project Lvl 2 | L1: Base Date | M1: Contractor | N1: Status | O1: Procurement | P1: Contract Type | Q1: BUA | R1: GIA | S1: GFA | T1: Keys | U1: NRM Lvl 1 | V1: Currency | W1: Total Cost | X1: Cost/BUA | Y1: Cost/GIA | Z1: Cost/GFA | AA1: Cost/Key | AB1: Chart
B3: Single Asset | C3: Villas | E3: UAE | F3: Dubai | G3: EMAAR | I3: Project V16.1 | K3: Azalea | L3: 2016 | M3: Pivot | N3: Award | O3: Competitive - Traditional | P3: Fixed Price Lump Sum | Q3: 32424.307 | R3: 30847 | S3: 24540 | T3: 108 | U3: Substructure | V3: AED | W3: 9760947 | X3: =W3/Q3 -> 301.03795 | Y3: =W3/R3 -> 316.431 | Z3: =W3/S3 -> 397.7566 | AA3: =W3/T3 -> 90379.139 | AB3: NO | AC3: =SUM(W3:W15) -> 130950000 | AD3: =W3/AC3 -> 0.074539496
B4: Single Asset | C4: Villas | E4: UAE | F4: Dubai | G4: EMAAR | I4: Project V16.1 | K4: Azalea | L4: 2016 | M4: Pivot | N4: Award | O4: Competitive - Traditional | P4: Fixed Price Lump Sum | Q4: 32424.307 | R4: 30847 | S4: 24540 | T4: 108 | U4: Superstructure | V4: AED | W4: 18188477 | X4: =W4/Q4 -> 560.95191 | Y4: =W4/R4 -> 589.6352 | Z4: =W4/S4 -> 741.17673 | AA4: =W4/T4 -> 168411.82 | AB4: NO | AD4: =W4/AC3 -> 0.13889635
B5: Single Asset | C5: Villas | E5: UAE | F5: Dubai | G5: EMAAR | I5: Project V16.1 | K5: Azalea | L5: 2016 | M5: Pivot | N5: Award | O5: Competitive - Traditional | P5: Fixed Price Lump Sum | Q5: 32424.307 | R5: 30847 | S5: 24540 | T5: 108 | U5: Building External Envelope | V5: AED | W5: 21367865 | X5: =W5/Q5 -> 659.0076 | Y5: =W5/R5 -> 692.7048 | Z5: =W5/S5 -> 870.73615 | AA5: =W5/T5 -> 197850.6 | AB5: NO | AD5: =W5/AC3 -> 0.16317575
B6: Single Asset | C6: Villas | E6: UAE | F6: Dubai | G6: EMAAR | I6: Project V16.1 | K6: Azalea | L6: 2016 | M6: Pivot | N6: Award | O6: Competitive - Traditional | P6: Fixed Price Lump Sum | Q6: 32424.307 | R6: 30847 | S6: 24540 | T6: 108 | U6: Internal Walls and Doors | V6: AED | W6: 5368377 | X6: =W6/Q6 -> 165.56644 | Y6: =W6/R6 -> 174.03239 | Z6: =W6/S6 -> 218.76027 | AA6: =W6/T6 -> 49707.194 | AB6: NO | AD6: =W6/AC3 -> 0.040995624
B7: Single Asset | C7: Villas | E7: UAE | F7: Dubai | G7: EMAAR | I7: Project V16.1 | K7: Azalea | L7: 2016 | M7: Pivot | N7: Award | O7: Competitive - Traditional | P7: Fixed Price Lump Sum | Q7: 32424.307 | R7: 30847 | S7: 24540 | T7: 108 | U7: Internal Finishes | V7: AED | W7: 11409384 | X7: =W7/Q7 -> 351.8775 | Y7: =W7/R7 -> 369.87013 | Z7: =W7/S7 -> 464.93007 | AA7: =W7/T7 -> 105642.44 | AB7: NO | AD7: =W7/AC3 -> 0.087127789
B8: Single Asset | C8: Villas | E8: UAE | F8: Dubai | G8: EMAAR | I8: Project V16.1 | K8: Azalea | L8: 2016 | M8: Pivot | N8: Award | O8: Competitive - Traditional | P8: Fixed Price Lump Sum | Q8: 32424.307 | R8: 30847 | S8: 24540 | T8: 108 | U8: FF&E | V8: AED | W8: 6470548 | X8: =W8/Q8 -> 199.55856 | Y8: =W8/R8 -> 209.76263 | Z8: =W8/S8 -> 263.67351 | AA8: =W8/T8 -> 59912.481 | AB8: NO | AD8: =W8/AC3 -> 0.049412356
B9: Single Asset | C9: Villas | E9: UAE | F9: Dubai | G9: EMAAR | I9: Project V16.1 | K9: Azalea | L9: 2016 | M9: Pivot | N9: Award | O9: Competitive - Traditional | P9: Fixed Price Lump Sum | Q9: 32424.307 | R9: 30847 | S9: 24540 | T9: 108 | U9: Sanitary Fittings | V9: AED | W9: 2261311 | X9: =W9/Q9 -> 69.741228 | Y9: =W9/R9 -> 73.307323 | Z9: =W9/S9 -> 92.147963 | AA9: =W9/T9 -> 20938.065 | AB9: NO | AD9: =W9/AC3 -> 0.017268507
B10: Single Asset | C10: Villas | E10: UAE | F10: Dubai | G10: EMAAR | I10: Project V16.1 | K10: Azalea | L10: 2016 | M10: Pivot | N10: Award | O10: Competitive - Traditional | P10: Fixed Price Lump Sum | Q10: 32424.307 | R10: 30847 | S10: 24540 | T10: 108 | U10: Services Equipment | V10: AED | W10: 0 | X10: =W10/Q10 -> 0 | Y10: =W10/R10 -> 0 | Z10: =W10/S10 -> 0 | AA10: =W10/T10 -> 0 | AB10: NO | AD10: =W10/AC3 -> 0
B11: Single Asset | C11: Villas | E11: UAE | F11: Dubai | G11: EMAAR | I11: Project V16.1 | K11: Azalea | L11: 2016 | M11: Pivot | N11: Award | O11: Competitive - Traditional | P11: Fixed Price Lump Sum | Q11: 32424.307 | R11: 30847 | S11: 24540 | T11: 108 | U11: Mechanical | V11: AED | W11: 14870759 | X11: =W11/Q11 -> 458.62997 | Y11: =W11/R11 -> 482.08121 | Z11: =W11/S11 -> 605.9804 | AA11: =W11/T11 -> 137692.21 | AB11: NO | AD11: =W11/AC3 -> 0.11356059
B12: Single Asset | C12: Villas | E12: UAE | F12: Dubai | G12: EMAAR | I12: Project V16.1 | K12: Azalea | L12: 2016 | M12: Pivot | N12: Award | O12: Competitive - Traditional | P12: Fixed Price Lump Sum | Q12: 32424.307 | R12: 30847 | S12: 24540 | T12: 108 | U12: Electrical | V12: AED | W12: 9887655 | X12: =W12/Q12 -> 304.94576 | Y12: =W12/R12 -> 320.53863 | Z12: =W12/S12 -> 402.91993 | AA12: =W12/T12 -> 91552.361 | AB12: NO | AD12: =W12/AC3 -> 0.075507102
B13: Single Asset | C13: Villas | E13: UAE | F13: Dubai | G13: EMAAR | I13: Project V16.1 | K13: Azalea | L13: 2016 | M13: Pivot | N13: Award | O13: Competitive - Traditional | P13: Fixed Price Lump Sum | Q13: 32424.307 | R13: 30847 | S13: 24540 | T13: 108 | U13: Conveying Systems | V13: AED | W13: 0 | X13: =W13/Q13 -> 0 | Y13: =W13/R13 -> 0 | Z13: =W13/S13 -> 0 | AA13: =W13/T13 -> 0 | AB13: NO | AD13: =W13/AC3 -> 0
B14: Single Asset | C14: Villas | E14: UAE | F14: Dubai | G14: EMAAR | I14: Project V16.1 | K14: Azalea | L14: 2016 | M14: Pivot | N14: Award | O14: Competitive - Traditional | P14: Fixed Price Lump Sum | Q14: 32424.307 | R14: 30847 | S14: 24540 | T14: 108 | U14: External Works | V14: AED | W14: 14420838 | X14: =W14/Q14 -> 444.75393 | Y14: =W14/R14 -> 467.49564 | Z14: =W14/S14 -> 587.64621 | AA14: =W14/T14 -> 133526.28 | AB14: NO | AD14: =W14/AC3 -> 0.11012477
B15: Single Asset | C15: Villas | E15: UAE | F15: Dubai | G15: EMAAR | I15: Project V16.1 | K15: Azalea | L15: 2016 | M15: Pivot | N15: Award | O15: Competitive - Traditional | P15: Fixed Price Lump Sum | Q15: 32424.307 | R15: 30847 | S15: 24540 | T15: 108 | U15: General Requirements | V15: AED | W15: 16943839 | X15: =W15/Q15 -> 522.56595 | Y15: =W15/R15 -> 549.28645 | Z15: =W15/S15 -> 690.45799 | AA15: =W15/T15 -> 156887.4 | AB15: NO | AD15: =W15/AC3 -> 0.12939167
B16: Single Asset | C16: Villas | E16: UAE | F16: Dubai | G16: EMAAR | I16: Project V18.1 | K16: Sidra 3 | L16: 2018 | M16: Trojan | N16: Award | O16: Competitive - Traditional | P16: Fixed Price Lump Sum | Q16: 107978 | R16: 86196 | S16: 81881 | T16: 339 | U16: Substructure | V16: AED | W16: 52851049 | X16: =W16/Q16 -> 489.46127 | Y16: =W16/R16 -> 613.14967 | Z16: =W16/S16 -> 645.46169 | AA16: =W16/T16 -> 155902.8 | AB16: YES | AC16: =SUM(W16:W28) -> 392000000 | AD16: =W16/AC16 -> 0.1348241
B17: Single Asset | C17: Villas | E17: UAE | F17: Dubai | G17: EMAAR | I17: Project V18.1 | K17: Sidra 3 | L17: 2018 | M17: Trojan | N17: Award | O17: Competitive - Traditional | P17: Fixed Price Lump Sum | Q17: 107978 | R17: 86196 | S17: 81881 | T17: 339 | U17: Superstructure | V17: AED | W17: 98979809 | X17: =W17/Q17 -> 916.66644 | Y17: =W17/R17 -> 1148.3109 | Z17: =W17/S17 -> 1208.8251 | AA17: =W17/T17 -> 291975.84 | AB17: YES | AD17: =W17/AC16 -> 0.25249951
B18: Single Asset | C18: Villas | E18: UAE | F18: Dubai | G18: EMAAR | I18: Project V18.1 | K18: Sidra 3 | L18: 2018 | M18: Trojan | N18: Award | O18: Competitive - Traditional | P18: Fixed Price Lump Sum | Q18: 107978 | R18: 86196 | S18: 81881 | T18: 339 | U18: Building External Envelope | V18: AED | W18: 49457359 | X18: =W18/Q18 -> 458.03181 | Y18: =W18/R18 -> 573.77789 | Z18: =W18/S18 -> 604.01508 | AA18: =W18/T18 -> 145891.91 | AB18: YES | AD18: =W18/AC16 -> 0.12616673
B19: Single Asset | C19: Villas | E19: UAE | F19: Dubai | G19: EMAAR | I19: Project V18.1 | K19: Sidra 3 | L19: 2018 | M19: Trojan | N19: Award | O19: Competitive - Traditional | P19: Fixed Price Lump Sum | Q19: 107978 | R19: 86196 | S19: 81881 | T19: 339 | U19: Internal Walls and Doors | V19: AED | W19: 11002315 | X19: =W19/Q19 -> 101.89404 | Y19: =W19/R19 -> 127.64299 | Z19: =W19/S19 -> 134.36957 | AA19: =W19/T19 -> 32455.206 | AB19: YES | AD19: =W19/AC16 -> 0.02806713
B20: Single Asset | C20: Villas | E20: UAE | F20: Dubai | G20: EMAAR | I20: Project V18.1 | K20: Sidra 3 | L20: 2018 | M20: Trojan | N20: Award | O20: Competitive - Traditional | P20: Fixed Price Lump Sum | Q20: 107978 | R20: 86196 | S20: 81881 | T20: 339 | U20: Internal Finishes | V20: AED | W20: 33820941 | X20: =W20/Q20 -> 313.22067 | Y20: =W20/R20 -> 392.37251 | Z20: =W20/S20 -> 413.04993 | AA20: =W20/T20 -> 99766.788 | AB20: YES | AD20: =W20/AC16 -> 0.086277911
B21: Single Asset | C21: Villas | E21: UAE | F21: Dubai | G21: EMAAR | I21: Project V18.1 | K21: Sidra 3 | L21: 2018 | M21: Trojan | N21: Award | O21: Competitive - Traditional | P21: Fixed Price Lump Sum | Q21: 107978 | R21: 86196 | S21: 81881 | T21: 339 | U21: FF&E | V21: AED | W21: 13113832 | X21: =W21/Q21 -> 121.44911 | Y21: =W21/R21 -> 152.13968 | Z21: =W21/S21 -> 160.1572 | AA21: =W21/T21 -> 38683.87 | AB21: YES | AD21: =W21/AC16 -> 0.033453653
B22: Single Asset | C22: Villas | E22: UAE | F22: Dubai | G22: EMAAR | I22: Project V18.1 | K22: Sidra 3 | L22: 2018 | M22: Trojan | N22: Award | O22: Competitive - Traditional | P22: Fixed Price Lump Sum | Q22: 107978 | R22: 86196 | S22: 81881 | T22: 339 | U22: Sanitary Fittings | V22: AED | W22: 4536571 | X22: =W22/Q22 -> 42.013845 | Y22: =W22/R22 -> 52.630876 | Z22: =W22/S22 -> 55.404441 | AA22: =W22/T22 -> 13382.215 | AB22: YES | AD22: =W22/AC16 -> 0.011572885
B23: Single Asset | C23: Villas | E23: UAE | F23: Dubai | G23: EMAAR | I23: Project V18.1 | K23: Sidra 3 | L23: 2018 | M23: Trojan | N23: Award | O23: Competitive - Traditional | P23: Fixed Price Lump Sum | Q23: 107978 | R23: 86196 | S23: 81881 | T23: 339 | U23: Services Equipment | V23: AED | W23: 0 | X23: =W23/Q23 -> 0 | Y23: =W23/R23 -> 0 | Z23: =W23/S23 -> 0 | AA23: =W23/T23 -> 0 | AB23: YES | AD23: =W23/AC16 -> 0
B24: Single Asset | C24: Villas | E24: UAE | F24: Dubai | G24: EMAAR | I24: Project V18.1 | K24: Sidra 3 | L24: 2018 | M24: Trojan | N24: Award | O24: Competitive - Traditional | P24: Fixed Price Lump Sum | Q24: 107978 | R24: 86196 | S24: 81881 | T24: 339 | U24: Mechanical | V24: AED | W24: 39378792 | X24: =W24/Q24 -> 364.69273 | Y24: =W24/R24 -> 456.85173 | Z24: =W24/S24 -> 480.9271 | AA24: =W24/T24 -> 116161.63 | AB24: YES | AD24: =W24/AC16 -> 0.1004561
B25: Single Asset | C25: Villas | E25: UAE | F25: Dubai | G25: EMAAR | I25: Project V18.1 | K25: Sidra 3 | L25: 2018 | M25: Trojan | N25: Award | O25: Competitive - Traditional | P25: Fixed Price Lump Sum | Q25: 107978 | R25: 86196 | S25: 81881 | T25: 339 | U25: Electrical | V25: AED | W25: 24214867 | X25: =W25/Q25 -> 224.25741 | Y25: =W25/R25 -> 280.92797 | Z25: =W25/S25 -> 295.73243 | AA25: =W25/T25 -> 71430.286 | AB25: YES | AD25: =W25/AC16 -> 0.06177262
B26: Single Asset | C26: Villas | E26: UAE | F26: Dubai | G26: EMAAR | I26: Project V18.1 | K26: Sidra 3 | L26: 2018 | M26: Trojan | N26: Award | O26: Competitive - Traditional | P26: Fixed Price Lump Sum | Q26: 107978 | R26: 86196 | S26: 81881 | T26: 339 | U26: Conveying Systems | V26: AED | W26: 0 | X26: =W26/Q26 -> 0 | Y26: =W26/R26 -> 0 | Z26: =W26/S26 -> 0 | AA26: =W26/T26 -> 0 | AB26: YES | AD26: =W26/AC16 -> 0
B27: Single Asset | C27: Villas | E27: UAE | F27: Dubai | G27: EMAAR | I27: Project V18.1 | K27: Sidra 3 | L27: 2018 | M27: Trojan | N27: Award | O27: Competitive - Traditional | P27: Fixed Price Lump Sum | Q27: 107978 | R27: 86196 | S27: 81881 | T27: 339 | U27: External Works | V27: AED | W27: 29894168 | X27: =W27/Q27 -> 276.85425 | Y27: =W27/R27 -> 346.81619 | Z27: =W27/S27 -> 365.09285 | AA27: =W27/T27 -> 88183.386 | AB27: YES | AD27: =W27/AC16 -> 0.076260633
B28: Single Asset | C28: Villas | E28: UAE | F28: Dubai | G28: EMAAR | I28: Project V18.1 | K28: Sidra 3 | L28: 2018 | M28: Trojan | N28: Award | O28: Competitive - Traditional | P28: Fixed Price Lump Sum | Q28: 107978 | R28: 86196 | S28: 81881 | T28: 339 | U28: General Requirements | V28: AED | W28: 34750297 | X28: =W28/Q28 -> 321.82757 | Y28: =W28/R28 -> 403.1544 | Z28: =W28/S28 -> 424.40001 | AA28: =W28/T28 -> 102508.25 | AB28: YES | AD28: =W28/AC16 -> 0.088648717
B29: Single Asset | C29: Villas | E29: UAE | F29: Dubai | G29: EMAAR | I29: Project V18.2 | K29: Club Villas | L29: 2018 | M29: Pivot | N29: Award | O29: Competitive - Traditional | P29: Fixed Price Lump Sum | Q29: 42973 | R29: 41225 | S29: 34232 | T29: 150 | U29: Substructure | V29: AED | W29: 9197511 | X29: =W29/Q29 -> 214.03 | Y29: =W29/R29 -> 223.10518 | Z29: =W29/S29 -> 268.68167 | AA29: =W29/T29 -> 61316.74 | AB29: YES | AC29: =SUM(W29:W41) -> 157509543 | AD29: =W29/AC29 -> 0.058393357
B30: Single Asset | C30: Villas | E30: UAE | F30: Dubai | G30: EMAAR | I30: Project V18.2 | K30: Club Villas | L30: 2018 | M30: Pivot | N30: Award | O30: Competitive - Traditional | P30: Fixed Price Lump Sum | Q30: 42973 | R30: 41225 | S30: 34232 | T30: 150 | U30: Superstructure | V30: AED | W30: 18381854 | X30: =W30/Q30 -> 427.75357 | Y30: =W30/R30 -> 445.89094 | Z30: =W30/S30 -> 536.97867 | AA30: =W30/T30 -> 122545.69 | AB30: YES | AD30: =W30/AC29 -> 0.11670311
B31: Single Asset | C31: Villas | E31: UAE | F31: Dubai | G31: EMAAR | I31: Project V18.2 | K31: Club Villas | L31: 2018 | M31: Pivot | N31: Award | O31: Competitive - Traditional | P31: Fixed Price Lump Sum | Q31: 42973 | R31: 41225 | S31: 34232 | T31: 150 | U31: Building External Envelope | V31: AED | W31: 23767948 | X31: =W31/Q31 -> 553.09027 | Y31: =W31/R31 -> 576.5421 | Z31: =W31/S31 -> 694.31958 | AA31: =W31/T31 -> 158452.99 | AB31: YES | AD31: =W31/AC29 -> 0.15089846
B32: Single Asset | C32: Villas | E32: UAE | F32: Dubai | G32: EMAAR | I32: Project V18.2 | K32: Club Villas | L32: 2018 | M32: Pivot | N32: Award | O32: Competitive - Traditional | P32: Fixed Price Lump Sum | Q32: 42973 | R32: 41225 | S32: 34232 | T32: 150 | U32: Internal Walls and Doors | V32: AED | W32: 7688363 | X32: =W32/Q32 -> 178.91148 | Y32: =W32/R32 -> 186.49759 | Z32: =W32/S32 -> 224.59579 | AA32: =W32/T32 -> 51255.753 | AB32: YES | AD32: =W32/AC29 -> 0.048812046
B33: Single Asset | C33: Villas | E33: UAE | F33: Dubai | G33: EMAAR | I33: Project V18.2 | K33: Club Villas | L33: 2018 | M33: Pivot | N33: Award | O33: Competitive - Traditional | P33: Fixed Price Lump Sum | Q33: 42973 | R33: 41225 | S33: 34232 | T33: 150 | U33: Internal Finishes | V33: AED | W33: 27354609 | X33: =W33/Q33 -> 636.55339 | Y33: =W33/R33 -> 663.54418 | Z33: =W33/S33 -> 799.09468 | AA33: =W33/T33 -> 182364.06 | AB33: YES | AD33: =W33/AC29 -> 0.17366953
B34: Single Asset | C34: Villas | E34: UAE | F34: Dubai | G34: EMAAR | I34: Project V18.2 | K34: Club Villas | L34: 2018 | M34: Pivot | N34: Award | O34: Competitive - Traditional | P34: Fixed Price Lump Sum | Q34: 42973 | R34: 41225 | S34: 34232 | T34: 150 | U34: FF&E | V34: AED | W34: 12114027 | X34: =W34/Q34 -> 281.89856 | Y34: =W34/R34 -> 293.85147 | Z34: =W34/S34 -> 353.8802 | AA34: =W34/T34 -> 80760.18 | AB34: YES | AD34: =W34/AC29 -> 0.076909797
B35: Single Asset | C35: Villas | E35: UAE | F35: Dubai | G35: EMAAR | I35: Project V18.2 | K35: Club Villas | L35: 2018 | M35: Pivot | N35: Award | O35: Competitive - Traditional | P35: Fixed Price Lump Sum | Q35: 42973 | R35: 41225 | S35: 34232 | T35: 150 | U35: Sanitary Fittings | V35: AED | W35: 2041954 | X35: =W35/Q35 -> 47.517139 | Y35: =W35/R35 -> 49.531935 | Z35: =W35/S35 -> 59.650444 | AA35: =W35/T35 -> 13613.027 | AB35: YES | AD35: =W35/AC29 -> 0.012964002
B36: Single Asset | C36: Villas | E36: UAE | F36: Dubai | G36: EMAAR | I36: Project V18.2 | K36: Club Villas | L36: 2018 | M36: Pivot | N36: Award | O36: Competitive - Traditional | P36: Fixed Price Lump Sum | Q36: 42973 | R36: 41225 | S36: 34232 | T36: 150 | U36: Services Equipment | V36: AED | W36: 0 | X36: =W36/Q36 -> 0 | Y36: =W36/R36 -> 0 | Z36: =W36/S36 -> 0 | AA36: =W36/T36 -> 0 | AB36: YES | AD36: =W36/AC29 -> 0
B37: Single Asset | C37: Villas | E37: UAE | F37: Dubai | G37: EMAAR | I37: Project V18.2 | K37: Club Villas | L37: 2018 | M37: Pivot | N37: Award | O37: Competitive - Traditional | P37: Fixed Price Lump Sum | Q37: 42973 | R37: 41225 | S37: 34232 | T37: 150 | U37: Mechanical | V37: AED | W37: 16503507 | X37: =W37/Q37 -> 384.04363 | Y37: =W37/R37 -> 400.32764 | Z37: =W37/S37 -> 482.10759 | AA37: =W37/T37 -> 110023.38 | AB37: YES | AD37: =W37/AC29 -> 0.10477782
B38: Single Asset | C38: Villas | E38: UAE | F38: Dubai | G38: EMAAR | I38: Project V18.2 | K38: Club Villas | L38: 2018 | M38: Pivot | N38: Award | O38: Competitive - Traditional | P38: Fixed Price Lump Sum | Q38: 42973 | R38: 41225 | S38: 34232 | T38: 150 | U38: Electrical | V38: AED | W38: 12737336 | X38: =W38/Q38 -> 296.40323 | Y38: =W38/R38 -> 308.97116 | Z38: =W38/S38 -> 372.08857 | AA38: =W38/T38 -> 84915.573 | AB38: YES | AD38: =W38/AC29 -> 0.080867075
B39: Single Asset | C39: Villas | E39: UAE | F39: Dubai | G39: EMAAR | I39: Project V18.2 | K39: Club Villas | L39: 2018 | M39: Pivot | N39: Award | O39: Competitive - Traditional | P39: Fixed Price Lump Sum | Q39: 42973 | R39: 41225 | S39: 34232 | T39: 150 | U39: Conveying Systems | V39: AED | W39: 0 | X39: =W39/Q39 -> 0 | Y39: =W39/R39 -> 0 | Z39: =W39/S39 -> 0 | AA39: =W39/T39 -> 0 | AB39: YES | AD39: =W39/AC29 -> 0
B40: Single Asset | C40: Villas | E40: UAE | F40: Dubai | G40: EMAAR | I40: Project V18.2 | K40: Club Villas | L40: 2018 | M40: Pivot | N40: Award | O40: Competitive - Traditional | P40: Fixed Price Lump Sum | Q40: 42973 | R40: 41225 | S40: 34232 | T40: 150 | U40: External Works | V40: AED | W40: 11879865 | X40: =W40/Q40 -> 276.44951 | Y40: =W40/R40 -> 288.17138 | Z40: =W40/S40 -> 347.03976 | AA40: =W40/T40 -> 79199.1 | AB40: YES | AD40: =W40/AC29 -> 0.075423144
B41: Single Asset | C41: Villas | E41: UAE | F41: Dubai | G41: EMAAR | I41: Project V18.2 | K41: Club Villas | L41: 2018 | M41: Pivot | N41: Award | O41: Competitive - Traditional | P41: Fixed Price Lump Sum | Q41: 42973 | R41: 41225 | S41: 34232 | T41: 150 | U41: General Requirements | V41: AED | W41: 15842569 | X41: =W41/Q41 -> 368.66332 | Y41: =W41/R41 -> 384.29518 | Z41: =W41/S41 -> 462.79998 | AA41: =W41/T41 -> 105617.13 | AB41: YES | AD41: =W41/AC29 -> 0.10058165
...

Sheet Sheet1
B2: =COUNTIF(Data!$C$2:$C$1056,Sheet1!B3)/13 -> 18 | C2: =COUNTIF(Data!$C$2:$C$1056,Sheet1!C3)/13 -> 10 | D2: =COUNTIF(Data!$C$2:$C$1056,Sheet1!D3)/13 -> 26 | E2: =COUNTIF(Data!$C$2:$C$1056,Sheet1!E3)/13 -> 2 | F2: =COUNTIF(Data!$C$2:$C$1056,Sheet1!F3)/13 -> 7 | G2: =COUNTIF(Data!$C$2:$C$1056,Sheet1!G3)/13 -> 6 | H2: =COUNTIF(Data!$C$2:$C$1056,Sheet1!H3)/13 -> 6 | I2: =COUNTIF(Data!$C$2:$C$1056,Sheet1!I3)/13 -> 5
B3: Villas | C3: Townhouses | D3: Apartments | E3: Apartments, Serviced | F3: Retail | G3: Offices | H3: Hospitality | I3: Thematic | K3: Totals
A5: Substructure | B5: =SUMIFS(Data!$W$2:$W$1056,Data!$U$2:$U$1056,Sheet1!$A5,Data!$C$2:$C$1056,Sheet1!B$3) -> 8.3364248e+08 | C5: =SUMIFS(Data!$W$2:$W$1056,Data!$U$2:$U$1056,Sheet1!$A5,Data!$C$2:$C$1056,Sheet1!C$3) -> 165729953 | D5: =SUMIFS(Data!$W$2:$W$1056,Data!$U$2:$U$1056,Sheet1!$A5,Data!$C$2:$C$1056,Sheet1!D$3) -> 9.751722e+08 | E5: =SUMIFS(Data!$W$2:$W$1056,Data!$U$2:$U$1056,Sheet1!$A5,Data!$C$2:$C$1056,Sheet1!E$3) -> 64146913 | F5: =SUMIFS(Data!$W$2:$W$1056,Data!$U$2:$U$1056,Sheet1!$A5,Data!$C$2:$C$1056,Sheet1!F$3) -> 4.285611e+08 | G5: =SUMIFS(Data!$W$2:$W$1056,Data!$U$2:$U$1056,Sheet1!$A5,Data!$C$2:$C$1056,Sheet1!G$3) -> 2.5589842e+08 | H5: =SUMIFS(Data!$W$2:$W$1056,Data!$U$2:$U$1056,Sheet1!$A5,Data!$C$2:$C$1056,Sheet1!H$3) -> 3.4100231e+08 | I5: =SUMIFS(Data!$W$2:$W$1056,Data!$U$2:$U$1056,Sheet1!$A5,Data!$C$2:$C$1056,Sheet1!I$3) -> 89262397 | K5: =SUM(B5:J5) -> 3.1534158e+09
A6: Superstructure | B6: =SUMIFS(Data!$W$2:$W$1056,Data!$U$2:$U$1056,Sheet1!$A6,Data!$C$2:$C$1056,Sheet1!B$3) -> 1.8630618e+09 | C6: =SUMIFS(Data!$W$2:$W$1056,Data!$U$2:$U$1056,Sheet1!$A6,Data!$C$2:$C$1056,Sheet1!C$3) -> 389116402 | D6: =SUMIFS(Data!$W$2:$W$1056,Data!$U$2:$U$1056,Sheet1!$A6,Data!$C$2:$C$1056,Sheet1!D$3) -> 1.8792568e+09 | E6: =SUMIFS(Data!$W$2:$W$1056,Data!$U$2:$U$1056,Sheet1!$A6,Data!$C$2:$C$1056,Sheet1!E$3) -> 1.1619409e+08 | F6: =SUMIFS(Data!$W$2:$W$1056,Data!$U$2:$U$1056,Sheet1!$A6,Data!$C$2:$C$1056,Sheet1!F$3) -> 1.2712375e+09 | G6: =SUMIFS(Data!$W$2:$W$1056,Data!$U$2:$U$1056,Sheet1!$A6,Data!$C$2:$C$1056,Sheet1!G$3) -> 2.6442381e+08 | H6: =SUMIFS(Data!$W$2:$W$1056,Data!$U$2:$U$1056,Sheet1!$A6,Data!$C$2:$C$1056,Sheet1!H$3) -> 5.877716e+08 | I6: =SUMIFS(Data!$W$2:$W$1056,Data!$U$2:$U$1056,Sheet1!$A6,Data!$C$2:$C$1056,Sheet1!I$3) -> 2.9329284e+08 | K6: =SUM(B6:J6) -> 6.6643548e+09
A7: Building External Envelope | B7: =SUMIFS(Data!$W$2:$W$1056,Data!$U$2:$U$1056,Sheet1!$A7,Data!$C$2:$C$1056,Sheet1!B$3) -> 2.8763647e+09 | C7: =SUMIFS(Data!$W$2:$W$1056,Data!$U$2:$U$1056,Sheet1!$A7,Data!$C$2:$C$1056,Sheet1!C$3) -> 240965617 | D7: =SUMIFS(Data!$W$2:$W$1056,Data!$U$2:$U$1056,Sheet1!$A7,Data!$C$2:$C$1056,Sheet1!D$3) -> 1.563142e+09 | E7: =SUMIFS(Data!$W$2:$W$1056,Data!$U$2:$U$1056,Sheet1!$A7,Data!$C$2:$C$1056,Sheet1!E$3) -> 1.0946141e+08 | F7: =SUMIFS(Data!$W$2:$W$1056,Data!$U$2:$U$1056,Sheet1!$A7,Data!$C$2:$C$1056,Sheet1!F$3) -> 2.0166002e+08 | G7: =SUMIFS(Data!$W$2:$W$1056,Data!$U$2:$U$1056,Sheet1!$A7,Data!$C$2:$C$1056,Sheet1!G$3) -> 1.5054727e+08 | H7: =SUMIFS(Data!$W$2:$W$1056,Data!$U$2:$U$1056,Sheet1!$A7,Data!$C$2:$C$1056,Sheet1!H$3) -> 4.2901856e+08 | I7: =SUMIFS(Data!$W$2:$W$1056,Data!$U$2:$U$1056,Sheet1!$A7,Data!$C$2:$C$1056,Sheet1!I$3) -> 4.1298094e+08 | K7: =SUM(B7:J7) -> 5.9841406e+09
A8: Internal Walls and Doors | B8: =SUMIFS(Data!$W$2:$W$1056,Data!$U$2:$U$1056,Sheet1!$A8,Data!$C$2:$C$1056,Sheet1!B$3) -> 6.8733344e+08 | C8: =SUMIFS(Data!$W$2:$W$1056,Data!$U$2:$U$1056,Sheet1!$A8,Data!$C$2:$C$1056,Sheet1!C$3) -> 123740571 | D8: =SUMIFS(Data!$W$2:$W$1056,Data!$U$2:$U$1056,Sheet1!$A8,Data!$C$2:$C$1056,Sheet1!D$3) -> 6.1090386e+08 | E8: =SUMIFS(Data!$W$2:$W$1056,Data!$U$2:$U$1056,Sheet1!$A8,Data!$C$2:$C$1056,Sheet1!E$3) -> 43492867 | F8: =SUMIFS(Data!$W$2:$W$1056,Data!$U$2:$U$1056,Sheet1!$A8,Data!$C$2:$C$1056,Sheet1!F$3) -> 1.8254337e+08 | G8: =SUMIFS(Data!$W$2:$W$1056,Data!$U$2:$U$1056,Sheet1!$A8,Data!$C$2:$C$1056,Sheet1!G$3) -> 47569665 | H8: =SUMIFS(Data!$W$2:$W$1056,Data!$U$2:$U$1056,Sheet1!$A8,Data!$C$2:$C$1056,Sheet1!H$3) -> 1.3011277e+08 | I8: =SUMIFS(Data!$W$2:$W$1056,Data!$U$2:$U$1056,Sheet1!$A8,Data!$C$2:$C$1056,Sheet1!I$3) -> 36536479 | K8: =SUM(B8:J8) -> 1.862233e+09
A9: Internal Finishes | B9: =SUMIFS(Data!$W$2:$W$1056,Data!$U$2:$U$1056,Sheet1!$A9,Data!$C$2:$C$1056,Sheet1!B$3) -> 2.0108529e+09 | C9: =SUMIFS(Data!$W$2:$W$1056,Data!$U$2:$U$1056,Sheet1!$A9,Data!$C$2:$C$1056,Sheet1!C$3) -> 206822062 | D9: =SUMIFS(Data!$W$2:$W$1056,Data!$U$2:$U$1056,Sheet1!$A9,Data!$C$2:$C$1056,Sheet1!D$3) -> 1.3676785e+09 | E9: =SUMIFS(Data!$W$2:$W$1056,Data!$U$2:$U$1056,Sheet1!$A9,Data!$C$2:$C$1056,Sheet1!E$3) -> 1.3251978e+08 | F9: =SUMIFS(Data!$W$2:$W$1056,Data!$U$2:$U$1056,Sheet1!$A9,Data!$C$2:$C$1056,Sheet1!F$3) -> 4.6215131e+08 | G9: =SUMIFS(Data!$W$2:$W$1056,Data!$U$2:$U$1056,Sheet1!$A9,Data!$C$2:$C$1056,Sheet1!G$3) -> 1.0136012e+08 | H9: =SUMIFS(Data!$W$2:$W$1056,Data!$U$2:$U$1056,Sheet1!$A9,Data!$C$2:$C$1056,Sheet1!H$3) -> 6.036426e+08 | I9: =SUMIFS(Data!$W$2:$W$1056,Data!$U$2:$U$1056,Sheet1!$A9,Data!$C$2:$C$1056,Sheet1!I$3) -> 1.3234235e+08 | K9: =SUM(B9:J9) -> 5.0173696e+09
A10: FF&E | B10: =SUMIFS(Data!$W$2:$W$1056,Data!$U$2:$U$1056,Sheet1!$A10,Data!$C$2:$C$1056,Sheet1!B$3) -> 9.4403333e+08 | C10: =SUMIFS(Data!$W$2:$W$1056,Data!$U$2:$U$1056,Sheet1!$A10,Data!$C$2:$C$1056,Sheet1!C$3) -> 153651984 | D10: =SUMIFS(Data!$W$2:$W$1056,Data!$U$2:$U$1056,Sheet1!$A10,Data!$C$2:$C$1056,Sheet1!D$3) -> 7.0353077e+08 | E10: =SUMIFS(Data!$W$2:$W$1056,Data!$U$2:$U$1056,Sheet1!$A10,Data!$C$2:$C$1056,Sheet1!E$3) -> 1.05755e+08 | F10: =SUMIFS(Data!$W$2:$W$1056,Data!$U$2:$U$1056,Sheet1!$A10,Data!$C$2:$C$1056,Sheet1!F$3) -> 93507001 | G10: =SUMIFS(Data!$W$2:$W$1056,Data!$U$2:$U$1056,Sheet1!$A10,Data!$C$2:$C$1056,Sheet1!G$3) -> 48409855 | H10: =SUMIFS(Data!$W$2:$W$1056,Data!$U$2:$U$1056,Sheet1!$A10,Data!$C$2:$C$1056,Sheet1!H$3) -> 4.8121401e+08 | I10: =SUMIFS(Data!$W$2:$W$1056,Data!$U$2:$U$1056,Sheet1!$A10,Data!$C$2:$C$1056,Sheet1!I$3) -> 3.4479788e+08 | K10: =SUM(B10:J10) -> 2.8748998e+09
A11: Sanitary Fittings | B11: =SUMIFS(Data!$W$2:$W$1056,Data!$U$2:$U$1056,Sheet1!$A11,Data!$C$2:$C$1056,Sheet1!B$3) -> 2.529536e+08 | C11: =SUMIFS(Data!$W$2:$W$1056,Data!$U$2:$U$1056,Sheet1!$A11,Data!$C$2:$C$1056,Sheet1!C$3) -> 56749711 | D11: =SUMIFS(Data!$W$2:$W$1056,Data!$U$2:$U$1056,Sheet1!$A11,Data!$C$2:$C$1056,Sheet1!D$3) -> 1.9658904e+08 | E11: =SUMIFS(Data!$W$2:$W$1056,Data!$U$2:$U$1056,Sheet1!$A11,Data!$C$2:$C$1056,Sheet1!E$3) -> 15944558 | F11: =SUMIFS(Data!$W$2:$W$1056,Data!$U$2:$U$1056,Sheet1!$A11,Data!$C$2:$C$1056,Sheet1!F$3) -> 76925072 | G11: =SUMIFS(Data!$W$2:$W$1056,Data!$U$2:$U$1056,Sheet1!$A11,Data!$C$2:$C$1056,Sheet1!G$3) -> 17839538 | H11: =SUMIFS(Data!$W$2:$W$1056,Data!$U$2:$U$1056,Sheet1!$A11,Data!$C$2:$C$1056,Sheet1!H$3) -> 38769092 | I11: =SUMIFS(Data!$W$2:$W$1056,Data!$U$2:$U$1056,Sheet1!$A11,Data!$C$2:$C$1056,Sheet1!I$3) -> 2019183 | K11: =SUM(B11:J11) -> 6.577898e+08
A12: Services Equipment | B12: =SUMIFS(Data!$W$2:$W$1056,Data!$U$2:$U$1056,Sheet1!$A12,Data!$C$2:$C$1056,Sheet1!B$3) -> 12418434 | C12: =SUMIFS(Data!$W$2:$W$1056,Data!$U$2:$U$1056,Sheet1!$A12,Data!$C$2:$C$1056,Sheet1!C$3) -> 0 | D12: =SUMIFS(Data!$W$2:$W$1056,Data!$U$2:$U$1056,Sheet1!$A12,Data!$C$2:$C$1056,Sheet1!D$3) -> 21599746 | E12: =SUMIFS(Data!$W$2:$W$1056,Data!$U$2:$U$1056,Sheet1!$A12,Data!$C$2:$C$1056,Sheet1!E$3) -> 9403395 | F12: =SUMIFS(Data!$W$2:$W$1056,Data!$U$2:$U$1056,Sheet1!$A12,Data!$C$2:$C$1056,Sheet1!F$3) -> 0 | G12: =SUMIFS(Data!$W$2:$W$1056,Data!$U$2:$U$1056,Sheet1!$A12,Data!$C$2:$C$1056,Sheet1!G$3) -> 3006379 | H12: =SUMIFS(Data!$W$2:$W$1056,Data!$U$2:$U$1056,Sheet1!$A12,Data!$C$2:$C$1056,Sheet1!H$3) -> 1.414001e+08 | I12: =SUMIFS(Data!$W$2:$W$1056,Data!$U$2:$U$1056,Sheet1!$A12,Data!$C$2:$C$1056,Sheet1!I$3) -> 0 | K12: =SUM(B12:J12) -> 1.8782805e+08
A13: Mechanical | B13: =SUMIFS(Data!$W$2:$W$1056,Data!$U$2:$U$1056,Sheet1!$A13,Data!$C$2:$C$1056,Sheet1!B$3) -> 1.5994269e+09 | C13: =SUMIFS(Data!$W$2:$W$1056,Data!$U$2:$U$1056,Sheet1!$A13,Data!$C$2:$C$1056,Sheet1!C$3) -> 324516477 | D13: =SUMIFS(Data!$W$2:$W$1056,Data!$U$2:$U$1056,Sheet1!$A13,Data!$C$2:$C$1056,Sheet1!D$3) -> 1.5465313e+09 | E13: =SUMIFS(Data!$W$2:$W$1056,Data!$U$2:$U$1056,Sheet1!$A13,Data!$C$2:$C$1056,Sheet1!E$3) -> 1.9316529e+08 | F13: =SUMIFS(Data!$W$2:$W$1056,Data!$U$2:$U$1056,Sheet1!$A13,Data!$C$2:$C$1056,Sheet1!F$3) -> 7.4369798e+08 | G13: =SUMIFS(Data!$W$2:$W$1056,Data!$U$2:$U$1056,Sheet1!$A13,Data!$C$2:$C$1056,Sheet1!G$3) -> 1.9353979e+08 | H13: =SUMIFS(Data!$W$2:$W$1056,Data!$U$2:$U$1056,Sheet1!$A13,Data!$C$2:$C$1056,Sheet1!H$3) -> 3.572437e+08 | I13: =SUMIFS(Data!$W$2:$W$1056,Data!$U$2:$U$1056,Sheet1!$A13,Data!$C$2:$C$1056,Sheet1!I$3) -> 1.3201686e+08 | K13: =SUM(B13:J13) -> 5.0901383e+09
A14: Electrical | B14: =SUMIFS(Data!$W$2:$W$1056,Data!$U$2:$U$1056,Sheet1!$A14,Data!$C$2:$C$1056,Sheet1!B$3) -> 9.7424555e+08 | C14: =SUMIFS(Data!$W$2:$W$1056,Data!$U$2:$U$1056,Sheet1!$A14,Data!$C$2:$C$1056,Sheet1!C$3) -> 145626967 | D14: =SUMIFS(Data!$W$2:$W$1056,Data!$U$2:$U$1056,Sheet1!$A14,Data!$C$2:$C$1056,Sheet1!D$3) -> 1.3244055e+09 | E14: =SUMIFS(Data!$W$2:$W$1056,Data!$U$2:$U$1056,Sheet1!$A14,Data!$C$2:$C$1056,Sheet1!E$3) -> 35337879 | F14: =SUMIFS(Data!$W$2:$W$1056,Data!$U$2:$U$1056,Sheet1!$A14,Data!$C$2:$C$1056,Sheet1!F$3) -> 9.3012091e+08 | G14: =SUMIFS(Data!$W$2:$W$1056,Data!$U$2:$U$1056,Sheet1!$A14,Data!$C$2:$C$1056,Sheet1!G$3) -> 2.819004e+08 | H14: =SUMIFS(Data!$W$2:$W$1056,Data!$U$2:$U$1056,Sheet1!$A14,Data!$C$2:$C$1056,Sheet1!H$3) -> 4.7515453e+08 | I14: =SUMIFS(Data!$W$2:$W$1056,Data!$U$2:$U$1056,Sheet1!$A14,Data!$C$2:$C$1056,Sheet1!I$3) -> 1.9583676e+08 | K14: =SUM(B14:J14) -> 4.3626285e+09
A15: Conveying Systems | B15: =SUMIFS(Data!$W$2:$W$1056,Data!$U$2:$U$1056,Sheet1!$A15,Data!$C$2:$C$1056,Sheet1!B$3) -> 2.1465233e+08 | C15: =SUMIFS(Data!$W$2:$W$1056,Data!$U$2:$U$1056,Sheet1!$A15,Data!$C$2:$C$1056,Sheet1!C$3) -> 0 | D15: =SUMIFS(Data!$W$2:$W$1056,Data!$U$2:$U$1056,Sheet1!$A15,Data!$C$2:$C$1056,Sheet1!D$3) -> 2.1339517e+08 | E15: =SUMIFS(Data!$W$2:$W$1056,Data!$U$2:$U$1056,Sheet1!$A15,Data!$C$2:$C$1056,Sheet1!E$3) -> 30037609 | F15: =SUMIFS(Data!$W$2:$W$1056,Data!$U$2:$U$1056,Sheet1!$A15,Data!$C$2:$C$1056,Sheet1!F$3) -> 1.1099032e+08 | G15: =SUMIFS(Data!$W$2:$W$1056,Data!$U$2:$U$1056,Sheet1!$A15,Data!$C$2:$C$1056,Sheet1!G$3) -> 38609786 | H15: =SUMIFS(Data!$W$2:$W$1056,Data!$U$2:$U$1056,Sheet1!$A15,Data!$C$2:$C$1056,Sheet1!H$3) -> 91534943 | I15: =SUMIFS(Data!$W$2:$W$1056,Data!$U$2:$U$1056,Sheet1!$A15,Data!$C$2:$C$1056,Sheet1!I$3) -> 13449156 | K15: =SUM(B15:J15) -> 7.1266931e+08
A16: External Works | B16: =SUMIFS(Data!$W$2:$W$1056,Data!$U$2:$U$1056,Sheet1!$A16,Data!$C$2:$C$1056,Sheet1!B$3) -> 1.2055403e+09 | C16: =SUMIFS(Data!$W$2:$W$1056,Data!$U$2:$U$1056,Sheet1!$A16,Data!$C$2:$C$1056,Sheet1!C$3) -> 164797790 | D16: =SUMIFS(Data!$W$2:$W$1056,Data!$U$2:$U$1056,Sheet1!$A16,Data!$C$2:$C$1056,Sheet1!D$3) -> 5.1244067e+08 | E16: =SUMIFS(Data!$W$2:$W$1056,Data!$U$2:$U$1056,Sheet1!$A16,Data!$C$2:$C$1056,Sheet1!E$3) -> 14700961 | F16: =SUMIFS(Data!$W$2:$W$1056,Data!$U$2:$U$1056,Sheet1!$A16,Data!$C$2:$C$1056,Sheet1!F$3) -> 2.1463552e+08 | G16: =SUMIFS(Data!$W$2:$W$1056,Data!$U$2:$U$1056,Sheet1!$A16,Data!$C$2:$C$1056,Sheet1!G$3) -> 30743025 | H16: =SUMIFS(Data!$W$2:$W$1056,Data!$U$2:$U$1056,Sheet1!$A16,Data!$C$2:$C$1056,Sheet1!H$3) -> 1.5578615e+08 | I16: =SUMIFS(Data!$W$2:$W$1056,Data!$U$2:$U$1056,Sheet1!$A16,Data!$C$2:$C$1056,Sheet1!I$3) -> 1.7374795e+08 | K16: =SUM(B16:J16) -> 2.4723924e+09
A17: General Requirements | B17: =SUMIFS(Data!$W$2:$W$1056,Data!$U$2:$U$1056,Sheet1!$A17,Data!$C$2:$C$1056,Sheet1!B$3) -> 1.5533865e+09 | C17: =SUMIFS(Data!$W$2:$W$1056,Data!$U$2:$U$1056,Sheet1!$A17,Data!$C$2:$C$1056,Sheet1!C$3) -> 163391460 | D17: =SUMIFS(Data!$W$2:$W$1056,Data!$U$2:$U$1056,Sheet1!$A17,Data!$C$2:$C$1056,Sheet1!D$3) -> 1.456522e+09 | E17: =SUMIFS(Data!$W$2:$W$1056,Data!$U$2:$U$1056,Sheet1!$A17,Data!$C$2:$C$1056,Sheet1!E$3) -> 92637598 | F17: =SUMIFS(Data!$W$2:$W$1056,Data!$U$2:$U$1056,Sheet1!$A17,Data!$C$2:$C$1056,Sheet1!F$3) -> 7.5251571e+08 | G17: =SUMIFS(Data!$W$2:$W$1056,Data!$U$2:$U$1056,Sheet1!$A17,Data!$C$2:$C$1056,Sheet1!G$3) -> 2.1305444e+08 | H17: =SUMIFS(Data!$W$2:$W$1056,Data!$U$2:$U$1056,Sheet1!$A17,Data!$C$2:$C$1056,Sheet1!H$3) -> 4.0655481e+08 | I17: =SUMIFS(Data!$W$2:$W$1056,Data!$U$2:$U$1056,Sheet1!$A17,Data!$C$2:$C$1056,Sheet1!I$3) -> 232280490 | K17: =SUM(B17:J17) -> 4.870343e+09
B19: =SUM(B5:B18) -> 1.5027912e+10 | C19: =SUM(C5:C18) -> 2135108994 | D19: =SUM(D5:D18) -> 1.2371168e+10 | E19: =SUM(E5:E18) -> 9.6279735e+08 | F19: =SUM(F5:F18) -> 5.4685458e+09 | G19: =SUM(G5:G18) -> 1.6469025e+09 | H19: =SUM(H5:H18) -> 4.2392052e+09 | I19: =SUM(I5:I18) -> 2.0585633e+09 | K19: =SUM(K5:K18) -> 4.3910203e+10
A21: Substructure | B21: =B5/B$19 -> 0.055472941 | C21: =C5/C$19 -> 0.077621308 | D21: =D5/D$19 -> 0.078826205 | E21: =E5/E$19 -> 0.06662556 | F21: =F5/F$19 -> 0.078368384 | G21: =G5/G$19 -> 0.15538165 | H21: =H5/H$19 -> 0.080440152 | I21: =I5/I$19 -> 0.043361502 | K21: =K5/K$19 -> 0.071815104
A22: Superstructure | B22: =B6/B$19 -> 0.12397343 | C22: =C6/C$19 -> 0.18224662 | D22: =D6/D$19 -> 0.15190618 | E22: =E6/E$19 -> 0.12068385 | F22: =F6/F$19 -> 0.23246353 | G22: =G6/G$19 -> 0.16055826 | H22: =H6/H$19 -> 0.13865137 | I22: =I6/I$19 -> 0.14247453 | K22: =K6/K$19 -> 0.15177235
A23: Building External Envelope | B23: =B7/B$19 -> 0.19140149 | C23: =C7/C$19 -> 0.1128587 | D23: =D7/D$19 -> 0.12635363 | E23: =E7/E$19 -> 0.11369102 | F23: =F7/F$19 -> 0.036876352 | G23: =G7/G$19 -> 0.091412374 | H23: =H7/H$19 -> 0.10120259 | I23: =I7/I$19 -> 0.2006161 | K23: =K7/K$19 -> 0.13628132
A24: Internal Walls and Doors | B24: =B8/B$19 -> 0.045737121 | C24: =C8/C$19 -> 0.057955154 | D24: =D8/D$19 -> 0.049381261 | E24: =E8/E$19 -> 0.045173438 | F24: =F8/F$19 -> 0.033380605 | G24: =G8/G$19 -> 0.028884324 | H24: =H8/H$19 -> 0.030692727 | I24: =I8/I$19 -> 0.017748533 | K24: =K8/K$19 -> 0.04241003
A25: Internal Finishes | B25: =B9/B$19 -> 0.13380787 | C25: =C9/C$19 -> 0.096867215 | D25: =D9/D$19 -> 0.11055371 | E25: =E9/E$19 -> 0.13764037 | F25: =F9/F$19 -> 0.084510824 | G25: =G9/G$19 -> 0.061545912 | H25: =H9/H$19 -> 0.14239523 | I25: =I9/I$19 -> 0.064288696 | K25: =K9/K$19 -> 0.11426432
A26: FF&E | B26: =B10/B$19 -> 0.062818661 | C26: =C10/C$19 -> 0.071964469 | D26: =D10/D$19 -> 0.056868582 | E26: =E10/E$19 -> 0.10984139 | F26: =F10/F$19 -> 0.017099062 | G26: =G10/G$19 -> 0.029394488 | H26: =H10/H$19 -> 0.11351515 | I26: =I10/I$19 -> 0.16749443 | K26: =K10/K$19 -> 0.065472251
A27: Sanitary Fittings | B27: =B11/B$19 -> 0.016832252 | C27: =C11/C$19 -> 0.026579304 | D27: =D11/D$19 -> 0.015890904 | E27: =E11/E$19 -> 0.016560658 | F27: =F11/F$19 -> 0.014066824 | G27: =G11/G$19 -> 0.010832176 | H27: =H11/H$19 -> 0.0091453682 | I27: =I11/I$19 -> 0.00098087001 | K27: =K11/K$19 -> 0.014980341
A28: Services Equipment | B28: =B12/B$19 -> 0.00082635793 | C28: =C12/C$19 -> 0 | D28: =D12/D$19 -> 0.0017459747 | E28: =E12/E$19 -> 0.0097667437 | F28: =F12/F$19 -> 0 | G28: =G12/G$19 -> 0.0018254748 | H28: =H12/H$19 -> 0.033355333 | I28: =I12/I$19 -> 0 | K28: =K12/K$19 -> 0.0042775492
A29: Mechanical | B29: =B13/B$19 -> 0.10643041 | C29: =C13/C$19 -> 0.15199059 | D29: =D13/D$19 -> 0.12501094 | E29: =E13/E$19 -> 0.20062923 | F29: =F13/F$19 -> 0.13599557 | G29: =G13/G$19 -> 0.11751746 | H29: =H13/H$19 -> 0.084271388 | I29: =I13/I$19 -> 0.064130582 | K29: =K13/K$19 -> 0.11592154
A30: Electrical | B30: =B14/B$19 -> 0.064829069 | C30: =C14/C$19 -> 0.06820587 | D30: =D14/D$19 -> 0.10705582 | E30: =E14/E$19 -> 0.036703341 | F30: =F14/F$19 -> 0.1700856 | G30: =G14/G$19 -> 0.17117006 | H30: =H14/H$19 -> 0.11208576 | I30: =I14/I$19 -> 0.095132739 | K30: =K14/K$19 -> 0.099353413
A31: Conveying Systems | B31: =B15/B$19 -> 0.014283576 | C31: =C15/C$19 -> 0 | D31: =D15/D$19 -> 0.017249396 | E31: =E15/E$19 -> 0.031198267 | F31: =F15/F$19 -> 0.02029613 | G31: =G15/G$19 -> 0.023443881 | H31: =H15/H$19 -> 0.021592478 | I31: =I15/I$19 -> 0.006533273 | K31: =K15/K$19 -> 0.016230153
A32: External Works | B32: =B16/B$19 -> 0.08022008 | C32: =C16/C$19 -> 0.07718472 | D32: =D16/D$19 -> 0.041422175 | E32: =E16/E$19 -> 0.015269009 | F32: =F16/F$19 -> 0.039249103 | G32: =G16/G$19 -> 0.01866718 | H32: =H16/H$19 -> 0.036748906 | I32: =I16/I$19 -> 0.08440253 | K32: =K16/K$19 -> 0.056305647
A33: General Requirements | B33: =B17/B$19 -> 0.10336675 | C33: =C17/C$19 -> 0.076526051 | D33: =D17/D$19 -> 0.11773521 | E33: =E17/E$19 -> 0.096217131 | F33: =F17/F$19 -> 0.13760801 | G33: =G17/G$19 -> 0.12936676 | H33: =H17/H$19 -> 0.095903546 | I33: =I17/I$19 -> 0.11283621 | K33: =K17/K$19 -> 0.11091597
A36: STRUCTURE | B36: =SUM(B21:B23) -> 0.37084785 | C36: =SUM(C21:C23) -> 0.37272663 | D36: =SUM(D21:D23) -> 0.35708602 | E36: =SUM(E21:E23) -> 0.30100043 | F36: =SUM(F21:F23) -> 0.34770827 | G36: =SUM(G21:G23) -> 0.40735229 | H36: =SUM(H21:H23) -> 0.32029411 | I36: =SUM(I21:I23) -> 0.38645213 | K36: =SUM(K21:K23) -> 0.35986878
A37: INTERNAL FIT-OUT | B37: =SUM(B24:B27) -> 0.2591959 | C37: =SUM(C24:C27) -> 0.25336614 | D37: =SUM(D24:D27) -> 0.23269446 | E37: =SUM(E24:E27) -> 0.30921585 | F37: =SUM(F24:F27) -> 0.14905731 | G37: =SUM(G24:G27) -> 0.1306569 | H37: =SUM(H24:H27) -> 0.29574848 | I37: =SUM(I24:I27) -> 0.25051253 | K37: =SUM(K24:K27) -> 0.23712694
A38: MEP | B38: =SUM(B28:B31) -> 0.18636941 | C38: =SUM(C28:C31) -> 0.22019646 | D38: =SUM(D28:D31) -> 0.25106214 | E38: =SUM(E28:E31) -> 0.27829758 | F38: =SUM(F28:F31) -> 0.3263773 | G38: =SUM(G28:G31) -> 0.31395687 | H38: =SUM(H28:H31) -> 0.25130496 | I38: =SUM(I28:I31) -> 0.16579659 | K38: =SUM(K28:K31) -> 0.23578265
A39: EXTEERNAL | B39: =B32 -> 0.08022008 | C39: =C32 -> 0.07718472 | D39: =D32 -> 0.041422175 | E39: =E32 -> 0.015269009 | F39: =F32 -> 0.039249103 | G39: =G32 -> 0.01866718 | H39: =H32 -> 0.036748906 | I39: =I32 -> 0.08440253 | K39: =K32 -> 0.056305647
A40: PRELIMS | B40: =B33 -> 0.10336675 | C40: =C33 -> 0.076526051 | D40: =D33 -> 0.11773521 | E40: =E33 -> 0.096217131 | F40: =F33 -> 0.13760801 | G40: =G33 -> 0.12936676 | H40: =H33 -> 0.095903546 | I40: =I33 -> 0.11283621 | K40: =K33 -> 0.11091597
B41: =SUM(B36:B40) -> 1 | C41: =SUM(C36:C40) -> 1 | D41: =SUM(D36:D40) -> 1 | E41: =SUM(E36:E40) -> 1 | F41: =SUM(F36:F40) -> 1 | G41: =SUM(G36:G40) -> 1 | H41: =SUM(H36:H40) -> 1 | I41: =SUM(I36:I40) -> 1 | K41: =SUM(K36:K40) -> 1
