Workbook

Sheet Rates
A1: Asset | B1: Country | C1: City | D1: Project | E1: Base Date | F1: Contractor | G1: Status | H1: Contract Type | I1: BUA | J1: GIA | K1: GFA | L1: Keys | M1: NRM Lvl 1 | N1: POMI | O1: Description | P1: Quantity | Q1: Unit | R1: Contract Rate | S1: Average Tender Rate
A3: Townhouses | B3: UAE | C3: Dubai | D3: The Valley - Nara | E3: 2022 | F3: METAC | G3: Award | H3: Fixed Price Lump Sum | I3: 69927 | K3: 53764 | L3: 372 | M3: Foundations | N3: Concrete Work | O3: Plain concrete; concrete grade C20/16 | P3: 30 | Q3: m3 | R3: 370 | S3: 309
A4: =A3 -> Townhouses | B4: =B3 -> UAE | C4: =C3 -> Dubai | D4: =D3 -> The Valley - Nara | E4: =E3 -> 2022 | F4: =F3 -> METAC | G4: =G3 -> Award | H4: =H3 -> Fixed Price Lump Sum | M4: Lowest Floor Construction | N4: Concrete Work | O4: Reinforced concrete; concrete grade C25 | P4: 51 | Q4: m3 | R4: 370 | S4: 305

Sheet Data
B1: Asset Lvl 1 | C1: Asset Lvl 2 | D1: Asset Lvl 3 | E1: Country | F1: City | G1: Developer | H1: Alias Lvl 1 | I1: Alias Lvl 2 | J1: Project Lvl 1 | K1: Project Lvl 2 | L1: Base Date | M1: Contractor | N1: Status | O1: Procurement | P1: Contract Type | Q1: BUA | R1: GIA | S1: GFA | T1: Keys | U1: NRM Lvl 1 | V1: Currency | W1: Total Cost | X1: Cost/BUA | Y1: Cost/GIA | Z1: Cost/GFA | AA1: Cost/Key | AB1: Chart
B3: Single Asset | C3: Storage and Distribution | D3: Warehouse | E3: UAE | F3: Abu Dhabi | G3: TBA | I3: Project IND19.1 | K3: Project A | L3: 2019 | M3: TBA | N3: Award | O3: Competitive - Traditional | P3: Fixed Price Lump Sum | Q3: 48016.5 | R3: 45730 | S3: 43443.5 | T3: 0 | U3: Facilitating Works | V3: AED | W3: 1424325 | X3: =W3/Q3 -> 29.663241 | Y3: =W3/R3 -> 31.146403 | Z3: =W3/S3 -> 32.785687 | AB3: YES | AC3: =SUM(W3:W16) -> 1.3932218e+08 | AD3: =W3/AC3 -> 0.010223246
B4: Single Asset | C4: Storage and Distribution | D4: Warehouse | E4: UAE | F4: Abu Dhabi | G4: TBA | I4: Project IND19.1 | K4: Project A | L4: 2019 | M4: TBA | N4: Award | O4: Competitive - Traditional | P4: Fixed Price Lump Sum | Q4: 48016.5 | R4: 45730 | S4: 43443.5 | T4: 0 | U4: Substructure | V4: AED | W4: 27368485 | X4: =W4/Q4 -> 569.98084 | Y4: =W4/R4 -> 598.47988 | Z4: =W4/S4 -> 629.97882 | AB4: YES | AD4: =W4/AC3 -> 0.19644025
B5: Single Asset | C5: Storage and Distribution | D5: Warehouse | E5: UAE | F5: Abu Dhabi | G5: TBA | I5: Project IND19.1 | K5: Project A | L5: 2019 | M5: TBA | N5: Award | O5: Competitive - Traditional | P5: Fixed Price Lump Sum | Q5: 48016.5 | R5: 45730 | S5: 43443.5 | T5: 0 | U5: Superstructure | V5: AED | W5: 20086487 | X5: =W5/Q5 -> 418.32468 | Y5: =W5/R5 -> 439.24091 | Z5: =W5/S5 -> 462.35886 | AB5: YES | AD5: =W5/AC3 -> 0.14417293
B6: Single Asset | C6: Storage and Distribution | D6: Warehouse | E6: UAE | F6: Abu Dhabi | G6: TBA | I6: Project IND19.1 | K6: Project A | L6: 2019 | M6: TBA | N6: Award | O6: Competitive - Traditional | P6: Fixed Price Lump Sum | Q6: 48016.5 | R6: 45730 | S6: 43443.5 | T6: 0 | U6: Building External Envelope | V6: AED | W6: 16069190 | X6: =W6/Q6 -> 334.65974 | Y6: =W6/R6 -> 351.39273 | Z6: =W6/S6 -> 369.88709 | AB6: YES | AD6: =W6/AC3 -> 0.11533834
B7: Single Asset | C7: Storage and Distribution | D7: Warehouse | E7: UAE | F7: Abu Dhabi | G7: TBA | I7: Project IND19.1 | K7: Project A | L7: 2019 | M7: TBA | N7: Award | O7: Competitive - Traditional | P7: Fixed Price Lump Sum | Q7: 48016.5 | R7: 45730 | S7: 43443.5 | T7: 0 | U7: Internal Walls and Doors | V7: AED | W7: 4017297.4 | X7: =W7/Q7 -> 83.664936 | Y7: =W7/R7 -> 87.848183 | Z7: =W7/S7 -> 92.471771 | AB7: YES | AD7: =W7/AC3 -> 0.028834586
B8: Single Asset | C8: Storage and Distribution | D8: Warehouse | E8: UAE | F8: Abu Dhabi | G8: TBA | I8: Project IND19.1 | K8: Project A | L8: 2019 | M8: TBA | N8: Award | O8: Competitive - Traditional | P8: Fixed Price Lump Sum | Q8: 48016.5 | R8: 45730 | S8: 43443.5 | T8: 0 | U8: Internal Finishes | V8: AED | W8: 3360917 | X8: =W8/Q8 -> 69.995043 | Y8: =W8/R8 -> 73.494796 | Z8: =W8/S8 -> 77.362943 | AB8: YES | AD8: =W8/AC3 -> 0.024123344
B9: Single Asset | C9: Storage and Distribution | D9: Warehouse | E9: UAE | F9: Abu Dhabi | G9: TBA | I9: Project IND19.1 | K9: Project A | L9: 2019 | M9: TBA | N9: Award | O9: Competitive - Traditional | P9: Fixed Price Lump Sum | Q9: 48016.5 | R9: 45730 | S9: 43443.5 | T9: 0 | U9: FF&E | V9: AED | W9: 1192620 | X9: =W9/Q9 -> 24.837712 | Y9: =W9/R9 -> 26.079598 | Z9: =W9/S9 -> 27.452208 | AB9: YES | AD9: =W9/AC3 -> 0.0085601588
B10: Single Asset | C10: Storage and Distribution | D10: Warehouse | E10: UAE | F10: Abu Dhabi | G10: TBA | I10: Project IND19.1 | K10: Project A | L10: 2019 | M10: TBA | N10: Award | O10: Competitive - Traditional | P10: Fixed Price Lump Sum | Q10: 48016.5 | R10: 45730 | S10: 43443.5 | T10: 0 | U10: Sanitary Fittings | V10: AED | W10: 0 | X10: =W10/Q10 -> 0 | Y10: =W10/R10 -> 0 | Z10: =W10/S10 -> 0 | AB10: YES | AD10: =W10/AC3 -> 0
B11: Single Asset | C11: Storage and Distribution | D11: Warehouse | E11: UAE | F11: Abu Dhabi | G11: TBA | I11: Project IND19.1 | K11: Project A | L11: 2019 | M11: TBA | N11: Award | O11: Competitive - Traditional | P11: Fixed Price Lump Sum | Q11: 48016.5 | R11: 45730 | S11: 43443.5 | T11: 0 | U11: Services Equipment | V11: AED | W11: 0 | X11: =W11/Q11 -> 0 | Y11: =W11/R11 -> 0 | Z11: =W11/S11 -> 0 | AB11: YES | AD11: =W11/AC3 -> 0
B12: Single Asset | C12: Storage and Distribution | D12: Warehouse | E12: UAE | F12: Abu Dhabi | G12: TBA | I12: Project IND19.1 | K12: Project A | L12: 2019 | M12: TBA | N12: Award | O12: Competitive - Traditional | P12: Fixed Price Lump Sum | Q12: 48016.5 | R12: 45730 | S12: 43443.5 | T12: 0 | U12: Mechanical | V12: AED | W12: 11045654 | X12: =W12/Q12 -> 230.03872 | Y12: =W12/R12 -> 241.54066 | Z12: =W12/S12 -> 254.25333 | AB12: YES | AD12: =W12/AC3 -> 0.079281376
B13: Single Asset | C13: Storage and Distribution | D13: Warehouse | E13: UAE | F13: Abu Dhabi | G13: TBA | I13: Project IND19.1 | K13: Project A | L13: 2019 | M13: TBA | N13: Award | O13: Competitive - Traditional | P13: Fixed Price Lump Sum | Q13: 48016.5 | R13: 45730 | S13: 43443.5 | T13: 0 | U13: Electrical | V13: AED | W13: 9037353.6 | X13: =W13/Q13 -> 188.2135 | Y13: =W13/R13 -> 197.62418 | Z13: =W13/S13 -> 208.02545 | AB13: YES | AD13: =W13/AC3 -> 0.064866581
B14: Single Asset | C14: Storage and Distribution | D14: Warehouse | E14: UAE | F14: Abu Dhabi | G14: TBA | I14: Project IND19.1 | K14: Project A | L14: 2019 | M14: TBA | N14: Award | O14: Competitive - Traditional | P14: Fixed Price Lump Sum | Q14: 48016.5 | R14: 45730 | S14: 43443.5 | T14: 0 | U14: Conveying Systems | V14: AED | W14: 0 | X14: =W14/Q14 -> 0 | Y14: =W14/R14 -> 0 | Z14: =W14/S14 -> 0 | AB14: YES | AD14: =W14/AC3 -> 0
B15: Single Asset | C15: Storage and Distribution | D15: Warehouse | E15: UAE | F15: Abu Dhabi | G15: TBA | I15: Project IND19.1 | K15: Project A | L15: 2019 | M15: TBA | N15: Award | O15: Competitive - Traditional | P15: Fixed Price Lump Sum | Q15: 48016.5 | R15: 45730 | S15: 43443.5 | T15: 0 | U15: External Works | V15: AED | W15: 34216186 | X15: =W15/Q15 -> 712.59227 | Y15: =W15/R15 -> 748.22188 | Z15: =W15/S15 -> 787.60198 | AB15: YES | AD15: =W15/AC3 -> 0.24559037
B16: Single Asset | C16: Storage and Distribution | D16: Warehouse | E16: UAE | F16: Abu Dhabi | G16: TBA | I16: Project IND19.1 | K16: Project A | L16: 2019 | M16: TBA | N16: Award | O16: Competitive - Traditional | P16: Fixed Price Lump Sum | Q16: 48016.5 | R16: 45730 | S16: 43443.5 | T16: 0 | U16: General Requirements | V16: AED | W16: 11503667 | X16: =W16/Q16 -> 239.57737 | Y16: =W16/R16 -> 251.55624 | Z16: =W16/S16 -> 264.79605 | AB16: YES | AD16: =W16/AC3 -> 0.082568811
B17: Single Asset | C17: Manufacturing | D17: Light Assembly | E17: UAE | F17: Abu Dhabi | G17: TBA | I17: Project IND20.1 | K17: Project B | L17: 2020 | M17: TBA | N17: Award | O17: Competitive - Traditional | P17: Fixed Price Lump Sum | Q17: 26865.3 | R17: 25586 | S17: 24306.7 | T17: 0 | U17: Facilitating Works | V17: AED | W17: 1604816 | X17: =W17/Q17 -> 59.735644 | Y17: =W17/R17 -> 62.722426 | Z17: =W17/S17 -> 66.023607 | AB17: YES | AC17: =SUM(W17:W30) -> 1.3025493e+08 | AD17: =W17/AC17 -> 0.012320578
B18: Single Asset | C18: Manufacturing | D18: Light Assembly | E18: UAE | F18: Abu Dhabi | G18: TBA | I18: Project IND20.1 | K18: Project B | L18: 2020 | M18: TBA | N18: Award | O18: Competitive - Traditional | P18: Fixed Price Lump Sum | Q18: 26865.3 | R18: 25586 | S18: 24306.7 | T18: 0 | U18: Substructure | V18: AED | W18: 12048509 | X18: =W18/Q18 -> 448.47849 | Y18: =W18/R18 -> 470.90241 | Z18: =W18/S18 -> 495.68675 | AB18: YES | AD18: =W18/AC17 -> 0.092499446
B19: Single Asset | C19: Manufacturing | D19: Light Assembly | E19: UAE | F19: Abu Dhabi | G19: TBA | I19: Project IND20.1 | K19: Project B | L19: 2020 | M19: TBA | N19: Award | O19: Competitive - Traditional | P19: Fixed Price Lump Sum | Q19: 26865.3 | R19: 25586 | S19: 24306.7 | T19: 0 | U19: Superstructure | V19: AED | W19: 21539241 | X19: =W19/Q19 -> 801.7495 | Y19: =W19/R19 -> 841.83698 | Z19: =W19/S19 -> 886.14419 | AB19: YES | AD19: =W19/AC17 -> 0.16536219
B20: Single Asset | C20: Manufacturing | D20: Light Assembly | E20: UAE | F20: Abu Dhabi | G20: TBA | I20: Project IND20.1 | K20: Project B | L20: 2020 | M20: TBA | N20: Award | O20: Competitive - Traditional | P20: Fixed Price Lump Sum | Q20: 26865.3 | R20: 25586 | S20: 24306.7 | T20: 0 | U20: Building External Envelope | V20: AED | W20: 17231393 | X20: =W20/Q20 -> 641.3996 | Y20: =W20/R20 -> 673.46958 | Z20: =W20/S20 -> 708.91535 | AB20: YES | AD20: =W20/AC17 -> 0.13228975
B21: Single Asset | C21: Manufacturing | D21: Light Assembly | E21: UAE | F21: Abu Dhabi | G21: TBA | I21: Project IND20.1 | K21: Project B | L21: 2020 | M21: TBA | N21: Award | O21: Competitive - Traditional | P21: Fixed Price Lump Sum | Q21: 26865.3 | R21: 25586 | S21: 24306.7 | T21: 0 | U21: Internal Walls and Doors | V21: AED | W21: 4307848.2 | X21: =W21/Q21 -> 160.3499 | Y21: =W21/R21 -> 168.3674 | Z21: =W21/S21 -> 177.22884 | AB21: YES | AD21: =W21/AC17 -> 0.033072438
B22: Single Asset | C22: Manufacturing | D22: Light Assembly | E22: UAE | F22: Abu Dhabi | G22: TBA | I22: Project IND20.1 | K22: Project B | L22: 2020 | M22: TBA | N22: Award | O22: Competitive - Traditional | P22: Fixed Price Lump Sum | Q22: 26865.3 | R22: 25586 | S22: 24306.7 | T22: 0 | U22: Internal Finishes | V22: AED | W22: 7623187 | X22: =W22/Q22 -> 283.75589 | Y22: =W22/R22 -> 297.94368 | Z22: =W22/S22 -> 313.62493 | AB22: YES | AD22: =W22/AC17 -> 0.058525131
B23: Single Asset | C23: Manufacturing | D23: Light Assembly | E23: UAE | F23: Abu Dhabi | G23: TBA | I23: Project IND20.1 | K23: Project B | L23: 2020 | M23: TBA | N23: Award | O23: Competitive - Traditional | P23: Fixed Price Lump Sum | Q23: 26865.3 | R23: 25586 | S23: 24306.7 | T23: 0 | U23: FF&E | V23: AED | W23: 1754020 | X23: =W23/Q23 -> 65.289425 | Y23: =W23/R23 -> 68.553897 | Z23: =W23/S23 -> 72.161996 | AB23: YES | AD23: =W23/AC17 -> 0.013466054
B24: Single Asset | C24: Manufacturing | D24: Light Assembly | E24: UAE | F24: Abu Dhabi | G24: TBA | I24: Project IND20.1 | K24: Project B | L24: 2020 | M24: TBA | N24: Award | O24: Competitive - Traditional | P24: Fixed Price Lump Sum | Q24: 26865.3 | R24: 25586 | S24: 24306.7 | T24: 0 | U24: Sanitary Fittings | V24: AED | W24: 316473.05 | X24: =W24/Q24 -> 11.779993 | Y24: =W24/R24 -> 12.368993 | Z24: =W24/S24 -> 13.019992 | AB24: YES | AD24: =W24/AC17 -> 0.0024296435
B25: Single Asset | C25: Manufacturing | D25: Light Assembly | E25: UAE | F25: Abu Dhabi | G25: TBA | I25: Project IND20.1 | K25: Project B | L25: 2020 | M25: TBA | N25: Award | O25: Competitive - Traditional | P25: Fixed Price Lump Sum | Q25: 26865.3 | R25: 25586 | S25: 24306.7 | T25: 0 | U25: Services Equipment | V25: AED | W25: 0 | X25: =W25/Q25 -> 0 | Y25: =W25/R25 -> 0 | Z25: =W25/S25 -> 0 | AB25: YES | AD25: =W25/AC17 -> 0
B26: Single Asset | C26: Manufacturing | D26: Light Assembly | E26: UAE | F26: Abu Dhabi | G26: TBA | I26: Project IND20.1 | K26: Project B | L26: 2020 | M26: TBA | N26: Award | O26: Competitive - Traditional | P26: Fixed Price Lump Sum | Q26: 26865.3 | R26: 25586 | S26: 24306.7 | T26: 0 | U26: Mechanical | V26: AED | W26: 17089545 | X26: =W26/Q26 -> 636.11963 | Y26: =W26/R26 -> 667.92561 | Z26: =W26/S26 -> 703.07959 | AB26: YES | AD26: =W26/AC17 -> 0.13120075
B27: Single Asset | C27: Manufacturing | D27: Light Assembly | E27: UAE | F27: Abu Dhabi | G27: TBA | I27: Project IND20.1 | K27: Project B | L27: 2020 | M27: TBA | N27: Award | O27: Competitive - Traditional | P27: Fixed Price Lump Sum | Q27: 26865.3 | R27: 25586 | S27: 24306.7 | T27: 0 | U27: Electrical | V27: AED | W27: 14241287 | X27: =W27/Q27 -> 530.09969 | Y27: =W27/R27 -> 556.60468 | Z27: =W27/S27 -> 585.89966 | AB27: YES | AD27: =W27/AC17 -> 0.10933396
B28: Single Asset | C28: Manufacturing | D28: Light Assembly | E28: UAE | F28: Abu Dhabi | G28: TBA | I28: Project IND20.1 | K28: Project B | L28: 2020 | M28: TBA | N28: Award | O28: Competitive - Traditional | P28: Fixed Price Lump Sum | Q28: 26865.3 | R28: 25586 | S28: 24306.7 | T28: 0 | U28: Conveying Systems | V28: AED | W28: 0 | X28: =W28/Q28 -> 0 | Y28: =W28/R28 -> 0 | Z28: =W28/S28 -> 0 | AB28: YES | AD28: =W28/AC17 -> 0
B29: Single Asset | C29: Manufacturing | D29: Light Assembly | E29: UAE | F29: Abu Dhabi | G29: TBA | I29: Project IND20.1 | K29: Project B | L29: 2020 | M29: TBA | N29: Award | O29: Competitive - Traditional | P29: Fixed Price Lump Sum | Q29: 26865.3 | R29: 25586 | S29: 24306.7 | T29: 0 | U29: External Works | V29: AED | W29: 20538614 | X29: =W29/Q29 -> 764.50343 | Y29: =W29/R29 -> 802.7286 | Z29: =W29/S29 -> 844.97748 | AB29: YES | AD29: =W29/AC17 -> 0.15768012
B30: Single Asset | C30: Manufacturing | D30: Light Assembly | E30: UAE | F30: Abu Dhabi | G30: TBA | I30: Project IND20.1 | K30: Project B | L30: 2020 | M30: TBA | N30: Award | O30: Competitive - Traditional | P30: Fixed Price Lump Sum | Q30: 26865.3 | R30: 25586 | S30: 24306.7 | T30: 0 | U30: General Requirements | V30: AED | W30: 11960000 | X30: =W30/Q30 -> 445.18394 | Y30: =W30/R30 -> 467.44313 | Z30: =W30/S30 -> 492.0454 | AB30: YES | AD30: =W30/AC17 -> 0.091819939
B31: Single Asset | C31: Storage and Distribution | D31: Warehouse & Office | E31: UAE | F31: Abu Dhabi | G31: TBA | I31: Project IND22.1 | K31: Project C | L31: 2022 | M31: TBA | N31: Award | O31: Competitive - Traditional | P31: Fixed Price Lump Sum | Q31: 5163.9 | R31: 4918 | S31: 4672.1 | T31: 0 | U31: Facilitating Works | V31: AED | W31: 166618 | X31: =W31/Q31 -> 32.265923 | Y31: =W31/R31 -> 33.879219 | Z31: =W31/S31 -> 35.662336 | AB31: YES | AC31: =SUM(W31:W44) -> 22603454 | AD31: =W31/AC31 -> 0.0073713513
B32: Single Asset | C32: Storage and Distribution | D32: Warehouse & Office | E32: UAE | F32: Abu Dhabi | G32: TBA | I32: Project IND22.1 | K32: Project C | L32: 2022 | M32: TBA | N32: Award | O32: Competitive - Traditional | P32: Fixed Price Lump Sum | Q32: 5163.9 | R32: 4918 | S32: 4672.1 | T32: 0 | U32: Substructure | V32: AED | W32: 5280 | X32: =W32/Q32 -> 1.022483 | Y32: =W32/R32 -> 1.0736072 | Z32: =W32/S32 -> 1.1301128 | AB32: YES | AD32: =W32/AC31 -> 0.00023359262
B33: Single Asset | C33: Storage and Distribution | D33: Warehouse & Office | E33: UAE | F33: Abu Dhabi | G33: TBA | I33: Project IND22.1 | K33: Project C | L33: 2022 | M33: TBA | N33: Award | O33: Competitive - Traditional | P33: Fixed Price Lump Sum | Q33: 5163.9 | R33: 4918 | S33: 4672.1 | T33: 0 | U33: Superstructure | V33: AED | W33: 2048663 | X33: =W33/Q33 -> 396.72786 | Y33: =W33/R33 -> 416.56425 | Z33: =W33/S33 -> 438.48869 | AB33: YES | AD33: =W33/AC31 -> 0.090634953
B34: Single Asset | C34: Storage and Distribution | D34: Warehouse & Office | E34: UAE | F34: Abu Dhabi | G34: TBA | I34: Project IND22.1 | K34: Project C | L34: 2022 | M34: TBA | N34: Award | O34: Competitive - Traditional | P34: Fixed Price Lump Sum | Q34: 5163.9 | R34: 4918 | S34: 4672.1 | T34: 0 | U34: Building External Envelope | V34: AED | W34: 1638930.4 | X34: =W34/Q34 -> 317.38229 | Y34: =W34/R34 -> 333.2514 | Z34: =W34/S34 -> 350.79095 | AB34: YES | AD34: =W34/AC31 -> 0.072507963
B35: Single Asset | C35: Storage and Distribution | D35: Warehouse & Office | E35: UAE | F35: Abu Dhabi | G35: TBA | I35: Project IND22.1 | K35: Project C | L35: 2022 | M35: TBA | N35: Award | O35: Competitive - Traditional | P35: Fixed Price Lump Sum | Q35: 5163.9 | R35: 4918 | S35: 4672.1 | T35: 0 | U35: Internal Walls and Doors | V35: AED | W35: 409732.6 | X35: =W35/Q35 -> 79.345572 | Y35: =W35/R35 -> 83.312851 | Z35: =W35/S35 -> 87.697738 | AB35: YES | AD35: =W35/AC31 -> 0.018126991
B36: Single Asset | C36: Storage and Distribution | D36: Warehouse & Office | E36: UAE | F36: Abu Dhabi | G36: TBA | I36: Project IND22.1 | K36: Project C | L36: 2022 | M36: TBA | N36: Award | O36: Competitive - Traditional | P36: Fixed Price Lump Sum | Q36: 5163.9 | R36: 4918 | S36: 4672.1 | T36: 0 | U36: Internal Finishes | V36: AED | W36: 2820606 | X36: =W36/Q36 -> 546.21623 | Y36: =W36/R36 -> 573.52704 | Z36: =W36/S36 -> 603.71268 | AB36: YES | AD36: =W36/AC31 -> 0.1247865
B37: Single Asset | C37: Storage and Distribution | D37: Warehouse & Office | E37: UAE | F37: Abu Dhabi | G37: TBA | I37: Project IND22.1 | K37: Project C | L37: 2022 | M37: TBA | N37: Award | O37: Competitive - Traditional | P37: Fixed Price Lump Sum | Q37: 5163.9 | R37: 4918 | S37: 4672.1 | T37: 0 | U37: FF&E | V37: AED | W37: 78579 | X37: =W37/Q37 -> 15.216987 | Y37: =W37/R37 -> 15.977837 | Z37: =W37/S37 -> 16.818775 | AB37: YES | AD37: =W37/AC31 -> 0.0034764156
B38: Single Asset | C38: Storage and Distribution | D38: Warehouse & Office | E38: UAE | F38: Abu Dhabi | G38: TBA | I38: Project IND22.1 | K38: Project C | L38: 2022 | M38: TBA | N38: Award | O38: Competitive - Traditional | P38: Fixed Price Lump Sum | Q38: 5163.9 | R38: 4918 | S38: 4672.1 | T38: 0 | U38: Sanitary Fittings | V38: AED | W38: 74295.81 | X38: =W38/Q38 -> 14.387538 | Y38: =W38/R38 -> 15.106915 | Z38: =W38/S38 -> 15.902016 | AB38: YES | AD38: =W38/AC31 -> 0.0032869229
B39: Single Asset | C39: Storage and Distribution | D39: Warehouse & Office | E39: UAE | F39: Abu Dhabi | G39: TBA | I39: Project IND22.1 | K39: Project C | L39: 2022 | M39: TBA | N39: Award | O39: Competitive - Traditional | P39: Fixed Price Lump Sum | Q39: 5163.9 | R39: 4918 | S39: 4672.1 | T39: 0 | U39: Services Equipment | V39: AED | W39: 0 | X39: =W39/Q39 -> 0 | Y39: =W39/R39 -> 0 | Z39: =W39/S39 -> 0 | AB39: YES | AD39: =W39/AC31 -> 0
B40: Single Asset | C40: Storage and Distribution | D40: Warehouse & Office | E40: UAE | F40: Abu Dhabi | G40: TBA | I40: Project IND22.1 | K40: Project C | L40: 2022 | M40: TBA | N40: Award | O40: Competitive - Traditional | P40: Fixed Price Lump Sum | Q40: 5163.9 | R40: 4918 | S40: 4672.1 | T40: 0 | U40: Mechanical | V40: AED | W40: 4011973.7 | X40: =W40/Q40 -> 776.92708 | Y40: =W40/R40 -> 815.77343 | Z40: =W40/S40 -> 858.70888 | AB40: YES | AD40: =W40/AC31 -> 0.17749384
B41: Single Asset | C41: Storage and Distribution | D41: Warehouse & Office | E41: UAE | F41: Abu Dhabi | G41: TBA | I41: Project IND22.1 | K41: Project C | L41: 2022 | M41: TBA | N41: Award | O41: Competitive - Traditional | P41: Fixed Price Lump Sum | Q41: 5163.9 | R41: 4918 | S41: 4672.1 | T41: 0 | U41: Electrical | V41: AED | W41: 3343311.5 | X41: =W41/Q41 -> 647.43923 | Y41: =W41/R41 -> 679.81119 | Z41: =W41/S41 -> 715.59073 | AB41: YES | AD41: =W41/AC31 -> 0.14791153
...

Sheet Sheet1
B2: =COUNTIF(Data!$C$2:$C$87,Sheet1!B3)/14 -> 3 | C2: =COUNTIF(Data!$C$2:$C$87,Sheet1!C3)/14 -> 3
B3: Manufacturing | C3: Storage and Distribution | E3: Totals
A5: Facilitating Works | B5: =SUMIFS(Data!$W$2:$W$87,Data!$U$2:$U$87,Sheet1!$A5,Data!$C$2:$C$87,Sheet1!B$3) -> 2455306 | C5: =SUMIFS(Data!$W$2:$W$87,Data!$U$2:$U$87,Sheet1!$A5,Data!$C$2:$C$87,Sheet1!C$3) -> 2909849 | E5: =SUM(B5:D5) -> 5365155
A6: Substructure | B6: =SUMIFS(Data!$W$2:$W$87,Data!$U$2:$U$87,Sheet1!$A6,Data!$C$2:$C$87,Sheet1!B$3) -> 15935227 | C6: =SUMIFS(Data!$W$2:$W$87,Data!$U$2:$U$87,Sheet1!$A6,Data!$C$2:$C$87,Sheet1!C$3) -> 39873765 | E6: =SUM(B6:D6) -> 55808992
A7: Superstructure | B7: =SUMIFS(Data!$W$2:$W$87,Data!$U$2:$U$87,Sheet1!$A7,Data!$C$2:$C$87,Sheet1!B$3) -> 27564288 | C7: =SUMIFS(Data!$W$2:$W$87,Data!$U$2:$U$87,Sheet1!$A7,Data!$C$2:$C$87,Sheet1!C$3) -> 36375421 | E7: =SUM(B7:D7) -> 63939709
A8: Building External Envelope | B8: =SUMIFS(Data!$W$2:$W$87,Data!$U$2:$U$87,Sheet1!$A8,Data!$C$2:$C$87,Sheet1!B$3) -> 22051431 | C8: =SUMIFS(Data!$W$2:$W$87,Data!$U$2:$U$87,Sheet1!$A8,Data!$C$2:$C$87,Sheet1!C$3) -> 29100337 | E8: =SUM(B8:D8) -> 51151768
A9: Internal Walls and Doors | B9: =SUMIFS(Data!$W$2:$W$87,Data!$U$2:$U$87,Sheet1!$A9,Data!$C$2:$C$87,Sheet1!B$3) -> 5512857.7 | C9: =SUMIFS(Data!$W$2:$W$87,Data!$U$2:$U$87,Sheet1!$A9,Data!$C$2:$C$87,Sheet1!C$3) -> 7275084.2 | E9: =SUM(B9:D9) -> 12787942
A10: Internal Finishes | B10: =SUMIFS(Data!$W$2:$W$87,Data!$U$2:$U$87,Sheet1!$A10,Data!$C$2:$C$87,Sheet1!B$3) -> 8329895 | C10: =SUMIFS(Data!$W$2:$W$87,Data!$U$2:$U$87,Sheet1!$A10,Data!$C$2:$C$87,Sheet1!C$3) -> 9431418 | E10: =SUM(B10:D10) -> 17761313
A11: FF&E | B11: =SUMIFS(Data!$W$2:$W$87,Data!$U$2:$U$87,Sheet1!$A11,Data!$C$2:$C$87,Sheet1!B$3) -> 1900562 | C11: =SUMIFS(Data!$W$2:$W$87,Data!$U$2:$U$87,Sheet1!$A11,Data!$C$2:$C$87,Sheet1!C$3) -> 1885601 | E11: =SUM(B11:D11) -> 3786163
A12: Sanitary Fittings | B12: =SUMIFS(Data!$W$2:$W$87,Data!$U$2:$U$87,Sheet1!$A12,Data!$C$2:$C$87,Sheet1!B$3) -> 435255.93 | C12: =SUMIFS(Data!$W$2:$W$87,Data!$U$2:$U$87,Sheet1!$A12,Data!$C$2:$C$87,Sheet1!C$3) -> 339534.63 | E12: =SUM(B12:D12) -> 774790.56
A13: Services Equipment | B13: =SUMIFS(Data!$W$2:$W$87,Data!$U$2:$U$87,Sheet1!$A13,Data!$C$2:$C$87,Sheet1!B$3) -> 0 | C13: =SUMIFS(Data!$W$2:$W$87,Data!$U$2:$U$87,Sheet1!$A13,Data!$C$2:$C$87,Sheet1!C$3) -> 0 | E13: =SUM(B13:D13) -> 0
A14: Mechanical | B14: =SUMIFS(Data!$W$2:$W$87,Data!$U$2:$U$87,Sheet1!$A14,Data!$C$2:$C$87,Sheet1!B$3) -> 23503820 | C14: =SUMIFS(Data!$W$2:$W$87,Data!$U$2:$U$87,Sheet1!$A14,Data!$C$2:$C$87,Sheet1!C$3) -> 29380524 | E14: =SUM(B14:D14) -> 52884345
A15: Electrical | B15: =SUMIFS(Data!$W$2:$W$87,Data!$U$2:$U$87,Sheet1!$A15,Data!$C$2:$C$87,Sheet1!B$3) -> 19586517 | C15: =SUMIFS(Data!$W$2:$W$87,Data!$U$2:$U$87,Sheet1!$A15,Data!$C$2:$C$87,Sheet1!C$3) -> 24316412 | E15: =SUM(B15:D15) -> 43902929
A16: Conveying Systems | B16: =SUMIFS(Data!$W$2:$W$87,Data!$U$2:$U$87,Sheet1!$A16,Data!$C$2:$C$87,Sheet1!B$3) -> 0 | C16: =SUMIFS(Data!$W$2:$W$87,Data!$U$2:$U$87,Sheet1!$A16,Data!$C$2:$C$87,Sheet1!C$3) -> 0 | E16: =SUM(B16:D16) -> 0
... A18: General Requirements | B18: =SUMIFS(Data!$W$2:$W$87,Data!$U$2:$U$87,Sheet1!$A18,Data!$C$2:$C$87,Sheet1!B$3) -> 13567059 | C18: =SUMIFS(Data!$W$2:$W$87,Data!$U$2:$U$87,Sheet1!$A18,Data!$C$2:$C$87,Sheet1!C$3) -> 20177667 | E18: =SUM(B18:D18) -> 33744726
B20: =SUM(B5:B19) -> 1.6320743e+08 | C20: =SUM(C5:C19) -> 2.4975728e+08 | E20: =SUM(E5:E19) -> 4.1296471e+08
A22: Facilitating Works | B22: =B5/B$20 -> 0.015044082 | C22: =C5/C$20 -> 0.011650708 | E22: =E5/E$20 -> 0.0129918
A23: Substructure | B23: =B6/B$20 -> 0.097637875 | C23: =C6/C$20 -> 0.15965006 | E23: =E6/E$20 -> 0.13514228
A24: Superstructure | B24: =B7/B$20 -> 0.16889113 | C24: =C7/C$20 -> 0.14564309 | E24: =E7/E$20 -> 0.15483093
A25: Building External Envelope | B25: =B8/B$20 -> 0.13511291 | C25: =C8/C$20 -> 0.11651447 | E25: =E8/E$20 -> 0.12386474
A26: Internal Walls and Doors | B26: =B9/B$20 -> 0.033778226 | C26: =C9/C$20 -> 0.029128617 | E26: =E9/E$20 -> 0.030966185
A27: Internal Finishes | B27: =B10/B$20 -> 0.051038698 | C27: =C10/C$20 -> 0.037762335 | E27: =E10/E$20 -> 0.043009275
A28: FF&E | B28: =B11/B$20 -> 0.01164507 | C28: =C11/C$20 -> 0.007549734 | E28: =E11/E$20 -> 0.0091682482
A29: Sanitary Fittings | B29: =B12/B$20 -> 0.0026668879 | C29: =C12/C$20 -> 0.0013594584 | E29: =E12/E$20 -> 0.0018761665
A30: Services Equipment | B30: =B13/B$20 -> 0 | C30: =C13/C$20 -> 0 | E30: =E13/E$20 -> 0
A31: Mechanical | B31: =B14/B$20 -> 0.14401195 | C31: =C14/C$20 -> 0.11763631 | E31: =E14/E$20 -> 0.1280602
A32: Electrical | B32: =B15/B$20 -> 0.12000995 | C32: =C15/C$20 -> 0.097360174 | E32: =E15/E$20 -> 0.10631157
A33: Conveying Systems | B33: =B16/B$20 -> 0 | C33: =C16/C$20 -> 0 | E33: =E16/E$20 -> 0
... A35: General Requirements | B35: =B18/B$20 -> 0.083127702 | C35: =C18/C$20 -> 0.080789105 | E35: =E18/E$20 -> 0.08171334
A38: STRUCTURE | B38: =SUM(B22:B25) -> 0.41668599 | C38: =SUM(C22:C25) -> 0.43345833 | E38: =SUM(E22:E25) -> 0.42682975
A39: INTERNAL FIT-OUT | B39: =SUM(B26:B29) -> 0.099128882 | C39: =SUM(C26:C29) -> 0.075800145 | E39: =SUM(E26:E29) -> 0.085019876
A40: MEP | B40: =SUM(B30:B33) -> 0.2640219 | C40: =SUM(C30:C33) -> 0.21499648 | E40: =SUM(E30:E33) -> 0.23437178
A41: EXTEERNAL | B41: =B34 -> 0.13703552 | C41: =C34 -> 0.19495594 | E41: =E34 -> 0.17206526
A42: PRELIMS | B42: =B35 -> 0.083127702 | C42: =C35 -> 0.080789105 | E42: =E35 -> 0.08171334
B43: =SUM(B38:B42) -> 1 | C43: =SUM(C38:C42) -> 1 | E43: =SUM(E38:E42) -> 1
