Workbook
Name \__: #REF!
Name \0: #REF!
Name \0: #REF!
Name \0: #N/A
Name \1: "#REF!"
Name \3671: #REF!
Name \A: #REF!
Name \AA: #REF!
Name \ab: #REF!
Name \B: #REF!
Name \b: #N/A
Name \BA: "#REF!"
Name \c: #N/A
Name \C: #REF!
Name \C: #REF!
Name \CALCS: "#REF!"
Name \CC: #REF!
Name \D: #REF!
Name \DATA: "#REF!"
Name \E: #REF!
Name \F: #REF!
Name \G: #REF!
Name \gvfbd: #REF!
Name \gzfbhxcn: #REF!
Name \h: #REF!
Name \I: #REF!
Name \i: #N/A
Name \INSERT: "#REF!"
Name \j: #REF!
Name \k: #REF!
Name \l: #REF!
Name \LA: "#REF!"
Name \LP: "#REF!"
Name \LPS: "#REF!"
Name \m: #REF!
Name \MENU: "#REF!"
Name \n: #REF!
Name \o: #REF!
Name \OO: #REF!
Name \p: #N/A
Name \p: #REF!
Name \PRIME: "#REF!"
Name \PRINT: "#REF!"
Name \Q: #REF!
Name \q: #N/A
Name \r: #REF!
Name \s: #N/A
Name \SORT: "#REF!"
Name \t: #REF!
Name \U: #REF!
Name \V: #REF!
Name \v1: #REF!
Name \w: "#REF!"
Name \X: #REF!
Name \X: #REF!
Name \Y: #REF!
Name \z: #REF!
Name \Z: #REF!
Name \Z: #REF!
Name \z: #N/A

Sheet Building
C3: Scope | D3: (Multiple Items)
C5: Sum of Element Rate | D5: Column Labels
C6: Row Labels | D6: PROJECT 1 Low Rise | E6: PROJECT 3 Mid Rise | F6: PROJECT 5 High Rise | G6: PROJECT 6 High Rise | H6: PROJECT 2 Low Rise | I6: PROJECT 4A Mid Rise | J6: PROJECT 4B Mid Rise
C7: Substructure | D7: 589.9803 | E7: 594.86581 | F7: 617.31212 | G7: 545.08 | H7: 601.71625 | I7: 650 | J7: 572.0189
C8: Superstructure | D8: 1001.3 | E8: 1191.8597 | F8: 1447.4739 | G8: 1736.9687 | H8: 1441.417 | I8: 750 | J8: 1062.0403
C9: Building External Envelope | D9: 1156.329 | E9: 1141.4016 | F9: 1014.5703 | G9: 995.62244 | H9: 1126.4742 | I9: 393.55793 | J9: 1141.4016
C10: Internal Walls and Doors | D10: 189.45266 | E10: 140.2757 | F10: 153.63058 | G10: 397.404 | H10: 229.36243 | I10: 143.80656 | J10: 241.0282
C11: Internal Finishes | D11: 364.90458 | E11: 546.59152 | F11: 507.13993 | G11: 601.25067 | H11: 474.30868 | I11: 200.56366 | J11: 373.57759
C12: FF&E | D12: 32.948289 | E12: 98.128713 | F12: 110.68981 | G12: 170 | H12: 53.839147 | I12: 82.957606 | J12: 129.85718
C13: Sanitary Fittings | D13: 47.363165 | E13: 9.6741862 | F13: 108.919 | G13: 116.28 | H13: 36.10156 | I13: 81.630449 | J13: 83.368326
C14: Services Equipment | D14: 10.29634 | E14: 20.960737 | F14: 46.700281 | G14: 45 | H14: 16.919026 | I14: 10.817758 | J14: 19.5
C15: Mechanical | D15: 875.6979 | E15: 1035.1379 | F15: 1086.0617 | G15: 1252.86 | H15: 822.55123 | I15: 806.47367 | J15: 785.48212
C16: Electrical | D16: 745.45503 | E16: 1181.8631 | F16: 1219.1509 | G16: 1568.184 | H16: 816.76494 | I16: 714.46314 | J16: 870.11785
C17: Conveying Systems | D17: 94.41744 | E17: 227.0209 | F17: 209.91109 | G17: 152.76 | H17: 44.454315 | I17: 106.80776 | J17: 169.13155
C18: External Works | D18: 499.47547 | E18: 588.42368 | F18: 418.18821 | G18: 943.10328 | H18: 637.71753 | I18: 403.01749 | J18: 436.53237
... C20: Grand Total | D20: 5607.6202 | E20: 6776.2036 | F20: 6939.7479 | G20: 8524.5131 | H20: 6301.6264 | I20: 4344.096 | J20: 5884.056
C46: Scope | D46: 02- Multi Family
C48: Sum of Element Rate | D48: Column Labels
C49: Row Labels | D49: MF PROJECT 1 | E49: MF PROJECT 2 | F49: MF PROJECT 3 | G49: MF PROJECT 4 | H49: MF PROJECT 5 | I49: MF PROJECT 6
C50: General Requirements | D50: 0 | E50: 0 | F50: 0 | G50: 0 | H50: 0 | I50: 0
C51: Substructure | D51: 373 | E51: 452 | F51: 456 | G51: 314 | H51: 286 | I51: 294
C52: Superstructure | D52: 892 | E52: 927 | F52: 922 | G52: 891.8 | H52: 951 | I52: 767
C53: Building External Envelope | D53: 409 | E53: 415 | F53: 683.8 | G53: 954 | H53: 663 | I53: 978
C54: Internal Walls and Doors | D54: 317 | E54: 540 | F54: 238 | G54: 590 | H54: 196 | I54: 440
C55: Internal Finishes | D55: 675 | E55: 605 | F55: 1010 | G55: 1138 | H55: 549 | I55: 1172
C56: FF&E | D56: 413 | E56: 394 | F56: 232 | G56: 359 | H56: 307 | I56: 481
C57: Sanitary Fittings | D57: 85 | E57: 117 | F57: 88 | G57: 181 | H57: 68 | I57: 155
C58: Services Equipment | D58: 51 | E58: 56 | F58: 94 | G58: 94 | H58: 175 | I58: 94
C59: Mechanical | D59: 759 | E59: 781 | F59: 968 | G59: 1108 | H59: 1503 | I59: 1421
C60: Electrical | D60: 1292 | E60: 1303 | F60: 1377 | G60: 1040 | H60: 1376 | I60: 1212
C61: Conveying Systems | D61: 278 | E61: 276 | F61: 102 | G61: 160 | H61: 197 | I61: 53
... C63: Grand Total | D63: 5988 | E63: 6335 | F63: 6733.8 | G63: 7402.8 | H63: 6773 | I63: 7625

Sheet GCover

Sheet QA.QC
A1: Quality Assurance
A3: CONTROLLED DOCUMENT DISTRIBUTION
A5: VERSION | B5: date of issue | C5: method | D5: issued to
A6: Rev 00
A12: QUALITY ASSURANCE & CONTACT DETAILS
A14: QA / QC CHECK | B14: NAME | C14: CONTACT TELEPHONE | D14: E-MAIL ADDRESS
A15: Prepared By
A19: Checked By
A28: Approved By

Sheet Contents
A2: Contents
A4: Section | C4: Headings
A5: Section 1 | C5: Introduction
A6: Section 2 | C6: Executive Summary
B7: 2.2 | C7: Executive Summary Building
B8: 2.2 | C8: Executive Summary infrastructure
A9: Section 3 | C9: Dataset
A10: Section 4 | C10: Data Interrogation Charts
A11: Section 5
A12: Section 6
A13: Section 7
A14: Section 8

Sheet 1. Introduction
A2: 1. Introduction
A4: 1.1 Project Data
A6: Project/asset name | B6: RUA Al Madinah Superblock 5
A8: Building type | B8: Hotels + Residential Apartment Building + 4 Level Common Basement
A10: Fit out level | B10: Complete Building including Fit out
A12: Construction stage duration (Months) | B12: TBC
A14: Procurement stage | B14: Detail Design
A16: Gross internal area (GIA) | B16: 642637.65 | C16: m2
A18: Gross external area (GEA) | B18: 670375 | C18: m2
A26: Building Type: | B26: Hotels + Residential Apartment Building + 4 Level Common Basement (Mixed Used)
A28: Scope of works: | B28: The Superblock 5 consists of 4 and 5 star international hotels, as well as one apartment building. All the 18 no. buildings will share a common 4 level basement.
A30: Enabling works: | B30: Traditional bulk excavation of a depth of 12 meters, Shoring & Piling
A32: Substructure: | B32: Four level basements to accommodate parking and MEP services
A34: Superstructure: | B34: Construction of 18 nrs of hotel towers + residential towers which are in 3 clusters; superstructure levels varies from 12 floors to 21 floors
A36: Envelope: | B36: Aesthetic envelop consist with curtain walls and building façade
A38: Internal fitting out: | B38: All the fitting out and finishes consist with high-end
A40: Heating and cooling: | B40: Central cooling, Centralized hot and cold water system.
A42: Electrical and data: | B42: MEP services to medium specifications; Electrical main and sub main, power, lighting, fire fighting, communication systems and security systems.
A44: External works: | B44: Asphalt roads, pre-cast concrete pavers, hydraulically pressed precast kerbs, natural granite, soft scaping and irrigation system to planting, site furniture, water features
A46: Procurement Route: | B46: The Cost Plan prepared based on the traditional procurement method, designed by the employer.
A54: 1.2 Basis of Costs
A56: a) The Detail Design Cost Plan has been priced based on Q1 2024 market rates.
A57: b) The area schedules used have been prepared by De Leeuw International based on the Drawings provided.
A58: c) All areas indicated above are subject to design development and could vary as a consequence of site surveys, Planning and NOC requirements.
A59: d) At this stage of design development all quantities shown are indicative and to be refined when the design evolves
A60: e) All the quantities have been provided by Rua (via P&T design consultant). Omnium have carried out the pricing exercise for the BoQ and produced the estimate.
A61: 1.3 Assumptions
A63: General
A64: a) Excavated material can be disposed within 30km of the site location.
A65: b) The majority of building materials are available locally or within Gulf Corporation countries; international specifications are minimal.
A67: Civil/Structural/Architectural
A68: a) 4m level difference in site levels considered for pricing
... A216: - ongoing supply chain issues due to Covid pandemic

Sheet Exec Summ Buildings
B2: Residential | E2: Multi Family | H2: Commercial | K2: Retail
A3: Group Elements | B3: Villa Average | C3: Townhouse Average | D3: Duplex Average | E3: Low-rise Average | F3: Mid-rise Average | G3: High Rise Average | H3: Com-Low-rise Average | I3: Com-Mid-rise Average | J3: Com-High Rise Average | K3: Neighbourhood Centre Average | L3: District Centre (Community Mall) Average | M3: Mixed Use Retail Average | N3: Outlet Mall Average | O3: Lifestyle Retail Average | P3: Regional Mall Average
A4: Substructure | B4: =+INDEX('Building Pivot'!$B$11:$BJ$23,MATCH($A4,'Building Pivot'!$A$11:$A$23,0),MATCH(B$3,'Building Pivot'!$B$9:$BJ$9,0)) -> 316.25 | C4: =+INDEX('Building Pivot'!$B$11:$BJ$23,MATCH($A4,'Building Pivot'!$A$11:$A$23,0),MATCH(C$3,'Building Pivot'!$B$9:$BJ$9,0)) -> 230.66667 | D4: =+INDEX('Building Pivot'!$B$11:$BJ$23,MATCH(A4,'Building Pivot'!$A$11:$A$23,0),MATCH(D$3,'Building Pivot'!$B$9:$BJ$9,0)) -> 230.5 | E4: =+INDEX('Building Pivot'!$B$11:$BJ$23,MATCH($A4,'Building Pivot'!$A$11:$A$23,0),MATCH(E$3,'Building Pivot'!$B$9:$BJ$9,0)) -> 294 | F4: =+INDEX('Building Pivot'!$B$11:$BJ$23,MATCH($A4,'Building Pivot'!$A$11:$A$23,0),MATCH(F$3,'Building Pivot'!$B$9:$BJ$9,0)) -> 352 | G4: =+INDEX('Building Pivot'!$B$11:$BJ$23,MATCH($A4,'Building Pivot'!$A$11:$A$23,0),MATCH(G$3,'Building Pivot'!$B$9:$BJ$9,0)) -> 412.5 | H4: =+INDEX('Building Pivot'!$B$11:$BJ$23,MATCH($A4,'Building Pivot'!$A$11:$A$23,0),MATCH(H$3,'Building Pivot'!$B$9:$BJ$9,0)) -> 595.84827 | I4: =+INDEX('Building Pivot'!$B$11:$BJ$23,MATCH($A4,'Building Pivot'!$A$11:$A$23,0),MATCH(I$3,'Building Pivot'!$B$9:$BJ$9,0)) -> 605.62824 | J4: =+INDEX('Building Pivot'!$B$11:$BJ$23,MATCH($A4,'Building Pivot'!$A$11:$A$23,0),MATCH(J$3,'Building Pivot'!$B$9:$BJ$9,0)) -> 581.19606 | K4: =+INDEX('Building Pivot'!$B$11:$BJ$23,MATCH($A4,'Building Pivot'!$A$11:$A$23,0),MATCH(K$3,'Building Pivot'!$B$9:$BJ$9,0)) -> 660 | L4: =+INDEX('Building Pivot'!$B$11:$BJ$23,MATCH($A4,'Building Pivot'!$A$11:$A$23,0),MATCH(L$3,'Building Pivot'!$B$9:$BJ$9,0)) -> 557 | ... P4: =+INDEX('Building Pivot'!$B$11:$BJ$23,MATCH($A4,'Building Pivot'!$A$11:$A$23,0),MATCH(P$3,'Building Pivot'!$B$9:$BJ$9,0)) -> 651
A5: Superstructure | B5: =+INDEX('Building Pivot'!$B$11:$BJ$23,MATCH($A5,'Building Pivot'!$A$11:$A$23,0),MATCH(B$3,'Building Pivot'!$B$9:$BJ$9,0)) -> 554.25 | C5: =+INDEX('Building Pivot'!$B$11:$BJ$23,MATCH($A5,'Building Pivot'!$A$11:$A$23,0),MATCH(C$3,'Building Pivot'!$B$9:$BJ$9,0)) -> 435 | D5: =+INDEX('Building Pivot'!$B$11:$BJ$23,MATCH(A5,'Building Pivot'!$A$11:$A$23,0),MATCH(D$3,'Building Pivot'!$B$9:$BJ$9,0)) -> 450.5 | E5: =+INDEX('Building Pivot'!$B$11:$BJ$23,MATCH($A5,'Building Pivot'!$A$11:$A$23,0),MATCH(E$3,'Building Pivot'!$B$9:$BJ$9,0)) -> 767 | F5: =+INDEX('Building Pivot'!$B$11:$BJ$23,MATCH($A5,'Building Pivot'!$A$11:$A$23,0),MATCH(F$3,'Building Pivot'!$B$9:$BJ$9,0)) -> 921.6 | G5: =+INDEX('Building Pivot'!$B$11:$BJ$23,MATCH($A5,'Building Pivot'!$A$11:$A$23,0),MATCH(G$3,'Building Pivot'!$B$9:$BJ$9,0)) -> 909.5 | H5: =+INDEX('Building Pivot'!$B$11:$BJ$23,MATCH($A5,'Building Pivot'!$A$11:$A$23,0),MATCH(H$3,'Building Pivot'!$B$9:$BJ$9,0)) -> 1221.3585 | I5: =+INDEX('Building Pivot'!$B$11:$BJ$23,MATCH($A5,'Building Pivot'!$A$11:$A$23,0),MATCH(I$3,'Building Pivot'!$B$9:$BJ$9,0)) -> 1001.3 | J5: =+INDEX('Building Pivot'!$B$11:$BJ$23,MATCH($A5,'Building Pivot'!$A$11:$A$23,0),MATCH(J$3,'Building Pivot'!$B$9:$BJ$9,0)) -> 1592.2213 | K5: =+INDEX('Building Pivot'!$B$11:$BJ$23,MATCH($A5,'Building Pivot'!$A$11:$A$23,0),MATCH(K$3,'Building Pivot'!$B$9:$BJ$9,0)) -> 850 | L5: =+INDEX('Building Pivot'!$B$11:$BJ$23,MATCH($A5,'Building Pivot'!$A$11:$A$23,0),MATCH(L$3,'Building Pivot'!$B$9:$BJ$9,0)) -> 1463 | ... P5: =+INDEX('Building Pivot'!$B$11:$BJ$23,MATCH($A5,'Building Pivot'!$A$11:$A$23,0),MATCH(P$3,'Building Pivot'!$B$9:$BJ$9,0)) -> 1460.5
A6: Building External Envelope | B6: =+INDEX('Building Pivot'!$B$11:$BJ$23,MATCH($A6,'Building Pivot'!$A$11:$A$23,0),MATCH(B$3,'Building Pivot'!$B$9:$BJ$9,0)) -> 805.775 | C6: =+INDEX('Building Pivot'!$B$11:$BJ$23,MATCH($A6,'Building Pivot'!$A$11:$A$23,0),MATCH(C$3,'Building Pivot'!$B$9:$BJ$9,0)) -> 755.33333 | D6: =+INDEX('Building Pivot'!$B$11:$BJ$23,MATCH($A6,'Building Pivot'!$A$11:$A$23,0),MATCH(D$3,'Building Pivot'!$B$9:$BJ$9,0)) -> 896.75 | E6: =+INDEX('Building Pivot'!$B$11:$BJ$23,MATCH($A6,'Building Pivot'!$A$11:$A$23,0),MATCH(E$3,'Building Pivot'!$B$9:$BJ$9,0)) -> 978 | F6: =+INDEX('Building Pivot'!$B$11:$BJ$23,MATCH($A6,'Building Pivot'!$A$11:$A$23,0),MATCH(F$3,'Building Pivot'!$B$9:$BJ$9,0)) -> 766.93333 | G6: =+INDEX('Building Pivot'!$B$11:$BJ$23,MATCH($A6,'Building Pivot'!$A$11:$A$23,0),MATCH(G$3,'Building Pivot'!$B$9:$BJ$9,0)) -> 412 | H6: =+INDEX('Building Pivot'!$B$11:$BJ$23,MATCH($A6,'Building Pivot'!$A$11:$A$23,0),MATCH(H$3,'Building Pivot'!$B$9:$BJ$9,0)) -> 1141.4016 | I6: =+INDEX('Building Pivot'!$B$11:$BJ$23,MATCH($A6,'Building Pivot'!$A$11:$A$23,0),MATCH(I$3,'Building Pivot'!$B$9:$BJ$9,0)) -> 892.12039 | ... P6: =+INDEX('Building Pivot'!$B$11:$BJ$23,MATCH($A6,'Building Pivot'!$A$11:$A$23,0),MATCH(P$3,'Building Pivot'!$B$9:$BJ$9,0)) -> 974.9
A7: Internal Walls and Doors | B7: =+INDEX('Building Pivot'!$B$11:$BJ$23,MATCH($A7,'Building Pivot'!$A$11:$A$23,0),MATCH(B$3,'Building Pivot'!$B$9:$BJ$9,0)) -> 238 | C7: =+INDEX('Building Pivot'!$B$11:$BJ$23,MATCH($A7,'Building Pivot'!$A$11:$A$23,0),MATCH(C$3,'Building Pivot'!$B$9:$BJ$9,0)) -> 243.66667 | D7: =+INDEX('Building Pivot'!$B$11:$BJ$23,MATCH(A7,'Building Pivot'!$A$11:$A$23,0),MATCH(D$3,'Building Pivot'!$B$9:$BJ$9,0)) -> 297.5 | E7: =+INDEX('Building Pivot'!$B$11:$BJ$23,MATCH($A7,'Building Pivot'!$A$11:$A$23,0),MATCH(E$3,'Building Pivot'!$B$9:$BJ$9,0)) -> 440 | F7: =+INDEX('Building Pivot'!$B$11:$BJ$23,MATCH($A7,'Building Pivot'!$A$11:$A$23,0),MATCH(F$3,'Building Pivot'!$B$9:$BJ$9,0)) -> 341.33333 | G7: =+INDEX('Building Pivot'!$B$11:$BJ$23,MATCH($A7,'Building Pivot'!$A$11:$A$23,0),MATCH(G$3,'Building Pivot'!$B$9:$BJ$9,0)) -> 428.5 | H7: =+INDEX('Building Pivot'!$B$11:$BJ$23,MATCH($A7,'Building Pivot'!$A$11:$A$23,0),MATCH(H$3,'Building Pivot'!$B$9:$BJ$9,0)) -> 209.40754 | I7: =+INDEX('Building Pivot'!$B$11:$BJ$23,MATCH($A7,'Building Pivot'!$A$11:$A$23,0),MATCH(I$3,'Building Pivot'!$B$9:$BJ$9,0)) -> 175.03682 | J7: =+INDEX('Building Pivot'!$B$11:$BJ$23,MATCH($A7,'Building Pivot'!$A$11:$A$23,0),MATCH(J$3,'Building Pivot'!$B$9:$BJ$9,0)) -> 275.51729 | K7: =+INDEX('Building Pivot'!$B$11:$BJ$23,MATCH($A7,'Building Pivot'!$A$11:$A$23,0),MATCH(K$3,'Building Pivot'!$B$9:$BJ$9,0)) -> 45 | L7: =+INDEX('Building Pivot'!$B$11:$BJ$23,MATCH($A7,'Building Pivot'!$A$11:$A$23,0),MATCH(L$3,'Building Pivot'!$B$9:$BJ$9,0)) -> 209 | ... P7: =+INDEX('Building Pivot'!$B$11:$BJ$23,MATCH($A7,'Building Pivot'!$A$11:$A$23,0),MATCH(P$3,'Building Pivot'!$B$9:$BJ$9,0)) -> 169
A8: Internal Finishes | B8: =+INDEX('Building Pivot'!$B$11:$BJ$23,MATCH($A8,'Building Pivot'!$A$11:$A$23,0),MATCH(B$3,'Building Pivot'!$B$9:$BJ$9,0)) -> 314.5 | C8: =+INDEX('Building Pivot'!$B$11:$BJ$23,MATCH($A8,'Building Pivot'!$A$11:$A$23,0),MATCH(C$3,'Building Pivot'!$B$9:$BJ$9,0)) -> 270.66667 | D8: =+INDEX('Building Pivot'!$B$11:$BJ$23,MATCH(A8,'Building Pivot'!$A$11:$A$23,0),MATCH(D$3,'Building Pivot'!$B$9:$BJ$9,0)) -> 158 | E8: =+INDEX('Building Pivot'!$B$11:$BJ$23,MATCH($A8,'Building Pivot'!$A$11:$A$23,0),MATCH(E$3,'Building Pivot'!$B$9:$BJ$9,0)) -> 1172 | F8: =+INDEX('Building Pivot'!$B$11:$BJ$23,MATCH($A8,'Building Pivot'!$A$11:$A$23,0),MATCH(F$3,'Building Pivot'!$B$9:$BJ$9,0)) -> 899 | G8: =+INDEX('Building Pivot'!$B$11:$BJ$23,MATCH($A8,'Building Pivot'!$A$11:$A$23,0),MATCH(G$3,'Building Pivot'!$B$9:$BJ$9,0)) -> 640 | H8: =+INDEX('Building Pivot'!$B$11:$BJ$23,MATCH($A8,'Building Pivot'!$A$11:$A$23,0),MATCH(H$3,'Building Pivot'!$B$9:$BJ$9,0)) -> 419.60663 | I8: =+INDEX('Building Pivot'!$B$11:$BJ$23,MATCH($A8,'Building Pivot'!$A$11:$A$23,0),MATCH(I$3,'Building Pivot'!$B$9:$BJ$9,0)) -> 373.57759 | J8: =+INDEX('Building Pivot'!$B$11:$BJ$23,MATCH($A8,'Building Pivot'!$A$11:$A$23,0),MATCH(J$3,'Building Pivot'!$B$9:$BJ$9,0)) -> 554.1953 | K8: =+INDEX('Building Pivot'!$B$11:$BJ$23,MATCH($A8,'Building Pivot'!$A$11:$A$23,0),MATCH(K$3,'Building Pivot'!$B$9:$BJ$9,0)) -> 120 | L8: =+INDEX('Building Pivot'!$B$11:$BJ$23,MATCH($A8,'Building Pivot'!$A$11:$A$23,0),MATCH(L$3,'Building Pivot'!$B$9:$BJ$9,0)) -> 383 | ... P8: =+INDEX('Building Pivot'!$B$11:$BJ$23,MATCH($A8,'Building Pivot'!$A$11:$A$23,0),MATCH(P$3,'Building Pivot'!$B$9:$BJ$9,0)) -> 309
A9: FF&E | B9: =+INDEX('Building Pivot'!$B$11:$BJ$23,MATCH($A9,'Building Pivot'!$A$11:$A$23,0),MATCH(B$3,'Building Pivot'!$B$9:$BJ$9,0)) -> 189 | C9: =+INDEX('Building Pivot'!$B$11:$BJ$23,MATCH($A9,'Building Pivot'!$A$11:$A$23,0),MATCH(C$3,'Building Pivot'!$B$9:$BJ$9,0)) -> 161.66667 | D9: =+INDEX('Building Pivot'!$B$11:$BJ$23,MATCH(A9,'Building Pivot'!$A$11:$A$23,0),MATCH(D$3,'Building Pivot'!$B$9:$BJ$9,0)) -> 106 | E9: =+INDEX('Building Pivot'!$B$11:$BJ$23,MATCH($A9,'Building Pivot'!$A$11:$A$23,0),MATCH(E$3,'Building Pivot'!$B$9:$BJ$9,0)) -> 481 | F9: =+INDEX('Building Pivot'!$B$11:$BJ$23,MATCH($A9,'Building Pivot'!$A$11:$A$23,0),MATCH(F$3,'Building Pivot'!$B$9:$BJ$9,0)) -> 299.33333 | G9: =+INDEX('Building Pivot'!$B$11:$BJ$23,MATCH($A9,'Building Pivot'!$A$11:$A$23,0),MATCH(G$3,'Building Pivot'!$B$9:$BJ$9,0)) -> 403.5 | H9: =+INDEX('Building Pivot'!$B$11:$BJ$23,MATCH($A9,'Building Pivot'!$A$11:$A$23,0),MATCH(H$3,'Building Pivot'!$B$9:$BJ$9,0)) -> 43.393718 | I9: =+INDEX('Building Pivot'!$B$11:$BJ$23,MATCH($A9,'Building Pivot'!$A$11:$A$23,0),MATCH(I$3,'Building Pivot'!$B$9:$BJ$9,0)) -> 103.64783 | J9: =+INDEX('Building Pivot'!$B$11:$BJ$23,MATCH($A9,'Building Pivot'!$A$11:$A$23,0),MATCH(J$3,'Building Pivot'!$B$9:$BJ$9,0)) -> 140.34491 | K9: =+INDEX('Building Pivot'!$B$11:$BJ$23,MATCH($A9,'Building Pivot'!$A$11:$A$23,0),MATCH(K$3,'Building Pivot'!$B$9:$BJ$9,0)) -> 115 | L9: =+INDEX('Building Pivot'!$B$11:$BJ$23,MATCH($A9,'Building Pivot'!$A$11:$A$23,0),MATCH(L$3,'Building Pivot'!$B$9:$BJ$9,0)) -> 209 | ... P9: =+INDEX('Building Pivot'!$B$11:$BJ$23,MATCH($A9,'Building Pivot'!$A$11:$A$23,0),MATCH(P$3,'Building Pivot'!$B$9:$BJ$9,0)) -> 121.5
A10: Sanitary Fittings | B10: =+INDEX('Building Pivot'!$B$11:$BJ$23,MATCH($A10,'Building Pivot'!$A$11:$A$23,0),MATCH(B$3,'Building Pivot'!$B$9:$BJ$9,0)) -> 76.25 | C10: =+INDEX('Building Pivot'!$B$11:$BJ$23,MATCH($A10,'Building Pivot'!$A$11:$A$23,0),MATCH(C$3,'Building Pivot'!$B$9:$BJ$9,0)) -> 63.333333 | D10: =+INDEX('Building Pivot'!$B$11:$BJ$23,MATCH(A10,'Building Pivot'!$A$11:$A$23,0),MATCH(D$3,'Building Pivot'!$B$9:$BJ$9,0)) -> 66.25 | E10: =+INDEX('Building Pivot'!$B$11:$BJ$23,MATCH($A10,'Building Pivot'!$A$11:$A$23,0),MATCH(E$3,'Building Pivot'!$B$9:$BJ$9,0)) -> 155 | F10: =+INDEX('Building Pivot'!$B$11:$BJ$23,MATCH($A10,'Building Pivot'!$A$11:$A$23,0),MATCH(F$3,'Building Pivot'!$B$9:$BJ$9,0)) -> 112.33333 | G10: =+INDEX('Building Pivot'!$B$11:$BJ$23,MATCH($A10,'Building Pivot'!$A$11:$A$23,0),MATCH(G$3,'Building Pivot'!$B$9:$BJ$9,0)) -> 101 | H10: =+INDEX('Building Pivot'!$B$11:$BJ$23,MATCH($A10,'Building Pivot'!$A$11:$A$23,0),MATCH(H$3,'Building Pivot'!$B$9:$BJ$9,0)) -> 41.732363 | I10: =+INDEX('Building Pivot'!$B$11:$BJ$23,MATCH($A10,'Building Pivot'!$A$11:$A$23,0),MATCH(I$3,'Building Pivot'!$B$9:$BJ$9,0)) -> 58.22432 | J10: =+INDEX('Building Pivot'!$B$11:$BJ$23,MATCH($A10,'Building Pivot'!$A$11:$A$23,0),MATCH(J$3,'Building Pivot'!$B$9:$BJ$9,0)) -> 112.5995 | K10: =+INDEX('Building Pivot'!$B$11:$BJ$23,MATCH($A10,'Building Pivot'!$A$11:$A$23,0),MATCH(K$3,'Building Pivot'!$B$9:$BJ$9,0)) -> 25 | L10: =+INDEX('Building Pivot'!$B$11:$BJ$23,MATCH($A10,'Building Pivot'!$A$11:$A$23,0),MATCH(L$3,'Building Pivot'!$B$9:$BJ$9,0)) -> 70 | ... P10: =+INDEX('Building Pivot'!$B$11:$BJ$23,MATCH($A10,'Building Pivot'!$A$11:$A$23,0),MATCH(P$3,'Building Pivot'!$B$9:$BJ$9,0)) -> 82
A11: Services Equipment | B11: =+INDEX('Building Pivot'!$B$11:$BJ$23,MATCH($A11,'Building Pivot'!$A$11:$A$23,0),MATCH(B$3,'Building Pivot'!$B$9:$BJ$9,0)) -> 0 | C11: =+INDEX('Building Pivot'!$B$11:$BJ$23,MATCH($A11,'Building Pivot'!$A$11:$A$23,0),MATCH(C$3,'Building Pivot'!$B$9:$BJ$9,0)) -> 0 | D11: =+INDEX('Building Pivot'!$B$11:$BJ$23,MATCH(A11,'Building Pivot'!$A$11:$A$23,0),MATCH(D$3,'Building Pivot'!$B$9:$BJ$9,0)) -> 0 | E11: =+INDEX('Building Pivot'!$B$11:$BJ$23,MATCH($A11,'Building Pivot'!$A$11:$A$23,0),MATCH(E$3,'Building Pivot'!$B$9:$BJ$9,0)) -> 94 | F11: =+INDEX('Building Pivot'!$B$11:$BJ$23,MATCH($A11,'Building Pivot'!$A$11:$A$23,0),MATCH(F$3,'Building Pivot'!$B$9:$BJ$9,0)) -> 121 | G11: =+INDEX('Building Pivot'!$B$11:$BJ$23,MATCH($A11,'Building Pivot'!$A$11:$A$23,0),MATCH(G$3,'Building Pivot'!$B$9:$BJ$9,0)) -> 53.5 | H11: =+INDEX('Building Pivot'!$B$11:$BJ$23,MATCH($A11,'Building Pivot'!$A$11:$A$23,0),MATCH(H$3,'Building Pivot'!$B$9:$BJ$9,0)) -> 13.607683 | I11: =+INDEX('Building Pivot'!$B$11:$BJ$23,MATCH($A11,'Building Pivot'!$A$11:$A$23,0),MATCH(I$3,'Building Pivot'!$B$9:$BJ$9,0)) -> 17.092831 | J11: =+INDEX('Building Pivot'!$B$11:$BJ$23,MATCH($A11,'Building Pivot'!$A$11:$A$23,0),MATCH(J$3,'Building Pivot'!$B$9:$BJ$9,0)) -> 45.850141 | K11: =+INDEX('Building Pivot'!$B$11:$BJ$23,MATCH($A11,'Building Pivot'!$A$11:$A$23,0),MATCH(K$3,'Building Pivot'!$B$9:$BJ$9,0)) -> 0 | L11: =+INDEX('Building Pivot'!$B$11:$BJ$23,MATCH($A11,'Building Pivot'!$A$11:$A$23,0),MATCH(L$3,'Building Pivot'!$B$9:$BJ$9,0)) -> 0 | ... P11: =+INDEX('Building Pivot'!$B$11:$BJ$23,MATCH($A11,'Building Pivot'!$A$11:$A$23,0),MATCH(P$3,'Building Pivot'!$B$9:$BJ$9,0)) -> 53
A12: Mechanical | B12: =+INDEX('Building Pivot'!$B$11:$BJ$23,MATCH($A12,'Building Pivot'!$A$11:$A$23,0),MATCH(B$3,'Building Pivot'!$B$9:$BJ$9,0)) -> 545.75 | C12: =+INDEX('Building Pivot'!$B$11:$BJ$23,MATCH($A12,'Building Pivot'!$A$11:$A$23,0),MATCH(C$3,'Building Pivot'!$B$9:$BJ$9,0)) -> 530.95833 | D12: =+INDEX('Building Pivot'!$B$11:$BJ$23,MATCH(A12,'Building Pivot'!$A$11:$A$23,0),MATCH(D$3,'Building Pivot'!$B$9:$BJ$9,0)) -> 568 | E12: =+INDEX('Building Pivot'!$B$11:$BJ$23,MATCH($A12,'Building Pivot'!$A$11:$A$23,0),MATCH(E$3,'Building Pivot'!$B$9:$BJ$9,0)) -> 1421 | F12: =+INDEX('Building Pivot'!$B$11:$BJ$23,MATCH($A12,'Building Pivot'!$A$11:$A$23,0),MATCH(F$3,'Building Pivot'!$B$9:$BJ$9,0)) -> 1193 | G12: =+INDEX('Building Pivot'!$B$11:$BJ$23,MATCH($A12,'Building Pivot'!$A$11:$A$23,0),MATCH(G$3,'Building Pivot'!$B$9:$BJ$9,0)) -> 770 | H12: =+INDEX('Building Pivot'!$B$11:$BJ$23,MATCH($A12,'Building Pivot'!$A$11:$A$23,0),MATCH(H$3,'Building Pivot'!$B$9:$BJ$9,0)) -> 849.12457 | I12: =+INDEX('Building Pivot'!$B$11:$BJ$23,MATCH($A12,'Building Pivot'!$A$11:$A$23,0),MATCH(I$3,'Building Pivot'!$B$9:$BJ$9,0)) -> 875.6979 | J12: =+INDEX('Building Pivot'!$B$11:$BJ$23,MATCH($A12,'Building Pivot'!$A$11:$A$23,0),MATCH(J$3,'Building Pivot'!$B$9:$BJ$9,0)) -> 1169.4609 | K12: =+INDEX('Building Pivot'!$B$11:$BJ$23,MATCH($A12,'Building Pivot'!$A$11:$A$23,0),MATCH(K$3,'Building Pivot'!$B$9:$BJ$9,0)) -> 520 | L12: =+INDEX('Building Pivot'!$B$11:$BJ$23,MATCH($A12,'Building Pivot'!$A$11:$A$23,0),MATCH(L$3,'Building Pivot'!$B$9:$BJ$9,0)) -> 836 | ... P12: =+INDEX('Building Pivot'!$B$11:$BJ$23,MATCH($A12,'Building Pivot'!$A$11:$A$23,0),MATCH(P$3,'Building Pivot'!$B$9:$BJ$9,0)) -> 810.5
A13: Electrical | B13: =+INDEX('Building Pivot'!$B$11:$BJ$23,MATCH($A13,'Building Pivot'!$A$11:$A$23,0),MATCH(B$3,'Building Pivot'!$B$9:$BJ$9,0)) -> 417.25 | C13: =+INDEX('Building Pivot'!$B$11:$BJ$23,MATCH($A13,'Building Pivot'!$A$11:$A$23,0),MATCH(C$3,'Building Pivot'!$B$9:$BJ$9,0)) -> 438.20833 | D13: =+INDEX('Building Pivot'!$B$11:$BJ$23,MATCH(A13,'Building Pivot'!$A$11:$A$23,0),MATCH(D$3,'Building Pivot'!$B$9:$BJ$9,0)) -> 476 | E13: =+INDEX('Building Pivot'!$B$11:$BJ$23,MATCH($A13,'Building Pivot'!$A$11:$A$23,0),MATCH(E$3,'Building Pivot'!$B$9:$BJ$9,0)) -> 1212 | F13: =+INDEX('Building Pivot'!$B$11:$BJ$23,MATCH($A13,'Building Pivot'!$A$11:$A$23,0),MATCH(F$3,'Building Pivot'!$B$9:$BJ$9,0)) -> 1264.3333 | G13: =+INDEX('Building Pivot'!$B$11:$BJ$23,MATCH($A13,'Building Pivot'!$A$11:$A$23,0),MATCH(G$3,'Building Pivot'!$B$9:$BJ$9,0)) -> 1297.5 | H13: =+INDEX('Building Pivot'!$B$11:$BJ$23,MATCH($A13,'Building Pivot'!$A$11:$A$23,0),MATCH(H$3,'Building Pivot'!$B$9:$BJ$9,0)) -> 781.10999 | I13: =+INDEX('Building Pivot'!$B$11:$BJ$23,MATCH($A13,'Building Pivot'!$A$11:$A$23,0),MATCH(I$3,'Building Pivot'!$B$9:$BJ$9,0)) -> 922.14802 | J13: =+INDEX('Building Pivot'!$B$11:$BJ$23,MATCH($A13,'Building Pivot'!$A$11:$A$23,0),MATCH(J$3,'Building Pivot'!$B$9:$BJ$9,0)) -> 1393.6675 | K13: =+INDEX('Building Pivot'!$B$11:$BJ$23,MATCH($A13,'Building Pivot'!$A$11:$A$23,0),MATCH(K$3,'Building Pivot'!$B$9:$BJ$9,0)) -> 1110 | L13: =+INDEX('Building Pivot'!$B$11:$BJ$23,MATCH($A13,'Building Pivot'!$A$11:$A$23,0),MATCH(L$3,'Building Pivot'!$B$9:$BJ$9,0)) -> 1115 | ... P13: =+INDEX('Building Pivot'!$B$11:$BJ$23,MATCH($A13,'Building Pivot'!$A$11:$A$23,0),MATCH(P$3,'Building Pivot'!$B$9:$BJ$9,0)) -> 1314.5
A14: Conveying Systems | B14: =+INDEX('Building Pivot'!$B$11:$BJ$23,MATCH($A14,'Building Pivot'!$A$11:$A$23,0),MATCH(B$3,'Building Pivot'!$B$9:$BJ$9,0)) -> 0 | C14: =+INDEX('Building Pivot'!$B$11:$BJ$23,MATCH($A14,'Building Pivot'!$A$11:$A$23,0),MATCH(C$3,'Building Pivot'!$B$9:$BJ$9,0)) -> 0 | D14: =+INDEX('Building Pivot'!$B$11:$BJ$23,MATCH(A14,'Building Pivot'!$A$11:$A$23,0),MATCH(D$3,'Building Pivot'!$B$9:$BJ$9,0)) -> 0 | E14: =+INDEX('Building Pivot'!$B$11:$BJ$23,MATCH($A14,'Building Pivot'!$A$11:$A$23,0),MATCH(E$3,'Building Pivot'!$B$9:$BJ$9,0)) -> 53 | F14: =+INDEX('Building Pivot'!$B$11:$BJ$23,MATCH($A14,'Building Pivot'!$A$11:$A$23,0),MATCH(F$3,'Building Pivot'!$B$9:$BJ$9,0)) -> 153 | G14: =+INDEX('Building Pivot'!$B$11:$BJ$23,MATCH($A14,'Building Pivot'!$A$11:$A$23,0),MATCH(G$3,'Building Pivot'!$B$9:$BJ$9,0)) -> 277 | H14: =+INDEX('Building Pivot'!$B$11:$BJ$23,MATCH($A14,'Building Pivot'!$A$11:$A$23,0),MATCH(H$3,'Building Pivot'!$B$9:$BJ$9,0)) -> 69.435878 | I14: =+INDEX('Building Pivot'!$B$11:$BJ$23,MATCH($A14,'Building Pivot'!$A$11:$A$23,0),MATCH(I$3,'Building Pivot'!$B$9:$BJ$9,0)) -> 167.65341 | J14: =+INDEX('Building Pivot'!$B$11:$BJ$23,MATCH($A14,'Building Pivot'!$A$11:$A$23,0),MATCH(J$3,'Building Pivot'!$B$9:$BJ$9,0)) -> 181.33555 | K14: =+INDEX('Building Pivot'!$B$11:$BJ$23,MATCH($A14,'Building Pivot'!$A$11:$A$23,0),MATCH(K$3,'Building Pivot'!$B$9:$BJ$9,0)) -> 0 | L14: =+INDEX('Building Pivot'!$B$11:$BJ$23,MATCH($A14,'Building Pivot'!$A$11:$A$23,0),MATCH(L$3,'Building Pivot'!$B$9:$BJ$9,0)) -> 0 | ... P14: =+INDEX('Building Pivot'!$B$11:$BJ$23,MATCH($A14,'Building Pivot'!$A$11:$A$23,0),MATCH(P$3,'Building Pivot'!$B$9:$BJ$9,0)) -> 198.5
A15: External Works | B15: =+INDEX('Building Pivot'!$B$11:$BJ$23,MATCH($A15,'Building Pivot'!$A$11:$A$23,0),MATCH(B$3,'Building Pivot'!$B$9:$BJ$9,0)) -> 213.25 | C15: =+INDEX('Building Pivot'!$B$11:$BJ$23,MATCH($A15,'Building Pivot'!$A$11:$A$23,0),MATCH(C$3,'Building Pivot'!$B$9:$BJ$9,0)) -> 286.66667 | D15: =+INDEX('Building Pivot'!$B$11:$BJ$23,MATCH(A15,'Building Pivot'!$A$11:$A$23,0),MATCH(D$3,'Building Pivot'!$B$9:$BJ$9,0)) -> 197 | E15: =+INDEX('Building Pivot'!$B$11:$BJ$23,MATCH($A15,'Building Pivot'!$A$11:$A$23,0),MATCH(E$3,'Building Pivot'!$B$9:$BJ$9,0)) -> 558 | F15: =+INDEX('Building Pivot'!$B$11:$BJ$23,MATCH($A15,'Building Pivot'!$A$11:$A$23,0),MATCH(F$3,'Building Pivot'!$B$9:$BJ$9,0)) -> 546 | G15: =+INDEX('Building Pivot'!$B$11:$BJ$23,MATCH($A15,'Building Pivot'!$A$11:$A$23,0),MATCH(G$3,'Building Pivot'!$B$9:$BJ$9,0)) -> 456.5 | H15: =+INDEX('Building Pivot'!$B$11:$BJ$23,MATCH($A15,'Building Pivot'!$A$11:$A$23,0),MATCH(H$3,'Building Pivot'!$B$9:$BJ$9,0)) -> 568.5965 | I15: =+INDEX('Building Pivot'!$B$11:$BJ$23,MATCH($A15,'Building Pivot'!$A$11:$A$23,0),MATCH(I$3,'Building Pivot'!$B$9:$BJ$9,0)) -> 475.99118 | J15: =+INDEX('Building Pivot'!$B$11:$BJ$23,MATCH($A15,'Building Pivot'!$A$11:$A$23,0),MATCH(J$3,'Building Pivot'!$B$9:$BJ$9,0)) -> 680.64575 | K15: =+INDEX('Building Pivot'!$B$11:$BJ$23,MATCH($A15,'Building Pivot'!$A$11:$A$23,0),MATCH(K$3,'Building Pivot'!$B$9:$BJ$9,0)) -> 243 | L15: =+INDEX('Building Pivot'!$B$11:$BJ$23,MATCH($A15,'Building Pivot'!$A$11:$A$23,0),MATCH(L$3,'Building Pivot'!$B$9:$BJ$9,0)) -> 366 | ... P15: =+INDEX('Building Pivot'!$B$11:$BJ$23,MATCH($A15,'Building Pivot'!$A$11:$A$23,0),MATCH(P$3,'Building Pivot'!$B$9:$BJ$9,0)) -> 396
A16: General Requirements | B16: =+INDEX('Building Pivot'!$B$11:$BJ$23,MATCH($A16,'Building Pivot'!$A$11:$A$23,0),MATCH(B$3,'Building Pivot'!$B$9:$BJ$9,0)) -> 0 | C16: =+INDEX('Building Pivot'!$B$11:$BJ$23,MATCH($A16,'Building Pivot'!$A$11:$A$23,0),MATCH(C$3,'Building Pivot'!$B$9:$BJ$9,0)) -> 0 | D16: =+INDEX('Building Pivot'!$B$11:$BJ$23,MATCH(A16,'Building Pivot'!$A$11:$A$23,0),MATCH(D$3,'Building Pivot'!$B$9:$BJ$9,0)) -> 0 | E16: =+INDEX('Building Pivot'!$B$11:$BJ$23,MATCH($A16,'Building Pivot'!$A$11:$A$23,0),MATCH(E$3,'Building Pivot'!$B$9:$BJ$9,0)) -> 0 | F16: =+INDEX('Building Pivot'!$B$11:$BJ$23,MATCH($A16,'Building Pivot'!$A$11:$A$23,0),MATCH(F$3,'Building Pivot'!$B$9:$BJ$9,0)) -> 0 | G16: =+INDEX('Building Pivot'!$B$11:$BJ$23,MATCH($A16,'Building Pivot'!$A$11:$A$23,0),MATCH(G$3,'Building Pivot'!$B$9:$BJ$9,0)) -> 0 | H16: =+INDEX('Building Pivot'!$B$11:$BJ$23,MATCH($A16,'Building Pivot'!$A$11:$A$23,0),MATCH(H$3,'Building Pivot'!$B$9:$BJ$9,0)) -> 0 | I16: =+INDEX('Building Pivot'!$B$11:$BJ$23,MATCH($A16,'Building Pivot'!$A$11:$A$23,0),MATCH(I$3,'Building Pivot'!$B$9:$BJ$9,0)) -> 0 | J16: =+INDEX('Building Pivot'!$B$11:$BJ$23,MATCH($A16,'Building Pivot'!$A$11:$A$23,0),MATCH(J$3,'Building Pivot'!$B$9:$BJ$9,0)) -> 0 | K16: =+INDEX('Building Pivot'!$B$11:$BJ$23,MATCH($A16,'Building Pivot'!$A$11:$A$23,0),MATCH(K$3,'Building Pivot'!$B$9:$BJ$9,0)) -> 0 | L16: =+INDEX('Building Pivot'!$B$11:$BJ$23,MATCH($A16,'Building Pivot'!$A$11:$A$23,0),MATCH(L$3,'Building Pivot'!$B$9:$BJ$9,0)) -> 0 | ... P16: =+INDEX('Building Pivot'!$B$11:$BJ$23,MATCH($A16,'Building Pivot'!$A$11:$A$23,0),MATCH(P$3,'Building Pivot'!$B$9:$BJ$9,0)) -> 0
A17: Total | B17: =+SUM(B4:B16) -> 3670.275 | C17: =+SUM(C4:C16) -> 3416.1667 | D17: =+SUM(D4:D16) -> 3446.5 | E17: =+SUM(E4:E16) -> 7625 | F17: =+SUM(F4:F16) -> 6969.8667 | G17: =+SUM(G4:G16) -> 6161.5 | H17: =+SUM(H4:H16) -> 5954.6233 | I17: =+SUM(I4:I16) -> 5668.1185 | ... P17: =+SUM(P4:P16) -> 6540.4

Sheet Exec Summ Infra
AA3: Average | AB3: Max
B4: Desnsity | C4: Low to Use | D4: Mid to Use | E4: High to Use | F4: =+'[3]ROM Temp'!H$1 -> Low | G4: =+'[3]ROM Temp'!I$1 -> Low | H4: =+'[3]ROM Temp'!J$1 -> Low | I4: =+'[3]ROM Temp'!K$1 -> Low | J4: =+'[3]ROM Temp'!L$1 -> Low | K4: =+'[3]ROM Temp'!M$1 -> Low | L4: =+'[3]ROM Temp'!N$1 -> Low | M4: =+'[3]ROM Temp'!O$1 -> Low | ... W4: =+'[3]ROM Temp'!Y$1 -> Low | X4: =+'[3]ROM Temp'!AA$1 -> Low | Y4: =+'[3]ROM Temp'!AB$1 -> Low | Z4: =+'[3]ROM Temp'!AE$1 -> Low | AC4: =+'[3]ROM Temp'!AD$1 -> Mid | AD4: =+'[3]ROM Temp'!Z$1 -> Mid | AE4: =+'[3]ROM Temp'!AF$1 -> Mid | AH4: =+'[3]ROM Temp'!AC$1 -> High
B5: FAR | F5: =+'[3]ROM Temp'!H$2 -> 0.68168455 | G5: =+'[3]ROM Temp'!I$2 -> 0.65438664 | H5: =+'[3]ROM Temp'!J$2 -> 0.68351082 | I5: =+'[3]ROM Temp'!K$2 -> 0.60029375 | J5: =+'[3]ROM Temp'!L$2 -> 0.6 | K5: =+'[3]ROM Temp'!M$2 -> 0.6 | L5: =+'[3]ROM Temp'!N$2 -> 0.6 | M5: =+'[3]ROM Temp'!O$2 -> 0.65496894 | ... W5: =+'[3]ROM Temp'!Y$2 -> 0.4670758 | X5: =+'[3]ROM Temp'!AA$2 -> 0.584307 | Y5: =+'[3]ROM Temp'!AB$2 -> 0.25114043 | Z5: =+'[3]ROM Temp'!AE$2 -> 0.6 | AA5: =AVERAGEIF(F5:Z5,"<>0") -> 0.52061739 | AB5: =+MAX(F5:Z5) -> 0.68351082 | AC5: =+'[3]ROM Temp'!AD$2 -> 1.1 | AD5: =+'[3]ROM Temp'!Z$2 -> 1.0549914 | AE5: =+'[3]ROM Temp'!AF$2 -> 0.8 | AH5: =+'[3]ROM Temp'!AC$2 -> 2.9946292
B6: Projects | F6: =+'[3]ROM Temp'!H$3 -> Sidra 2 | G6: =+'[3]ROM Temp'!I$3 -> Sidra 3 | H6: =+'[3]ROM Temp'!J$3 -> Sidra 4 | I6: =+'[3]ROM Temp'!K$3 -> Sidra 5 | J6: =+'[3]ROM Temp'!L$3 -> Makkah Phase 01 | K6: =+'[3]ROM Temp'!M$3 -> Al Arous 1A & 1B | L6: =+'[3]ROM Temp'!N$3 -> Riyadh East | M6: =+'[3]ROM Temp'!O$3 -> Roshan Rate | ... W6: =+'[3]ROM Temp'!Y$3 -> PJA Fronds I to P | X6: =+'[3]ROM Temp'!AA$3 -> PJA Spine District | Y6: =+'[3]ROM Temp'!AB$3 -> Chevron Business Administration and Residential Community | Z6: =+'[3]ROM Temp'!AE$3 -> Al-Thuraya Infrastructure - Roads & Utilities TP4 | AC6: =+'[3]ROM Temp'!AD$3 -> RENAISSANCE | AD6: =+'[3]ROM Temp'!Z$3 -> Ghaf Woods | AE6: =+'[3]ROM Temp'!AF$3 -> Al-Thuraya Infrastructure - Roads & Utilities TP4 | AH6: =+'[3]ROM Temp'!AC$3 -> RUA Madinah Infrastructure (Both early works and main infra)
B7: Location | F7: KSA,Riyadh | G7: KSA,Riyadh | H7: KSA,Riyadh | I7: KSA,Riyadh | J7: KSA,Makkah | K7: KSA,Jeddah | L7: KSA,Riyadh | M7: KSA,Riyadh | N7: KSA,Riyadh | O7: KSA,Riyadh | P7: KSA,Riyadh | Q7: KSA,Riyadh | R7: KSA,Riyadh | S7: KSA,Riyadh | T7: KSA,Riyadh | U7: KSA,Riyadh | V7: KSA,Riyadh | W7: KSA,Riyadh | X7: KSA,Riyadh | Y7: KSA,Riyadh | Z7: KSA,Riyadh
B8: Average Gross FAR (RCDC Defined for Low, Mid and High)) | C8: =+(0.6+0.33)/2 -> 0.465 | D8: =+(1.5+0.6)/2 -> 1.05 | E8: =+(4+1.5)/2 -> 2.75
A9: S/No | B9: CESMM Summary | C9: Low to Use | D9: Mid to Use | E9: High to Use | F9: =+'[3]ROM Temp'!H$4 -> Project 01 | G9: =+'[3]ROM Temp'!I$4 -> Project 02 | H9: =+'[3]ROM Temp'!J$4 -> Project 03 | I9: =+'[3]ROM Temp'!K$4 -> Project 04 | J9: =+'[3]ROM Temp'!L$4 -> Project 05 | K9: =+'[3]ROM Temp'!M$4 -> Project 06 | L9: =+'[3]ROM Temp'!N$4 -> Project 07 | M9: =+'[3]ROM Temp'!O$4 -> Project 08 | ... W9: =+'[3]ROM Temp'!Y$4 -> Project 18 | X9: =+'[3]ROM Temp'!AA$4 -> Project 20 | Y9: =+'[3]ROM Temp'!AB$4 -> Project 21 | Z9: =+'[3]ROM Temp'!AE$4 -> Project 24 | AC9: =+'[3]ROM Temp'!AD$4 -> Project 23 | AD9: =+'[3]ROM Temp'!Z$4 -> Project 19 | AE9: =+'[3]ROM Temp'!AF$4 -> Project 25 | AH9: =+'[3]ROM Temp'!AC$4 -> Project 22
A11: 1 | B11: General Items | AA11: =+SUM(AA12:AA35)*0.1 -> 33.943256 | AB11: =+SUM(AB12:AB35)*0.1 -> 69.819 | AC11: =+ROUND('[3]ROM Temp'!AD6,2) -> 60.01 | AD11: =+ROUND('[3]ROM Temp'!Z6,2) -> 0 | AE11: =+ROUND('[3]ROM Temp'!AF6,2) -> 10.88 | AF11: =+SUM(AF12:AF35)*0.1 -> 46.510333 | AG11: =+SUM(AG12:AG35)*0.1 -> 59.453 | AH11: =+ROUND('[3]ROM Temp'!AC6,2) -> 0
A12: 2 | B12: Ground Investigation | C12: =+(AA12*2+AB12)/3*0+MAX(F12:Z12) -> 1.42 | D12: =+(AF12*2+AG12)/3 -> 2.0433333 | E12: =+AH12*0+MAX(F12:Z12,AC12:AE12) -> 3 | F12: =+ROUND('[3]ROM Temp'!H7,2) -> 0.43 | G12: =+ROUND('[3]ROM Temp'!I7,2) -> 0 | H12: =+ROUND('[3]ROM Temp'!J7,2) -> 0 | I12: =+ROUND('[3]ROM Temp'!K7,2) -> 0 | J12: =+ROUND('[3]ROM Temp'!L7,2) -> 0 | K12: =+ROUND('[3]ROM Temp'!M7,2) -> 1.42 | L12: =+ROUND('[3]ROM Temp'!N7,2) -> 0 | M12: =+ROUND('[3]ROM Temp'!O7,2) -> 1.06 | ... W12: =+ROUND('[3]ROM Temp'!Y7,2) -> 0 | X12: =+ROUND('[3]ROM Temp'!AA7,2) -> 0.06 | Y12: =+ROUND('[3]ROM Temp'!AB7,2) -> 0 | Z12: =+ROUND('[3]ROM Temp'!AE7,2) -> 0 | AA12: =AVERAGEIF(F12:Z12,"<>0") -> 0.7425 | AB12: =+MAX(F12:Z12) -> 1.42 | AC12: =+ROUND('[3]ROM Temp'!AD7,2) -> 3 | AD12: =+ROUND('[3]ROM Temp'!Z7,2) -> 0 | AE12: =+ROUND('[3]ROM Temp'!AF7,2) -> 0.13 | AF12: =AVERAGEIF(AC12:AE12,"<>0") -> 1.565 | AG12: =+MAX(AC12:AE12) -> 3 | AH12: =+ROUND('[3]ROM Temp'!AC7,2) -> 1.86
A13: =A12+1 -> 3 | B13: Demolition and Site Clearance | C13: =+(AA13*2+AB13)/3*0+D13 -> 4.6266667 | D13: =+(AF13*2+AG13)/3 -> 4.6266667 | E13: =+AH13 -> 4.84 | F13: =+ROUND('[3]ROM Temp'!H8,2) -> 0 | G13: =+ROUND('[3]ROM Temp'!I8,2) -> 2.51 | H13: =+ROUND('[3]ROM Temp'!J8,2) -> 2.59 | I13: =+ROUND('[3]ROM Temp'!K8,2) -> 2.6 | J13: =+ROUND('[3]ROM Temp'!L8,2) -> 3.36 | K13: =+ROUND('[3]ROM Temp'!M8,2) -> 4.15 | L13: =+ROUND('[3]ROM Temp'!N8,2) -> 0 | M13: =+ROUND('[3]ROM Temp'!O8,2) -> 3.86 | ... W13: =+ROUND('[3]ROM Temp'!Y8,2) -> 0.47 | X13: =+ROUND('[3]ROM Temp'!AA8,2) -> 0.8 | Y13: =+ROUND('[3]ROM Temp'!AB8,2) -> 8.29 | Z13: =+ROUND('[3]ROM Temp'!AE8,2) -> 3.3 | AA13: =AVERAGEIF(F13:Z13,"<>0") -> 6.7226667 | AB13: =+MAX(F13:Z13) -> 34.29 | AC13: =+ROUND('[3]ROM Temp'!AD8,2) -> 6 | AD13: =+ROUND('[3]ROM Temp'!Z8,2) -> 1.65 | AE13: =+ROUND('[3]ROM Temp'!AF8,2) -> 4.17 | AF13: =AVERAGEIF(AC13:AE13,"<>0") -> 3.94 | AG13: =+MAX(AC13:AE13) -> 6 | AH13: =+ROUND('[3]ROM Temp'!AC8,2) -> 4.84
A14: =A13+1 -> 4 | B14: Earthworks | C14: =+(AA14*2+AB14)/3*0+M14 -> 32.5 | D14: =+(AF14*2+AG14)/3*0+MAX(F14:Z14,AC14:AE14) -> 44.67 | E14: =+AH14 -> 44.67 | F14: =+ROUND('[3]ROM Temp'!H9,2) -> 4.69 | G14: =+ROUND('[3]ROM Temp'!I9,2) -> 29.62 | H14: =+ROUND('[3]ROM Temp'!J9,2) -> 28.53 | I14: =+ROUND('[3]ROM Temp'!K9,2) -> 44.67 | J14: =+ROUND('[3]ROM Temp'!L9,2) -> 14.45 | K14: =+ROUND('[3]ROM Temp'!M9,2) -> 15.98 | L14: =+ROUND('[3]ROM Temp'!N9,2) -> 18.12 | M14: =+ROUND('[3]ROM Temp'!O9,2) -> 32.5 | ... W14: =+ROUND('[3]ROM Temp'!Y9,2) -> 3.09 | X14: =+ROUND('[3]ROM Temp'!AA9,2) -> 17.62 | Y14: =+ROUND('[3]ROM Temp'!AB9,2) -> 38.59 | Z14: =+ROUND('[3]ROM Temp'!AE9,2) -> 13.2 | AA14: =AVERAGEIF(F14:Z14,"<>0") -> 18.715714 | AB14: =+MAX(F14:Z14) -> 44.67 | AC14: =+ROUND('[3]ROM Temp'!AD9,2) -> 35 | AD14: =+ROUND('[3]ROM Temp'!Z9,2) -> 14.31 | AE14: =+ROUND('[3]ROM Temp'!AF9,2) -> 13.43 | AF14: =AVERAGEIF(AC14:AE14,"<>0") -> 20.913333 | AG14: =+MAX(AC14:AE14) -> 35 | AH14: =+ROUND('[3]ROM Temp'!AC9,2) -> 44.67
A15: =A14+1 -> 5 | B15: Structural Metal Works | C15: =+(AA15*2+AB15)/3 -> 0.70444444 | D15: =+(AF15*2+AG15)/3*0+(C15+E15*2)/3 -> 0.91481481 | E15: =+AH15*0+MAX(F15:Z15,AC15:AE15) -> 1.02 | F15: =+ROUND('[3]ROM Temp'!H10,2) -> 0.02 | G15: =+ROUND('[3]ROM Temp'!I10,2) -> 0 | H15: =+ROUND('[3]ROM Temp'!J10,2) -> 0 | I15: =+ROUND('[3]ROM Temp'!K10,2) -> 0 | J15: =+ROUND('[3]ROM Temp'!L10,2) -> 0 | K15: =+ROUND('[3]ROM Temp'!M10,2) -> 1.02 | L15: =+ROUND('[3]ROM Temp'!N10,2) -> 0 | M15: =+ROUND('[3]ROM Temp'!O10,2) -> 0.6 | ... W15: =+ROUND('[3]ROM Temp'!Y10,2) -> 0 | X15: =+ROUND('[3]ROM Temp'!AA10,2) -> 0 | Y15: =+ROUND('[3]ROM Temp'!AB10,2) -> 0 | Z15: =+ROUND('[3]ROM Temp'!AE10,2) -> 0 | AA15: =AVERAGEIF(F15:Z15,"<>0") -> 0.54666667 | AB15: =+MAX(F15:Z15) -> 1.02 | AC15: =+ROUND('[3]ROM Temp'!AD10,2) -> 0 | AD15: =+ROUND('[3]ROM Temp'!Z10,2) -> 0 | AE15: =+ROUND('[3]ROM Temp'!AF10,2) -> 0 | AF15: 0 | AG15: =+MAX(AC15:AE15) -> 0 | AH15: =+ROUND('[3]ROM Temp'!AC10,2) -> 0
A16: 6 | B16: Roads and Paving's | C16: =+(AA16*2+AB16)/3 -> 48.119365 | D16: =+(AF16*2+AG16)/3*0+(C16+E16*2)/3 -> 57.566455 | E16: =+AH16*0+MAX(F16:Z16,AC16:AE16,AH16) -> 62.29 | F16: =+ROUND('[3]ROM Temp'!H11,2) -> 24.87 | G16: =+ROUND('[3]ROM Temp'!I11,2) -> 40.88 | H16: =+ROUND('[3]ROM Temp'!J11,2) -> 40.66 | I16: =+ROUND('[3]ROM Temp'!K11,2) -> 21.93 | J16: =+ROUND('[3]ROM Temp'!L11,2) -> 40.38 | K16: =+ROUND('[3]ROM Temp'!M11,2) -> 28.44 | L16: =+ROUND('[3]ROM Temp'!N11,2) -> 37.1 | M16: =+ROUND('[3]ROM Temp'!O11,2) -> 38.31 | ... W16: =+ROUND('[3]ROM Temp'!Y11,2) -> 18.76 | X16: =+ROUND('[3]ROM Temp'!AA11,2) -> 57.79 | Y16: =+ROUND('[3]ROM Temp'!AB11,2) -> 49.18 | Z16: =+ROUND('[3]ROM Temp'!AE11,2) -> 41.1 | AA16: =AVERAGEIF(F16:Z16,"<>0") -> 41.239048 | AB16: =+MAX(F16:Z16) -> 61.88 | AC16: =+ROUND('[3]ROM Temp'!AD11,2) -> 45 | AD16: =+ROUND('[3]ROM Temp'!Z11,2) -> 18.25 | AE16: =+ROUND('[3]ROM Temp'!AF11,2) -> 62.29 | AF16: =AVERAGEIF(AC16:AE16,"<>0") -> 41.846667 | AG16: =+MAX(AC16:AE16) -> 62.29 | AH16: =+ROUND('[3]ROM Temp'!AC11,2) -> 52.54
A17: =A16+1 -> 7 | B17: Potable Water Works | C17: =+(AA17*2+AB17)/3 -> 41.319048 | D17: =+(AF17*2+AG17)/3*0+(C17+E17*2)/3 -> 55.199683 | E17: =+AH17*0+MAX(F17:Z17,AC17:AE17,AH17) -> 62.14 | F17: =+ROUND('[3]ROM Temp'!H12,2) -> 20.09 | G17: =+ROUND('[3]ROM Temp'!I12,2) -> 23.18 | H17: =+ROUND('[3]ROM Temp'!J12,2) -> 28.13 | I17: =+ROUND('[3]ROM Temp'!K12,2) -> 18.63 | J17: =+ROUND('[3]ROM Temp'!L12,2) -> 18.22 | K17: =+ROUND('[3]ROM Temp'!M12,2) -> 16.62 | L17: =+ROUND('[3]ROM Temp'!N12,2) -> 35.22 | M17: =+ROUND('[3]ROM Temp'!O12,2) -> 26.23 | ... W17: =+ROUND('[3]ROM Temp'!Y12,2) -> 36.24 | X17: =+ROUND('[3]ROM Temp'!AA12,2) -> 33.58 | Y17: =+ROUND('[3]ROM Temp'!AB12,2) -> 15.28 | Z17: =+ROUND('[3]ROM Temp'!AE12,2) -> 28.6 | AA17: =AVERAGEIF(F17:Z17,"<>0") -> 30.908571 | AB17: =+MAX(F17:Z17) -> 62.14 | AC17: =+ROUND('[3]ROM Temp'!AD12,2) -> 25 | AD17: =+ROUND('[3]ROM Temp'!Z12,2) -> 14.46 | AE17: =+ROUND('[3]ROM Temp'!AF12,2) -> 57.72 | AF17: =AVERAGEIF(AC17:AE17,"<>0") -> 32.393333 | AG17: =+MAX(AC17:AE17) -> 57.72 | AH17: =+ROUND('[3]ROM Temp'!AC12,2) -> 35.49
A18: =A17+1 -> 8 | B18: TSE & Irrigation Network | C18: =+(AA18*2+AB18)/3 -> 29.080635 | D18: =+(AF18*2+AG18)/3*0+(C18+E18*2)/3 -> 33.473545 | E18: =+AH18 -> 35.67 | F18: =+ROUND('[3]ROM Temp'!H13,2) -> 6.05 | G18: =+ROUND('[3]ROM Temp'!I13,2) -> 9.26 | H18: =+ROUND('[3]ROM Temp'!J13,2) -> 10.98 | I18: =+ROUND('[3]ROM Temp'!K13,2) -> 7.45 | J18: =+ROUND('[3]ROM Temp'!L13,2) -> 8.03 | K18: =+ROUND('[3]ROM Temp'!M13,2) -> 3.61 | L18: =+ROUND('[3]ROM Temp'!N13,2) -> 9.36 | M18: =+ROUND('[3]ROM Temp'!O13,2) -> 8.39 | ... W18: =+ROUND('[3]ROM Temp'!Y13,2) -> 24.63 | X18: =+ROUND('[3]ROM Temp'!AA13,2) -> 7.57 | Y18: =+ROUND('[3]ROM Temp'!AB13,2) -> 7.81 | Z18: =+ROUND('[3]ROM Temp'!AE13,2) -> 13.2 | AA18: =AVERAGEIF(F18:Z18,"<>0") -> 18.380952 | AB18: =+MAX(F18:Z18) -> 50.48 | AC18: =+ROUND('[3]ROM Temp'!AD13,2) -> 11 | AD18: =+ROUND('[3]ROM Temp'!Z13,2) -> 6.36 | AE18: =+ROUND('[3]ROM Temp'!AF13,2) -> 18.29 | AF18: =AVERAGEIF(AC18:AE18,"<>0") -> 11.883333 | AG18: =+MAX(AC18:AE18) -> 18.29 | AH18: =+ROUND('[3]ROM Temp'!AC13,2) -> 35.67
A19: =A18+1 -> 9 | B19: Sewerage Network | C19: =+(AA19*2+AB19)/3 -> 40.862381 | D19: =AVERAGE(E19,C19) -> 49.35619 | E19: =MAX(F19:AE19) -> 57.85 | F19: =+ROUND('[3]ROM Temp'!H14,2) -> 19.59 | G19: =+ROUND('[3]ROM Temp'!I14,2) -> 22.04 | H19: =+ROUND('[3]ROM Temp'!J14,2) -> 23.7 | I19: =+ROUND('[3]ROM Temp'!K14,2) -> 18.17 | J19: =+ROUND('[3]ROM Temp'!L14,2) -> 18.61 | K19: =+ROUND('[3]ROM Temp'!M14,2) -> 41.55 | L19: =+ROUND('[3]ROM Temp'!N14,2) -> 43.04 | M19: =+ROUND('[3]ROM Temp'!O14,2) -> 33.22 | ... W19: =+ROUND('[3]ROM Temp'!Y14,2) -> 52.46 | X19: =+ROUND('[3]ROM Temp'!AA14,2) -> 44.6 | Y19: =+ROUND('[3]ROM Temp'!AB14,2) -> 7.05 | Z19: =+ROUND('[3]ROM Temp'!AE14,2) -> 17.6 | AA19: =AVERAGEIF(F19:Z19,"<>0") -> 32.368571 | AB19: =+MAX(F19:Z19) -> 57.85 | AC19: =+ROUND('[3]ROM Temp'!AD14,2) -> 22 | AD19: =+ROUND('[3]ROM Temp'!Z14,2) -> 28.35 | AE19: =+ROUND('[3]ROM Temp'!AF14,2) -> 55.32 | AF19: =AVERAGEIF(AC19:AE19,"<>0") -> 35.223333 | AG19: =+MAX(AC19:AE19) -> 55.32 | AH19: =+ROUND('[3]ROM Temp'!AC14,2) -> 63.63
A20: =A19+1 -> 10 | B20: Sewer Treatment Plant/Pumping Station (100% primary) | C20: =+(AA20*2+AB20)/3 -> 15.753333 | D20: =AVERAGE(E20,C20) -> 54.459104 | E20: =+AH20*0+C20*(E8/C8) -> 93.164875 | F20: =+ROUND('[3]ROM Temp'!H15,2) -> 0 | G20: =+ROUND('[3]ROM Temp'!I15,2) -> 0 | H20: =+ROUND('[3]ROM Temp'!J15,2) -> 0 | I20: =+ROUND('[3]ROM Temp'!K15,2) -> 0 | J20: =+ROUND('[3]ROM Temp'!L15,2) -> 21.58 | K20: =+ROUND('[3]ROM Temp'!M15,2) -> 0 | L20: =+ROUND('[3]ROM Temp'!N15,2) -> 0 | M20: =+ROUND('[3]ROM Temp'!O15,2) -> 0 | ... W20: =+ROUND('[3]ROM Temp'!Y15,2) -> 0 | X20: =+ROUND('[3]ROM Temp'!AA15,2) -> 0 | Y20: =+ROUND('[3]ROM Temp'!AB15,2) -> 0 | Z20: =+ROUND('[3]ROM Temp'!AE15,2) -> 7.2 | AA20: =AVERAGEIF(F20:Z20,"<>0") -> 12.84 | AB20: =+MAX(F20:Z20) -> 21.58 | AC20: =+ROUND('[3]ROM Temp'!AD15,2) -> 10.21 | AD20: =+ROUND('[3]ROM Temp'!Z15,2) -> 0 | AE20: =+ROUND('[3]ROM Temp'!AF15,2) -> 0 | AF20: =AVERAGEIF(AC20:AE20,"<>0") -> 10.21 | AG20: =+MAX(AC20:AE20) -> 10.21 | AH20: =+ROUND('[3]ROM Temp'!AC15,2) -> 0
A21: =A20+1 -> 11 | B21: Sewerage Lifting Station (100% primary) | C21: =+(AA21*2+AB21)/3 -> 9.5133333 | D21: =AVERAGE(E21,C21) -> 10.751667 | E21: =MAX(G21:AH21) -> 11.99 | F21: =+ROUND('[3]ROM Temp'!H16,2) -> 0 | G21: =+ROUND('[3]ROM Temp'!I16,2) -> 0 | H21: =+ROUND('[3]ROM Temp'!J16,2) -> 0 | I21: =+ROUND('[3]ROM Temp'!K16,2) -> 0 | J21: =+ROUND('[3]ROM Temp'!L16,2) -> 0 | K21: =+ROUND('[3]ROM Temp'!M16,2) -> 0 | L21: =+ROUND('[3]ROM Temp'!N16,2) -> 4.56 | M21: =+ROUND('[3]ROM Temp'!O16,2) -> 0 | ... W21: =+ROUND('[3]ROM Temp'!Y16,2) -> 0 | X21: =+ROUND('[3]ROM Temp'!AA16,2) -> 0 | Y21: =+ROUND('[3]ROM Temp'!AB16,2) -> 11.99 | Z21: =+ROUND('[3]ROM Temp'!AE16,2) -> 0 | AA21: =AVERAGEIF(F21:Z21,"<>0") -> 8.275 | AB21: =+MAX(F21:Z21) -> 11.99 | AC21: =+ROUND('[3]ROM Temp'!AD16,2) -> 1.56 | AD21: =+ROUND('[3]ROM Temp'!Z16,2) -> 0 | AE21: =+ROUND('[3]ROM Temp'!AF16,2) -> 0 | AF21: =AVERAGEIF(AC21:AE21,"<>0") -> 1.56 | AG21: =+MAX(AC21:AE21) -> 1.56 | AH21: =+ROUND('[3]ROM Temp'!AC16,2) -> 0
A22: =A21+1 -> 12 | B22: Drainage Network | C22: =+(AA22*2+AB22)/3 -> 34.748 | D22: =+(AF22*2+AG22)/3 -> 36.933333 | E22: =+AH22 -> 71.96 | F22: =+ROUND('[3]ROM Temp'!H17,2) -> 12.5 | G22: =+ROUND('[3]ROM Temp'!I17,2) -> 14.09 | H22: =+ROUND('[3]ROM Temp'!J17,2) -> 18.49 | I22: =+ROUND('[3]ROM Temp'!K17,2) -> 11.65 | J22: =+ROUND('[3]ROM Temp'!L17,2) -> 42.08 | K22: =+ROUND('[3]ROM Temp'!M17,2) -> 41.86 | L22: =+ROUND('[3]ROM Temp'!N17,2) -> 33.06 | M22: =+ROUND('[3]ROM Temp'!O17,2) -> 33.27 | ... W22: =+ROUND('[3]ROM Temp'!Y17,2) -> 0 | X22: =+ROUND('[3]ROM Temp'!AA17,2) -> 0 | Y22: =+ROUND('[3]ROM Temp'!AB17,2) -> 47.42 | Z22: =+ROUND('[3]ROM Temp'!AE17,2) -> 29.7 | AA22: =AVERAGEIF(F22:Z22,"<>0") -> 28.412 | AB22: =+MAX(F22:Z22) -> 47.42 | AC22: =+ROUND('[3]ROM Temp'!AD17,2) -> 35 | AD22: =+ROUND('[3]ROM Temp'!Z17,2) -> 0 | AE22: =+ROUND('[3]ROM Temp'!AF17,2) -> 37.9 | AF22: =AVERAGEIF(AC22:AE22,"<>0") -> 36.45 | AG22: =+MAX(AC22:AE22) -> 37.9 | AH22: =+ROUND('[3]ROM Temp'!AC17,2) -> 71.96
A23: =A22+1 -> 13 | B23: Potable Water tank & Pumping Station/tank (100% primary) | C23: =D23 -> 6.11 | D23: =+(AF23*2+AG23)/3 -> 6.11 | E23: =+AH23*0+D23*(E8/D8) -> 16.002381 | F23: =+ROUND('[3]ROM Temp'!H18,2) -> 0 | G23: =+ROUND('[3]ROM Temp'!I18,2) -> 0 | H23: =+ROUND('[3]ROM Temp'!J18,2) -> 0 | I23: =+ROUND('[3]ROM Temp'!K18,2) -> 0 | J23: =+ROUND('[3]ROM Temp'!L18,2) -> 0 | K23: =+ROUND('[3]ROM Temp'!M18,2) -> 0 | L23: =+ROUND('[3]ROM Temp'!N18,2) -> 0 | M23: =+ROUND('[3]ROM Temp'!O18,2) -> 0 | ... W23: =+ROUND('[3]ROM Temp'!Y18,2) -> 0 | X23: =+ROUND('[3]ROM Temp'!AA18,2) -> 0 | Y23: =+ROUND('[3]ROM Temp'!AB18,2) -> 0 | Z23: =+ROUND('[3]ROM Temp'!AE18,2) -> 0 | AA23: 0 | AB23: =+MAX(F23:Z23) -> 0 | AC23: =+ROUND('[3]ROM Temp'!AD18,2) -> 6.11 | AD23: =+ROUND('[3]ROM Temp'!Z18,2) -> 0 | AE23: =+ROUND('[3]ROM Temp'!AF18,2) -> 0 | AF23: =AVERAGEIF(AC23:AE23,"<>0") -> 6.11 | AG23: =+MAX(AC23:AE23) -> 6.11 | AH23: =+ROUND('[3]ROM Temp'!AC18,2) -> 0
A24: =A23+1 -> 14 | B24: Irrigation Pumping Station/Water tank (100% primary) | C24: =AC24 -> 6.52 | D24: =AVERAGE(C24,E24) -> 7.22 | E24: =AB24 -> 7.92 | F24: =+ROUND('[3]ROM Temp'!H19,2) -> 0 | G24: =+ROUND('[3]ROM Temp'!I19,2) -> 0 | H24: =+ROUND('[3]ROM Temp'!J19,2) -> 0 | I24: =+ROUND('[3]ROM Temp'!K19,2) -> 0 | J24: =+ROUND('[3]ROM Temp'!L19,2) -> 0 | K24: =+ROUND('[3]ROM Temp'!M19,2) -> 0 | L24: =+ROUND('[3]ROM Temp'!N19,2) -> 0 | M24: =+ROUND('[3]ROM Temp'!O19,2) -> 0 | ... W24: =+ROUND('[3]ROM Temp'!Y19,2) -> 0 | X24: =+ROUND('[3]ROM Temp'!AA19,2) -> 0 | Y24: =+ROUND('[3]ROM Temp'!AB19,2) -> 0 | Z24: =+ROUND('[3]ROM Temp'!AE19,2) -> 7.92 | AA24: =AVERAGEIF(F24:Z24,"<>0") -> 7.92 | AB24: =+MAX(F24:Z24) -> 7.92 | AC24: =+ROUND('[3]ROM Temp'!AD19,2) -> 6.52 | AD24: =+ROUND('[3]ROM Temp'!Z19,2) -> 0 | AE24: =+ROUND('[3]ROM Temp'!AF19,2) -> 0 | AF24: =AVERAGEIF(AC24:AE24,"<>0") -> 6.52 | AG24: =+MAX(AC24:AE24) -> 6.52 | AH24: =+ROUND('[3]ROM Temp'!AC19,2) -> 0
A25: =A24+1 -> 15 | B25: Storm Water Pumping Station (100% primary) | C25: =+(AA25*2+AB25)/3*0+D25*(C8/D8) -> 4.4285714 | D25: =+(AF25*2+AG25)/3 -> 10 | E25: =+AH25*0+D25*(E8/D8) -> 26.190476 | F25: =+ROUND('[3]ROM Temp'!H20,2) -> 0 | G25: =+ROUND('[3]ROM Temp'!I20,2) -> 0 | H25: =+ROUND('[3]ROM Temp'!J20,2) -> 0 | I25: =+ROUND('[3]ROM Temp'!K20,2) -> 0 | J25: =+ROUND('[3]ROM Temp'!L20,2) -> 0 | K25: =+ROUND('[3]ROM Temp'!M20,2) -> 0 | L25: =+ROUND('[3]ROM Temp'!N20,2) -> 0 | M25: =+ROUND('[3]ROM Temp'!O20,2) -> 0 | ... W25: =+ROUND('[3]ROM Temp'!Y20,2) -> 0 | X25: =+ROUND('[3]ROM Temp'!AA20,2) -> 0 | Y25: =+ROUND('[3]ROM Temp'!AB20,2) -> 0 | Z25: =+ROUND('[3]ROM Temp'!AE20,2) -> 0 | AA25: 0 | AB25: =+MAX(F25:Z25) -> 0 | AC25: =+ROUND('[3]ROM Temp'!AD20,2) -> 10 | AD25: =+ROUND('[3]ROM Temp'!Z20,2) -> 0 | AE25: =+ROUND('[3]ROM Temp'!AF20,2) -> 0 | AF25: =AVERAGEIF(AC25:AE25,"<>0") -> 10 | AG25: =+MAX(AC25:AE25) -> 10 | AH25: =+ROUND('[3]ROM Temp'!AC20,2) -> 0
A26: =A25+1 -> 16 | B26: Electrical Works (HV, LV, MV) | C26: =+(AA26*2+AB26)/3*0+M26 -> 48 | D26: =+(AF26*2+AG26)/3*0+(C26+E26*2)/3 -> 82.073333 | E26: =+AH26*0+MAX(F26:Z26,AD26:AE26,AH26) -> 99.11 | F26: =+ROUND('[3]ROM Temp'!H21,2) -> 28.76 | G26: =+ROUND('[3]ROM Temp'!I21,2) -> 33.49 | H26: =+ROUND('[3]ROM Temp'!J21,2) -> 31.83 | I26: =+ROUND('[3]ROM Temp'!K21,2) -> 24.27 | J26: =+ROUND('[3]ROM Temp'!L21,2) -> 27.18 | K26: =+ROUND('[3]ROM Temp'!M21,2) -> 25.37 | L26: =+ROUND('[3]ROM Temp'!N21,2) -> 55 | M26: =+ROUND('[3]ROM Temp'!O21,2) -> 48 | ... W26: =+ROUND('[3]ROM Temp'!Y21,2) -> 14.02 | X26: =+ROUND('[3]ROM Temp'!AA21,2) -> 7.18 | Y26: =+ROUND('[3]ROM Temp'!AB21,2) -> 57 | Z26: =+ROUND('[3]ROM Temp'!AE21,2) -> 26.55 | AA26: =AVERAGEIF(F26:Z26,"<>0") -> 29.886667 | AB26: =+MAX(F26:Z26) -> 59 | AC26: =+ROUND('[3]ROM Temp'!AD21,2) -> 40 | AD26: =+ROUND('[3]ROM Temp'!Z21,2) -> 13.58 | AE26: =+ROUND('[3]ROM Temp'!AF21,2) -> 54.48 | AF26: =AVERAGEIF(AC26:AE26,"<>0") -> 36.02 | AG26: =+MAX(AC26:AE26) -> 54.48 | AH26: =+ROUND('[3]ROM Temp'!AC21,2) -> 99.11
A27: =A26+1 -> 17 | B27: Street Lighting Network | C27: =+(AA27*2+AB27)/3 -> 18.240667 | D27: =+(AF27*2+AG27)/3*0+(E27+C27)/2 -> 21.555333 | E27: =+AH27 -> 24.87 | F27: =+ROUND('[3]ROM Temp'!H22,2) -> 11.76 | G27: =+ROUND('[3]ROM Temp'!I22,2) -> 7.7 | H27: =+ROUND('[3]ROM Temp'!J22,2) -> 8.42 | I27: =+ROUND('[3]ROM Temp'!K22,2) -> 6.67 | J27: =+ROUND('[3]ROM Temp'!L22,2) -> 8.02 | K27: =+ROUND('[3]ROM Temp'!M22,2) -> 0 | L27: =+ROUND('[3]ROM Temp'!N22,2) -> 22.7 | M27: =+ROUND('[3]ROM Temp'!O22,2) -> 14.43 | ... W27: =+ROUND('[3]ROM Temp'!Y22,2) -> 10.39 | X27: =+ROUND('[3]ROM Temp'!AA22,2) -> 23.48 | Y27: =+ROUND('[3]ROM Temp'!AB22,2) -> 17.77 | Z27: =+ROUND('[3]ROM Temp'!AE22,2) -> 7.7 | AA27: =AVERAGEIF(F27:Z27,"<>0") -> 14.206 | AB27: =+MAX(F27:Z27) -> 26.31 | AC27: =+ROUND('[3]ROM Temp'!AD22,2) -> 14 | AD27: =+ROUND('[3]ROM Temp'!Z22,2) -> 3.51 | AE27: =+ROUND('[3]ROM Temp'!AF22,2) -> 21.9 | AF27: =AVERAGEIF(AC27:AE27,"<>0") -> 13.136667 | AG27: =+MAX(AC27:AE27) -> 21.9 | AH27: =+ROUND('[3]ROM Temp'!AC22,2) -> 24.87
A28: =A27+1 -> 18 | B28: Telecommunication Network (Including ICT and ITS) | C28: =+(AA28*2+AB28)/3 -> 21.433651 | D28: =+(AF28*2+AG28)/3*0+(E28*2+C28)/3 -> 29.58455 | E28: =+AH28 -> 33.66 | F28: =+ROUND('[3]ROM Temp'!H23,2) -> 8.92 | G28: =+ROUND('[3]ROM Temp'!I23,2) -> 8.37 | H28: =+ROUND('[3]ROM Temp'!J23,2) -> 13.04 | I28: =+ROUND('[3]ROM Temp'!K23,2) -> 6.76 | J28: =+ROUND('[3]ROM Temp'!L23,2) -> 20.25 | K28: =+ROUND('[3]ROM Temp'!M23,2) -> 24.91 | L28: =+ROUND('[3]ROM Temp'!N23,2) -> 20.85 | M28: =+ROUND('[3]ROM Temp'!O23,2) -> 19.47 | ... W28: =+ROUND('[3]ROM Temp'!Y23,2) -> 7.98 | X28: =+ROUND('[3]ROM Temp'!AA23,2) -> 7.24 | Y28: =+ROUND('[3]ROM Temp'!AB23,2) -> 33.84 | Z28: =+ROUND('[3]ROM Temp'!AE23,2) -> 8.8 | AA28: =AVERAGEIF(F28:Z28,"<>0") -> 15.230476 | AB28: =+MAX(F28:Z28) -> 33.84 | AC28: =+ROUND('[3]ROM Temp'!AD23,2) -> 26 | AD28: =+ROUND('[3]ROM Temp'!Z23,2) -> 3.21 | AE28: =+ROUND('[3]ROM Temp'!AF23,2) -> 21.9 | AF28: =AVERAGEIF(AC28:AE28,"<>0") -> 17.036667 | AG28: =+MAX(AC28:AE28) -> 26 | AH28: =+ROUND('[3]ROM Temp'!AC23,2) -> 33.66
A29: =A28+1 -> 19 | B29: CCTV System | C29: =+(AA29*2+AB29)/3*0+M29 -> 12.56 | D29: =+(AF29*2+AG29)/3 -> 14.58 | E29: =+AH29*0+D29*(E8/D8) -> 38.185714 | F29: =+ROUND('[3]ROM Temp'!H24,2) -> 13.96 | G29: =+ROUND('[3]ROM Temp'!I24,2) -> 12.28 | H29: =+ROUND('[3]ROM Temp'!J24,2) -> 10.72 | I29: =+ROUND('[3]ROM Temp'!K24,2) -> 6.72 | J29: =+ROUND('[3]ROM Temp'!L24,2) -> 0 | K29: =+ROUND('[3]ROM Temp'!M24,2) -> 0 | L29: =+ROUND('[3]ROM Temp'!N24,2) -> 8.59 | M29: =+ROUND('[3]ROM Temp'!O24,2) -> 12.56 | ... W29: =+ROUND('[3]ROM Temp'!Y24,2) -> 6.33 | X29: =+ROUND('[3]ROM Temp'!AA24,2) -> 14.95 | Y29: =+ROUND('[3]ROM Temp'!AB24,2) -> 5.75 | Z29: =+ROUND('[3]ROM Temp'!AE24,2) -> 0 | AA29: =AVERAGEIF(F29:Z29,"<>0") -> 9.3427273 | AB29: =+MAX(F29:Z29) -> 14.95 | AC29: =+ROUND('[3]ROM Temp'!AD24,2) -> 12 | AD29: =+ROUND('[3]ROM Temp'!Z24,2) -> 15.87 | AE29: =+ROUND('[3]ROM Temp'!AF24,2) -> 0 | AF29: =AVERAGEIF(AC29:AE29,"<>0") -> 13.935 | AG29: =+MAX(AC29:AE29) -> 15.87 | AH29: =+ROUND('[3]ROM Temp'!AC24,2) -> 0
A30: =A29+1 -> 20 | B30: Traffic signal | C30: =+(AA30*2+AB30)/3*0+D30*(C8/D8) -> 0.88571429 | D30: =+(AF30*2+AG30)/3 -> 2 | E30: =+AH30*0+D30*(E8/D8) -> 5.2380952 | F30: =+ROUND('[3]ROM Temp'!H25,2) -> 0 | G30: =+ROUND('[3]ROM Temp'!I25,2) -> 0 | H30: =+ROUND('[3]ROM Temp'!J25,2) -> 0 | I30: =+ROUND('[3]ROM Temp'!K25,2) -> 0 | J30: =+ROUND('[3]ROM Temp'!L25,2) -> 0 | K30: =+ROUND('[3]ROM Temp'!M25,2) -> 0 | L30: =+ROUND('[3]ROM Temp'!N25,2) -> 0 | M30: =+ROUND('[3]ROM Temp'!O25,2) -> 0 | ... W30: =+ROUND('[3]ROM Temp'!Y25,2) -> 0 | X30: =+ROUND('[3]ROM Temp'!AA25,2) -> 0 | Y30: =+ROUND('[3]ROM Temp'!AB25,2) -> 0 | Z30: =+ROUND('[3]ROM Temp'!AE25,2) -> 0 | AA30: 0 | AB30: =+MAX(F30:Z30) -> 0 | AC30: =+ROUND('[3]ROM Temp'!AD25,2) -> 2 | AD30: =+ROUND('[3]ROM Temp'!Z25,2) -> 0 | AE30: =+ROUND('[3]ROM Temp'!AF25,2) -> 0 | AF30: =AVERAGEIF(AC30:AE30,"<>0") -> 2 | AG30: =+MAX(AC30:AE30) -> 2 | AH30: =+ROUND('[3]ROM Temp'!AC25,2) -> 0
A31: =A30+1 -> 21 | B31: Soft Landscaping | C31: =+(AA31*2+AB31)/3*0+MAX(F31:Z31) -> 55 | D31: =+(AF31*2+AG31)/3*0+C31*1.1 -> 60.5 | E31: =+AH31*0+C31*1.2 -> 66 | F31: =+ROUND('[3]ROM Temp'!H26,2) -> 19.29 | G31: =+ROUND('[3]ROM Temp'!I26,2) -> 23.49 | H31: =+ROUND('[3]ROM Temp'!J26,2) -> 34.25 | I31: =+ROUND('[3]ROM Temp'!K26,2) -> 21.33 | J31: =+ROUND('[3]ROM Temp'!L26,2) -> 38.01 | K31: =+ROUND('[3]ROM Temp'!M26,2) -> 47.98 | L31: =+ROUND('[3]ROM Temp'!N26,2) -> 21.43 | M31: =+ROUND('[3]ROM Temp'!O26,2) -> 55 | ... W31: =+ROUND('[3]ROM Temp'!Y26,2) -> 0 | X31: =+ROUND('[3]ROM Temp'!AA26,2) -> 0 | Y31: =+ROUND('[3]ROM Temp'!AB26,2) -> 20.67 | Z31: =+ROUND('[3]ROM Temp'!AE26,2) -> 17.53 | AA31: =AVERAGEIF(F31:Z31,"<>0") -> 29.898 | AB31: =+MAX(F31:Z31) -> 55 | AC31: =+ROUND('[3]ROM Temp'!AD26,2) -> 35 | AD31: =+ROUND('[3]ROM Temp'!Z26,2) -> 0 | AE31: =+ROUND('[3]ROM Temp'!AF26,2) -> 0 | AF31: =AVERAGEIF(AC31:AE31,"<>0") -> 35 | AG31: =+MAX(AC31:AE31) -> 35 | AH31: =+ROUND('[3]ROM Temp'!AC26,2) -> 0
A32: =A31+1 -> 22 | B32: Hard Landscaping | C32: =+(AA32*2+AB32)/3*0+MAX(F32:Z32) -> 42.37 | D32: =+(AF32*2+AG32)/3*0+C32*1.1 -> 46.607 | E32: =+AH32*0+C32*1.2 -> 50.844 | F32: =+ROUND('[3]ROM Temp'!H27,2) -> 36.91 | G32: =+ROUND('[3]ROM Temp'!I27,2) -> 26.77 | H32: =+ROUND('[3]ROM Temp'!J27,2) -> 33.93 | I32: =+ROUND('[3]ROM Temp'!K27,2) -> 21.4 | J32: =+ROUND('[3]ROM Temp'!L27,2) -> 39.59 | K32: =+ROUND('[3]ROM Temp'!M27,2) -> 40.52 | L32: =+ROUND('[3]ROM Temp'!N27,2) -> 39.1 | M32: =+ROUND('[3]ROM Temp'!O27,2) -> 42.37 | ... W32: =+ROUND('[3]ROM Temp'!Y27,2) -> 0 | X32: =+ROUND('[3]ROM Temp'!AA27,2) -> 0 | Y32: =+ROUND('[3]ROM Temp'!AB27,2) -> 39.85 | Z32: =+ROUND('[3]ROM Temp'!AE27,2) -> 17.53 | AA32: =AVERAGEIF(F32:Z32,"<>0") -> 33.797 | AB32: =+MAX(F32:Z32) -> 42.37 | AC32: =+ROUND('[3]ROM Temp'!AD27,2) -> 39.68 | AD32: =+ROUND('[3]ROM Temp'!Z27,2) -> 0 | AE32: =+ROUND('[3]ROM Temp'!AF27,2) -> 0 | AF32: =AVERAGEIF(AC32:AE32,"<>0") -> 39.68 | AG32: =+MAX(AC32:AE32) -> 39.68 | AH32: =+ROUND('[3]ROM Temp'!AC27,2) -> 0
A33: =A32+1 -> 23 | B33: ITS Network (Included in Telecommunication Network) | C33: =+(AA33*2+AB33)/3 -> 0 | D33: =+(AF33*2+AG33)/3 -> 0 | E33: =+AH33 -> 0 | F33: =+ROUND('[3]ROM Temp'!H28,2) -> 0 | G33: =+ROUND('[3]ROM Temp'!I28,2) -> 0 | H33: =+ROUND('[3]ROM Temp'!J28,2) -> 0 | I33: =+ROUND('[3]ROM Temp'!K28,2) -> 0 | J33: =+ROUND('[3]ROM Temp'!L28,2) -> 0 | K33: =+ROUND('[3]ROM Temp'!M28,2) -> 0 | L33: =+ROUND('[3]ROM Temp'!N28,2) -> 0 | M33: =+ROUND('[3]ROM Temp'!O28,2) -> 0 | ... W33: =+ROUND('[3]ROM Temp'!Y28,2) -> 0 | X33: =+ROUND('[3]ROM Temp'!AA28,2) -> 0 | Y33: =+ROUND('[3]ROM Temp'!AB28,2) -> 0 | Z33: =+ROUND('[3]ROM Temp'!AE28,2) -> 0 | AA33: 0 | AB33: =+MAX(F33:Z33) -> 0 | AC33: =+ROUND('[3]ROM Temp'!AD28,2) -> 0 | AD33: =+ROUND('[3]ROM Temp'!Z28,2) -> 0 | AE33: =+ROUND('[3]ROM Temp'!AF28,2) -> 0 | AF33: 0 | AG33: =+MAX(AC33:AE33) -> 0 | AH33: =+ROUND('[3]ROM Temp'!AC28,2) -> 0
A34: =A33+1 -> 24 | B34: ICT Network (Telecommunication Network) | C34: =+(AA34*2+AB34)/3 -> 0 | D34: =+(AF34*2+AG34)/3 -> 0 | E34: =+AH34 -> 0 | F34: =+ROUND('[3]ROM Temp'!H29,2) -> 0 | G34: =+ROUND('[3]ROM Temp'!I29,2) -> 0 | H34: =+ROUND('[3]ROM Temp'!J29,2) -> 0 | I34: =+ROUND('[3]ROM Temp'!K29,2) -> 0 | J34: =+ROUND('[3]ROM Temp'!L29,2) -> 0 | K34: =+ROUND('[3]ROM Temp'!M29,2) -> 0 | L34: =+ROUND('[3]ROM Temp'!N29,2) -> 0 | M34: =+ROUND('[3]ROM Temp'!O29,2) -> 0 | ... W34: =+ROUND('[3]ROM Temp'!Y29,2) -> 0 | X34: =+ROUND('[3]ROM Temp'!AA29,2) -> 0 | Y34: =+ROUND('[3]ROM Temp'!AB29,2) -> 0 | Z34: =+ROUND('[3]ROM Temp'!AE29,2) -> 0 | AA34: 0 | AB34: =+MAX(F34:Z34) -> 0 | AC34: =+ROUND('[3]ROM Temp'!AD29,2) -> 0 | AD34: =+ROUND('[3]ROM Temp'!Z29,2) -> 0 | AE34: =+ROUND('[3]ROM Temp'!AF29,2) -> 0 | AF34: 0 | AG34: =+MAX(AC34:AE34) -> 0 | AH34: =+ROUND('[3]ROM Temp'!AC29,2) -> 0
A35: =A34+1 -> 25 | B35: Power Station/Bulk substation & Primary substation (100% primary) | C35: =M35 -> 64.06 | D35: =AF35 -> 89.68 | E35: =D35+(D35-C35) -> 115.3 | F35: =+ROUND('[3]ROM Temp'!H30,2) -> 0 | G35: =+ROUND('[3]ROM Temp'!I30,2) -> 0 | H35: =+ROUND('[3]ROM Temp'!J30,2) -> 0 | I35: =+ROUND('[3]ROM Temp'!K30,2) -> 0 | J35: =+ROUND('[3]ROM Temp'!L30,2) -> 0 | K35: =+ROUND('[3]ROM Temp'!M30,2) -> 0 | L35: =+ROUND('[3]ROM Temp'!N30,2) -> 0 | M35: =+ROUND('[3]ROM Temp'!O30,2) -> 64.06 | ... W35: =+ROUND('[3]ROM Temp'!Y30,2) -> 0 | X35: =+ROUND('[3]ROM Temp'!AA30,2) -> 0 | Y35: =+ROUND('[3]ROM Temp'!AB30,2) -> 0 | Z35: =+ROUND('[3]ROM Temp'!AE30,2) -> 0 | AA35: 0 | AB35: =+MAX(F35:Z35) -> 64.06 | AC35: =+ROUND('[3]ROM Temp'!AD30,2) -> 89.68 | AD35: =+ROUND('[3]ROM Temp'!Z30,2) -> 0 | AE35: =+ROUND('[3]ROM Temp'!AF30,2) -> 0 | AF35: =AVERAGEIF(AC35:AE35,"<>0") -> 89.68 | AG35: =+MAX(AC35:AE35) -> 89.68 | AH35: =+ROUND('[3]ROM Temp'!AC30,2) -> 0
B37: Infra Rate (SAR/Gross Land Area) | C37: =+SUM(C11:C35) -> 538.25581 | D37: =+SUM(D11:D35) -> 719.90501 | E37: =+SUM(E11:E35) -> 931.91554 | F37: =+SUM(F11:F35) -> 207.84 | G37: =+SUM(G11:G35) -> 253.68 | H37: =+SUM(H11:H35) -> 285.27 | I37: =+SUM(I11:I35) -> 212.25 | J37: =+SUM(J11:J35) -> 299.76 | ... AE37: =+SUM(AE11:AE35) -> 358.41 | AH37: =+SUM(AH11:AH35) -> 468.3
D39: =+D37/C37 -> 1.3374775 | E39: =+E37/D37 -> 1.2944979
E40: =+E37/C37 -> 1.7313618
B41: Gross FAR (RCDC) | C41: 0.33-0.60 | D41: 0.6-1.5 | E41: 1.5-4.0

Sheet Building Pivot
A6: Sum of Cost/GFA | B6: Column Labels
B7: Commercial | M7: Commercial Average | N7: Residential | AM7: Residential Average | AN7: Retail | BJ7: Retail Average
