Workbook

Sheet Fly-Bill 4
A22: BILL NO. 4
A24: PARKING FLOORS REFURBISHMENT

Sheet Bill 4 Concrete
A1: Item | B1: Description | C1: Quantity | D1: Unit | E1: Rate | F1: Amount
E2: AED | F2: AED
B4: CONCRETE WORK
B6: REINFORCED CONCRETE
B9: Note: Refer to the following:
B11: 1. Drawing Reference Nr. S-00011 and S-60001
B13: 2. Structures Specification dated 28 March 2022
B15: Plain poured concrete; compressive strength 15 MPa with cement type SRPC
A17: A | B17: Blinding; 100mm thick | C17: 78 | D17: m³ | E17: 395.25 | F17: =C17*E17 -> 30829.5
A19: B | B19: Concrete screed | C19: 5 | D19: m³ | E19: 563.21 | F19: =C19*E19 -> 2816.05
B21: Reinforced concrete; compressive strength 60 MPa with cement type CEM I+GGBS
A23: C | B23: Slab on grade; 200mm thick | C23: 273 | D23: m³ | E23: 404.64 | F23: =C23*E23 -> 110466.72
A25: D | B25: Suspended slab; 200mm thick | C25: 7 | D25: m³ | E25: 417.06 | F25: =C25*E25 -> 2919.42
A27: E | B27: Suspended slab; 300mm thick | C27: 45 | D27: m³ | E27: 417.06 | F27: =C27*E27 -> 18767.7
A29: F | B29: Suspended slab; 350mm thick | C29: 0 | D29: m³ | E29: 404.64 | F29: =C29*E29 -> 0
A31: G | B31: Suspended slab; 400mm thick | C31: 56 | D31: m³ | E31: 417.06 | F31: =C31*E31 -> 23355.36
A33: H | B33: Suspended slab; 450mm thick | C33: 0 | D33: m³ | E33: 417.06 | F33: =C33*E33 -> 0
A35: J | B35: Suspended slab; 700mm thick | C35: 0 | D35: m³ | E35: 417.06 | F35: =C35*E35 -> 0
A37: K | B37: Suspended slab; 900mm thick | C37: 0 | D37: m³ | E37: 417.06 | F37: =C37*E37 -> 0
A39: L | B39: Beams | C39: 0 | D39: m³ | E39: 408.53 | F39: =C39*E39 -> 0
A41: M | B41: Upstand | C41: 142 | D41: m³ | E41: 411.46 | F41: =C41*E41 -> 58427.32
A43: N | B43: Columns | C43: 156 | D43: m³ | E43: 411.46 | F43: =C43*E43 -> 64187.76
A45: P | B45: Columns; curved | C45: 21 | D45: m³ | E45: 411.46 | F45: =C45*E45 -> 8640.66
A47: Q | B47: Walls; 300mm thick | C47: 300 | D47: m³ | E47: 411.46 | F47: =C47*E47 -> 123438
C50: To Collection | E50: AED | F50: =SUM(F16:F48) -> 443848.49
B53: REINFORCED CONCRETE (Cont´d)
A55: A | B55: Walls; 350mm thick | C55: 218 | D55: m³ | E55: 411.46 | F55: =C55*E55 -> 89698.28
A57: B | B57: Walls; 450mm thick | C57: 64 | D57: m³ | E57: 411.46 | F57: =C57*E57 -> 26333.44
A59: C | B59: Walls; 600mm thick | C59: 0 | D59: m³ | E59: 411.46 | F59: =C59*E59 -> 0
B61: Reinforcement; various diameter; high yield deformed type 2; 460N/mm2; shall comply to ASTM 615 or BS4449
A63: D | B63: Slab on grade | C63: 36.11 | D63: t | E63: 4382.11 | F63: =C63*E63 -> 158237.99
A65: E | B65: Suspended slab | C65: 13.9 | D65: t | E65: 4431.91 | F65: =C65*E65 -> 61603.549
A67: F | B67: Beams | C67: 0 | D67: t | E67: 4431.91 | F67: =C67*E67 -> 0
A69: G | B69: Upstand | C69: 21.05 | D69: t | E69: 4431.91 | F69: =C69*E69 -> 93291.705
A71: H | B71: Columns | C71: 57.2 | D71: t | E71: 4431.91 | F71: =C71*E71 -> 253505.25
A73: J | B73: Walls | C73: 66.67 | D73: t | E73: 4431.91 | F73: =C73*E73 -> 295475.44
B75: Shuttering; including supports, finish and all ancillary works as necessary
A77: K | B77: Soffits of suspended slab | C77: 327 | D77: m² | E77: 135.71 | F77: =C77*E77 -> 44377.17
A79: L | B79: Sides and soffits of beams | C79: 0 | D79: m² | E79: 148.36 | F79: =C79*E79 -> 0
A81: M | B81: Sides of upstand | C81: 1170 | D81: m² | E81: 150.18 | F81: =C81*E81 -> 175710.6
...

Sheet Bill 4 - Masonry
A1: Item | B1: Description | C1: Quantity | D1: Unit | E1: Rate | F1: Amount
E2: AED | F2: AED
B4: MASONRY
B6: WALLS AND PIERS
B8: Note: Refer to the following:
B10: 1. Drawing Reference Nr. A-700 to A-710 and A-962
B12: Hollow concrete block wall; bedded and jointed in cement and sand mortar; including damp proof courses, insulation, fire rating, mesh, grouts, lintels, posts, reinforcement, fixings, anchors, ties, accessories, plaster (measured separately) and all ancillary works as necessary
A14: A | B14: Type 2; 200mm thick; 2hour fire rated; RW55; to external | C14: 1,883 | D14: m² | E14: 170.19 | F14: =C14*E14 -> 320467.77
A16: B | B16: Type 2; 200mm thick; 2hour fire rated; RW55; to internal | C16: 4531 | D16: m² | E16: 153.63 | F16: =C16*E16 -> 696097.53
C43: To Collection | E43: AED | F43: =SUM(F8:F39) -> 1016565.3
B46: GENERALLY
B48: Allow for any other works which are not included above and which are required to complete the Masonry in accordance with the Specification and the drawings (Tenderer to list below): | D48: Item | F48: =C48*E48 -> 0
B50: Thermal insulated blockwall enclosing skylight well / void from Level 3 up to skylights (A317, A318 and A319)
A51: A | B51: 200mm thick; Type 2 | C51: 1560 | D51: m² | E51: 238.27 | F51: =+C51*E51 -> 371701.2
B54: Quantity Adjustments
A56: B | B56: Variance in quantity following in-house Quantity Take Off | C56: 1 | D56: item | F56: =+C56*E56 -> 0
C86: To Collection | E86: AED | F86: =SUM(F47:F82) -> 371701.2
B89: COLLECTION
B91: Page 4/D/1 | F91: =F43 -> 1016565.3
B93: Page 4/D/2 | F93: =F86 -> 371701.2
C136: To Collection | E136: AED | F136: =SUM(F88:F123) -> 1388266.5

Sheet Bill 4 Woodwork
A1: Item | B1: Description | C1: Quantity | D1: Unit | E1: Rate | F1: Amount | G1: VE Ref.
E2: AED | F2: AED
B4: WOODWORK
B6: COMPOSITE ITEMS
B8: Note: Refer to the following:
B10: 1. Interior FF&E Schedule and Mood Boards dated April 2022
B12: 2. Drawing Reference Nr. ID-600 series
B14: Wheelchair self service cabinet; comprising solid countertop type SS-02, stainless steel panel type MT-06, plastic laminate strip laminate type PL-04, metal skirting and fascia type MT-02; including signage (by Others), fixings and all ancillary works as necessary
A16: A | B16: I-WCS-01; overall size 1106 x 1153 x 1530mm high | C16: 18 | D16: Nr. | E16: 3470.44 | F16: =C16*E16 -> 62467.92 | G16: EM-24
B18: FHC cabinet; including stainless steel doors, finishes, metal skirting, backing, ironmongery, fixings and all ancillary works as necessary
A20: B | B20: Overall size 800 x 350 x 1800mm high | C20: 177 | D20: Nr. | E20: 613.86 | F20: =C20*E20 -> 108653.22
A22: C | B22: Skirting; 100mm high; type MT-02 | C22: 266 | D22: m | E22: 214.58 | F22: =C22*E22 -> 57078.28
A24: D | B24: To walls; white metal type MT-08 | C24: 922 | D24: m² | E24: 1648.89 | F24: =C24*E24 -> 1520276.6
B39: ** VE Reference "EM-" denotes items raised by Client in the VE Schedule
C41: To Collection | E41: AED | F41: =SUM(F14:F34) -> 1748476
B44: GENERALLY
B46: Allow for any other works which are not included above and which are required to complete the Woodwork in accordance with the Specification and the drawings (Tenderer to list below): | D46: Item | F46: =C46*E46 -> 0
B48: Quantity Adjustments
A50: A | B50: Variance in quantity following in-house Quantity Take Off | C50: 1 | D50: item | F50: =C50*E50 -> 0
C86: To Collection | E86: AED | F86: =SUM(F45:F62) -> 0
B89: COLLECTION
B91: Page 4/F/1 | F91: =F41 -> 1748476
B93: Page 4/F/2 | F93: =F86 -> 0
C137: Carried To Summary | E137: AED | F137: =SUM(F89:F113) -> 1748476

Sheet Bill 4 - Thermal and Moisture
A1: Item | B1: Description | C1: Quantity | D1: Unit | E1: Rate | F1: Amount
E2: AED | F2: AED
B4: THERMAL AND MOISTURE PROTECTION
B6: COVERINGS AND LININGS
B8: Note: Refer to the following:
B10: 1. Drawing Reference Nr. S-00011 and S-60001
B12: 2. Structures Specification dated 28 March 2022
B14: Cold-applied waterproofing system; including surface preparation and all ancillary works as necessary; as Detail 8 Drawing Nr. A-951
A16: A | B16: To wet areas | C16: 1,038 | D16: m² | E16: 23.69 | F16: =C16*E16 -> 24590.22
A18: B | B18: Turning-ups / skirting; 200mm high | C18: 1,234 | D18: m | E18: 10.77 | F18: =C18*E18 -> 13290.18
B20: Waterproofing; including surface preparation, protection, accessories and all ancillary works as necessary
A22: C | B22: Waterproofing membrane; to slab on grade | C22: 779 | D22: m² | E22: 37.69 | F22: =C22*E22 -> 29360.51
C48: To Collection | E48: AED | F48: =SUM(F11:F40) -> 67240.91
B51: GENERALLY
A53: A | B53: Allow for any other works which are not included above and which are required to complete the Thermal and Moisture Protection in accordance with the Specification and the drawings (Tenderer to list below): | D53: Item | F53: =C53*E53 -> 0
A55: B | B55: 3mm thick protectiob board to vertical surfaces | C55: 5 | D55: m² | E55: 22.62 | F55: =C55*E55 -> 113.1
B58: Quantity Adjustments
A60: C | B60: Variance in quantity following in-house Quantity Take Off | C60: 1 | D60: item | F60: =C60*E60 -> 0
C93: To Collection | E93: AED | F93: =SUM(F51:F67) -> 113.1
B96: COLLECTION
B98: Page 4/G/1 | F98: =F48 -> 67240.91
B100: Page 4/G/2 | F100: =F93 -> 113.1
C143: Carried To Summary | E143: AED | F143: =SUM(F96:F117) -> 67354.01

Sheet Bill 4 Doors and Windows
A1: Item | B1: Description | C1: Quantity | D1: Unit | E1: Rate | F1: Amount | G1: VE Ref.
E2: AED | F2: AED
B4: DOORS AND WINDOWS
B6: DOORS
B8: Note: Refer to the following
B10: 1. Drawing Reference Nr. ID-900 series, A-800 to A-801
B12: Hollow metal doors and frames; building into brick, block concrete walls and gypsum partitions; including ironmongery (measured separately), finishes, architrave, weatherstripping and all necessary fixings and accessories
A14: A | B14: Type DS-04; 1100 x 2200mm high; single leaf door | C14: 12 | D14: Nr. | E14: 1967.57 | F14: =C14*E14 -> 23610.84
A16: B | B16: Type DS-06; 1200 x 2200mm high; single leaf door | C16: 8 | D16: Nr. | E16: 2156.03 | F16: =C16*E16 -> 17248.24
A18: C | B18: Type DS-08; 1600 x 2200mm high; double leaf door | C18: 10 | D18: Nr. | E18: 3077.89 | F18: =C18*E18 -> 30778.9
A20: D | B20: Type DS-10; 1800 x 2200mm high; double leaf door; FR-90min. | C20: 0 | D20: Nr. | E20: 3240.51 | F20: =C20*E20 -> 0
A22: E | B22: Type DS-12; 1250 x 2140mm high; single leaf door | C22: 1 | D22: Nr. | E22: 2188.34 | F22: =C22*E22 -> 2188.34
A24: F | B24: Type DS-17; 2000 x 2200mm high; double leaf door | C24: 4 | D24: Nr. | E24: 3222.2 | F24: =C24*E24 -> 12888.8
A26: G | B26: Type GR-502; 1800 x 2140mm | C26: 1 | D26: Nr. | E26: 3168.36 | F26: =C26*E26 -> 3168.36
A28: H | B28: 1800 x 2140mm high (assumed as metal door) | C28: 5 | D28: Nr. | E28: 3168.36 | F28: =C28*E28 -> 15841.8
A30: J | B30: 1100 x 2140mm high (assumed as metal door) | C30: 6 | D30: Nr. | E30: 1956.8 | F30: =C30*E30 -> 11740.8
A32: K | B32: 1250 x 2140mm high (assumed as metal door) | C32: 3 | D32: Nr. | E32: 2188.34 | F32: =C32*E32 -> 6565.02
A34: L | B34: 1250 x 2923mm high (assumed as metal door) | C34: 1 | D34: Nr. | E34: 2640.66 | F34: =C34*E34 -> 2640.66
C41: To Collection | E41: AED | F41: =SUM(F13:F37) -> 126671.76
B44: DOORS (Cont´d)
B46: Glass doors; building into brick, block concrete walls and gypsum partitions; including sliding door system, frames, ironmongery, finishes, architrave, weatherstripping and all necessary fixings and accessories
A48: A | B48: Type DG-01; 4100 x 2286mm high | C48: 6 | D48: Nr. | E48: 38091.45 | F48: =C48*E48 -> 228548.7
A50: B | B50: Type DG-02; 1473 x 2896mm high | C50: 2 | D50: Nr. | E50: 8062.03 | F50: =C50*E50 -> 16124.06
A52: C | B52: 1200 x 3373mm high (assumed as glass door) | C52: 1 | D52: Nr. | E52: 7649.37 | F52: =C52*E52 -> 7649.37
A54: D | B54: 4267 x 4267mm high (assumed as glass door) | C54: 1 | D54: Nr. | E54: 34414.29 | F54: =C54*E54 -> 34414.29
B56: SCREENS / CURTAIN WALLS
B58: Glass wall; including extruded mullion profile, gaskets, thermal insulation, waterproofing membrane, ironmongery, accessories and all ancillary works as necessary
A60: E | B60: To parking lobby | C60: 126 | D60: m² | E60: 6001.92 | F60: Refer to Bill No. 6 - Provisional Sum | G60: PTC26
A62: F | B62: Extra over sliding door; size 2000 x 22000mm including mechanism | C62: 2 | D62: Nr. | E62: 33317.83 | F62: Refer to Bill No. 6 - Provisional Sum | G62: PTC26
C84: To Collection | E84: AED | F84: =SUM(F46:F70) -> 286736.42
B87: IRONMONGERY
B89: Ironmongery; for metal doors; including all ancillary works as necessary
A91: A | B91: Type DS-04; 1100 x 2200mm high; single leaf door | C91: 12 | D91: Nr. | E91: 3755.29 | F91: =C91*E91 -> 45063.48
A93: B | B93: Type DS-06; 1200 x 2200mm high; single leaf door | C93: 8 | D93: Nr. | E93: 3792.98 | F93: =C93*E93 -> 30343.84
A95: C | B95: Type DS-08; 1600 x 2200mm high; double leaf door | C95: 10 | D95: Nr. | E95: 2806.51 | F95: =C95*E95 -> 28065.1
A97: D | B97: Type DS-10; 1800 x 2200mm high; double leaf door; FR-90min. | C97: 0 | D97: Nr. | E97: 2986.35 | F97: =C97*E97 -> 0
A99: E | B99: Type DS-12; 1250 x 2140mm high; single leaf door | C99: 1 | D99: Nr. | E99: 4838.69 | F99: =C99*E99 -> 4838.69
A101: F | B101: Type DS-17; 2000 x 2200mm high; double leaf door | C101: 4 | D101: Nr. | E101: 2553.42 | F101: =C101*E101 -> 10213.68
A103: G | B103: Type GR-502; 1800 x 2140mm | C103: 1 | D103: Nr. | E103: 900.32 | F103: =C103*E103 -> 900.32
A105: H | B105: 1800 x 2140mm high (assumed as metal door) | C105: 5 | D105: Nr. | E105: 900.32 | F105: =C105*E105 -> 4501.6
...

Sheet Bill 4 - Finishes
A1: Item | B1: Description | C1: Quantity | D1: Unit | E1: Rate | F1: Amount | G1: VE Ref.
E2: AED | F2: AED
B4: FINISHES
B6: BACKGROUNDS
B8: Note: Refer to the following
B10: 1. Typical Detail Reference No. ID-500 series, A-951 to 953
B12: 2. Room finishes schedule Reference No. A-820
B14: 3. Material Schedule G-004
B16: 4. Drawings listed on Drawing Nr. ID-000 and G-001, all inclusive
B18: 5. Interior Architectural Specification Document 000110 dated 22 April 2022, all inclusive
B20: Sand cement screed; including surface preparation and all ancillary works as necessary
A22: A | B22: Screed; to receive tile | C22: 7433 | D22: m² | E22: 69.77 | F22: =C22*E22 -> 518600.41
A24: B | B24: Screed; to receive epoxy paint | C24: 1937 | D24: m² | E24: 73.77 | F24: =C24*E24 -> 142892.49
B26: Cement plaster; including surface preparation and all ancillary works as necessary
A28: C | B28: Wall plaster; 15mm thick; to receive tiles | C28: 1990 | D28: m² | E28: 48.05 | F28: =C28*E28 -> 95619.5
A30: D | B30: Wall plaster; 15mm thick; to receive paint | C30: 2953 | D30: m² | E30: 48.05 | F30: =C30*E30 -> 141891.65 | G30: EM-18 EM-20
B41: ** VE Reference "EM-" denotes items raised by Client in the VE Schedule
C43: To Collection | E43: AED | F43: =SUM(F20:F40) -> 899004.05
B46: INTERNAL FINISHINGS
B48: Note: Refer to the following
B50: 1. Typical Detail Reference No. ID-500 series, A-951 to 953
B52: 2. Room finishes schedule Reference No. A-820
B54: 3. Material Schedule G-004
B56: 4. Drawings listed on Drawing Nr. ID-000 and G-001, all inclusive
B58: 5. Interior Architectural Specification Document 000110 dated 22 April 2022, all inclusive
B60: Full bodied anti-slip floor tiles; laid on cement and sand screed (measured separately); including adhesive mortar, grout, joint and edge treatment sealer and all ancillary works as necessary
A62: A | B62: Type PC-01; 9mm thick | C62: 1,184 | D62: m² | E62: 177.82 | F62: =C62*E62 -> 210538.88 | G62: EM-17
A64: B | B64: Skirting; type PC-01 | C64: 590 | D64: m | E64: 74.67 | F64: =C64*E64 -> 44055.3 | G64: EM-17
B66: Porcelain floor tiles; laid on cement and sand screed (measured separately); including adhesive mortar, grout, joint and edge treatment sealer and all ancillary works as necessary
A68: C | B68: Type TL-01/TL-02/TL-03; 10mm thick | C68: 4458 | D68: m² | E68: 218.91 | F68: =C68*E68 -> 975900.78 | G68: EM-17
A70: D | B70: Type TL-06; 600 x 600 x 10mm thick | C70: 1792 | D70: m² | E70: 220.27 | F70: =C70*E70 -> 394723.84 | G70: EM-17
A72: E | B72: Skirting; type TL-01/TL-02/TL-03; 100mm high | C72: 20 | D72: m | E72: 111.26 | F72: =C72*E72 -> 2225.2 | G72: EM-17
A74: F | B74: Skirting; type TL-06; 100mm high | C74: 9 | D74: m | E74: 111.09 | F74: =C74*E74 -> 999.81 | G74: EM-17
B76: Stainless steel skirting; including adhesive, fixings and all ancillary works as necessary
B78: ** VE Reference "EM-" denotes items raised by Client in the VE Schedule
C80: To Collection | E80: AED | F80: =SUM(F60:F76) -> 1628443.8
B83: INTERNAL FINISHINGS (Cont´d)
A85: A | B85: Type MT-01; 100mm high | C85: 54 | D85: m | E85: 350.11 | F85: =C85*E85 -> 18905.94
A87: B | B87: Type MT-02; 100mm high; in dark grey color; T22 Onyx Black Grane FPR finish | C87: 555 | D87: m | E87: 214.58 | F87: =C87*E87 -> 119091.9
B89: Full bodied anti-slip floor tiles; render on cement and sand plaster (measured separately); including adhesive mortar, grout, joint and edge treatment sealer and all ancillary works as necessary
...

Sheet Bill 4 - Accessories
A1: Item | B1: Description | C1: Quantity | D1: Unit | E1: Rate | F1: Amount | G1: VE Ref.
E2: AED | F2: AED
B4: ACCESSORIES
B6: PARTITIONS
B8: Note: Refer to the following:
B10: 1. Drawing Reference Nr. A-700 to A-710 and A-962
B12: Drywall partition; including metal studs, supports and all ancillary works as necessary
A14: A | B14: Type 3; 150mm thick; to external | C14: 124 | D14: m² | E14: 252.32 | F14: =C14*E14 -> 31287.68
A16: B | B16: Type 3; 150mm thick; to internal | C16: 1,250 | D16: m² | E16: 189.24 | F16: =C16*E16 -> 236550
A18: C | B18: Allow cubicle partition to B1 male staff toilet | D18: Item | F18: 22221.58
A20: D | B20: Allow cubicle partition to B1 female staff toilet | D20: Item | F20: 38887.76
A22: E | B22: Allow urinal partition to B1 male staff toilet | C22: 1 | D22: Item | E22: 10230.93 | F22: =C22*E22 -> 10230.93
C50: To Collection | E50: AED | F50: =SUM(F10:F33) -> 339177.95
B53: SANITARY ACCESSORIES
A55: A | B55: Allow sanitary accessories to B1 male staff toilet | C55: 1 | D55: Item | E55: 38930.95 | F55: =C55*E55 -> 38930.95 | G55: EM-41
A57: B | B57: Allow sanitary accessories to B1 female staff toilet | C57: 1 | D57: Item | E57: 38262.42 | F57: =C57*E57 -> 38262.42 | G57: EM-41
B96: ** VE Reference "EM-" denotes items raised by Client in the VE Schedule
C98: To Collection | E98: AED | F98: =SUM(F52:F75) -> 77193.37
B101: PARKING ACCESSORIES
B103: Note : refer to the following
B105: 1. Drawing Reference Nr. A-950
B107: Parking accessories; including all ancillary works as necessary
A109: A | B109: Parking space line - ADA; 2700 x 5500mm | C109: 182 | D109: Nr.
A111: B | B111: Single parking space line; 2500 x 5500mm | C111: 48 | D111: Nr. | F111: =C111*E111 -> 0
A113: C | B113: Single parking space line; 2700 x 5500mm | C113: 3,518 | D113: Nr. | F113: Included in Provisional Sum (Bill No. 6) as clarified
A115: D | B115: Single parking space line; motor bike; 1500 x 5500mm | C115: 103 | D115: Nr. | F115: =C115*E115 -> 0
A117: E | B117: Direction arrows | C117: 144 | D117: Nr. | F117: =C117*E117 -> 0
A119: F | B119: Roof ladder | C119: 2 | D119: Nr. | E119: 7000.11 | F119: =C119*E119 -> 14000.22
A121: G | B121: Wheel stopper | C121: 3,851 | D121: Nr. | F121: Included in Provisional Sum (Bill No. 6) as clarified
A123: H | B123: Column guards | D123: Item | F123: Included in Provisional Sum (Bill No. 6) as clarified
A125: J | B125: Column guards (RATE ONLY) | D125: Nr. | E125: 118.46 | F125: =C125*E125 -> 0
A127: K | B127: Crash guards; 4m long x 200mm high; high impact resistance rubber profiled fixed to wall with chemical anchor | D127: Item | F127: Included in Provisional Sum (Bill No. 6) as clarified
A129: L | B129: Crash guards; 4m long x 200mm high; high impact resistance rubber profiled fixed to wall with chemical anchor (RATE ONLY) | D129: Nr. | E129: 1206.17 | F129: =C129*E129 -> 0
A131: M | B131: Speed humps | D131: Item | F131: Included in Provisional Sum (Bill No. 6) as clarified
A133: N | B133: Speed humps (RATE ONLY) | D133: Nr. | E133: 236.93 | F133: =C133*E133 -> 0
C136: To Collection | E136: AED | F136: =SUM(F106:F134) -> 14000.22
B139: SIGNAGE AND WAYFINDING
B141: Note: Refer to the following
B143: 1. 100% Detailed Design - EGD, Project Sign Type Family Sheet No. G-2
B145: Interior Signage
...

Sheet Bill 4 - Furnishings
A1: Item | B1: Description | C1: Quantity | D1: Unit | E1: Rate | F1: Amount
E2: AED | F2: AED
B4: FURNISHINGS
B6: LOOSE FURNITURE
B8: Note: Refer to the following
B10: 1. Interior FF&E Schedule and Mood Boards dated April 2022
B12: Loose furniture; including all ancillary works as necessary
A14: A | B14: Type I-BA-03: bench seating | C14: 32 | D14: Nr. | E14: 2012.14 | F14: =C14*E14 -> 64388.48
A16: B | B16: Type I-WB-02: recycling & waste bin | C16: 39 | D16: Nr. | E16: 470.12 | F16: =C16*E16 -> 18334.68
A18: C | B18: Planter | C18: 24 | D18: Nr. | E18: 5192.82 | F18: =C18*E18 -> 124627.68
C51: To Collection | E51: AED | F51: =SUM(F9:F33) -> 207350.84
B54: GENERALLY
B56: Allow for any other works which are not included above and which are required to complete the Furnishings in accordance with the Specification and the drawings (Tenderer to list below): | D56: Item | F56: =C56*E56 -> 0
B58: Crash rail along perimiter of skylight wells at levels 3 and lower roof
A60: A | B60: Supply and installation 900mm high painted mild steel of RAL 860-3 colour handrails | C60: 551 | D60: m | E60: 1280.29 | F60: =C60*E60 -> 705439.79
B62: Quantity Adjustments
A64: B | B64: Variance in quantity following in-house Quantity Take Off | C64: 1 | D64: item | F64: =C64*E64 -> 0
C98: To Collection | E98: AED | F98: =SUM(F55:F78) -> 705439.79
B101: COLLECTION
B103: Page 4/M/1 | F103: =F51 -> 207350.84
B105: Page 4/M/2 | F105: =F98 -> 705439.79
C149: Carried To Summary | E149: AED | F149: =SUM(F101:F128) -> 912790.63

Sheet Bill 4 - Mechanical
A1: Item | B1: Description | C1: Quantity | D1: Unit | E1: Rate | F1: Amount | G1: VE Ref.
E2: AED | F2: AED
B4: MECHANICAL ENGINEERING INSTALLATIONS
B6: DRAINAGE INSTALLATION
B8: Note: Please refer to the following:
B10: 1) Drawing Nr. D-12200 to D-12259, D-13100 to D-13110 and 3D View Al-Khail R20 Plumb; all inclusive
B12: 2) Drainage general notes, symbols and legends and Drainage equipment schedule Drawing Nr. D-09102 and D-00050
B14: 3) Al Khail Avenue Mall Redevelopment - Mechanical Specification dated March 28, 2022
B16: uPVC pipework; including fittings, supports and ancillary work as necessary
B18: Rainwater pipework
A20: A | B20: 110mm diameter | C20: 29 | D20: m | E20: 130.82 | F20: =C20*E20 -> 3793.78
A22: B | B22: 150mm diameter | C22: 88 | D22: m | E22: 183.55 | F22: =C22*E22 -> 16152.4
A24: C | B24: 160mm diameter | C24: 16 | D24: m | E24: 183.55 | F24: =C24*E24 -> 2936.8
A26: D | B26: 200mm diameter | C26: 138 | D26: m | E26: 159.77 | F26: =C26*E26 -> 22048.26
B28: Accessories; including supports and ancillary work as necessary
A30: E | B30: Roof drain; 2" diameter | C30: 2 | D30: Nr. | E30: 279.82 | F30: =C30*E30 -> 559.64
A32: F | B32: Roof drain; 4" diameter | C32: 11 | D32: Nr. | E32: 581.9 | F32: =C32*E32 -> 6400.9
A34: G | B34: Roof side drain; 4" diameter | C34: 10 | D34: Nr. | E34: 710.63 | F34: =C34*E34 -> 7106.3
B36: Flexible elastomeric insulation, 13mm thick to rainwater pipes including support, accessories and other ancillary works as necessary
A38: H | B38: 110mm diameter | C38: 29 | D38: m | E38: 36.6 | F38: =C38*E38 -> 1061.4
A40: J | B40: 150mm diameter | C40: 88 | D40: m | E40: 43.8 | F40: =C40*E40 -> 3854.4
C44: To Collection | E44: AED | F44: =SUM(F19:F42) -> 63913.88
B47: DRAINAGE INSTALLATION (Cont´d)
A49: A | B49: 160mm diameter | C49: 16 | D49: m | E49: 43.8 | F49: =C49*E49 -> 700.8
A51: B | B51: 200mm diameter | C51: 138 | D51: m | E51: 47.11 | F51: =C51*E51 -> 6501.18
B53: uPVC pipework; including fittings, supports and ancillary work as necessary
B55: Waste pipework
A57: C | B57: 50mm diameter | C57: 21 | D57: m | E57: 57.19 | F57: =C57*E57 -> 1200.99
A59: D | B59: 80mm diameter | C59: 88 | D59: m | E59: 119.7 | F59: =C59*E59 -> 10533.6
A61: E | B61: 110mm diameter | C61: 1,463 | D61: m | E61: 130.82 | F61: =C61*E61 -> 191389.66
A63: F | B63: 150mm diameter | C63: 1,075 | D63: m | E63: 183.55 | F63: =C63*E63 -> 197316.25
A65: G | B65: 160mm diameter | C65: 75 | D65: m | E65: 183.55 | F65: =C65*E65 -> 13766.25
A67: H | B67: 200mm diameter | C67: 24 | D67: m | E67: 159.77 | F67: =C67*E67 -> 3834.48
B69: Soil pipework
A71: J | B71: 50mm diameter | C71: 4 | D71: m | E71: 57.19 | F71: =C71*E71 -> 228.76
A73: K | B73: 110mm diameter | C73: 319 | D73: m | E73: 130.82 | F73: =C73*E73 -> 41731.58
A75: L | B75: 150mm diameter | C75: 561 | D75: m | E75: 183.55 | F75: =C75*E75 -> 102971.55
A77: M | B77: 160mm diameter | C77: 71 | D77: m | E77: 183.55 | F77: =C77*E77 -> 13032.05
A79: N | B79: 200mm diameter | C79: 86 | D79: m | E79: 159.77 | F79: =C79*E79 -> 13740.22
B81: Kitchen waste pipework
...

Sheet Bill 4 - Electrical
A1: Item | B1: Description | C1: Quantity | D1: Unit | E1: Rate | F1: Amount | G1: VE Ref.
E2: AED | F2: AED
B4: ELECTRICAL ENGINEERING INSTALLATIONS
B6: POWER INSTALLATION
B8: Note: Please refer to the following:
B10: 1) Drawing Nr. E-00003 to 10200, E-12500 to 12554, E-12730 to 12784, E-12925 to 12979, E-12860 to 12879 and Al Khail_R20_ELEC_LT: 3D View; all inclusive
B12: 2) Al Khail Avenue Mall Redevelopment Electrical Specifications dated March 28, 2022
B14: XLPE cables including earth connectivity conductor cables, terminations, lugs, supports and all ancillary work
B16: 1 x 2C x 4mm² CU/XLPE/LSOH + 1 x 1C x 4mm² CU/LSOH ECC
A18: A | B18: From MCP-M-01-1B01 to 2x16A weatherproof isolator for EF-B1-02 | C18: 1 | D18: Item | E18: 6570.14 | F18: =C18*E18 -> 6570.14
A20: B | B20: From MCP-M-01-1B01 to 2x16A weatherproof isolator for EF-B1-03 | C20: 1 | D20: Item | E20: 1314.03 | F20: =C20*E20 -> 1314.03
A22: C | B22: From MCP-M-04-RF01 to 2x16A weatherproof isolator for EF-LR-01 | C22: 1 | D22: Item | E22: 3583.71 | F22: =C22*E22 -> 3583.71
A24: D | B24: From MCP-M-04-RF01 to 2x16A weatherproof isolator for EF-LR-02 | C24: 1 | D24: Item | E24: 3583.71 | F24: =C24*E24 -> 3583.71
A26: E | B26: From MCP-M-04-UR01 to 2x16A weatherproof isolator for EF-UR-01 | C26: 1 | D26: Item | E26: 5972.85 | F26: =C26*E26 -> 5972.85
A28: F | B28: From MCP-M-04-UR01 to 2x16A weatherproof isolator for EF-UR-02 | C28: 1 | D28: Item | E28: 5972.85 | F28: =C28*E28 -> 5972.85
B30: 1 x 4C x 4mm² CU/XLPE/LSOH + 1 x 1C x 4mm² CU/LSOH ECC
A32: G | B32: From MCP-M-01-UR02 to VFD for recovery wheel | C32: 1 | D32: Item | E32: 4332.58 | F32: =C32*E32 -> 4332.58
B34: 1 x 4C x 4mm² CU/XLPE/SWA/PVC + 1 x 1C x 4mm² CU/PVC ECC
C37: To Collection | E37: AED | F37: =SUM(F16:F34) -> 31329.87
B40: POWER INSTALLATION (Cont´d)
A42: A | B42: From SMDB-S-04-B1-SF to 20A weatherproof isolator for HWCS-01 | C42: 1 | D42: Item | E42: 6670.06 | F42: =C42*E42 -> 6670.06
B44: 1 x 4C x 6mm² CU/XLPE/LSOH + 1 x 1C x 6mm² CU/LSOH ECC
A46: B | B46: From EMCP-M-01-UR01 to VFD for EPF-UR-08 | C46: 1 | D46: Item | E46: 1472.98 | F46: =C46*E46 -> 1472.98
A48: C | B48: From EMCP-M-01-UR01 to VFD for EPF-UR-09 | C48: 1 | D48: Item | E48: 1543.12 | F48: =C48*E48 -> 1543.12
B50: 1 x 4C x 10mm² CU/XLPE/SWA/PVC + 1 x 1C x 10mm² CU/PVC ECC
A52: D | B52: From SMDB-S-01-1B01 to FP-07 | C52: 100 | D52: m | E52: 44.83 | F52: =C52*E52 -> 4483
A54: E | B54: From SMDB-S-04-1B02 to FP-05 | C54: 100 | D54: m | E54: 44.83 | F54: =C54*E54 -> 4483
A56: F | B56: From SMDB-S-04-B1-SF to 40A weatherproof isolator for EWH-06 | C56: 1 | D56: Item | E56: 11207.51 | F56: =C56*E56 -> 11207.51
A58: G | B58: From SMDB-S-04-B1-SF to DB-S--04-1B08 | C58: 1 | D58: Item | E58: 358.64 | F58: =C58*E58 -> 358.64
A60: H | B60: From SMDB-S-04-RF01 to DB-S-04-RF07 | C60: 1 | D60: Item | E60: 717.28 | F60: =C60*E60 -> 717.28
A62: J | B62: From SMDB-S-04-UR01 to DB-S-04-UR03 | C62: 1 | D62: Item | E62: 717.28 | F62: =C62*E62 -> 717.28
B64: 1 x 4C x 16mm² CU/XLPE/SWA/PVC + 1 x 1C x 16mm² CU/PVC ECC
A66: K | B66: From SMDB-S-01-1B01 to FP-04 | C66: 100 | D66: m | E66: 54.92 | F66: =C66*E66 -> 5492
A68: L | B68: From SMDB-S-04-B1-SF to DB-S--04-1B07 | C68: 1 | D68: Item | E68: 384.49 | F68: =C68*E68 -> 384.49
B70: 1 x 4C x 25mm² CU/XLPE/LSOH + 1 x 1C x 16mm² CU/LSOH ECC
A72: M | B72: From MCP-M-04-RF01 to VFD for AHU-M-LR-01 | C72: 1 | D72: Item | E72: 5568.14 | F72: =C72*E72 -> 5568.14
A74: N | B74: From MCP-M-04-RF01 to VFD for AHU-M-RF-01 | C74: 1 | D74: Item | E74: 5568.14 | F74: =C74*E74 -> 5568.14
C82: To Collection | E82: AED | F82: =SUM(F41:F78) -> 48665.64
B85: POWER INSTALLATION (Cont´d)
B87: 1 x 4C x 25mm² CU/XLPE/SWA/LSOH + 1 x 1C x 16mm² CU/LSOH ECC
...

Sheet Bill 4-Sum
A1: Item | B1: Description | C1: Page Nr. | D1: Amount AED
B5: SUMMARY
B8: CONCRETE WORK | C8: 4/C/1 - 4/C/4 | D8: ='Bill 4 Concrete'!F242 -> 3482318.8
B11: MASONRY | C11: 4/D/1 - 4/D/2 | D11: ='Bill 4 - Masonry'!F136 -> 1388266.5
B13: WOODWORK | C13: 4/F/1 - 4/F/2 | D13: ='Bill 4 Woodwork'!F137 -> 1748476
B16: THERMAL AND MOISTURE PROTECTION | C16: 4/G/1 - 4/G/2 | D16: ='Bill 4 - Thermal and Moisture'!F143 -> 67354.01
B19: DOORS AND WINDOWS | C19: 4/H/1 - 4/H/4 | D19: ='Bill 4 Doors and Windows'!F222 -> 549172.63
B22: FINISHES | C22: 4/J/1 - 4/J/6 | D22: ='Bill 4 - Finishes'!F290 -> 6357559.3
B25: ACCESSORIES | C25: 4/K/1 - 4/K/7 | D25: ='Bill 4 - Accessories'!F333 -> 1017703.5
B28: FURNISHINGS | C28: 4/M/1 - 4/M/2 | D28: ='Bill 4 - Furnishings'!F149 -> 912790.63
B31: MECHANICAL ENGINEERING INSTALLATIONS | C31: 4/Q1/1 - 4/Q1/32 | D31: ='Bill 4 - Mechanical'!F1483 -> 14227895
B34: ELECTRICAL ENGINEERING INSTALLATIONS | C34: 4/R/1 - 4/R/27 | D34: ='Bill 4 - Electrical'!F1249 -> 13035047
B45: TOTAL FOR BILL NO. 4 -PARKING FLOORS REFURBISHMENT
B46: TO MAIN SUMMARY | C46: AED | D46: =SUM(D6:D41) -> 42786583
