Workbook

Sheet Bill 14 Mall Metalwork
A1: Item | B1: Description | C1: Quantity | D1: Unit | E1: Rate | F1: Amount
E2: AED | F2: AED
B4: METALWORK
B6: STRUCTURAL METALWORK
B8: Note: Refer to the following:
B10: Structural steel frame; with grade S275; conforming to AISC 360-10; including teflon, stiffeners, fixings, supports and all ancillary works as necessary
A12: A | B12: CHS 193.7 x 5mm thick | C12: 1.59 | D12: t | E12: 12338.62 | F12: =C12*E12 -> 19618.406
A14: B | B14: L 150 x 150 x 10mm thick | C14: 3.38 | D14: t | E14: 11192.68 | F14: =C14*E14 -> 37831.258
A16: C | B16: PFC150 x 75 x 18mm thick | C16: 2.06 | D16: t | E16: 11192.68 | F16: =C16*E16 -> 23056.921
A18: D | B18: PFC260 x 90 x 35mm thick | C18: 0.85 | D18: t | E18: 11192.68 | F18: =C18*E18 -> 9513.778
A20: E | B20: Square tube; 500 x 1000 x 40mm thick | C20: 0.03 | D20: t | E20: 11192.68 | F20: =C20*E20 -> 335.7804
A22: F | B22: UB 254 x 146 x 37kg/m | C22: 0.51 | D22: t | E22: 11192.68 | F22: =C22*E22 -> 5708.2668
A24: G | B24: UB 305 x 165 x 46kg/m | C24: 1.48 | D24: t | E24: 11192.68 | F24: =C24*E24 -> 16565.166
A26: H | B26: UB 305 x 165 x 54 | C26: 5.31 | D26: t | E26: 11192.68 | F26: =C26*E26 -> 59433.131
A28: J | B28: UB 406 x 178 x 54kg/m | C28: 4.67 | D28: t | E28: 11192.68 | F28: =C28*E28 -> 52269.816
A30: K | B30: UB 406 x 178 x 60 | C30: 3.23 | D30: t | E30: 11192.68 | F30: =C30*E30 -> 36152.356
A32: L | B32: UB 457 x 191 x 133 | C32: 22.12 | D32: t | E32: 11192.68 | F32: =C32*E32 -> 247582.08
A34: M | B34: UB 533 x 210 x 122 | C34: 2.73 | D34: t | E34: 11192.68 | F34: =C34*E34 -> 30556.016
... A40: Q | B40: UB 1016 x 305 x 393 | C40: 12.82 | D40: t | E40: 11192.68 | F40: =C40*E40 -> 143490.16
C43: To Collection | E43: AED | F43: =SUM(F12:F40) -> 883693.3
B46: STRUCTURAL METALWORK (Cont´d)
A48: A | B48: Built-up section; 40mm thick metal plate | C48: 2.82 | D48: t | E48: 11192.68 | F48: =C48*E48 -> 31563.358
A50: B | B50: Baseplate; 12mm thick | C50: 0.44 | D50: t | E50: 10046.73 | F50: =C50*E50 -> 4420.5612
A52: C | B52: Baseplate; 16mm thick | C52: 0.2 | D52: t | E52: 10046.73 | F52: =C52*E52 -> 2009.346
A54: D | B54: Baseplate; 20mm thick | C54: 0.45 | D54: t | E54: 10046.73 | F54: =C54*E54 -> 4521.0285
A56: E | B56: Baseplate; 25mm thick | C56: 0.59 | D56: t | E56: 10046.73 | F56: =C56*E56 -> 5927.5707
A58: F | B58: EA 150 x 150 x 10mm thick | C58: 0.21 | D58: t | E58: 11192.68 | F58: =C58*E58 -> 2350.4628
A60: G | B60: M16; 200mm long | C60: 108 | D60: Nr. | E60: 35.55 | F60: =C60*E60 -> 3839.4
A62: H | B62: M16; 300mm long | C62: 116 | D62: Nr. | E62: 35.55 | F62: =C62*E62 -> 4123.8
A64: J | B64: M20; 200mm long | C64: 48 | D64: Nr. | E64: 35.55 | F64: =C64*E64 -> 1706.4
A66: K | B66: M24; 300mm long | C66: 80 | D66: Nr. | E66: 35.55 | F66: =C66*E66 -> 2844
A68: L | B68: Fittings | C68: 1 | D68: Item | E68: 114595.45 | F68: =C68*E68 -> 114595.45
A70: M | B70: Fixings | C70: 1 | D70: Item | E70: 36671.34 | F70: =C70*E70 -> 36671.34
B72: Structural steel frame; with grade S355; conforming to AISC 360-10; including teflon, stiffeners, fixings, supports and all ancillary works as necessary
A74: N | B74: CHS 508 x 16mm thick | C74: 21.29 | D74: t | E74: 12338.62 | F74: =C74*E74 -> 262689.22
A76: P | B76: CHS 406.4 x 10mm thick | C76: 0.95 | D76: t | E76: 12338.62 | F76: =C76*E76 -> 11721.689
A78: Q | B78: L 150 x 150 x 18mm thick | C78: 0.17 | D78: t | E78: 11192.68 | F78: =C78*E78 -> 1902.7556
A80: R | B80: PFC100 x 50 x 10mm thick | C80: 0.56 | D80: t | E80: 11192.68 | F80: =C80*E80 -> 6267.9008
A82: S | B82: PFC180 x 90 x 26mm thick | C82: 3.8 | D82: t | E82: 11192.68 | F82: =C82*E82 -> 42532.184
A84: T | B84: PFC260 x 90 x 35mm thick | C84: 1.46 | D84: t | E84: 11192.68 | F84: =C84*E84 -> 16341.313
...

Sheet Bill 14 - Parking Metalwork
A1: Item | B1: Description | C1: Quantity | D1: Unit | E1: Rate | F1: Amount
E2: AED | F2: AED
B4: METALWORK
B6: STRUCTURAL METALWORK
B8: Structural steel frame; with grade S275; conforming to AISC 360-10; including teflon, stiffeners, fixings, supports and all ancillary works as necessary
A10: A | B10: UB 457 x 191 x 82 | C10: 20.02 | D10: t | E10: 11192.68 | F10: =C10*E10 -> 224077.45
A12: B | B12: UB 533 x 210 x 92 | C12: 4.91 | D12: t | E12: 11192.68 | F12: =C12*E12 -> 54956.059
A14: C | B14: UB 610 x 229 x 140 | C14: 15.79 | D14: t | E14: 11192.68 | F14: =C14*E14 -> 176732.42
A16: D | B16: UB 762 x 267 x 197 | C16: 4.53 | D16: t | E16: 11192.68 | F16: =C16*E16 -> 50702.84
A18: E | B18: UB 1016 x 305 x 272 | C18: 4.6 | D18: t | E18: 11192.68 | F18: =C18*E18 -> 51486.328
A20: F | B20: EA 120 x 120 x 15mm thick | C20: 1.15 | D20: t | E20: 11192.68 | F20: =C20*E20 -> 12871.582
A22: G | B22: PFC260 x 90 x 35 | C22: 0.59 | D22: t | E22: 11192.68 | F22: =C22*E22 -> 6603.6812
A24: H | B24: M12; 100mm long | C24: 87 | D24: Nr | E24: 24.09 | F24: =C24*E24 -> 2095.83
A26: J | B26: M16; 200mm long | C26: 212 | D26: Nr. | E26: 35.55 | F26: =C26*E26 -> 7536.6
A28: K | B28: Fittings | C28: 1 | D28: Item | E28: 94524.1 | F28: =C28*E28 -> 94524.1
A30: L | B30: Fixings | C30: 1 | D30: Item | E30: 31722.22 | F30: =C30*E30 -> 31722.22
B32: Structural steel frame; with grade S355; conforming to AISC 360-10; including teflon, stiffeners, fixings, supports and all ancillary works as necessary
A34: M | B34: UB 203 x 102 x 23 | C34: 0.74 | D34: t | E34: 11192.68 | F34: =C34*E34 -> 8282.5832
A36: N | B36: UB 305 x 127 x 37 | C36: 0.36 | D36: t | E36: 11192.68 | F36: =C36*E36 -> 4029.3648
C39: To Collection | E39: AED | F39: =SUM(F8:F36) -> 725621.06
B42: STRUCTURAL METALWORK (Cont´d)
A44: A | B44: UB 406 x 140 x 39 | C44: 7.83 | D44: t | E44: 11192.68 | F44: =C44*E44 -> 87638.684
A46: B | B46: UB 406 x 178 x 54 | C46: 2.84 | D46: t | E46: 11192.68 | F46: =C46*E46 -> 31787.211
A48: C | B48: UB 457 x 191 x 133 | C48: 2.11 | D48: t | E48: 11192.68 | F48: =C48*E48 -> 23616.555
A50: D | B50: UB 533 x 210 x 82 | C50: 5.68 | D50: t | E50: 11192.68 | F50: =C50*E50 -> 63574.422
A52: E | B52: UC 254 x 254 x 132 | C52: 19.23 | D52: t | E52: 11192.68 | F52: =C52*E52 -> 215235.24
A54: F | B54: UC 305 x 305 x 97 | C54: 20.09 | D54: t | E54: 11192.68 | F54: =C54*E54 -> 224860.94
A56: G | B56: Baseplate; 15mm thick | C56: 1.03 | D56: t | E56: 10046.73 | F56: =C56*E56 -> 10348.132
A58: H | B58: Baseplate; 25mm thick | C58: 0.93 | D58: t | E58: 10046.73 | F58: =C58*E58 -> 9343.4589
A60: J | B60: EA 120 x 120 x 8mm thick | C60: 1.34 | D60: t | E60: 11192.68 | F60: =C60*E60 -> 14998.191
A62: K | B62: M16; 200mm long | C62: 234 | D62: Nr. | E62: 35.55 | F62: =C62*E62 -> 8318.7
A64: L | B64: M16; 300mm long | C64: 80 | D64: Nr. | E64: 35.55 | F64: =C64*E64 -> 2844
A66: M | B66: M24; 210mm long | C66: 48 | D66: Nr. | E66: 35.55 | F66: =C66*E66 -> 1706.4
A68: N | B68: M30; 300mm long | C68: 40 | D68: Nr. | E68: 69.93 | F68: =C68*E68 -> 2797.2
A70: P | B70: M30; 600mm long | C70: 48 | D70: Nr. | E70: 104.31 | F70: =C70*E70 -> 5006.88
A72: Q | B72: Fittings | C72: 1 | D72: Item | E72: 86562.25 | F72: =C72*E72 -> 86562.25
A74: R | B74: Fixings | C74: 1 | D74: Item | E74: 27503.8 | F74: =C74*E74 -> 27503.8
B76: Protective treatment; including surface preparation
A78: S | B78: Corrosion protection system | C78: 2,089 | D78: m² | E78: 26.44 | F78: =C78*E78 -> 55233.16
A80: T | B80: Fireproofing and intumescent cementitious coating system | C80: 2,089 | D80: m² | E80: 218.95 | F80: =C80*E80 -> 457386.55
...

Sheet Bill 14 - Additional Works
A1: BILL NO. 14 - ADDITIONAL SCOPE OF WORK
A2: METALWORK GMP
A3: Item | B3: Description | C3: Quantity | D3: Unit | E3: Rate AED | F3: Amount AED
B4: METALWORK
B5: STRUCTURAL METALWORK - ADDITIONAL WORKS
A8: A | B8: Design and Authority Approvals | C8: 1 | D8: Item | F8: Included
A10: B | B10: Structural Steel Works based on Drawings issued for Authority Approval | C10: 818.67 | D10: t | E10: 11315.745 | F10: =C10*E10 -> 9263861.1
A12: C | B12: Structural Steelworks Extra-over - Subcontractor's Design Provision | C12: =1178-C10 -> 359.33 | D12: t | E12: 11315.745 | F12: =C12*E12 -> 4066086.7
A14: D | B14: Corrosion Protection System | C14: 15031 | D14: m² | E14: 26.44 | F14: =C14*E14 -> 397419.64
A16: E | B16: Fire-proofing and Cementitious Coating | C16: 15031 | D16: m² | E16: 218.79037 | F16: =C16*E16 -> 3288638
A18: F | B18: Composite Slab - Metal Decking including Civil Works | C18: 3546 | D18: m² | E18: 287.49 | F18: =C18*E18 -> 1019439.5
A20: G | B20: Purlins Associated with the additional steelwork | C20: 506 | D20: m | E20: 61.72 | F20: =C20*E20 -> 31230.32
A22: H | B22: Fittings & Fixings for additional scope of works | C22: 1 | D22: Item | F22: =777644.01-0.12 -> 777643.89
E34: Carried To Summary AED | F34: =SUM(F4:F33) -> 18844319

Sheet Bill 14 - Mezzanine
A1: Item | B1: Description | C1: Quantity | D1: Unit | E1: Rate | F1: Amount
E2: AED | F2: AED
B4: METALWORK
B6: STRUCTURAL METALWORK - OMISSION
B8: GROUND FLOOR
B10: Refer- S-12145 & S-43166
B12: Images 5&6
B14: Structural steel frame; with grade S275; conforming to AISC 360-10; including teflon, stiffeners, fixings, supports and all ancillary works as necessary
A16: A | B16: UB 533 x 165 x 74kg/m | C16: 50.542 | D16: t | E16: 11192.68 | F16: =C16*E16 -> 565700.43
A18: B | B18: UB 610 x 305 x 238kg/m | C18: 16.184 | D18: t | E18: 11192.68 | F18: =C18*E18 -> 181142.33
A20: C | B20: UB 686 x 254 x 152kg/m | C20: 36.979 | D20: t | E20: 11192.68 | F20: =C20*E20 -> 413894.11
A22: D | B22: UB 1016 x 305 x 437kg/m | C22: 185.769 | D22: t | E22: 11192.68 | F22: =C22*E22 -> 2079253
A24: E | B24: Fixing and Fittings | D24: Item | F24: 274855.56
B26: Protective treatment; including surface preparation
A28: F | B28: Corrosion Protection System | C28: 3745.7936 | D28: m² | E28: 26.44 | F28: =C28*E28 -> 99038.782
A30: G | B30: Fireproofing and Cementitious Coating | C30: 3745.7936 | D30: m² | E30: 218.62 | F30: =C30*E30 -> 818905.39
B32: Composite slab; including reinforcement and all ancillary as necessary
A34: H | B34: Composite Slab - Metal Deck including Civils | C34: 2840 | D34: m² | E34: 287.49 | F34: =C34*E34 -> 816471.6
C47: To Collection | E47: AED | F47: =SUM(F14:F44) -> 5249261.2
B50: STRUCTURAL METALWORK - OMISSION (Cont´d)
B52: LEVEL 1
B54: Refer- S-12145 & S-43166
B56: Images 5&6
B58: Structural steel frame; with grade S275; conforming to AISC 360-10; including teflon, stiffeners, fixings, supports and all ancillary works as necessary
B60: 1M-SB01 UB 533x165x74 | C60: 2.886 | D60: t | E60: 11192.68 | F60: =C60*E60 -> 32302.074
B62: 1M-SB02 UB 1016x305x437 | C62: 3.808 | D62: t | E62: 11192.68 | F62: =C62*E62 -> 42621.725
B64: 1M-SB03 UB 686x254x152 | C64: 18.435 | D64: t | E64: 11192.68 | F64: =C64*E64 -> 206337.06
B66: 1M-SB04 UB 610x305x238 | C66: 5.444 | D66: t | E66: 11192.68 | F66: =C66*E66 -> 60932.95
B68: Fixings and Fittings | D68: Item | F68: 29029.063
B70: Protective treatment; including surface preparation
B72: Corrosion protection system | C72: 395.61462 | D72: m² | E72: 26.44 | F72: =C72*E72 -> 10460.051
B74: Fireproofing and Cementitious Coating | C74: 395.61462 | D74: m² | E74: 218.62 | F74: =C74*E74 -> 86489.268
B76: Composite slab; including reinforcement and all ancillary as necessary
B78: Composite Slab - Metal Deck including Civils | C78: 344.16 | D78: m² | E78: 287.49 | F78: =C78*E78 -> 98942.558
C85: To Collection | E85: AED | F85: =SUM(F50:F81) -> 567114.75
B88: GENERALLY
A90: A | B90: Allow for any other works which are not included above and which are required to complete the Metalwork in accordance with the Specification and the drawings (Tenderer to list below): | D90: Item | F90: =C90*E90 -> 0
C131: To Collection | E131: AED | F131: =SUM(F88:F109) -> 0
B134: COLLECTION
B136: Page 14/4/1 | F136: =F47 -> 5249261.2
...

Sheet METAL SUM
A1: BILL NO. 14 - STRUCTURAL METAL WORK GMP AL KHAIL MALL REFURBISHMENT
A2: Item | B2: Description | C2: Page Nr. | F2: Amount AED
B4: SUMMARY
B5: Structural Steel Work - Mall | F5: =+'Bill 14 Mall Metalwork'!F434 -> 36105381
B6: Structural Steel Work - Parking | F6: =+'Bill 14 - Parking Metalwork'!F181 -> 2054382.8
B7: Additional Steel Work | F7: =+'Bill 14 - Additional Works'!F34 -> 18844319
B8: Omission of Mezzanine Floors on GF and L1 | F8: =-'Bill 14 - Mezzanine'!F181 -> -5816375.9
A15: TOTAL FOR BILL NO. 14 - STRUCTURAL METAL WORK GMP | E15: TO MAIN SUMMARY | F15: =SUM(F5:F14) -> 51187707
