Workbook

Sheet Fly-Bill 5
A22: BILL NO. 5
A24: EXTERNAL WORKS

Sheet Bill 5 Sitework
A1: Item | B1: Description | C1: Quantity | D1: Unit | E1: Rate | F1: Amount | G1: VE Ref.
E2: AED | F2: AED
B4: SITE WORK
B6: EARTHWORKS
B8: Note: Refer to the following
B10: 1. Landscape Report dated April 11, 2022
B12: 2. Drawings listed on Reference Nr. V0195-TVS-ZZ-XX-DR-L-001, all inclusive
B14: Excavation; including earthwork support and all necessary works
A16: A | B16: Excavation to reduced level; to planting areas | C16: 6,833 | D16: m³ | E16: 21.34 | F16: =E16*C16 -> 145816.22
A18: B | B18: Excavation to reduced level; to paving areas | C18: 4,076 | D18: m³ | E18: 21.34 | F18: =E18*C18 -> 86981.84
A20: C | B20: Excavation to reduced level; to paving areas outside plot | C20: 3,166 | D20: m³ | E20: 21.34 | F20: =E20*C20 -> 67562.44
A22: D | B22: Pit excavation; to tree pits | C22: 3,401 | D22: m³ | E22: 34.69 | F22: =E22*C22 -> 117980.69
A24: E | B24: Pit excavation; to tree pits; roads | C24: 231 | D24: m³ | E24: 34.69 | F24: =E24*C24 -> 8013.39
B26: Disposal; to approved locations and all ancillary works as necessary
A28: F | B28: Removed off site including suitable trip | C28: 17,707 | D28: m³ | E28: 70.42 | F28: =E28*C28 -> 1246926.9
C49: To Collection | E49: AED | F49: =SUM(F3:F47) -> 1673281.5
B52: PAVING AND SURFACING
B54: Note: Refer to the following:
B56: 1. V0195-100 DD Al Khail Avenue Specifications
B58: 2. Hard landscape plan drawing Nr. V0195-TVS-ZZ-GF-DR-L-401 to 409
B60: 3. Hard landscape schedule drawing Nr. V0195- TVS- ZZ- XX- DR- L- 003
B62: 4. Landscape paving details drawing Nr. V0195-TVS-ZZ-XX-DR-L-901 to 906
B64: Mortar bed; including all ancillary works as necessary
A66: A | B66: 30mm thick; to paving areas | C66: 2266 | D66: m² | E66: 102.25 | F66: =E66*C66 -> 231698.5
A68: B | B68: 30mm thick; to paving areas to outside plot | C68: 769 | D68: m² | E68: 102.25 | F68: =E68*C68 -> 78630.25
B70: Sand bed; including all ancillary works as necessary
A72: C | B72: 50mm thick; to paving areas | C72: 8176 | D72: m² | E72: 15.19 | F72: =E72*C72 -> 124193.44
A74: D | B74: 50mm thick; to paving areas outside plot | C74: 6247 | D74: m² | E74: 15.19 | F74: =E74*C74 -> 94891.93
B76: Concrete base; including all ancillary works a necessary
A78: E | B78: 100mm thick; to paving areas | C78: 2368 | D78: m² | E78: 60 | F78: =E78*C78 -> 142080
A80: F | B80: 150mm thick; to paving areas outside plot | C80: 769 | D80: m² | E80: 85.61 | F80: =E80*C80 -> 65834.09
A82: G | B82: 200mm thick; to paving type P5 | C82: 32 | D82: m² | E82: 104.99 | F82: =E82*C82 -> 3359.68
B84: Compacted subbase; including all ancillary works a necessary
A86: H | B86: 150mm thick; to paving areas | C86: 10479 | D86: m² | E86: 29.28 | F86: =E86*C86 -> 306825.12
A88: J | B88: 150mm thick; to paving areas outside plot | C88: 7695 | D88: m² | E88: 29.28 | F88: =E88*C88 -> 225309.6
C93: To Collection | E93: AED | F93: =SUM(F51:F91) -> 1272822.6
B96: PAVING AND SURFACING (Cont´d)
B98: Compacted aggregate road base coarse; including all ancillary works a necessary
A100: A | B100: 150mm thick; to paving areas | C100: 8176 | D100: m² | E100: 29.28 | F100: =E100*C100 -> 239393.28
A102: B | B102: 150mm thick; to paving areas outside plot | C102: 6247 | D102: m² | E102: 29.28 | F102: =E102*C102 -> 182912.16
...

Sheet Bill 5 Concrete Work
A1: Item | B1: Description | C1: Quantity | D1: Unit | E1: Rate | F1: Amount
E2: AED | F2: AED
B4: CONCRETE WORK
B6: REINFORCED CONCRETE
B8: Note: Refer to the following:
B10: 1. Typical wall details drawing Nr. V0195- TVS- ZZ- XX- DR- L- 907 to 908
B12: Reinforced concrete; compressive strength 60 MPa with cement type CEM I+GGBS
A14: A | B14: Walls | C14: 79 | D14: m³ | E14: 411.46 | F14: =E14*C14 -> 32505.34
F15: =E15*C15 -> 0
A16: B | B16: Walls; to outside plot | C16: 39 | D16: m³ | E16: 411.46 | F16: =E16*C16 -> 16046.94
F17: =E17*C17 -> 0
A18: C | B18: Steps | C18: 21 | D18: m³ | E18: 408.53 | F18: =E18*C18 -> 8579.13
B20: Reinforcement; high yield deformed type 2; 460N/mm2; shall comply to ASTM 615 or BS4449
A22: D | B22: Walls; various diameters | C22: 1 | D22: Item | E22: 52296.51 | F22: =E22*C22 -> 52296.51
A24: E | B24: Walls; various diameters (RATE ONLY) | D24: t | E24: 4431.91 | F24: Rate only
A26: F | B26: Steps; various diameters | C26: 1 | D26: Item | E26: 13960.51 | F26: =E26*C26 -> 13960.51
A28: G | B28: Steps; various diameters (RATE ONLY) | D28: t | E28: 4431.91 | F28: Rate only
B30: Shuttering; including supports, finish and all ancillary works as necessary
A32: H | B32: Sides of walls; straight | C32: 384 | D32: m² | E32: 153.13 | F32: =E32*C32 -> 58801.92
F33: =E33*C33 -> 0
A34: J | B34: Sides of walls; straight; to outside plot | C34: 110 | D34: m² | E34: 153.13 | F34: =E34*C34 -> 16844.3
F35: =E35*C35 -> 0
A36: K | B36: Sides of walls; curved | C36: 599 | D36: m² | E36: 153.13 | F36: =E36*C36 -> 91724.87
F37: =E37*C37 -> 0
A38: L | B38: Sides of walls; curved; to outside plot | C38: 406 | D38: m² | E38: 153.13 | F38: =E38*C38 -> 62170.78
F39: =E39*C39 -> 0
A40: M | B40: Steps | C40: 9 | D40: m² | E40: 123.25 | F40: =E40*C40 -> 1109.25
C47: To Collection | E47: AED | F47: =SUM(F3:F45) -> 354039.55
B50: GENERALLY
A52: A | B52: Allow for any other works which are not included above and which are required to complete the Concrete Work in accordance with the Specification and the drawings (Tenderer to list below): | D52: Item
C93: To Collection | E93: AED
B96: COLLECTION
B98: Page 5/C/1 | F98: =F47 -> 354039.55
B100: Page 5/C/2
C144: Carried To Summary | E144: AED | F144: =SUM(F95:F142) -> 354039.55

Sheet Bill 5 Thermal and Moisture
A1: Item | B1: Description | C1: Quantity | D1: Unit | E1: Rate | F1: Amount
E2: AED | F2: AED
B4: THERMAL AND MOISTURE PROTECTION
B6: DAMP PROOFING
B8: Polythene separation layer; including all ancillary works as necessary
A10: A | B10: Laid horizontally; to paving type 6 and 7 outside plot | C10: 596 | D10: m² | E10: 7.79 | F10: =E10*C10 -> 4642.84
B12: Permeable geotextile membrane; including all ancillary works as necessary
A14: B | B14: Laid horizontally; to play area sand type A5 outside plot | C14: 215 | D14: m² | E14: 3.23 | F14: =E14*C14 -> 694.45
B16: Geotextile membrane; including all ancillary works as necessary
A18: C | B18: Laid horizontally; to limestone aggregates type A2 | C18: 178 | D18: m² | E18: 3.23 | F18: =E18*C18 -> 574.94
A20: D | B20: Laid horizontally; to limestone aggregates type A2 outside plot | C20: 251 | D20: m² | E20: 3.23 | F20: =E20*C20 -> 810.73
B22: Non-woven geotextile membrane 160N; including all ancillary works as necessary
A24: E | B24: To trees and palms | C24: 6,975 | D24: m² | E24: 3.23 | F24: =E24*C24 -> 22529.25
A26: F | B26: To trees and palms; to roads | C26: 443 | D26: m² | E26: 3.23 | F26: =E26*C26 -> 1430.89
A28: G | B28: Steps; various diameters (RATE ONLY) | D28: t | E28: 4431.91 | F28: Rate only
B30: Shuttering; including supports, finish and all ancillary works as necessary
A32: H | B32: Sides of walls; straight | C32: 384 | D32: m² | F32: Included
A34: J | B34: Sides of walls; straight; to outside plot | C34: 110 | D34: m² | F34: Included
A36: K | B36: Sides of walls; curved | C36: 599 | D36: m² | F36: Included
A38: L | B38: Sides of walls; curved; to outside plot | C38: 406 | D38: m² | F38: Included
A40: M | B40: Steps | C40: 9 | D40: m² | F40: Included
C43: To Collection | E43: AED | F43: =SUM(F3:F41) -> 30683.1
B46: GENERALLY
A48: A | B48: Allow for any other works which are not included above and which are required to complete the Thermal and Moisture Protection in accordance with the Specification and the drawings (Tenderer to list below): | D48: Item
A50: B | B50: Variance in quantity following in-house Quantity Take Off | C50: 1 | D50: item | F50: =E50*C50 -> 0
C89: To Collection | E89: AED | F89: =SUM(F45:F87) -> 0
B92: COLLECTION
B94: Page 5/G/1 | F94: =+F43 -> 30683.1
B96: Page 5/G/2 | F96: =+F89 -> 0
C139: Carried To Summary | E139: AED | F139: =SUM(F91:F137) -> 30683.1

Sheet Bill 5 Finishes
A1: Item | B1: Description | C1: Quantity | D1: Unit | E1: Rate | F1: Amount
E2: AED | F2: AED
B4: FINISHES
B6: FINISHINGS
B8: Granite tiles; render on cement and sand plaster (measured separately); including surface preparation, prime, finish coat and all ancillary works as necessary
A10: A | B10: Size 600L x 400W x 20mm thick; grey colour; in polished finish; to wall cladding | C10: 169 | D10: m² | E10: 378.8 | F10: =E10*C10 -> 64017.2
A12: B | B12: Size 400L x 200W x 30mm thick; grey colour; in polished finish; to coping | C12: 106 | D12: m | E12: 140.66 | F12: =E12*C12 -> 14909.96
B14: Reconstituted stone steps; type S2; white colour; in honed finish; including fixings, accessories and all ancillary works as necessary
A16: C | B16: Threads; 300mm wide | C16: 42 | D16: m | E16: 1860.14 | F16: =E16*C16 -> 78125.88
F17: =E17*C17 -> 0
A18: D | B18: Threads 450mm wide | C18: 30 | D18: m | E18: 2454.21 | F18: =E18*C18 -> 73626.3
F19: =E19*C19 -> 0
A20: E | B20: Riser; 150mm high | C20: 72 | D20: m | E20: 1181.57 | F20: =E20*C20 -> 85073.04
C44: To Collection | E44: AED | F44: =SUM(F3:F42) -> 315752.38
B47: GENERALLY
B49: Allow for any other works which are not included above and which are required to complete the Finishes in accordance with the Specification and the drawings (Tenderer to list below): | D49: Item
A51: A | B51: Variance in quantity following in-house Quantity Take Off | C51: 1 | D51: item | F51: =E51 -> 0
C91: To Collection | E91: AED | F91: =SUM(F48:F89) -> 0
B94: COLLECTION
B96: Page 5/J/1 | F96: =+F44 -> 315752.38
B98: Page 5/J/2 | F98: =+F91 -> 0
C142: Carried To Summary | E142: AED | F142: =SUM(F93:F140) -> 315752.38

Sheet Bill 5 Accessories
A1: Item | B1: Description | C1: Quantity | D1: Unit | E1: Rate | F1: Amount
E2: AED | F2: AED
B4: ACCESSORIES
B6: PARKING ACCESSORIES
B8: Parking accessories; including all ancillary works as necessary
A10: A | B10: Single parking space; 2800 x 5500mm | C10: 44 | D10: Nr. | F10: Part of Provisional Sum (Bill No.6) as clarified
C49: To Collection | E49: AED | F49: =SUM(F4:F47) -> 0
B52: WALLS AND SEATINGS
B54: Bespoke modular reconstituted stone walls; white colour; in honed finish; including finishes, concrete footing, shuttering, reinforcement, excavation, disposal, backfilling, blinding, subbase, strip light cove (measured elsewhere), waterproofing, fixings, accessories and all ancillary works as necessary; as Detail 3 Drawing Nr. V0195-TVS-ZZ-XX-DR-L-908
A56: A | B56: Wall type W3; 200mm wide x 645 - 1095mm high; to planters; straight | C56: 86 | D56: m | E56: 2300.57 | F56: =E56*C56 -> 197849.02
A58: B | B58: Wall type W3; 200mm wide x 645 - 1095mm high; to planters; curved | C58: 116 | D58: m | E58: 2714.12 | F58: =E58*C58 -> 314837.92
B60: Bespoke modular radial reconstituted stone low walls; white colour; in honed finish; including finishes, concrete footing, shuttering, reinforcement, excavation, disposal, backfilling, blinding, subbase, strip light cove (measured elsewhere), SS316L anchoring pin with epoxy, fixings, waterproofing, accessories and all ancillary works as necessary; as Detail 6 Drawing Nr. V0195-TVS-ZZ-XX-DR-L-908
A62: C | B62: Wall type W4; 200mm wide x 200mm high; straight | C62: 223 | D62: m | E62: 1089.38 | F62: =E62*C62 -> 242931.74
F63: =E63*C63 -> 0
A64: D | B64: Wall type W4; 200mm wide x 200mm high; curved | C64: 750 | D64: m | E64: 1161.08 | F64: =E64*C64 -> 870810
F65: =E65*C65 -> 0
A66: E | B66: Wall type W4; 200mm wide x 200mm high; straight outside plot | C66: 228 | D66: m | E66: 1089.38 | F66: =E66*C66 -> 248378.64
F67: =E67*C67 -> 0
A68: F | B68: Wall type W4; 200mm wide x 200mm high; curved outside plot | C68: 842 | D68: m | E68: 1161.08 | F68: =E68*C68 -> 977629.36
C76: To Collection | E76: AED | F76: =SUM(F51:F74) -> 2852436.7
B79: WALLS AND SEATINGS (Cont´d)
B81: Bespoke modular radial reconstituted stone amphitheater steps; white colour; in honed finish; including finishes, concrete, strip light cove (measured elsewhere), SS316L anchoring pin with epoxy, fixings, waterproofing, accessories and all ancillary works as necessary
A83: A | B83: Seating type S3 | C83: 51 | D83: m | E83: 1807.65 | F83: =E83*C83 -> 92190.15
C120: To Collection | E120: AED | F120: =SUM(F79:F118) -> 92190.15
B123: GENERALLY
B125: Allow for any other works which are not included above and which are required to complete the Accessories in accordance with the Specification and the drawings (Tenderer to list below): | D125: Item
A127: A | B127: Variance in quantity following in-house Quantity Take Off | C127: 1 | D127: item | F127: =+E127*C127 -> 0
C166: To Collection | E166: AED | F166: =SUM(F125:F163) -> 0
B169: COLLECTION
B171: Page 5/K/1 | F171: =+F49 -> 0
B173: Page 5/K/2 | F173: =+F76 -> 2852436.7
B175: Page 5/K/3 | F175: =+F120 -> 92190.15
B177: Page 5/K/4 | F177: =+F166 -> 0
C216: Carried To Summary | E216: AED | F216: =SUM(F168:F214) -> 2944626.8

Sheet Bill 5 Furnishings
A1: Item | B1: Description | C1: Quantity | D1: Unit | E1: Rate | F1: Amount
E2: AED | F2: AED
B4: FURNISHINGS
B6: SITE FURNITURE
B8: Site furniture; including all ancillary works as necessary
B10: External
A12: A | B12: F1: Bollards | C12: 199 | D12: Nr. | E12: 1979.21 | F12: =E12*C12 -> 393862.79
F13: =E13*C13 -> 0
A14: B | B14: F2: Bollards (Removable) | C14: 19 | D14: Nr. | E14: 4135.28 | F14: =E14*C14 -> 78570.32
F15: =E15*C15 -> 0
A16: C | B16: F3: Climbing play structure 1 | C16: 1 | D16: Nr. | E16: 114258.55 | F16: =E16*C16 -> 114258.55
F17: =E17*C17 -> 0
A18: D | B18: F4: Climbing play structure 2 | C18: 1 | D18: Nr. | E18: 18905.1 | F18: =E18*C18 -> 18905.1
F19: =E19*C19 -> 0
A20: E | B20: F5: Cycle stand | C20: 9 | D20: Nr. | E20: 1916.47 | F20: =E20*C20 -> 17248.23
F21: =E21*C21 -> 0
A22: F | B22: F6: Handrail; 900mm high | C22: 62 | D22: m | E22: 2013.78 | F22: =E22*C22 -> 124854.36
F23: =E23*C23 -> 0
A24: G | B24: F7: Litter bins | C24: 11 | D24: Nr. | E24: 3441.34 | F24: =E24*C24 -> 37854.74
F25: =E25*C25 -> 0
A26: H | B26: F8: Precast concrete pots | C26: 20 | D26: Nr. | E26: 4958.52 | F26: =E26*C26 -> 99170.4
F27: =E27*C27 -> 0
A28: J | B28: F9: Precast concrete timber clad seat; 650mm wide | C28: 106 | D28: m | E28: 2333.86 | F28: =E28*C28 -> 247389.16
F29: =E29*C29 -> 0
A30: K | B30: F10: Recycle bins | C30: 6 | D30: Nr. | E30: 6336.15 | F30: =E30*C30 -> 38016.9
F31: =E31*C31 -> 0
A32: L | B32: F11: Sculptural planting feature | C32: 3 | D32: Nr. | E32: 6406.57 | F32: =E32*C32 -> 19219.71
F33: =E33*C33 -> 0
A34: M | B34: F12: Shade structure | C34: 1 | D34: Nr. | E34: 148745.37 | F34: =E34*C34 -> 148745.37
F35: =E35*C35 -> 0
A36: N | B36: F13: Safety gate | C36: 4 | D36: Nr. | E36: 18889.74 | F36: =E36*C36 -> 75558.96
C50: To Collection | E50: AED | F50: =SUM(F4:F48) -> 1413654.6
B53: GENERALLY
A55: A | B55: Allow for any other works which are not included above and which are required to complete the Furnishings in accordance with the Specification and the drawings (Tenderer to list below): | D55: Item
B56: Parking Shades
A58: A | B58: Structural Steel frame to receive solar panels (by Others) including protective coating, concrete foundations etc. | C58: 19 | D58: t | F58: Deleted - Refer to PTC-18 Item 4
B60: Hard Landscaping
A62: B | B62: Seating type S3; 100mm wide x 450mm high, curved | C62: 128 | D62: m | E62: 3746.06 | F62: =E62*C62 -> 479495.68
C93: To Collection | E93: AED | F93: =SUM(F52:F91) -> 479495.68
B96: COLLECTION
...

Sheet Bill 5 - Mech
A1: Item | B1: Description | C1: Quantity | D1: Unit | E1: Rate | F1: Amount
E2: AED | F2: AED
B4: MECHANICAL ENGINEERING INSTALLATIONS
B6: IRRIGATION SYSTEM
B8: uPVC pipe irrigation duct; including excavation, backfilling, ropes, and all ancillary works as necessary
A10: A | B10: Duct uPVC pipe - size 50mm diameter | C10: 308 | D10: m | E10: 21.59 | F10: =E10*C10 -> 6649.72
F11: =E11*C11 -> 0
A12: B | B12: Duct uPVC pipe - size 75mm diameter | C12: 152 | D12: m | E12: 31.84 | F12: =E12*C12 -> 4839.68
F13: =E13*C13 -> 0
A14: C | B14: Duct uPVC pipe - size 110mm diameter | C14: 107 | D14: m | E14: 51.04 | F14: =E14*C14 -> 5461.28
F15: =E15*C15 -> 0
A16: D | B16: Duct uPVC pipe - size 160mm diameter | C16: 34 | D16: m | E16: 121.46 | F16: =E16*C16 -> 4129.64
F17: =E17*C17 -> 0
B18: Pipe specialties/accessories; including all related fixing materials and ancillary works as necessary | F18: =E18*C18 -> 0
F19: =E19*C19 -> 0
A20: E | B20: Drip solenoid valve (DV1) - size 2" diameter | C20: 1 | D20: Nr. | E20: 2787.09 | F20: =E20*C20 -> 2787.09
F21: =E21*C21 -> 0
A22: F | B22: Drip solenoid valve (DV1a) - size 2" diameter | C22: 1 | D22: Nr. | E22: 2787.09 | F22: =E22*C22 -> 2787.09
F23: =E23*C23 -> 0
A24: G | B24: Drip solenoid valve (DV2) - size 2" diameter | C24: 1 | D24: Nr. | E24: 2787.09 | F24: =E24*C24 -> 2787.09
F25: =E25*C25 -> 0
A26: H | B26: Drip solenoid valve (DV3) - size 2" diameter | C26: 1 | D26: Nr. | E26: 2787.09 | F26: =E26*C26 -> 2787.09
F27: =E27*C27 -> 0
A28: J | B28: Drip solenoid valve (DV4) - size 2" diameter | C28: 1 | D28: Nr. | E28: 2787.09 | F28: =E28*C28 -> 2787.09
F29: =E29*C29 -> 0
A30: K | B30: Drip solenoid valve (DV5) - size 2" diameter | C30: 1 | D30: Nr. | E30: 2787.09 | F30: =E30*C30 -> 2787.09
F31: =E31*C31 -> 0
A32: L | B32: Drip solenoid valve (DV6) - size 2" diameter | C32: 1 | D32: Nr. | E32: 2787.09 | F32: =E32*C32 -> 2787.09
F33: =E33*C33 -> 0
A34: M | B34: Drip solenoid valve (DV7) - size 1.5" diameter | C34: 1 | D34: Nr. | E34: 2538.71 | F34: =E34*C34 -> 2538.71
F35: =E35*C35 -> 0
A36: N | B36: Drip solenoid valve (DV8) - size 2" diameter | C36: 1 | D36: Nr. | E36: 2787.09 | F36: =E36*C36 -> 2787.09
F37: =E37*C37 -> 0
A38: P | B38: Drip solenoid valve (DV9) - size 2" diameter | C38: 1 | D38: Nr. | E38: 2787.09 | F38: =E38*C38 -> 2787.09
F39: =E39*C39 -> 0
A40: Q | B40: Drip solenoid valve (DV10) - size 2" diameter | C40: 1 | D40: Nr. | E40: 2787.09 | F40: =E40*C40 -> 2787.09
F41: =E41*C41 -> 0
A42: R | B42: Drip solenoid valve (DV11) - size 2" diameter | C42: 1 | D42: Nr. | E42: 2787.09 | F42: =E42*C42 -> 2787.09
F43: =E43*C43 -> 0
A44: S | B44: Drip solenoid valve (DV12) - size 2" diameter | C44: 1 | D44: Nr. | E44: 2787.09 | F44: =E44*C44 -> 2787.09
...

Sheet Bill 5 - Elec
A1: Item | B1: Description | C1: Quantity | D1: Unit | E1: Rate | F1: Amount | G1: VE Ref.
E2: AED | F2: AED
B4: ELECTRICAL ENGINEERING INSTALLATIONS
B6: POWER INSTALLATION
B8: Note: Refer to the following:
B10: 1) Drawing Nr. E-00003 to 10200 and E-12556 to 12634; all inclusive
B12: 2) Al Khail Avenue Mall Redevelopment Electrical Specifications dated March 28, 2022
B14: XLPE cables including earth connectivity conductor cables, terminations, lugs, supports and all ancillary work
B16: 1 x 2C x 35mm² CU/XLPE/SWA/LSOH + 1 x 1C x 25mm² CU/LSOH ECC
A18: A | B18: From SMDB-S-05-G01 to e01 signage isolator | C18: 1 | D18: Item | E18: 10138.73 | F18: =E18*C18 -> 10138.73
B20: 1 x 4C x 10mm² CU/XLPE/SWA/LSOH + 1 x 1C x 10mm² CU/LSOH ECC
A22: B | B22: From SMDB-S-05-G01 to electric vehicle charger isolator | C22: 1 | D22: Item | E22: 9170.31 | F22: =E22*C22 -> 9170.31
B24: 1 x 4mm² CCT + 1 x 4mm² RCC
A26: C | B26: From DB-S-01-G01 to 20A SP weatherproof isolator for signage | C26: 1 | D26: Item | E26: 3673.77 | F26: =E26*C26 -> 3673.77
A28: D | B28: From DB-S-04-G01 to 20A SP weatherproof isolator for signage | C28: 1 | D28: Item | E28: 3673.77 | F28: =E28*C28 -> 3673.77
A30: E | B30: From DB-S-04-G04 to 20A SP weatherproof isolator for signage | C30: 1 | D30: Item | E30: 3673.77 | F30: =E30*C30 -> 3673.77
A32: F | B32: Allow for cable from FP-07 to isolator for sump pump | C32: 1 | D32: Item | E32: 9170.31 | F32: =E32*C32 -> 9170.31
A34: G | B34: Allow for cable from SMDB-S-01-G01 to 63A SP isolator for signage | C34: 1 | D34: Item | E34: 11044.47 | F34: =E34*C34 -> 11044.47
A36: H | B36: Allow for cable from SMDB-S-01-G01 to isolator for electric vehicle charger | C36: 1 | D36: Item | E36: 11044.47 | F36: =E36*C36 -> 11044.47
C40: To Collection | E40: AED | F40: =SUM(F13:F37) -> 61589.6
B43: POWER INSTALLATION (Cont´d)
B45: MV trench; including excavation, backfilling, fitting, formworks, supports, necessary accessories and all ancillary work as necessary
A47: A | B47: MV trench with accessible cover | C47: 81 | D47: m | E47: 1745.72 | F47: =E47*C47 -> 141403.32
B49: Ducts; including trench excavation, backfilling, fitting, supports, necessary accessories and all ancillary work as necessary
A51: B | B51: 2 x 150mm diameter uPVC duct | C51: 45 | D51: m | E51: 138.28 | F51: =E51*C51 -> 6222.6
F52: =E52*C52 -> 0
A53: C | B53: 150mm diameter uPVC duct | C53: 136 | D53: m | E53: 81.31 | F53: =E53*C53 -> 11058.16
F54: =E54*C54 -> 0
A55: D | B55: 100mm concrete encased duct | C55: 15 | D55: m | E55: 394.15 | F55: =E55*C55 -> 5912.25
B57: Manholes; including excavation, backfilling, fitting, supports, necessary accessories and all ancillary work as necessary
A59: E | B59: Size 600 x 600mm | C59: 9 | D59: Nr. | E59: 10344.83 | F59: =E59*C59 -> 93103.47
B61: Road crossing cable protection and all ancillary works as necessary
A63: F | B63: 150mm 2 way road crossing encasement | C63: 51 | D63: m | E63: 528.92 | F63: =E63*C63 -> 26974.92
F64: =E64*C64 -> 0
A65: G | B65: 150mm 4 way road crossing encasement | C65: 5 | D65: m | E65: 790.24 | F65: =E65*C65 -> 3951.2
A67: H | B67: Allow for tie-in connection and all ancillary works as necessary | D67: Item | F67: Included
B69: Equipment; including supports and all ancillary work as necessary
B71: Feeder pillar
A73: J | B73: FP-04; TCL = 25.84kW | C73: 1 | D73: Nr. | E73: 5534.39 | F73: =E73*C73 -> 5534.39
C82: To Collection | E82: AED | F82: =SUM(F43:F80) -> 294160.31
...

Sheet Bill 5-Sum
A1: Item | B1: Description | C1: Page Nr. | D1: Amount AED
B5: SUMMARY
B8: SITE WORK | C8: 5/B/1 - 5/B/15 | D8: ='Bill 5 Sitework'!F618 -> 13202527
B11: CONCRETE WORK | C11: 5/C/1 - 5/C/2 | D11: ='Bill 5 Concrete Work'!F144 -> 354039.55
B14: THERMAL AND MOISTURE PROTECTION | C14: 5/G/1 - 5/G/2 | D14: ='Bill 5 Thermal and Moisture'!F139 -> 30683.1
B17: FINISHES | C17: 5/J/1 - 5/J/2 | D17: ='Bill 5 Finishes'!F142 -> 315752.38
B20: ACCESSORIES | C20: 5/K/1 - 5/K/4 | D20: ='Bill 5 Accessories'!F216 -> 2944626.8
B23: FURNISHINGS | C23: 5/M/1 - 5/M/2 | D23: ='Bill 5 Furnishings'!F143 -> 1893150.3
B26: MECHANICAL ENGINEERING INSTALLATIONS | C26: 5/Q1/1 - 5/Q1/6 | D26: ='Bill 5 - Mech'!F319 -> 836154.44
B29: ELECTRICAL ENGINEERING INSTALLATIONS | C29: 5/R/1 - 5/R/9 | D29: ='Bill 5 - Elec'!F408 -> 7998805.3
B50: TOTAL FOR BILL NO. 5 - EXTERNAL WORKS
B51: TO MAIN SUMMARY | C51: AED | D51: =SUM(D4:D49) -> 27575739
