Workbook

Sheet Fly-Bill 3
A22: BILL NO. 3
A24: MALL REFURBISHMENT

Sheet Bill 3 Siteworks
A1: Item | B1: Description | C1: Quantity | D1: Unit | E1: Rate | F1: Amount
E2: AED | F2: AED
B4: SITE WORK
B6: SITE PREPARATION
B8: Note: Refer to the following
B10: 1. Structure Specification dated 28 March 2022
B12: Anti-termite treatment; including surface preparation and all ancillary works as necessary
A14: A | B14: Horizontal and vertical surfaces; foundation | C14: 42 | D14: m² | E14: 1.62 | F14: =C14*E14 -> 68.04
A16: B | B16: Horizontal and vertical surfaces; ground beams | C16: 289 | D16: m² | E16: 1.62 | F16: =C16*E16 -> 468.18
A18: C | B18: Horizontal surfaces; slab on grade | C18: 534 | D18: m² | E18: 1.62 | F18: =C18*E18 -> 865.08
A20: D | B20: Horizontal and vertical surfaces; pilecaps | C20: 130 | D20: m² | E20: 1.62 | F20: =C20*E20 -> 210.6
B22: Dewatering; including all ancillary works as necessary
A24: E | B24: Generally | D24: Item | F24: Not required
C45: To Collection | E45: AED | F45: =SUM(F12:F35) -> 1611.9
B48: EARTHWORKS
B50: Excavation; including earthwork support and all necessary works
A52: A | B52: Excavation to reduced level | C52: 233 | D52: m³ | E52: 21.34 | F52: =C52*E52 -> 4972.22
A54: B | B54: Pit excavation; to pile caps | C54: 37 | D54: m³ | E54: 34.69 | F54: =C54*E54 -> 1283.53
A56: C | B56: Pit excavation; footing | C56: 6 | D56: m³ | E56: 34.69 | F56: =C56*E56 -> 208.14
A58: D | B58: Trench excavation; to ground beams | C58: 86 | D58: m³ | E58: 41.37 | F58: =C58*E58 -> 3557.82
B60: Disposal; to approved locations and all ancillary works as necessary
A62: E | B62: Backfilled into excavation; compacted back filling up to 95% compaction ratio | C62: 6 | D62: m³ | E62: 34.91 | F62: =C62*E62 -> 209.46
A64: F | B64: Removed off site including suitable trip | C64: 356 | D64: m³ | E64: 70.42 | F64: =C64*E64 -> 25069.52
B66: Engineering backfill; compacted wall graded; including all ancillary works as necessary
A68: G | B68: 95% maximum dry density | C68: 652 | D68: m² | E68: 15.95 | F68: =C68*E68 -> 10399.4
C89: To Collection | E89: AED | F89: =SUM(F49:F75) -> 45700.09
B92: PILING
B94: Note: Refer to the following:
B96: 1. Drawing Reference Nr. S-00011 and S-60001
B98: 2. Conduct additional boreholes, trial holes/pits and soil investigation to supplement subsurface investigation; as may required by the Engineer/ Employer, Dubai Municipality and other local authorities requirements
B100: 3. The Contractor shall be responsible for determining the final length of the piles and the rates shall include any extension or additional length as a result of the Contractor's design.
B102: 4. Boring cost shall be deemed to include the cost of drilling fluid, linings and temporary fill
B104: 5. Boring cost shall be deemed to include any soil obstruction
B106: 6. The working platform level is at the discretion of the Contractor and any cost associated will be deemed to be included within the rates.
B108: 7. Structures Specification dated 28 March 2022 Section 316300
B110: Boring
A112: A | B112: Type CA-P01; 600 mm diameter | C112: 5 | D112: Nr. | E112: 11354.28 | F112: =C112*E112 -> 56771.4
A114: B | B114: Type ESC-P01; 600 mm diameter | C114: 4 | D114: Nr. | E114: 10954.51 | F114: =C114*E114 -> 43818.04
A116: C | B116: Type FB-P1; 600 mm diameter | C116: 14 | D116: Nr. | E116: 20706.13 | F116: =C116*E116 -> 289885.82
B119: In-situ bored piles; concrete grade C50/60 with CEM I+GGBS+MS
...

Sheet Bill 3 Siteworks-EO
A1: Item | B1: Description | C1: Quantity | D1: Unit | E1: Rate | F1: Amount
E2: AED | F2: AED
B4: SITE WORK
B6: PILING
B8: Boring
B10: Extra-Over for Complying to Authority Comments
A12: A | B12: Omit 5nos of Type FB-P1; 600 mm diameter | C12: -5 | D12: Nr. | E12: 20706.13 | F12: =C12*E12 -> -103530.65
A14: B | B14: Add Type FB-P2; 750 mm diameter | C14: 5 | D14: Nr. | E14: 26291.234 | F14: =C14*E14 -> 131456.17
B16: Disposal
A18: C | B18: Materials arising from boreholes - Extra-Over for Complying to Authority Comments | D18: Item | E18: 2334.6456 | F18: =+E18 -> 2334.6456
A20: D | B20: Drilling fluids arising from boreholes - Extra-Over for Complying to Authority Comments | D20: Item | E20: 1647.2471 | F20: =+E20 -> 1647.2471
B22: Pile tests
A24: E | B24: To preliminary piles including construction of preliminary piles - Extra-Over for Complying to Authority Comments | D24: Item | E24: 23164.735 | F24: =+E24 -> 23164.735
C27: Carried To Summary | E27: AED | F27: =SUM(F5:F25) -> 55072.15

Sheet Bill 3 Concrete
A1: Item | B1: Description | C1: Quantity | D1: Unit | E1: Rate | F1: Amount
E2: AED | F2: AED
B4: CONCRETE WORK
B6: REINFORCED CONCRETE
B8: Note: Refer to the following:
B10: 1. Drawing Reference Nr. S-00011 and S-60001
B12: 2. Structures Specification dated 28 March 2022
B14: Plain poured concrete; compressive strength 15 MPa with cement type SRPC
A16: A | B16: Blinding; 100mm thick | C16: 85 | D16: m³ | E16: 395.25 | F16: =C16*E16 -> 33596.25
B18: Reinforced concrete; compressive strength 60 MPa with cement type CEM I+GGBS
A20: B | B20: Pile cap | C20: 27 | D20: m³ | E20: 396.11 | F20: =C20*E20 -> 10694.97
A22: C | B22: Footing | C22: 7 | D22: m³ | E22: 396.11 | F22: =C22*E22 -> 2772.77
A24: D | B24: Ground beams | C24: 64 | D24: m³ | E24: 408.53 | F24: =C24*E24 -> 26145.92
A26: E | B26: Slab on grade; 200mm thick | C26: 74 | D26: m³ | E26: 404.64 | F26: =C26*E26 -> 29943.36
A28: F | B28: Slab on grade; 300mm thick | C28: 103 | D28: m³ | E28: 404.64 | F28: =C28*E28 -> 41677.92
A30: G | B30: Slab on grade; 750mm thick | C30: 18 | D30: m³ | E30: 404.64 | F30: =C30*E30 -> 7283.52
A32: H | B32: Suspended slab; 200mm thick | C32: 424 | D32: m³ | E32: 417.06 | F32: =C32*E32 -> 176833.44
A34: J | B34: Suspended slab; 250mm thick | C34: 47 | D34: m³ | E34: 417.06 | F34: =C34*E34 -> 19601.82
A36: K | B36: Suspended slab; 300mm thick | C36: 27 | D36: m³ | E36: 417.06 | F36: =C36*E36 -> 11260.62
A38: L | B38: Suspended slab; 400mm thick | C38: 306 | D38: m³ | E38: 417.06 | F38: =C38*E38 -> 127620.36
A40: M | B40: Suspended slab; 450mm thick | C40: 67 | D40: m³ | E40: 417.06 | F40: =C40*E40 -> 27943.02
A42: N | B42: Suspended slab; 1050mm thick | C42: 46 | D42: m³ | E42: 417.06 | F42: =C42*E42 -> 19184.76
C48: To Collection | E48: AED | F48: =SUM(F14:F44) -> 534558.73
B51: REINFORCED CONCRETE (Cont´d)
A53: A | B53: Beams | C53: 668 | D53: m³ | E53: 408.53 | F53: =C53*E53 -> 272898.04
A55: B | B55: Upstand | C55: 83 | D55: m³ | E55: 411.46 | F55: =C55*E55 -> 34151.18
A57: C | B57: Columns | C57: 100 | D57: m³ | E57: 411.46 | F57: =C57*E57 -> 41146
A59: D | B59: Columns; curved | C59: 65 | D59: m³ | E59: 411.46 | F59: =C59*E59 -> 26744.9
A61: E | B61: Walls; 250mm thick | C61: 6 | D61: m³ | E61: 411.46 | F61: =C61*E61 -> 2468.76
A63: F | B63: Walls; 300mm thick | C63: 981 | D63: m³ | E63: 411.46 | F63: =C63*E63 -> 403642.26
A65: G | B65: Walls; 600mm thick | C65: 51 | D65: m³ | E65: 411.46 | F65: =C65*E65 -> 20984.46
A67: H | B67: Staircase | C67: 70 | D67: m³ | E67: 423.19 | F67: =C67*E67 -> 29623.3
A69: J | B69: Corbels | C69: 2 | D69: m³ | E69: 408.53 | F69: =C69*E69 -> 817.06
A71: K | B71: Pedestal | C71: 2 | D71: m³ | E71: 421.96 | F71: =C71*E71 -> 843.92
A73: L | B73: RC thickening; various thickness | E73: 0 | F73: Included in Strengthening Works
B75: Reinforcement; high yield deformed type 2; 460N/mm2; shall comply to ASTM 615 or BS4449
A77: M | B77: Pile cap; various diameters | C77: 7.17 | D77: t | E77: 4382.11 | F77: =C77*E77 -> 31419.729
A79: N | B79: Footing; various diameters | C79: 1.07 | D79: t | E79: 4382.11 | F79: =C79*E79 -> 4688.8577
A81: P | B81: Pedestal; various diameters | C81: 0.55 | D81: t | E81: 4431.91 | F81: =C81*E81 -> 2437.5505
A83: Q | B83: Ground beams; various diameters | C83: 15.64 | D83: t | E83: 4431.91 | F83: =C83*E83 -> 69315.072
...

Sheet Bill 3 Concrete-EO
A1: Item | B1: Description | C1: Quantity | D1: Unit | E1: Rate | F1: Amount
E2: AED | F2: AED
B4: CONCRETE WORK
B5: EXTRA-OVER FOR COMPLYING TO AUTHORITY COMMENTS
B7: REINFORCED CONCRETE
B9: Plain poured concrete; compressive strength 15 MPa with cement type SRPC
A11: A | B11: Blinding; 100mm thick | C11: 1 | D11: m³ | E11: 395.25 | F11: =C11*E11 -> 395.25
B13: Reinforced concrete; compressive strength 60 MPa with cement type CEM I+GGBS
A15: B | B15: Pile cap | C15: 6 | D15: m³ | E15: 396.11 | F15: =C15*E15 -> 2376.66
A17: C | B17: Beams | C17: 273 | D17: m³ | E17: 408.53 | F17: =C17*E17 -> 111528.69
A19: D | B19: Upstand | C19: 343 | D19: m³ | E19: 411.46 | F19: =C19*E19 -> 141130.78
A21: E | B21: Columns | C21: 346 | D21: m³ | E21: 411.46 | F21: =C21*E21 -> 142365.16
A23: F | B23: Walls; 300mm thick | C23: 788 | D23: m³ | E23: 411.46 | F23: =C23*E23 -> 324230.48
B25: Reinforcement; high yield deformed type 2; 460N/mm2; shall comply to ASTM 615 or BS4449
A26: G | B26: Pile cap; various diameters | C26: 1.29 | D26: t | E26: 4382.11 | F26: =C26*E26 -> 5652.9219
A28: H | B28: Beams; various diameters | C28: 133 | D28: t | E28: 4431.91 | F28: =C28*E28 -> 589444.03
A30: J | B30: Upstand; various diameters | C30: 10 | D30: t | E30: 4431.91 | F30: =C30*E30 -> 44319.1
A32: K | B32: Columns; various diameters | C32: 100 | D32: t | E32: 4431.91 | F32: =C32*E32 -> 443191
A34: L | B34: Walls; various diameters | C34: 122 | D34: t | E34: 4431.91 | F34: =C34*E34 -> 540693.02
C48: To Collection | E48: AED | F48: =SUM(F9:F44) -> 2345327.1
B51: REINFORCED CONCRETE (Cont´d)
B53: Shuttering; including supports, finish and all ancillary works as necessary
A55: A | B55: Sides of pile caps | C55: 18 | D55: m² | E55: 169.41 | F55: =C55*E55 -> 3049.38
A57: B | B57: Sides and soffits of beams | C57: 1321 | D57: m² | E57: 148.36 | F57: =C57*E57 -> 195983.56
A59: C | B59: Sides of upstand | C59: 1040 | D59: m² | E59: 150.18 | F59: =C59*E59 -> 156187.2
A61: D | B61: Sides of upstand (curved) | C61: 855 | D61: m² | E61: 195.234 | F61: =C61*E61 -> 166925.07
A63: E | B63: Sides of columns | C63: 1491 | D63: m² | E63: 138.34 | F63: =C63*E63 -> 206264.94
A65: F | B65: Sides of walls | C65: 2016 | D65: m² | E65: 153.13 | F65: =C65*E65 -> 308710.08
B67: Dowelling
A69: G | B69: Additional rebar; dowel connection to existing to new structure | C69: 53 | D69: t | E69: 4431.91 | F69: =+C69*E69 -> 234891.23
A71: H | B71: Post fix hilti | C71: 7162 | D71: no | E71: 75.3858 | F71: =+C71*E71 -> 539913.1
C96: To Collection | E96: AED | F96: =SUM(F51:F93) -> 1811924.6
B99: COLLECTION
B101: Page 3/C/EO/1 | F101: =F48 -> 2345327.1
B103: Page 3/C/EO/2 | F103: =F96 -> 1811924.6
C144: Carried To Summary | E144: AED | F144: =SUM(F98:F118) -> 4157251.7

Sheet Bill 3 Masonry
A1: Item | B1: Description | C1: Quantity | D1: Unit | E1: Rate | F1: Amount
E2: AED | F2: AED
B4: MASONRY
B6: WALLS AND PIERS
B8: Note: Refer to the following:
B10: 1. Drawing Reference Nr. A-700 to A-710 and A-962
B12: Hollow concrete block wall; bedded and jointed in cement and sand mortar; including damp proof courses, insulation, fire rating, mesh, grouts, lintels, posts, reinforcement, fixings, anchors, ties, accessories, plaster (measured separately) and all ancillary works as necessary
A14: A | B14: Type 2; 200mm thick; 2hour fire rated; RW55; to external | C14: 527 | D14: m² | E14: 170.19 | F14: =C14*E14 -> 89690.13
A16: B | B16: Type 2; 200mm thick; 2hour fire rated; RW55; to internal | C16: 35,804 | D16: m² | E16: 153.63 | F16: =C16*E16 -> 5500568.5
C42: To Collection | E42: AED | F42: =SUM(F12:F29) -> 5590258.6
B45: GENERALLY
A47: A | B47: Allow for any other works which are not included above and which are required to complete the Masonry in accordance with the Specification and the drawings (Tenderer to list below): | D47: Item | F47: =C47*E47 -> 0
C86: To Collection | E86: AED | F86: =SUM(F47:F62) -> 0
B89: COLLECTION
B91: Page 3/D/1 | F91: =F42 -> 5590258.6
B93: Page 3/D/2 | F93: =F86 -> 0
C134: Carried To Summary | E134: AED | F134: =SUM(F89:F100) -> 5590258.6

Sheet Bill 3 Metalwork REV
A1: Item | B1: Description | C1: Quantity | D1: Unit | E1: Rate | F1: Amount
E2: AED | F2: AED
B4: NON-STRUCTURAL METALWORK
B6: Note: Refer to the following
B8: 1. Drawing Reference Nr. AYB-GHD-DWG-FA-00001, all inclusive
B10: 2. Drawing Reference Nr. A-600
B12: 3. Architectural Specification dated April 22, 2022
B14: Handrail; comprising laminated safety glass, existing stainless steel handrail; 8mm stainless steel vertical post; including stainless steel glass connector, fixings, accessories and all ancillary works as necessary
A16: A | B16: Type A-1; 1200mm high | C16: 1110 | D16: m | F16: Deleted - Refer to PTC20 Rev. 3
A18: B | B18: Type A-1; 1200mm high; curved | C18: 674 | D18: m | F18: Deleted - Refer to PTC20 Rev. 3
B20: Handrail; comprising laminated safety glass, stainless steel handrail; 8mm stainless steel vertical post; including stainless steel glass connector, fixings, accessories and all ancillary works as necessary
A22: C | B22: Type A-2; 1200mm high | C22: 74 | D22: m | E22: 2583.04 | F22: =C22*E22 -> 191144.96
A24: D | B24: Type A-2; 1200mm high; curved | C24: 169 | D24: m | E24: 3318.05 | F24: =C24*E24 -> 560750.45
A26: E | B26: Type B-2; 1200mm high | C26: 201 | D26: m | E26: 2583.04 | F26: =C26*E26 -> 519191.04
A28: F | B28: Type B-2; 1200mm high; sloping | C28: 10 | D28: m | E28: 2898.05 | F28: =C28*E28 -> 28980.5
A30: G | B30: Type C; 1200mm high; curved | C30: 883 | D30: m | E30: 3318.05 | F30: =C30*E30 -> 2929838.2
C36: To Collection | E36: AED | F36: =SUM(F21:F32) -> 4229905.1
B39: NON-STRUCTURAL METALWORK
B41: Note: Refer to the following
B43: 1. Drawing Reference Nr. AYB-GHD-DWG-FA-00001, all inclusive
B45: 2. Drawing Reference Nr. A-600
B47: 3. Architectural Specification dated April 22, 2022
B49: Handrail; comprising laminated safety glass, existing stainless steel handrail to be wrapped with 3M Di-noc wood film type PL-01; 8mm stainless steel vertical post; including stainless steel glass connector, fixings, accessories and all ancillary works as necessary.
A51: A | B51: Type A-1; 1200mm high (RATE ONLY) | C51: 1110 | D51: m | E51: 457.7 | F51: RATE ONLY
A53: B | B53: Type A-1; 1200mm high; curved (RATE ONLY) | C53: 674 | D53: m | E53: 565.39 | F53: RATE ONLY
B55: Handrail; comprising laminated safety glass, stainless steel handrail wrapped with 3M Di-noc wood film type PL-01; 8mm stainless steel vertical post; including stainless steel glass connector, fixings, accessories and all ancillary works as necessary
A57: C | B57: Type A-2; 1200mm high (RATE ONLY) | C57: 74 | D57: m | E57: 2625.88 | F57: RATE ONLY
A59: D | B59: Type A-2; 1200mm high; curved (RATE ONLY) | C59: 169 | D59: m | E59: 3373.08 | F59: RATE ONLY
A61: E | B61: Type B-2; 1200mm high (RATE ONLY) | C61: 192 | D61: m | E61: 2625.88 | F61: RATE ONLY
A63: F | B63: Type B-2; 1200mm high; sloping (RATE ONLY) | C63: 10 | D63: m | E63: 2946.11 | F63: RATE ONLY
A65: G | B65: Type C; 1200mm high; curved (RATE ONLY) | C65: 883 | D65: m | E65: 3373.08 | F65: RATE ONLY
C72: To Collection | E72: AED
B75: NON-STRUCTURAL METALWORK
B77: Note: Refer to the following
B79: 1. Drawing Reference Nr. AYB-GHD-DWG-FA-00001, all inclusive
B81: 2. Drawing Reference Nr. A-600
B83: 3. Architectural Specification dated April 22, 2022
B85: Handrail; comprising laminated safety glass, existing stainless steel handrail to be removed and replaced with wood handrail WD-01; 8mm stainless steel vertical post; including stainless steel glass connector, fixings, accessories and all ancillary works as necessary
A87: A | B87: Type A-1; 1200mm high (RATE ONLY) | C87: 1110 | D87: m | E87: N/A | F87: RATE ONLY
A89: B | B89: Type A-1; 1200mm high; curved (RATE ONLY) | C89: 674 | D89: m | E89: N/A | F89: RATE ONLY
...

Sheet Bill 3 Woodwork
A1: Item | B1: Description | C1: Quantity | D1: Unit | E1: Rate | F1: Amount | G1: VE Ref.
E2: AED | F2: AED
B4: WOODWORK
B6: COMPOSITE ITEMS
B8: Note: Refer to the following
B10: 1. Interior FF&E Schedule and Mood Boards dated April 2022
B12: 2. Drawing Reference Nr. ID-600 series
B14: Waiting lounge planter with bench seating; comprising planter in outer carcass in stainless steel panel type MT-03, 3M Di-noc wood type PL-01, leather fabric type FB-02, metal skirting type MT-03; handrail, plants and LED light (measured elsewhere); including framings, supports and all ancillary works as necessary; as Drawing Nr. ID-601-13
A16: A | B16: Overall size 6930 x 940 x 1070mm high; L-shaped | C16: 1 | D16: Nr. | E16: 43993 | F16: =C16*E16 -> 43993
A18: B | B18: Overall size 5910 x 600 x 1070mm high; L-shaped | C18: 1 | D18: Nr. | E18: 40923.72 | F18: =C18*E18 -> 40923.72
A20: C | B20: Overall size 8570 x 600 x 945mm high; L-shaped | C20: 1 | D20: Nr. | E20: 49108.46 | F20: =C20*E20 -> 49108.46
A22: D | B22: Extra over for banquette seating; type I-BA-02; 500mm wide x 875mm high; L-shaped | C22: 12 | D22: m | E22: 2670.27 | F22: =C22*E22 -> 32043.24
B24: Waiting lounge planter with bench seating; comprising planter in outer carcass in stainless steel panel type MT-03, 3M Di-noc wood type PL-01, leather fabric type FB-02, ledge, metal skirting type MT-03; plants and LED light (measured elsewhere); including framings, supports and all ancillary works as necessary; as Drawing Nr. ID-601-14
A26: E | B26: Overall size 3710 x 600 x 1000mm high; U-shaped; as Drawing Nr. ID-601-14 | C26: 1 | D26: Nr. | E26: 20461.86 | F26: =C26*E26 -> 20461.86
A28: F | B28: Extra over for banquette seating; type I-BA-02; 700mm wide x 910mm high; U-shaped | C28: 13 | D28: m | E28: 2670.27 | F28: =C28*E28 -> 34713.51
C31: To Collection | E31: AED | F31: =SUM(F15:F28) -> 221243.79
B34: COMPOSITE ITEMS (Cont´d)
B36: Planter with bench seating; comprising planter in outer carcass in precast concrete type PC-01, coated fabric type FB-01, metal skirting type MT-02; plants and LED light (measured elsewhere); including framings, supports and all ancillary works as necessary; as Drawing Nr. ID-904-1 and ID-904-2
A38: A | B38: Overall size: 8000 x 1000 x 900mm high; irregular shaped | C38: 1 | D38: Nr. | E38: 34029.15 | F38: =C38*E38 -> 34029.15
A40: B | B40: Overall size: 9000 x 1000 x 900mm high; irregular shaped | C40: 1 | D40: Nr. | E40: 46031.65 | F40: =C40*E40 -> 46031.65
A42: C | B42: Overall size: 7380 x 1830 x 900mm high; irregular shaped | C42: 1 | D42: Nr. | E42: 49693.24 | F42: =C42*E42 -> 49693.24
B44: Planter with bench seating; comprising planter in outer carcass in 3M Di-noc wood type PL-01, coated fabric type FB-01, metal skirting type MT-02; plants and LED light (measured elsewhere); including framings, supports and all ancillary works as necessary; as Drawing Nr. ID-904-3
A46: D | B46: Overall size: 4000 x 1700 x 1000mm high; ellipse shaped | C46: 2 | D46: Nr. | E46: 25577.33 | F46: =C46*E46 -> 51154.66
B48: Information desk (2 person); comprising countertop and side panel in solid surface type SS-02, fascia and doors in type PL-04; stainless steel panel type MT-06 with solid wood slats match finish of PL-04; metal skirting; including screens, signage (by Others), ironmongery, drawers, shelves, doors, supports, frames, accessories and all ancillary works as necessary
A50: E | B50: Type I-INF-01; 5500 x 3500 x 1380mm high; irregular shaped | C50: 1 | D50: Nr. | E50: 31112.8 | F50: =C50*E50 -> 31112.8 | G50: EM-24
B52: ** VE Reference "EM-" denotes items raised by Client in the VE Schedule
C54: To Collection | E54: AED | F54: =SUM(F36:F51) -> 212021.5
B57: COMPOSITE ITEMS (Cont´d)
A59: A | B59: Solid countertop; type SS-02; 5500 x 3500mm; irregular shaped | C59: 7 | D59: m² | E59: 2046.19 | F59: =C59*E59 -> 14323.33
B61: Information desk (1 person); comprising countertop and side panel in solid surface type SS-02, fascia and doors in type PL-04; stainless steel panel type MT-06 with solid wood slats match finish of PL-04; metal skirting; including screens, signage (by Others), ironmongery, drawers, doors, supports, framing and all ancillary works as necessary
A63: B | B63: Type I-INF-02: overall size 4096 x 3210 x 1400mm high; irregular shaped | C63: 1 | D63: Nr. | E63: 25114.24 | F63: =C63*E63 -> 25114.24 | G63: EM-24
A65: C | B65: Solid countertop; type SS-02 overall size 4096 x 3210mm; irregular shaped | C65: 6 | D65: m² | E65: 2046.19 | F65: =C65*E65 -> 12277.14
B67: Hands free information desk; comprising countertop and side panel in solid surface type SS-02, fascia and doors in type PL-04; stainless steel panel type MT-06 with solid wood slats match finish of PL-04; metal skirting; including signage (by Others), ironmongery, drawers, doors, supports, framing and all ancillary works as necessary
A69: D | B69: Type I-INF-03; 2540 x 3300 x 1100mm high; irregular shaped | C69: 2 | D69: Nr. | E69: 21948.04 | F69: =C69*E69 -> 43896.08 | G69: EM-24
A71: E | B71: Solid countertop; 2540 x 3300mm; irregular shaped | C71: 10 | D71: m² | E71: 2046.19 | F71: =C71*E71 -> 20461.9
B73: Podium type desk; comprising countertop and side panel in solid surface type SS-02, fascia and doors in type PL-04; stainless steel panel type MT-06 with solid wood slats match finish of PL-04; metal skirting; including signage (by Others), ironmongery, drawers, doors, supports, framing and all ancillary works as necessary
B75: ** VE Reference "EM-" denotes items raised by Client in the VE Schedule
C77: To Collection | E77: AED | F77: =SUM(F57:F73) -> 116072.69
B80: COMPOSITE ITEMS (Cont´d)
A82: A | B82: Type I-INF-04; 900 x 700 x 1200mm high | C82: 3 | D82: Nr. | E82: 8796.93 | F82: =C82*E82 -> 26390.79 | G82: EM-24
...

Sheet Bill 3 Thermal
A1: Item | B1: Description | C1: Quantity | D1: Unit | E1: Rate | F1: Amount
E2: AED | F2: AED
B4: THERMAL AND MOISTURE PROTECTION
B6: COVERINGS AND LININGS
B8: Note: Refer to the following:
B10: 1. Drawing Reference Nr. S-00011 and S-60001
B12: 2. Structures Specification dated 28 March 2022
B14: Cold-applied waterproofing system; including surface preparation and all ancillary works as necessary; as Detail 8 Drawing Nr. A-951
A16: A | B16: To wet areas | C16: 3040 | D16: m² | E16: 23.69 | F16: =C16*E16 -> 72017.6
A18: B | B18: Turning-ups / skirting; 200mm high | C18: 3761 | D18: m | E18: 10.77 | F18: =C18*E18 -> 40505.97
B20: Waterproofing; including surface preparation, protection, accessories and all ancillary works as necessary
A22: C | B22: Waterproofing membrane; to foundation | C22: 51 | D22: m² | E22: 37.69 | F22: =C22*E22 -> 1922.19
A24: D | B24: Waterproofing membrane; to ground beams | C24: 907 | D24: m² | E24: 37.69 | F24: =C24*E24 -> 34184.83
A26: E | B26: Waterproofing membrane; to slab on grade | C26: 1386 | D26: m² | E26: 37.69 | F26: =C26*E26 -> 52238.34
A28: F | B28: Waterproofing membrane; to pilecaps | C28: 130 | D28: m² | E28: 37.69 | F28: =C28*E28 -> 4899.7
A30: G | B30: Waterproofing membrane; to paving | C30: 808 | D30: m² | E30: 37.69 | F30: =C30*E30 -> 30453.52
A32: H | B32: Waterproofing membrane; to paving band | C32: 16 | D32: m² | E32: 37.69 | F32: =C32*E32 -> 603.04
C44: To Collection | E44: AED | F44: =SUM(F13:F36) -> 236825.19
B47: GENERALLY
B49: Allow for any other works which are not included above and which are required to complete the Thermal and Moisture Protection in accordance with the Specification and the drawings (Tenderer to list below): | D49: Item | F49: =C49*E49 -> 0
A51: A | B51: 3mm thick protection board to vertical surfaces | C51: 942 | D51: m² | E51: 22.62 | F51: =+C51*E51 -> 21308.04
B53: Quantity Adjustments
A55: B | B55: Variance in quantity following in-house Quantity Take Off | C55: 1 | D55: item | F55: =+C55*E55 -> 0
C87: To Collection | E87: AED | F87: =SUM(F48:F71) -> 21308.04
B90: COLLECTION
B92: Page 3/G/1 | F92: =F44 -> 236825.19
B94: Page 3/G/2 | F94: =F87 -> 21308.04
C135: Carried To Summary | E135: AED | F135: =SUM(F90:F105) -> 258133.23

Sheet Bill 3 Doors and Windows
A1: Item | B1: Description | C1: Quantity | D1: Unit | E1: Rate | F1: Amount | G1: VE Ref.
E2: AED | F2: AED
B4: DOORS AND WINDOWS
B6: DOORS
B8: Note: Refer to the following
B10: 1. Drawing Reference Nr. ID-900 series, A-800 to A-801
B12: Hollow metal doors and frames; building into brick, block concrete walls and gypsum partitions; including ironmongery (measured separately), finishes, architrave, weatherstripping and all necessary fixings and accessories
A14: A | B14: Type DS-01; 1000 x 2200mm high; single leaf door | C14: 2 | D14: Nr. | E14: 1958.95 | F14: =C14*E14 -> 3917.9
A16: B | B16: Type DS-02; 900 x 2200mm high; single leaf door | C16: 2 | D16: Nr. | E16: 1951.42 | F16: =C16*E16 -> 3902.84
A18: C | B18: Type DS-04; 1100 x 2200mm high; single leaf door | C18: 14 | D18: Nr. | E18: 1967.57 | F18: =C18*E18 -> 27545.98
A20: D | B20: Type DS-05; 1100 x 2200mm high; single leaf door; FR-90min.; including exit panic device with horizontal push bar | C20: 3 | D20: Nr. | E20: 2240.04 | F20: =C20*E20 -> 6720.12
A22: E | B22: Type DS-06; 1200 x 2200mm high; single leaf door | C22: 39 | D22: Nr. | E22: 2156.03 | F22: =C22*E22 -> 84085.17
A24: F | B24: Type DS-07; 1000 x 2200mm high; double leaf door | C24: 1 | D24: Nr. | E24: 2498.5 | F24: =C24*E24 -> 2498.5
A26: G | B26: Type DS-08; 1600 x 2200mm high; double leaf door | C26: 19 | D26: Nr. | E26: 3077.89 | F26: =C26*E26 -> 58479.91
A28: H | B28: Type DS-10; 1800 x 2200mm high; double leaf door; FR-90min. | C28: 33 | D28: Nr. | E28: 3240.51 | F28: =C28*E28 -> 106936.83
A30: J | B30: Type DS-11; 1450 x 2200mm high; double leaf door; FR-90min. | C30: 3 | D30: Nr. | E30: 3155.43 | F30: =C30*E30 -> 9466.29
A32: K | B32: Type DS-12; 1250 x 2140mm high; single leaf door | C32: 3 | D32: Nr. | E32: 2188.34 | F32: =C32*E32 -> 6565.02
C35: To Collection | E35: AED | F35: =SUM(F13:F32) -> 310118.56
B38: DOORS (Cont´d)
A40: A | B40: Type DS-14; 2400 x 2200mm high; double leaf door | C40: 2 | D40: Nr. | E40: 3615.29 | F40: =C40*E40 -> 7230.58
A42: B | B42: Type DS-17; 2000 x 2200mm high; double leaf door | C42: 23 | D42: Nr. | E42: 3222.2 | F42: =C42*E42 -> 74110.6
A44: C | B44: Type DS-18; 1400 x 2200mm high; single leaf door | C44: 2 | D44: Nr. | E44: 3176.97 | F44: =C44*E44 -> 6353.94
A46: D | B46: Type ID-09; 2000 x 2400mm high; double leaf door | C46: 2 | D46: Nr. | E46: 3451.59 | F46: =C46*E46 -> 6903.18
A48: E | B48: Type GR-007; 1800 x 2140mm | C48: 2 | D48: Nr. | E48: 3168.36 | F48: =C48*E48 -> 6336.72
A50: F | B50: Type GR-013a; 1800 x 2140mm | C50: 1 | D50: Nr. | E50: 3168.36 | F50: =C50*E50 -> 3168.36
B52: Timber doors; building into brick, block concrete walls and gypsum partitions; including frames, ironmongery (measured separately), finishes, architrave, weatherstripping and all necessary fixings and accessories
A54: G | B54: Type ID-01; 1200 x 2200mm high; single leaf door | C54: 9 | D54: Nr. | E54: 5944.08 | F54: =C54*E54 -> 53496.72
A56: H | B56: Type ID-02; 1000 x 2100mm high; single sliding door | C56: 36 | D56: Nr. | E56: 4953.4 | F56: =C56*E56 -> 178322.4
A58: J | B58: Type ID-03; 900 x 2100mm high; single leaf door | C58: 48 | D58: Nr. | E58: 4733.25 | F58: =C58*E58 -> 227196
A60: K | B60: Type ID-04; 900 x 2100mm high; single leaf door | C60: 25 | D60: Nr. | E60: 4733.25 | F60: =C60*E60 -> 118331.25
A62: L | B62: Type ID-05; 900 x 2100mm high; single leaf door | C62: 28 | D62: Nr. | E62: 4733.25 | F62: =C62*E62 -> 132531
A64: M | B64: Type ID-06; 1200 x 2400mm high; single leaf door | C64: 4 | D64: Nr. | E64: 5944.08 | F64: =C64*E64 -> 23776.32
A66: N | B66: Type ID-07; 1200 x 2100mm high; single leaf door | C66: 4 | D66: Nr. | E66: 5944.08 | F66: =C66*E66 -> 23776.32
C71: To Collection | E71: AED | F71: =SUM(F39:F68) -> 861533.39
B74: DOORS (Cont´d)
A76: A | B76: Type ID-08; 2000 x 2400mm high; double leaf door | C76: 2 | D76: Nr. | E76: 9356.43 | F76: =C76*E76 -> 18712.86
A78: B | B78: Type ID-11; 900 x 2100mm high; single leaf door | C78: 10 | D78: Nr. | E78: 4733.25 | F78: =C78*E78 -> 47332.5
B80: Rolling shutter; building into brick, block concrete walls and gypsum partitions; including frames, ironmongery, finishes, architrave, weatherstripping and all necessary fixings accessories
A82: C | B82: Type RS-01; 7150 x 7000mm high | C82: 2 | D82: Nr. | E82: 201549.78 | F82: =C82*E82 -> 403099.56
C113: To Collection | E113: AED | F113: =SUM(F75:F89) -> 469144.92
...

Sheet Bill 3 Finishes
A1: Item | B1: Description | C1: Quantity | D1: Unit | E1: Rate | F1: Amount | G1: VE Ref.
E2: AED | F2: AED
B4: FINISHES
B6: BACKGROUNDS
B8: Note: Refer to the following
B10: 1. Typical Detail Reference No. ID-500 series, A-951 to 953
B12: 2. Room finishes schedule Reference No. A-820
B14: 3. Material Schedule G-004
B16: 4. Drawings listed on Drawing Nr. ID-000 and G-001, all inclusive
B18: 5. Interior Architectural Specification Document 000110 dated 22 April 2022, all inclusive
B20: Sand cement screed; including surface preparation and all ancillary works as necessary
A22: A | B22: Screed; to receive tile | C22: 50312 | D22: m² | E22: 41.77 | F22: =C22*E22 -> 2101532.2
A24: B | B24: Screed; to receive epoxy paint | C24: 5413 | D24: m² | E24: 45.11 | F24: =C24*E24 -> 244180.43
B26: Epoxy screed; including surface preparation and all ancillary works as necessary
A28: C | B28: Type SC-01 | C28: 15 | D28: m² | E28: 375.58 | F28: =C28*E28 -> 5633.7
B30: Lightweight fill; including all ancillary works as necessary
A32: D | B32: 800mm thick; to amphitheater step | C32: 39 | D32: m² | E32: 568.04 | F32: =C32*E32 -> 22153.56
A34: E | B34: 500mm thick; to amphitheater step | C34: 20 | D34: m² | E34: 355.03 | F34: =C34*E34 -> 7100.6
A36: F | B36: 200mm thick; to amphitheater step | C36: 7 | D36: m² | E36: 142.01 | F36: =C36*E36 -> 994.07
A38: G | B38: 400mm thick; to paving | C38: 808 | D38: m² | E38: 284.02 | F38: =C38*E38 -> 229488.16
A40: H | B40: 400mm thick; to paving band | C40: 16 | D40: m² | E40: 284.02 | F40: =C40*E40 -> 4544.32
C43: To Collection | E43: AED | F43: =SUM(F16:F41) -> 2615627.1
B46: BACKGROUNDS (Cont´d)
B48: Cement plaster; including surface preparation and all ancillary works as necessary
A50: A | B50: Wall plaster; 15mm thick; to receive tiles | C50: 10810 | D50: m² | E50: 48.05 | F50: =C50*E50 -> 519420.5
A52: B | B52: Wall plaster; 15mm thick; to receive grp panel | C52: 1023 | D52: m² | E52: 48.05 | F52: =C52*E52 -> 49155.15
A54: C | B54: Wall plaster; 15mm thick; to receive paint | C54: 12931 | D54: m² | E54: 48.05 | F54: =C54*E54 -> 621334.55 | G54: EM-18 EM-20
B85: ** VE Reference "EM-" denotes items raised by Client in the VE Schedule
C87: To Collection | E87: AED | F87: =SUM(F48:F66) -> 1189910.2
B90: INTERNAL FINISHINGS
B92: Note: Refer to the following
B94: 1. Typical Detail Reference No. ID-500 series, A-951 to 953
B96: 2. Room finishes schedule Reference No. A-820
B98: 3. Material Schedule G-004
B100: 4. Drawings listed on Drawing Nr. ID-000 and G-001, all inclusive
B102: 5. Interior Architectural Specification Document 000110 dated 22 April 2022, all inclusive
B104: Static conductive vinyl floor tiles; laid on cement and sand screed (measured separately); including adhesive mortar, grout, joint and edge treatment sealer and all ancillary works as necessary
A106: A | B106: Type VCT-01; 610 x 610 x 2mm thick | C106: 93 | D106: m² | E106: 269.24 | F106: =C106*E106 -> 25039.32
A108: B | B108: Skirting; type VCT-01; 100mm high | C108: 62 | D108: m | E108: 53.85 | F108: =C108*E108 -> 3338.7
B110: Full bodied anti-slip floor tiles; laid on cement and sand screed (measured separately); including adhesive mortar, grout, joint and edge treatment sealer and all ancillary works as necessary
...

Sheet Bill 3 - Accessories
A1: Item | B1: Description | C1: Quantity | D1: Unit | E1: Rate | F1: Amount | G1: VE Ref.
E2: AED | F2: AED
B4: ACCESSORIES
B6: PARTITIONS
B8: Note: Refer to the following
B10: 1. Typical Detail Reference No. ID-500 series, A-951 to 953
B12: 2. Room finishes schedule Reference No. A-820
B14: 3. Material Schedule G-004
B16: 4. Drawings listed on Drawing Nr. ID-000 and G-001, all inclusive
B18: 5. Interior Architectural Specification Document 000110 dated 22 April 2022, all inclusive
B20: Drywall partition; including metal studs, supports and all ancillary works as necessary
A22: A | B22: Type 3; 150mm thick; to external | C22: 212 | D22: m² | E22: 252.32 | F22: =C22*E22 -> 53491.84
A24: B | B24: Type 3; 150mm thick; to internal | C24: 4138 | D24: m² | E24: 189.24 | F24: =C24*E24 -> 783075.12
B26: Wall backing; including lightcove, supports, fixings, accessories and all ancillary works as necessary; as Detail 3 Drawing Nr. ID-705-4 and ID-509-2
A28: C | B28: Wall backing; to porcelain tiles | C28: 3,119 | D28: m² | E28: 126.16 | F28: =C28*E28 -> 393493.04
A30: D | B30: Wall backing; to grg panels | C30: 1,089 | D30: m² | E30: 126.16 | F30: =C30*E30 -> 137388.24
A32: E | B32: Wall backing; to paint; curved | C32: 1853 | D32: m² | E32: 168.21 | F32: =C32*E32 -> 311693.13
B34: Cubicle partition; metal panel type MT-04, 2150mm high doors in plastic laminate type PL-04; including ironmongery, finishes and all ancillary works as necessary
A36: F | B36: Overall size 1300 x 1800 x 2800mm high: front panel with 1 Nr. door | C36: 1 | D36: Nr. | E36: 5555.39 | F36: =C36*E36 -> 5555.39
C39: To Collection | E39: AED | F39: =SUM(F21:F37) -> 1684696.8
B42: PARTITIONS (Cont´d)
A44: A | B44: Overall size 2400 x 1800 x 2800mm high: front panel with 1 dividing panel and 2 Nr. doors | C44: 5 | D44: Nr. | E44: 11110.79 | F44: =C44*E44 -> 55553.95
A46: B | B46: Overall size 3600 x 1800 x 2800mm high: front panel with 2 dividing panel and 3 Nr. doors | C46: 2 | D46: Nr. | E46: 16666.18 | F46: =C46*E46 -> 33332.36
A48: C | B48: Overall size 3610 x 1600x 2800mm high: front panel with 2 dividing panel and 3 Nr. doors | C48: 2 | D48: Nr. | E48: 16666.18 | F48: =C48*E48 -> 33332.36
A50: D | B50: Overall size 5050 x 1600x 2800mm high: front panel with 3 dividing panel and 4 Nr. doors | C50: 2 | D50: Nr. | E50: 22221.58 | F50: =C50*E50 -> 44443.16
A52: E | B52: Overall size 5065L x 1800 x 2800mm high: front panel with 3 dividing panel and 4 Nr. doors | C52: 2 | D52: Nr. | E52: 22221.58 | F52: =C52*E52 -> 44443.16
A54: F | B54: Overall size 6000 x 2800mm high: front panel with 4 dividing panel and 5 Nr. doors | C54: 1 | D54: Nr. | E54: 27776.97 | F54: =C54*E54 -> 27776.97
B56: Overall size 6030 x 2800mm high: front panel with 4 dividing panel and 5 Nr. doors | C56: 2 | E56: 27776.97 | F56: =C56*E56 -> 55553.94
A58: G | B58: Overall size 6430 x 2800mm high: front panel with 4 dividing panel and 5 Nr. doors | C58: 2 | D58: Nr. | E58: 27776.97 | F58: =C58*E58 -> 55553.94
A60: H | B60: Overall size 6780 x 2800mm high: front panel with 5 dividing panel and 6 Nr. doors | C60: 2 | D60: Nr. | E60: 33332.37 | F60: =C60*E60 -> 66664.74
A62: J | B62: Overall size 7900 x 1800 x 2800mm high: front panel with 6 dividing panel and 7 Nr. doors | C62: 1 | D62: Nr. | E62: 38887.76 | F62: =C62*E62 -> 38887.76
A64: K | B64: Overall size 8150 x 1800 x 2800mm high: front panel with 6 dividing panel and 7 Nr. doors | C64: 1 | D64: Nr. | E64: 38887.76 | F64: =C64*E64 -> 38887.76
A66: L | B66: Overall size 8450 x 2800mm high: front panel with 6 dividing panel and 7 Nr. doors | C66: 5 | D66: Nr. | E66: 38887.76 | F66: =C66*E66 -> 194438.8
A68: M | B68: Overall size 9660 x 2800mm high: front panel with 7 dividing panel and 8 Nr. doors | C68: 2 | D68: Nr. | E68: 44443.16 | F68: =C68*E68 -> 88886.32
A70: N | B70: Overall size 10780 x 2800mm high: front panel with 8 dividing panel and 9 Nr. doors | C70: 2 | D70: Nr. | E70: 49998.55 | F70: =C70*E70 -> 99997.1
C73: To Collection | E73: AED | F73: =SUM(F42:F71) -> 877752.32
B76: PARTITIONS (Cont´d)
A78: A | B78: Overall size 10875L x 2800mm high: front panel with 8 dividing panel and 9 Nr. doors | C78: 5 | D78: Nr. | E78: 49998.55 | F78: =C78*E78 -> 249992.75
A80: B | B80: Overall size 10880 x 2800mm high: front panel with 8 dividing panel and 9 Nr. doors | C80: 1 | D80: Nr. | E80: 49998.55 | F80: =C80*E80 -> 49998.55
A82: C | B82: Overall size 10890 x 2800mm high: front panel with 8 dividing panel and 9 Nr. doors | C82: 2 | D82: Nr. | E82: 49998.55 | F82: =C82*E82 -> 99997.1
...

Sheet Bill 3 - Furnishings
A1: Item | B1: Description | C1: Quantity | D1: Unit | E1: Rate | F1: Amount
E2: AED | F2: AED
B4: FURNISHINGS
B6: LOOSE FURNITURE
B8: Note: Refer to the following
B10: 1. Interior FF&E Schedule and Mood Boards dated April 2022
B12: Loose furniture; including all ancillary works as necessary
B14: To Garden walk
A16: A | B16: Type I-BA-01: banquette seating | C16: 3 | D16: Nr. | E16: 10174.99 | F16: =C16*E16 -> 30524.97
A18: B | B18: Type I-CH-01: lounge chair | C18: 12 | D18: Nr. | E18: 2511.64 | F18: =C18*E18 -> 30139.68
A20: C | B20: Type I-CH-02: armchair | C20: 27 | D20: Nr. | E20: 1968.62 | F20: =C20*E20 -> 53152.74
A22: D | B22: Type I-SO-01: sofa | C22: 9 | D22: Nr. | E22: 5904.76 | F22: =C22*E22 -> 53142.84
A24: E | B24: Type I-TA-01: side table | C24: 39 | D24: Nr. | E24: 1425.59 | F24: =C24*E24 -> 55598.01
B26: To Pulse
A28: F | B28: Type I-BN-01: swing bench | C28: 11 | D28: Nr. | E28: 6578.37 | F28: =C28*E28 -> 72362.07
A30: G | B30: Type I-SO-02: three-seater sofa | C30: 6 | D30: Nr. | E30: 3596.61 | F30: =C30*E30 -> 21579.66
A32: H | B32: Type I-CH-03: armchair | C32: 35 | D32: Nr. | E32: 2511.64 | F32: =C32*E32 -> 87907.4
A34: J | B34: Type I-CH-04: armchair | C34: 44 | D34: Nr. | E34: 1288.47 | F34: =C34*E34 -> 56692.68
A36: K | B36: Type I-TA-02: side table | C36: 49 | D36: Nr. | E36: 1056.68 | F36: =C36*E36 -> 51777.32
A38: L | B38: Type I-TA-03: side table | C38: 31 | D38: Nr. | E38: 1150.26 | F38: =C38*E38 -> 35658.06
A40: M | B40: Type I-PL-02: planter | C40: 22 | D40: Nr. | E40: 2105.73 | F40: =C40*E40 -> 46326.06
B42: To Retail Zone A
A44: N | B44: Type I-SO-03: sofa | C44: 4 | D44: Nr. | E44: 5224.61 | F44: =C44*E44 -> 20898.44
A46: P | B46: Type I-CH-05: lounge chair | C46: 22 | D46: Nr. | E46: 1968.62 | F46: =C46*E46 -> 43309.64
A48: Q | B48: Type I-TA-04: side table | C48: 10 | D48: Nr. | E48: 1562.7 | F48: =C48*E48 -> 15627
C50: To Collection | E50: AED | F50: =SUM(F14:F48) -> 674696.57
B53: LOOSE FURNITURE (Cont´d)
A55: A | B55: Type I-PL-03: planter | C55: 12 | D55: Nr. | E55: 745.44 | F55: =C55*E55 -> 8945.28
B57: To Retail Zone B
A59: B | B59: Type I-BN-02: bench seating | C59: 3 | D59: Nr. | E59: 2511.64 | F59: =C59*E59 -> 7534.92
A61: C | B61: Type I-CH-06: lounge chair | C61: 6 | D61: Nr. | E61: 1193.79 | F61: =C61*E61 -> 7162.74
A63: D | B63: Type I-CH-07: lounge chair | C63: 7 | D63: Nr. | E63: 1562.7 | F63: =C63*E63 -> 10938.9
A65: E | B65: Type I-CH-08: high chair | C65: 24 | D65: Nr. | E65: 1193.79 | F65: =C65*E65 -> 28650.96
A67: F | B67: Type I-TA-05: coffee table | C67: 3 | D67: Nr. | E67: 1968.62 | F67: =C67*E67 -> 5905.86
A69: G | B69: Type I-TA-06: side table | C69: 3 | D69: Nr. | E69: 1425.59 | F69: =C69*E69 -> 4276.77
A71: H | B71: Type I-TA-07: community table | C71: 3 | D71: Nr. | E71: 4950.38 | F71: =C71*E71 -> 14851.14
A73: J | B73: Type I-PL-04: planter | C73: 6 | D73: Nr. | E73: 882.56 | F73: =C73*E73 -> 5295.36
B75: To East food cluster
A77: K | B77: Type I-BA-02: banquette seating | C77: 4 | D77: Nr. | E77: 2236.32 | F77: =C77*E77 -> 8945.28
A79: L | B79: Type I-CH-09: chair | C79: 7 | D79: Nr. | E79: 650.76 | F79: =C79*E79 -> 4555.32
...

Sheet Bill 3 - Special Cons
A1: Item | B1: Description | C1: Quantity | D1: Unit | E1: Rate | F1: Amount
E2: AED | F2: AED
B4: SPECIAL CONSTRUCTION
B6: WATER FEATURES
B8: Note: Refer to the following
B10: 1. Landscape Detailed Design Report dated 11 April 2022
B12: 2. Drawing listed in Reference Nr. V0195-TVS-ZZ-XX-DR-L-001, all inclusive
B14: Granite paving; including epoxy adhesive, joint and edge treatment and all ancillary works as necessary
A16: A | B16: Paving type WF2; size 600L x 600W x 30mm thick; dark grey colour; in polished finish | C16: 59 | D16: m² | E16: 1213.58 | F16: =C16*E16 -> 71601.22
B18: Granite cladding; including epoxy adhesive, joint and edge treatment and all ancillary works as necessary
A20: B | B20: Cladding type WF3; 20mm thick; dark grey colour; in polished finish | C20: 21 | D20: m² | E20: 759.06 | F20: =C20*E20 -> 15940.26
B22: Basin tiling; including epoxy adhesive, joint and edge treatment and all ancillary works as necessary
A24: C | B24: Tiling type WF4; 20mm thick; sukabumi basalt colour; in riven finish | C24: 127 | D24: m² | E24: 584.94 | F24: =C24*E24 -> 74287.38
B26: Internal waterproofing; including all ancillary works as necessary
A28: D | B28: To floors | C28: 186 | D28: m² | E28: 184.19 | F28: =C28*E28 -> 34259.34
A30: E | B30: To walls | C30: 28 | D30: m² | E30: 184.19 | F30: =C30*E30 -> 5157.32
B32: Concrete base; including concrete, shuttering, reinforcement, waterproofing, fixings and all ancillary works as necessary
A34: F | B34: To water feature | C34: 44 | D34: m³ | E34: 1603.77 | F34: =C34*E34 -> 70565.88
C37: To Collection | E37: AED | F37: =SUM(F13:F35) -> 271811.4
B40: WATER FEATURES (Cont´d)
A42: A | B42: Allow water supply for garden walk water features; including pipes, fittings, accessories and all ancillary works as necessary | D42: Item | E42: 307287.78 | F42: =+E42 -> 307287.78
A44: B | B44: Allow water feature equipment | D44: Item | F44: Refer to 3/N/3
C82: To Collection | E82: AED | F82: =SUM(F41:F59) -> 307287.78
B85: GENERALLY
A87: A | B87: Allow for any other works which are not included above and which are required to complete the Special Construction in accordance with the Specification and the drawings (Tenderer to list below): | D87: Item | F87: =C87*E87 -> 0
B89: Water Features
B91: Garden Walk (Internal)
A93: A | B93: Water Feature 01 - Cascade Water Feature | C93: 1 | D93: Item | E93: 228158.78 | F93: =+C93*E93 -> 228158.78
A95: B | B95: Water Feature 02 - Plant Pond | C95: 1 | D95: Item | E95: 164823.68 | F95: =+C95*E95 -> 164823.68
A97: C | B97: Water Feature 03 - Cascade Water Feature | C97: 1 | D97: Item | E97: 259933.87 | F97: =+C97*E97 -> 259933.87
A99: D | B99: Water Feature 04 - Plant Pond | C99: 1 | D99: Item | E99: 178452.74 | F99: =+C99*E99 -> 178452.74
A101: E | B101: Water Feature 05 - Cascade Water Feature | C101: 1 | D101: Item | E101: 270766.69 | F101: =+C101*E101 -> 270766.69
A103: F | B103: Water Feature 06 - Cascade Water Feature | C103: 1 | D103: Item | E103: 216200.54 | F103: =+C103*E103 -> 216200.54
A105: G | B105: Water Feature 07A & 7B - Plant Pond | C105: 1 | D105: Item | E105: 158053.33 | F105: =+C105*E105 -> 158053.33
A107: H | B107: Water Feature 08 - Cascade Water Feature | C107: 1 | D107: Item | E107: 235199.28 | F107: =+C107*E107 -> 235199.28
A109: J | B109: Water Feature 09 - Cascade Water Feature | C109: 1 | D109: Item | E109: 222005.54 | F109: =+C109*E109 -> 222005.54
B111: External
A113: K | B113: Outdoor Water Feature - Nozzles Water Feature | C113: 1 | D113: Item | E113: 323923.21 | F113: =+C113*E113 -> 323923.21
B115: Quantity Adjustments
A117: L | B117: Variance in quantity following in-house Quantity Take Off | C117: 1 | D117: item | F117: =+C117*E117 -> 0
...

Sheet Bill 3 - Conveying
A1: Item | B1: Description | C1: Quantity | D1: Unit | E1: Rate | F1: Amount | G1: VE Ref.
E2: AED | F2: AED
B4: CONVEYING SYSTEMS
B6: LIFTS
B8: Note: Refer to the following:
B10: 1. Drawing Nr. VT-001,002 and VT-101 to 129
B12: 2. Drawing Reference Nr. ID-700 series, all inclusive
B14: MRL Duplex type Passenger Elevator; including elevator car, traction motor, wire ropes, door controls, door sensors, rails, control panels, lighting fixtures, wirings, conduits, intercommunication system, counter weight, hauling, hoisting and all ancillary works as necessary
A16: A | B16: Ref. PE-M-17.1 & 2 - 1600kgs/21 persons capacity, 1.60m/s speed, 6 stops / 6 openings | C16: 2 | D16: Nr. | E16: 359543.6 | F16: =C16*E16 -> 719087.2
B18: MRL Group type Passenger / Trolley Elevator; including elevator car, traction motor, wire ropes, door controls, door sensors, rails, control panels, lighting fixtures, wirings, conduits, intercommunication system, counter weight, hauling, hoisting and all ancillary works as necessary
A20: B | B20: Ref. PE-M-18, 19 and 20 - 4000kgs / 53 persons capacity, 1m/s speed, 5 stops / 5 openings | C20: 3 | D20: Nr. | E20: 481570.52 | F20: =C20*E20 -> 1444711.6
A22: C | B22: Ref. PE-M-21and 22 - 4000kgs / 53 persons capacity, 1m/s speed, 7 stops / 7 openings | C22: 2 | D22: Nr. | E22: 519703.94 | F22: =C22*E22 -> 1039407.9
C34: To Collection | E34: AED | F34: =SUM(F14:F28) -> 3203206.6
B37: LIFTS (Cont´d)
B39: MRL Simplex type Service Elevator; including elevator car, traction motor, wire ropes, door controls, door sensors, rails, control panels, lighting fixtures, wirings, conduits, intercommunication system, counter weight, hauling, hoisting and all ancillary works as necessary
A41: A | B41: Ref. SE-M-08 - 2000kgs/21 persons capacity, 1m/s speed, 4 stops / 4 openings | C41: 1 | D41: Nr. | E41: 326857.82 | F41: =C41*E41 -> 326857.82
A43: B | B43: Ref. SE-M-09 - 2000kgs/21 persons capacity, 1m/s speed, 6 stops / 6 openings | C43: 1 | D43: Nr. | E43: 346469.29 | F43: =C43*E43 -> 346469.29
A45: C | B45: Ref. SE-M-10 - 2000kgs/21 persons capacity, 1m/s speed, 4 stops / 4 openings | C45: 1 | D45: Nr. | E45: 326857.82 | F45: =C45*E45 -> 326857.82
A47: D | B47: Ref. SE-M-11 - 2500kgs/33 persons capacity, 1m/s speed, 2 stops / 2 openings | C47: 1 | D47: Nr. | E47: 359543.6 | F47: =C47*E47 -> 359543.6
B49: Finishings; to lift cars for A, B and C; including fixing, fittings, accessories and all ancillary works as necessary
A51: E | B51: Floor tile; type TL-01; 500 x 500mm | C51: 39 | D51: m² | E51: 218.91 | F51: =C51*E51 -> 8537.49 | G51: EM-17
A53: F | B53: Stainless steel wall panel; type MT-01 | C53: 69 | D53: m² | E53: 3422.01 | F53: =C53*E53 -> 236118.69
A55: G | B55: Bumper rail; 20 x 60mm; type MT-02; L-shaped | C55: 46 | D55: m | E55: 880.91 | F55: =C55*E55 -> 40521.86
A57: H | B57: Stainless steel wall panel; type MT-06 | C57: 14 | D57: m² | E57: 3422.01 | F57: =C57*E57 -> 47908.14
A59: J | B59: 3M Di-noc wood; to walls; type PL-01 | C59: 64 | D59: m² | E59: 767.32 | F59: =C59*E59 -> 49108.48
A61: K | B61: Stainless steel skirting; type MT-01 | C61: 77 | D61: m | E61: 350.11 | F61: =C61*E61 -> 26958.47
A63: L | B63: Barissol ceiling; type BS-01 | C63: 12 | D63: m² | E63: 1654.18 | F63: =C63*E63 -> 19850.16
A65: M | B65: Gypsum ceiling board | C65: 33 | D65: m² | E65: 94.62 | F65: =C65*E65 -> 3122.46
A67: N | B67: Gypsum wall board | C67: 78 | D67: m² | E67: 126.16 | F67: =C67*E67 -> 9840.48
A69: P | B69: Lightcove; 370mm girth | C69: 57 | D69: m | E69: 147.19 | F69: =C69*E69 -> 8389.83
C71: To Collection | E71: AED | F71: =SUM(F39:F69) -> 1810084.6
B74: LIFTS (Cont´d)
A76: A | B76: Paint to gypsum ceiling; type PT-01 | C76: 33 | D76: m² | E76: 15.51 | F76: =C76*E76 -> 511.83
B78: Finishings; to lift cars for D; including fixing, fittings, accessories and all ancillary works as necessary
A80: B | B80: Floor tile; type TL-06; 500 x 500mm | C80: 13 | D80: m² | E80: 220.27 | F80: =C80*E80 -> 2863.51 | G80: EM-17
A82: C | B82: Stainless steel wall panel; type MT-02 | C82: 32.00 | D82: m² | E82: 2439.45 | F82: =C82*E82 -> 78062.4
A84: D | B84: Stainless steel wall panel; type MT-10 | C84: 31.00 | D84: m² | E84: 2303.93 | F84: =C84*E84 -> 71421.83
A86: E | B86: Stainless steel skirting; type MT-02 | C86: 25 | D86: m | E86: 214.58 | F86: =C86*E86 -> 5364.5
A88: F | B88: Bumper rail; 20 x 60mm; type MT-02; L-shaped | C88: 17 | D88: m | E88: 880.91 | F88: =C88*E88 -> 14975.47
A90: G | B90: Gypsum ceiling board | C90: 21 | D90: m² | E90: 94.62 | F90: =C90*E90 -> 1987.02
...

Sheet Bill 3 - Mech
A1: Item | B1: Description | C1: Quantity | D1: Unit | E1: Rate | F1: Amount | G1: VE Ref.
E2: AED | F2: AED
B4: MECHANICAL ENGINEERING INSTALLATIONS
B6: IRRIGATION SYSTEM
B8: Note: Please refer to the following:
B10: 1) Drawing Nr. V0195-TVS-ZZ-GF-DR-L-601 to 620 and 3D View Al-Khail R20 Irrig; all inclusive
B12: 2) Al Khail Avenue Mall Redevelopment - Mechanical Specification dated March 28, 2022
B14: Irrigation lateral line uPVC pipe; including fittings
A16: A | B16: uPVC class E pipe; size 32mm diameter | C16: 887 | D16: m | E16: 39.52 | F16: =C16*E16 -> 35054.24
A18: B | B18: uPVC class D pipe; size 50mm diameter | C18: 68 | D18: m | E18: 43.36 | F18: =C18*E18 -> 2948.48
A20: C | B20: uPVC class D pipe; size 63mm diameter | C20: 17 | D20: m | E20: 49.76 | F20: =C20*E20 -> 845.92
B22: Drip irrigation accessories; including compression fittings, spike, and all related fixing materials as necessary
A24: D | B24: Drip riser for shrub and ground cover | C24: 52 | D24: Nr | E24: 56.16 | F24: =C24*E24 -> 2920.32
A26: E | B26: Drip riser for trees | C26: 112 | D26: Nr | E26: 56.16 | F26: =C26*E26 -> 6289.92
B28: Pipe specialties/accessories; including all related fixing materials and ancillary works as necessary
A30: F | B30: Drip solenoid valve (DVP01) - size 1" diameter | C30: 1 | D30: Nr | E30: 2056.03 | F30: =C30*E30 -> 2056.03
A32: G | B32: Drip solenoid valve (DVP02) - size 1.5" diameter | C32: 1 | D32: Nr | E32: 2538.71 | F32: =C32*E32 -> 2538.71
A34: H | B34: Drip solenoid valve (DVP03) - size 1.5" diameter | C34: 1 | D34: Nr | E34: 2538.71 | F34: =C34*E34 -> 2538.71
A36: J | B36: Drip solenoid valve (DVP04) - size 1.5" diameter | C36: 1 | D36: Nr | E36: 2538.71 | F36: =C36*E36 -> 2538.71
A38: K | B38: Drip solenoid valve (DVP05) - size 1.5" diameter | C38: 1 | D38: Nr | E38: 2538.71 | F38: =C38*E38 -> 2538.71
C42: To Collection | E42: AED | F42: =SUM(F12:F39) -> 60269.75
B45: IRRIGATION SYSTEM (Cont´d)
A47: A | B47: Drip solenoid valve (DVP06) - size 1" diameter | C47: 1 | D47: Nr | E47: 2056.03 | F47: =C47*E47 -> 2056.03
A49: B | B49: Drip solenoid valve (DVP07) - size 1" diameter | C49: 1 | D49: Nr | E49: 2056.03 | F49: =C49*E49 -> 2056.03
A51: C | B51: Drip solenoid valve (DVP08) - size 1" diameter | C51: 1 | D51: Nr | E51: 2056.03 | F51: =C51*E51 -> 2056.03
A53: D | B53: Allow for connection to the nearest electrical power supply including cables, conduits, terminations and all ancillary works as necessary | D53: Item | E53: 18134.34 | F53: =+E53 -> 18134.34
C87: To Collection | E87: AED | F87: =SUM(F45:F78) -> 24302.43
B90: DRAINAGE INSTALLATION
B92: Note: Please refer to the following:
B94: 1) Drawing Nr. D-12200 to D-12259, D-13100 to D-13110 and 3D View Al-Khail R20 Plumb; all inclusive
B96: 2) Drainage general notes, symbols and legends and Drainage equipment schedule Drawing Nr. D-09102 and D-00050
B98: 3) Al Khail Avenue Mall Redevelopment - Mechanical Specification dated March 28, 2022
B100: uPVC pipework; including fittings, supports and ancillary work as necessary
B102: Rainwater pipework
A104: A | B104: 80mm diameter | C104: 19 | D104: m | E104: 119.7 | F104: =C104*E104 -> 2274.3
A106: B | B106: 110mm diameter | C106: 230 | D106: m | E106: 130.82 | F106: =C106*E106 -> 30088.6
A108: C | B108: 150mm diameter | C108: 34 | D108: m | E108: 183.55 | F108: =C108*E108 -> 6240.7
B110: Flexible elastomeric insulation, 13mm thick to rainwater pipes including support, accessories and other ancillary works as necessary
A112: D | B112: 80mm diameter | C112: 19 | D112: m | E112: 19.86 | F112: =C112*E112 -> 377.34
A114: E | B114: 110mm diameter | C114: 230 | D114: m | E114: 36.6 | F114: =C114*E114 -> 8418
...

Sheet Bill 3 Elec
A1: Item | B1: Description | C1: Quantity | D1: Unit | E1: Rate | F1: Amount | G1: VE Ref.
E2: AED | F2: AED
B4: ELECTRICAL ENGINEERING INSTALLATIONS
B6: POWER INSTALLATION
B8: Note: Please refer to the following:
B10: 1) Drawing Nr. E-00003 to 10200, E-12500 to 12554, E-12730 to 12784, E-12925 to 12979, E-12860 to 12879 and Al Khail_R20_ELEC_LT: 3D View; all inclusive
B12: 2) Al Khail Avenue Mall Redevelopment Electrical Specifications dated March 28, 2022
B14: XLPE cables including earth connectivity conductor cables, terminations, lugs, supports and all ancillary work
B16: 1 x 4C x 95mm² CU/XLPE/SWA/LSOH + 1 x 1C x 50mm² CU/LSOH ECC
A18: A | B18: From MDB-Z1-02-03 to SMDB-FB-F-055 | D18: Item | E18: 28134.38 | F18: =+E18 -> 28134.38
A20: B | B20: From MDB-Z1-02-03 to SMDB-FB-F-135A | D20: Item | E20: 37582.48 | F20: =+E20 -> 37582.48
B22: 1 x 4C x 185mm² CU/XLPE/SWA/LSOH + 1 x 1C x 95mm² CU/LSOH ECC
A24: C | B24: From MDB-Z1-02-03 to SMDB-FB-F-135B | D24: Item | E24: 93666.26 | F24: =+E24 -> 93666.26
A26: D | B26: From MDB-Z1-02-03 to SMDB-FB-F-135C | D26: Item | E26: 83303.18 | F26: =+E26 -> 83303.18
A28: E | B28: From MDB-Z1-02-03 to SMDB-FB-S-150D | D28: Item | E28: 150264.58 | F28: =+E28 -> 150264.58
B30: 1 x 4C x 300mm² CU/XLPE/SWA/LSOH + 1 x 1C x 150mm² CU/LSOH ECC
A32: F | B32: From MDB-Z1-02-03 to SMDB-FB-F-053 | D32: Item | E32: 98750.52 | F32: =+E32 -> 98750.52
B34: 1 x 4C x 4mm² CU/XLPE/SWA/PVC + 1 x 1C x 4mm² CU/PVC ECC
A36: G | B36: From SMDB-S-04-SF-MM to 20A TP isolator for ER-M-SF-01 | D36: Item | E36: 1520.78 | F36: =+E36 -> 1520.78
C40: To Collection | E40: AED | F40: =SUM(F14:F38) -> 493222.18
B43: POWER INSTALLATION (Cont´d)
B45: 1 x 4C x 10mm² CU/XLPE/PVC + 1 x 1C x 10mm² CU/PVC ECC
A47: A | B47: From SMDB-S-01-B2-FB1 to DB-S-01-GF-FB3 | D47: Item | E47: 1162.23 | F47: =+E47 -> 1162.23
B49: 1 x 4C x 10mm² CU/XLPE/SWA/LSOH + 1 x 1C x 10mm² CU/LSOH ECC
A51: B | B51: From SMDB-SH-01-102 to DB-CD-F-062 | D51: Item | E51: 5914.85 | F51: =+E51 -> 5914.85
A53: C | B53: From SMDB-SH-01-102 to DB-SH-F-060 | D53: Item | E53: 4768.56 | F53: =+E53 -> 4768.56
A55: D | B55: From SMDB-SH-01-103 to DB-SH-F-069A | D55: Item | E55: 7519.66 | F55: =+E55 -> 7519.66
A57: E | B57: From SMDB-SH-01-103 to DB-SH-F-073 | D57: Item | E57: 8665.95 | F57: =+E57 -> 8665.95
A59: F | B59: From SMDB-SH-02-GM1 to DB-SH-F-047A | D59: Item | E59: 6189.96 | F59: =+E59 -> 6189.96
A61: G | B61: From SMDB-SH-02-GM1 to DB-SH-F-051 | D61: Item | E61: 5823.15 | F61: =+E61 -> 5823.15
A63: H | B63: From SMDB-SH-02-GM1 to DB-SH-F-051A | D63: Item | E63: 5639.75 | F63: =+E63 -> 5639.75
A65: J | B65: From SMDB-SH-04-104 to DB-CF-F-114 | D65: Item | E65: 12517.48 | F65: =+E65 -> 12517.48
A67: K | B67: From SMDB-SH-04-104 to DB-SH-F-110A | D67: Item | E67: 13984.73 | F67: =+E67 -> 13984.73
A69: L | B69: From SMDB-SH-04-104 to DB-SH-F-116 | D69: Item | E69: 11829.71 | F69: =+E69 -> 11829.71
A71: M | B71: From SMDB-SH-04-105 to DB-SH-F-117 | D71: Item | E71: 10087.35 | F71: =+E71 -> 10087.35
A73: N | B73: From SMDB-SH-04-105 to DB-SH-F-125 | D73: Item | E73: 12334.08 | F73: =+E73 -> 12334.08
... A85: U | B85: From SMDB-SH-04-108 to DB-SH-F-069C | D85: Item | E85: 5364.63 | F85: =+E85 -> 5364.63
C88: To Collection | E88: AED | F88: =SUM(F45:F86) -> 134498.62
B91: POWER INSTALLATION (Cont´d)
A93: A | B93: From SMDB-SH-04-108 to DB-SH-F-075 | D93: Item | E93: 5960.71 | F93: =+E93 -> 5960.71
...

Sheet Bill 3-Sum
A1: Item | B1: Description | C1: Page Nr. | D1: Amount AED
B5: SUMMARY
B7: SITEWORK | C7: 3/B/1 - 3/B/6 | D7: ='Bill 3 Siteworks'!F294 -> 843572.28
B8: EXTRA-OVER FOR COMPLYING TO AUTHORITY COMMENTS | C8: 3/B/EO/1 | D8: =+'Bill 3 Siteworks-EO'!F27 -> 55072.15
B10: CONCRETE WORK | C10: 3/C/1 - 3/C/7 | D10: ='Bill 3 Concrete'!F329 -> 9184533
B11: EXTRA-OVER FOR COMPLYING TO AUTHORITY COMMENTS | C11: 3/C/EO/1 - 3/C/EO/3 | D11: =+'Bill 3 Concrete-EO'!F144 -> 4157251.7
B13: MASONRY | C13: 3/D/1 - 3/D/2 | D13: ='Bill 3 Masonry'!F134 -> 5590258.6
B16: METALWORK | C16: 3/E/1 - 3/E/7 | D16: =+'Bill 3 Metalwork REV'!F292 -> 6916464.1
B19: WOODWORK | C19: 3/F/1 - 3/F/12 | D19: ='Bill 3 Woodwork'!F414 -> 16618538
B22: THERMAL AND MOISTURE PROTECTION | C22: 3/G/1 - 3/G/2 | D22: ='Bill 3 Thermal'!F135 -> 258133.23
B25: DOORS AND WINDOWS | C25: 3/H/1 - 3/H/11 | D25: ='Bill 3 Doors and Windows'!F437 -> 37038781
B28: FINISHES | C28: 3/J/1 - 3/J/20 | D28: ='Bill 3 Finishes'!F834 -> 68215250
B31: ACCESSORIES | C31: 3/K/1 - 3/K/16 | D31: ='Bill 3 - Accessories'!F614 -> 10734621
B34: FURNISHINGS | C34: 3/M/1 - 3/M/5 | D34: ='Bill 3 - Furnishings'!F280 -> 2425676.9
B37: SPECIAL CONSTRUCTION | C37: 3/N/1 - 3/N/3 | D37: ='Bill 3 - Special Cons'!F172 -> 2836616.8
B40: CONVEYING SYSTEM | C40: 3/P/1 - 3/P/8 | D40: ='Bill 3 - Conveying'!F363 -> 9287021.8
B43: MECHANICAL ENGINEERING INSTALLATIONS | C43: 3/Q/1 - 3/Q/40 | D43: ='Bill 3 - Mech'!F1876 -> 29073030
B46: ELECTRICAL ENGINEERING INSTALLATIONS | C46: 3/R/1 - 3/R/66 | D46: ='Bill 3 Elec'!F3090 -> 91387645
B50: TOTAL FOR BILL NO. 3 -MALL REFURBISHMENT
B51: TO MAIN SUMMARY | C51: AED | D51: =SUM(D6:D48) -> 2.9462246e+08
