Workbook
Name \0: #REF!
Name \a: #REF!
Name \B: #REF!
Name \C: #REF!
Name \D: #REF!
Name \E: #REF!
Name \F: #REF!
Name \G: #REF!
Name \H: #REF!
Name \I: #REF!
Name \J: #REF!
Name \K: #REF!
Name \L: #REF!
Name \M: #REF!
Name \N: #REF!
Name \p: #REF!
Name \Q: #REF!
Name \R: #REF!
Name \S: #REF!
Name \T: #REF!
Name \U: #REF!
Name \V: #REF!
Name \x: #REF!
Name \Y: #REF!
Name \Z: #REF!
Name \zbcdBSA: #REF!
Name ________B19000: #REF!
Name ________B19999: #REF!
Name ________B20000: #REF!
Name ________boq1: #REF!
Name ________dep2: #REF!
Name ________dep3: #REF!
Name ________e20000: #REF!
Name ________e99991: #REF!
Name ________ext2: #REF!
Name ________ext3: #REF!
Name ________len2: #REF!
Name ________len3: #REF!
Name ________pc1: #REF!
Name ________pc2: #REF!
Name ________pc3: #REF!
Name ________tbc2: #REF!
Name ________tbc3: #REF!
Name ________wid2: #REF!
Name ________wid3: #REF!
Name _______dep2: #REF!
Name _______dep3: #REF!
Name _______ext2: #REF!
Name _______ext3: #REF!
Name _______len2: #REF!
Name _______len3: #REF!
Name _______pc1: #REF!
Name _______pc2: #REF!
Name _______pc3: #REF!
Name _______tbc2: #REF!
Name _______tbc3: #REF!
Name _______wid2: #REF!
Name _______wid3: #REF!
Name ______B19999: #REF!
Name ______B20000: #REF!

Sheet Fly-Bill 13
A22: BILL NO. 13
A24: REVISED STRUCTURES STRENGTHENING WORKS - GMP

Sheet Bill 13 Revised Strength.
A1: Item | B1: Description | C1: Quantity | D1: Unit | E1: Rate | F1: Amount
E2: AED | F2: AED
B4: ALTERATIONS
B6: REVISED STRUCTURE STRENGTHENING WORKS
B8: Design Obligation - Vertical & Horizontal Strengthening
A10: A | B10: All design requirements mentioned on the drawings or project specification’s and or authority requirements should be part of the Sub-contractor scope. | C10: 1 | D10: Sum | E10: 0 | F10: Included
A11: B | B11: Full design and detailing and construction of strengthening of Vertical element columns / walls is the Sub-contractor responsibility | C11: 1 | D11: Sum | E11: 0 | F11: Included
A12: C | B12: Full design and detailing and construction of strengthening of Horizontal elements beams and slab, concrete and steel sections is the Sub-contractor responsibility | C12: 1 | D12: Sum | E12: 0 | F12: Included
A13: D | B13: The Sub-contractor shall submit the the full package for strenthening Works to the Authorities and obtain their approval. The submission to Authorities must be fully reviewed and stamped by a 3rd party consultant approved by Trakhees (must use Qualiconsult) ahead of issue to the ERC and onward submission to Authorities for approval. | C13: 1 | D13: Sum | E13: 0 | F13: Included
C44: To Collection | E44: AED | F44: =SUM(F10:F13) -> 0
B47: REVISED STRUCTURE STRENGTHENING WORKS (Cont´d)
B49: Strengthening works; including supports, fixings, accessories and all ancillary works as necessary
A51: A | B51: Jacket existing column; size 1250 x 1250 x 3050mm high; CJ01; 150mm thick; 2 sided; to basement 2 | C51: 1.281 | D51: m³ | E51: 12790 | F51: =+C51*E51 -> 16383.99
A53: B | B53: Jacket existing column; size 1250 x 1250 x 3050mm high; CJ01; 150mm thick; 3 sided; to basement 2 | C53: 5.970375 | D53: m³ | E53: 12790 | F53: =+C53*E53 -> 76361.096
A55: C | B55: Jacket existing column; size 1250 x 1250 x 3050mm high; CJ01; 150mm thick; 4 sided; to basement 2 | C55: 25.5285 | D55: m³ | E55: 12790 | F55: =+C55*E55 -> 326509.51
A57: D | B57: Jacket existing column; size 1250 x 1950 x 3050mm high; CJ01; 150mm thick; 4 sided; to basement 2 | C57: 3.477 | D57: m³ | E57: 12790 | F57: =+C57*E57 -> 44470.83
A59: E | B59: Jacket existing column; size 1250 x 2000 x 3050mm high; CJ01; 150mm thick; 3 sided; to basement 2 | C59: 2.33325 | D59: m³ | E59: 12790 | F59: =+C59*E59 -> 29842.267
A61: F | B61: Jacket existing column; size 1250 x 1250 x 3050mm high; CJ02; 150mm thick; 3 sided; to basement 2 | C61: 5.970375 | D61: m³ | E61: 12790 | F61: =+C61*E61 -> 76361.096
A63: G | B63: Jacket existing column; size 1250 x 2000 x 3050mm high; CJ02; 150mm thick; 4 sided; to basement 2 | C63: 7.0455 | D63: m³ | E63: 12790 | F63: =+C63*E63 -> 90111.945
A65: H | B65: Jacket existing column; size 1250 x 1250 x 3050mm high; CJ03; 300mm thick; 2 sided; to basement 2 | C65: 5.673 | D65: m³ | E65: 12790 | F65: =+C65*E65 -> 72557.67
C74: To Collection | E74: AED | F74: =SUM(F48:F71) -> 732598.41
B77: REVISED STRUCTURE STRENGTHENING WORKS (Cont´d)
A79: A | B79: Jacket existing column; size 1250 x 1250 x 3050mm high; CJ03; 300mm thick; 3 sided; to basement 2 | C79: 40.76325 | D79: m³ | E79: 12790 | F79: =C79*E79 -> 521361.97
A81: B | B81: Jacket existing column; size 1250 x 1250 x 3050mm high; CJ03; 300mm thick; 4 sided; to basement 2 | C81: 94.794 | D81: m³ | E81: 12790 | F81: =C81*E81 -> 1212415.3
A83: C | B83: Jacket existing column; size 1250 x 1500 x 3050mm high; CJ03; 300mm thick; 3 sided; to basement 2 | C83: 9.9735 | D83: m³ | E83: 12790 | F83: =C83*E83 -> 127561.06
A85: D | B85: Jacket existing column; size 1250 x 2000 x 3050mm high; CJ03; 300mm thick; 3 sided; to basement 2 | C85: 11.8035 | D85: m³ | E85: 12790 | F85: =C85*E85 -> 150966.76
A87: E | B87: Jacket existing column; size 1250 x 1250 x 3050mm high; CJ04; 200mm thick; 3 sided; to basement 2 | C87: 33.306 | D87: m³ | E87: 12790 | F87: =C87*E87 -> 425983.74
A89: F | B89: Jacket existing column; size 1250 x 1250 x 3050mm high; CJ04; 200mm thick; 4 sided; to basement 2 | C89: 165.066 | D89: m³ | E89: 12790 | F89: =C89*E89 -> 2111194.1
A91: G | B91: Jacket existing column; size 1250 x 2000 x 3050mm high; CJ04; 200mm thick; 4 sided; to basement 2 | C91: 4.941 | D91: m³ | E91: 12790 | F91: =C91*E91 -> 63195.39
A93: H | B93: Jacket existing column; size 1250 x 1250 x 3050mm high; CJ05; 250mm thick; 4 sided; to basement 2 | C93: 5.3375 | D93: m³ | E93: 12790 | F93: =C93*E93 -> 68266.625
A95: J | B95: Jacket existing column; size 1250 x 2000 x 3050mm high; CJ05; 250mm thick; 4 sided; to basement 2 | C95: 12.9625 | D95: m³ | E95: 12790 | F95: =C95*E95 -> 165790.37
A97: K | B97: Jacket existing column; size 500 x 1250 x 3050mm high; CJ06; 150mm thick; 4 sided; to basement 2 | C97: 2.15025 | D97: m³ | E97: 12790 | F97: =C97*E97 -> 27501.697
C106: To Collection | E106: AED | F106: =SUM(F78:F100) -> 4874237
B109: REVISED STRUCTURE STRENGTHENING WORKS (Cont´d)
A111: A | B111: Jacket existing column; size 600 x 600 x 3050mm high; CJ06; 150mm thick; 4 sided; to basement 2 | C111: 1.647 | D111: m³ | E111: 12790 | F111: =C111*E111 -> 21065.13
A113: B | B113: Jacket existing column; size 1250 x 1250 x 3050mm high; CJ06; 150mm thick; 3 sided; to basement 2 | C113: 13.930875 | D113: m³ | E113: 12790 | F113: =C113*E113 -> 178175.89
A115: C | B115: Jacket existing column; size 1250 x 1250 x 3050mm high; CJ06; 150mm thick; 4 sided; to basement 2 | C115: 14.1825 | D115: m³ | E115: 12790 | F115: =C115*E115 -> 181394.17
A117: D | B117: Jacket existing column; size 1250 x 1250 x 3050mm high; CJ07; 150mm thick; 3 sided; to basement 2 | C117: 1.990125 | D117: m³ | E117: 12790 | F117: =C117*E117 -> 25453.699
A119: E | B119: Jacket existing column; size 1250 x 1250 x 3050mm high; CJ08; 200mm thick; 3 sided; to basement 2 | C119: 5.551 | D119: m³ | E119: 12790 | F119: =C119*E119 -> 70997.29
A121: F | B121: Jacket existing column; size 1250 x 1250 x 3050mm high; CJ08; 200mm thick; 4 sided; to basement 2 | C121: 24.156 | D121: m³ | E121: 12790 | F121: =C121*E121 -> 308955.24
...

Sheet Bill 13 Add'l
A1: Item | B1: Description | C1: Quantity | D1: Unit | E1: Rate | F1: Amount
E2: AED | F2: AED
B3: Post Submission Meeting dated 29th August 2023
B5: Additional Stregthening Works: Edge preparation deemed required but not detailed on drawings
A7: A | B7: Termination & Edge preparation by means of drilling, fixing anchor rebars and grouting them with micro concreting etc., in line with the enclosed markup drawings | C7: 163.3839 | D7: m³ | E7: 12790 | F7: =+C7*E7 -> 2089680.1
A9: B | B9: Manual chipping for concrete using manual jackhammers and removal of concrete | C9: 163.3839 | D9: m³ | E9: 2391.356 | F9: =+C9*E9 -> 390709.08
A11: C | B11: Additional Beams to be added as part of horizontal strengthening due to connection with new structure. Scope shall include for: - Surface preparation for location of adding the new beams - Drilling and epoxy anchoring for connections - Installation of Dowel Bars & steel rebars - Shuttering and casting of beams using micro concrete The mark up drawings attached cover all horizontal beams included in the strengthening scope | C11: 57.9975 | D11: m³ | E11: 12790 | F11: =+C11*E11 -> 741788.03
C33: Carried To Summary | E33: AED | F33: =SUM(F5:F31) -> 3222177.2

Sheet Bill 13 Finishes
A1: Item | B1: Description | C1: Quantity | D1: Unit | E1: Rate | F1: Amount
E2: AED | F2: AED
B3: ASSOCIATED FINISHES
B5: Finishes to Additional Jacketed Columns
B7: Cement plaster; including surface preparation and all ancillary works as necessary
A9: A | B9: Wall plaster; 15mm thick; to receive paint (Rate as per Bill Reference 3/J/2) | C9: 8489 | D9: m² | E9: 48.053063 | F9: =+C9*E9 -> 407922.45
B11: Paint
A13: B | B13: Paint Finishes to Jacketed Columns (Rate as per Bill Reference 4/J/6 Item B) | C13: 8489 | D13: m² | E13: 42.969906 | F13: =+C13*E13 -> 364771.53
B15: Finishes to Additional Jacketed Walls
B17: Cement plaster; including surface preparation and all ancillary works as necessary
A19: C | B19: Wall plaster; 15mm thick; to receive paint (Rate as per Bill Reference 3/J/2) | C19: 6423 | D19: m² | E19: 48.053063 | F19: =+C19*E19 -> 308644.82
B21: Paint
A23: D | B23: Paint Finishes to Jacketed Columns (Rate as per Bill Reference 4/J/6 Item B) | C23: 6423 | D23: m² | E23: 42.969906 | F23: =+C23*E23 -> 275995.71
B25: Finishes to Additional RC Beam Thickening / Jacketing
B27: Cement plaster; including surface preparation and all ancillary works as necessary
A29: E | B29: Wall plaster; 15mm thick; to receive paint (Rate as per Bill Reference 3/J/2) | C29: 2105 | D29: m² | E29: 48.053063 | F29: =+C29*E29 -> 101151.7
B31: Paint
A33: F | B33: Paint Finishes to Jacketed Columns (Rate as per Bill Reference 4/J/6 Item B) | C33: 2105 | D33: m² | E33: 42.969906 | F33: =+C33*E33 -> 90451.652
B35: Adjustments
A37: G | B37: Less Finishes associated w/ Strenghtening Works priced previously | D37: sum | F37: =-169237.86-0.11 -> -169237.97
C43: Carried To Summary | E43: AED | F43: =SUM(F7:F41) -> 1379699.9

Sheet Add Scaff SS-Vertical
A1: Dutco Construction Company LLC
A2: T061/22 - Al Khail Mall Redevelopment Works
A4: STRUCTURE STRENGTHENING WORKS - VERTICAL AND HORIZONTAL
A6: Item | B6: Description | C6: Unit | D6: Scaffold Qty | E6: Rate | F6: Rate | G6: Duration | H6: Amount
E7: for Installation / Unit | F7: for hire of materials/Day | G7: of Hire (Days) | H7: AED
B9: BILL NO. 2- DEMOLITIONS AND ALTERATIONS
B11: ALTERATIONS
B13: STRUCTURE STRENGTHENING WORKS
B15: RC Walls and Columns
B17: 1. Demolition Plan Drawing Nr. S-12200 series
B18: 2. Demolition Section and Details Drawing Nr. S-30200 series
B19: Strengthening works; including supports, fixings, accessories and all ancillary works as necessary Additional rebar; dowel connection to existing to new structure and Post fix hilti
B20: Basement 2
B22: Refer PTC 30 /Authority approved drawings-series 12100
B23: Section and Details Drawing Nr. S-61001
A25: A | B25: Jacket existing column; size 1250 x 1250 x 3050mm high; to basement 2 -refer S-43316
A26: A.01 | B26: CJ01-150mm thick (12 Nr) | C26: m³ | D26: 390.156 | E26: 45 | F26: 0.45 | G26: 14 | H26: =+D26*E26+D26*F26*G26 -> 20015.003
A27: A.02 | B27: CJ02-150mm thick (3 Nr) | C27: m³ | D27: 97.539 | E27: 45 | F27: 0.45 | G27: 14 | H27: =+D27*E27+D27*F27*G27 -> 5003.7507
A28: A.03 | B28: CJ03-300mm thick (27 Nr) | C28: m³ | D28: 942.084 | E28: 45 | F28: 0.45 | G28: 14 | H28: =+D28*E28+D28*F28*G28 -> 48328.909
A29: A.04 | B29: CJ04-200mm thick (53 Nr) | C29: m³ | D29: 1765.218 | E29: 45 | F29: 0.45 | G29: 14 | H29: =+D29*E29+D29*F29*G29 -> 90555.683
A30: A.05 | B30: CJ05-250mm thick (1 Nr) | C30: m³ | D30: 34.099 | E30: 45 | F30: 0.45 | G30: 14 | H30: =+D30*E30+D30*F30*G30 -> 1749.2787
A31: A.06 | B31: CJ06-150mm thick (13 Nr) | C31: m³ | D31: 422.669 | E31: 45 | F31: 0.45 | G31: 14 | H31: =+D31*E31+D31*F31*G31 -> 21682.92
A32: A.07 | B32: CJ07-150mm thick (1 Nr) | C32: m³ | D32: 32.513 | E32: 45 | F32: 0.45 | G32: 14 | H32: =+D32*E32+D32*F32*G32 -> 1667.9169
A33: A.08 | B33: CJ08-200mm thick (6 Nr) | C33: m³ | D33: 199.836 | E33: 45 | F33: 0.45 | G33: 14 | H33: =+D33*E33+D33*F33*G33 -> 10251.587
H34: =+D34*E34+D34*F34*G34 -> 0
A35: B | B35: Jacket existing column; size 1250 x 2000 x 3050mm high; to basement 2 -refer S-43316 | H35: =+D35*E35+D35*F35*G35 -> 0
A36: B.01 | B36: CJ01-150mm thick (1 Nr) | C36: m³ | D36: 38.4605 | E36: 45 | F36: 0.45 | G36: 14 | H36: =+D36*E36+D36*F36*G36 -> 1973.0236
A37: B.02 | B37: CJ02-150mm thick (2 Nr) | C37: m³ | D37: 76.921 | E37: 45 | F37: 0.45 | G37: 14 | H37: =+D37*E37+D37*F37*G37 -> 3946.0473
A38: B.03 | B38: CJ03-300mm thick (2 Nr) | C38: m³ | D38: 81.679 | E38: 45 | F38: 0.45 | G38: 14 | H38: =+D38*E38+D38*F38*G38 -> 4190.1327
A39: B.04 | B39: CJ04-200mm thick (1 Nr) | C39: m³ | D39: 39.2535 | E39: 45 | F39: 0.45 | G39: 14 | H39: =+D39*E39+D39*F39*G39 -> 2013.7045
A40: B.05 | B40: CJ05-250mm thick (2 Nr) | C40: m³ | D40: 80.093 | E40: 45 | F40: 0.45 | G40: 14 | H40: =+D40*E40+D40*F40*G40 -> 4108.7709
A41: B.06 | B41: CJ08-200mm thick (2 Nr) | C41: m³ | D41: 78.507 | E41: 45 | F41: 0.45 | G41: 14 | H41: =+D41*E41+D41*F41*G41 -> 4027.4091
A42: B.07 | B42: CJ11-250mm thick (1 Nr) | C42: m³ | D42: 40.0465 | E42: 45 | F42: 0.45 | G42: 14 | H42: =+D42*E42+D42*F42*G42 -> 2054.3854
H43: =+D43*E43+D43*F43*G43 -> 0
A44: C | B44: Jacket existing column; size 1250 x 1500 x 3050mm high; to basement 2 -refer S-43316 | H44: =+D44*E44+D44*F44*G44 -> 0
A45: C.01 | B45: CJ01-150mm thick (1 Nr) | C45: m³ | D45: 34.4955 | E45: 45 | F45: 0.45 | G45: 14 | H45: =+D45*E45+D45*F45*G45 -> 1769.6191
A46: C.02 | B46: CJ02-150mm thick (2 Nr) | C46: m³ | D46: 68.991 | E46: 45 | F46: 0.45 | G46: 14 | H46: =+D46*E46+D46*F46*G46 -> 3539.2383
A47: C.03 | B47: CJ03-300mm thick (2 Nr) | C47: m³ | D47: 73.749 | E47: 45 | F47: 0.45 | G47: 14 | H47: =+D47*E47+D47*F47*G47 -> 3783.3237
D49: To Collection | E49: AED | H49: =SUM(H10:H47) -> 230660.7
A52: A | B52: Jacket existing column; size 500 x 1250 x 3050mm high; to basement 2 -refer S-43316
...

Sheet Add Scaff SS- Horiz
A1: Dutco Construction Company LLC
A2: T061/22 - Al Khail Mall Redevelopment Works
A4: STRUCTURE STRENGTHENING WORKS - VERTICAL AND HORIZONTAL
A6: Item | B6: Description | C6: Unit | D6: Scaffold Qty | E6: Rate | F6: Rate | G6: Duration | H6: Amount
E7: for Installation / Unit | F7: for hire of materials/Day | G7: of Hire (Days) | H7: AED
B8: BILL NO. 2- DEMOLITIONS AND ALTERATIONS
B9: ALTERATIONS
B10: STRUCTURE STRENGTHENING WORKS
B12: RC Beam Thickening/Jacketing
B13: RC thickening work various thickeness -Reinforced concrete; compressive strength 60 MPa with cement type CEM I+GGBS + including steel fixing and dowel bars (BJ+Beam thickening)
B14: Ground floor
A15: A | B15: RC Beams - various sizes at G-01 (Ref. S-43126) | C15: m³ | D15: 199.8 | E15: 45 | F15: 0.45 | G15: 14 | H15: =+D15*E15+D15*F15*G15 -> 10249.74
A16: B | B16: RC Beams - various sizes at G-03 (Ref. S-43126) | C16: m³ | D16: 364.08 | E16: 45 | F16: 0.45 | G16: 14 | H16: =+D16*E16+D16*F16*G16 -> 18677.304
A17: C | B17: RC Beams - various sizes at G-04 (Ref. S-43127) | C17: m³ | D17: 390.72 | E17: 45 | F17: 0.45 | G17: 14 | H17: =+D17*E17+D17*F17*G17 -> 20043.936
A18: D | B18: RC Beams - various sizes at G-05 (Ref. S-43128) | C18: m³ | D18: 164.28 | E18: 45 | F18: 0.45 | G18: 14 | H18: =+D18*E18+D18*F18*G18 -> 8427.564
A19: E | B19: RC Beams - various sizes at G-06 (Ref. S-43129) | C19: m³ | D19: 590.52 | E19: 45 | F19: 0.45 | G19: 14 | H19: =+D19*E19+D19*F19*G19 -> 30293.676
B21: First & Second Floor
A22: F | B22: RC Beams at Zone A (S-43206 & S-43204) | C22: m³ | D22: 743.4 | E22: 45 | F22: 0.45 | G22: 14 | H22: =+D22*E22+D22*F22*G22 -> 38136.42
B24: Beam Jacketing First and Second Floor - Zone 1&3
B25: Drawing Reference: S -12141, S -12143, S -12151, S -12153
A26: G | B26: BJ-01 | C26: m³ | D26: 871.08 | E26: 45 | F26: 0.45 | G26: 14 | H26: =+D26*E26+D26*F26*G26 -> 44686.404
A27: H | B27: BJ-03 | C27: m³ | D27: 109.2 | E27: 45 | F27: 0.45 | G27: 14 | H27: =+D27*E27+D27*F27*G27 -> 5601.96
A28: J | B28: BJ-04 | C28: m³ | D28: 63 | E28: 45 | F28: 0.45 | G28: 14 | H28: =+D28*E28+D28*F28*G28 -> 3231.9
A29: K | B29: BJ-05 | C29: m³ | D29: 67.2 | E29: 45 | F29: 0.45 | G29: 14 | H29: =+D29*E29+D29*F29*G29 -> 3447.36
A30: L | B30: BJ-06 | C30: m³ | D30: 33.6 | E30: 45 | F30: 0.45 | G30: 14 | H30: =+D30*E30+D30*F30*G30 -> 1723.68
D48: Carried To Summary | H48: =SUM(H8:H46) -> 184519.94

Sheet Add Scaffolding-Summary
A1: Dutco Construction Company LLC
A2: T061/22 - Al Khail Mall Redevelopment Works
A4: STRUCTURE STRENGTHENING WORKS - VERTICAL AND HORIZONTAL SUMMARY
A6: Item | B6: Description | C6: Page Ref. | D6: Amount
D7: AED
B9: SUMMARY
B13: SCAFFOLDING TO COLUMNS / WALLS (JACKETING) | D13: =+'Add Scaff SS-Vertical'!H367 -> 706537.53
B15: SCAFFOLDING TO RC BEAM / THICKENING (JACKETING) | D15: =+'Add Scaff SS- Horiz'!H48 -> 184519.94
B17: ADJUSTMENT TO SCAFFOLDING - AGREED W/ OMNIUM | D17: -124748.05
B45: Carried To Main Summary | D45: =SUM(D8:D43) -> 766309.43

Sheet Omit Scaff SS
A1: Dutco Construction Company LLC
A2: T061/22 - Al Khail Mall Redevelopment Works
A4: STRUCTURE STRENGTHENING WORKS - VERTICAL AND HORIZONTAL
A6: Item | B6: Description | C6: Unit | D6: Scaffold Qty | E6: Rate | F6: Rate | G6: Duration | H6: Amount
E7: for Installation / Unit | F7: for hire of materials/Day | G7: of Hire (Days) | H7: AED
B8: BILL NO. 2- DEMOLITIONS AND ALTERATIONS
B9: ALTERATIONS
B10: STRUCTURE STRENGTHENING WORKS
B13: Jacket existing column & RC Wall Buttress Structures
A15: A | B15: To various sizes at different locations | C15: m2 | D15: 1632.1135 | E15: 45 | F15: 0.45 | G15: 14 | H15: =+D15*E15+D15*F15*G15 -> 83727.423
D49: Carried To Summary | H49: =SUM(H8:H47) -> 83727.423 | K49: 83727.42
K50: =+H49-K49 -> 0.00255

Sheet Bill 13 Scaffolding
A1: Item | B1: Description | C1: Quantity | D1: Unit | E1: Rate | F1: Amount
E2: AED | F2: AED
B3: ACCESS SCAFFOLDING
B5: Scaffolding to Additional Jacketed Columns
A7: A | B7: Access Scaffolding for add'l Strengthening Works | C7: 1 | D7: item | E7: =+'Add Scaffolding-Summary'!D45 -> 766309.43 | F7: =+C7*E7 -> 766309.43
A9: B | B9: Less Scaffolding associated w/ Strenghtening Works priced previously | C9: -1 | D9: item | E9: =+'Omit Scaff SS'!H49 -> 83727.423 | F9: =+C9*E9 -> -83727.423
B11: The above amounts are based on the below schedule of rates
A13: C | B13: Erection / Dismantling of scaffold | C13: 1 | D13: m³ | E13: 45 | F13: RATE ONLY
A15: D | B15: Rate for hire of scaffold materials | C15: 1 | D15: m³-day | E15: 14 | F15: RATE ONLY
C41: Carried To Summary | E41: AED | F41: =SUM(F7:F39) -> 682582.01

Sheet Bill 13-Sum
A1: Item | B1: Description | C1: Page Nr. | D1: Amount AED
B5: SUMMARY
B8: REVISED STRENGTHENING WORKS | C8: 13/1/1 - 13/1/16 | D8: =+'Bill 13 Revised Strength.'!F650 -> 27724988
B10: ADDITIONAL STRENGTHENING WORKS (NOT DETAILED ON DRAWINGS) | C10: 13/2/1 | D10: =+'Bill 13 Add''l'!F33 -> 3222177.2
B12: ASSOCIATED FINISHES | C12: 13/3/1 | D12: =+'Bill 13 Finishes'!F43 -> 1379699.9
B14: ACCESS SCAFFOLDING TO STRENGTHENING WORKS | C14: 13/4/1 | D14: =+'Bill 13 Scaffolding'!F41 -> 682582.01
B47: TOTAL FOR BILL NO. 13 - STRENGHTENING WORKS GMP
B48: TO MAIN SUMMARY | C48: AED | D48: =SUM(D6:D39) -> 33009448
